Workbook

Sheet Basic Infrastructure
A1: # | B1: Item of Work | C1: Unit | D1: Qty. | E1: Rate | F1: Amount
A3: A. Site Development
A4: A1 | B4: Fencing : Chain Linked fencing 2.6 in total, 0.6 m below ground with metal stakes of 2. mt, 2 feet underground and 2 m above ground | C4: RMT | D4: 14000 | E4: 13.22 | F4: =E4*D4 -> 185080
A5: A2 | B5: All weather boundary road for full property 8 m wide mcadamised with soil and stones wet and compressed with road roller | C5: LS | D5: LS | E5: LS | F5: 500000
A6: A3 | B6: Arterial road full length with one crossing at 1000 m from South east corner of property. Macadammised all weather road with one divider 1 m wide and coaltar topping with kerbs and infrastructure corridor for telecommunication electricity and water lines. | K6: =165*165 -> 27225 | L6: =195*210 -> 40950 | M6: =K6/L6 -> 0.66483516
A7: A4 | B7: All weather internal roads for full property 8 m wide mcadamised with soil and stones wet and compressed with road roller running from South to north at a distance of 200 m with storm water drainage, irrigation lines and two cross roads at 500 m distance each
A8: A5 | B8: Guard posts all along the bounday at 1000 m distance | C8: No. | D8: 15 | E8: =500000/88 -> 5681.8182 | F8: =E8*D8 -> 85227.273
A9: A6 | B9: Entry gate and guard room | C9: No. | D9: 1 | E9: =2000000/88 -> 22727.273 | F9: =E9*D9 -> 22727.273
A10: Sub-Total | F10: =SUM(F4:F9) -> 793034.55
I11: GM | J11: 1 | K11: 2000 | L11: =K11*J11 -> 2000
A12: B. Land Preparation | I12: Sales | J12: 1 | K12: 1500 | L12: =K12*J12 -> 1500
A13: # | B13: Item of Work | C13: Unit | D13: Qty. | E13: Rate | F13: Amount | I13: Crop Mgr | J13: 3 | K13: 1000 | L13: =K13*J13 -> 3000
A14: B1 | B14: Land clearing - clearing of bushes, removal of root mass and making suitable for operation by a tractor | C14: Ha | D14: 300 | E14: =6250/88 -> 71.022727 | F14: =D14*E14 -> 21306.818 | I14: Field supervisors | J14: 3 | K14: 1000 | L14: =K14*J14 -> 3000
A15: B2 | B15: MB Ploughing of arable land to a depth of 30 cm | C15: Ha | D15: 300 | E15: =6250/88 -> 71.022727 | F15: =D15*E15 -> 21306.818 | N15: =100*10000 -> 1000000
A16: B3 | B16: Disc/ Cultivator ploughing - cross - to breal soil lumps (if any) | C16: Ha | D16: =D15 -> 300 | E16: =5000/88 -> 56.818182 | F16: =D16*E16 -> 17045.455 | I16: other permanent labour inc drivers | L16: =K16*J16 -> 0
A17: B4 | B17: Manure application: manure cost, transportation, spreading in the field | C17: Ha | D17: =D16 -> 300 | E17: =75000/88 -> 852.27273 | F17: =D17*E17 -> 255681.82 | I17: FnA | J17: 3 | K17: 600 | L17: =K17*J17 -> 1800
A18: B5 | B18: Planing and rotavator application for mixing of manure in the top soil | C18: Ha | D18: =D17 -> 300 | E18: =E15 -> 71.022727 | F18: =D18*E18 -> 21306.818 | I18: Workshop | J18: 2 | K18: 600 | L18: =K18*J18 -> 1200
A19: B6 | B19: Water tank for Drip Irrigation | C19: CUM | D19: =15*15*3 -> 675 | E19: =12000/88 -> 136.36364 | F19: =E19*D19 -> 92045.455 | I19: Warehouse | J19: 2 | K19: 600 | L19: =K19*J19 -> 1200
I20: Deshelling | J20: 4 | K20: 600 | L20: =K20*J20 -> 2400
A21: Total Carried Over to Summary | F21: =SUM(F14:F19) -> 428693.18 | I21: Canteen | J21: 1 | K21: 3000 | L21: =K21*J21 -> 3000
L22: =SUM(L11:L21) -> 19100
A23: C. Buildings
A24: # | B24: Item of Work | C24: Unit | D24: Qty. | E24: Rate | F24: Amount
A25: C1 | B25: Administration building, including Medical room, creche, offices, conference room, officers canteen | C25: SQM | D25: 350 | E25: 250 | F25: =D25*E25 -> 87500
A26: C2 | B26: Tube well cabins with generator pump room and residence for operator approximately 30 SQMT each | C26: No.s | D26: 35 | E26: =(12000/88)*30 -> 4090.9091 | F26: =D26*E26 -> 143181.82
A27: C3 | B27: Warehouse inclusive of area for deshelling | C27: SQM | D27: 2400 | E27: =10000/88 -> 113.63636 | F27: =D27*E27 -> 272727.27
A28: C4 | B28: Residential buldings as per details | C28: SQM | D28: 1000 | E28: 250 | F28: =D28*E28 -> 250000
A29: C5 | B29: Collection centers in field | C29: SQM | D29: 1500 | E29: =900/88 -> 10.227273 | F29: =D29*E29 -> 15340.909
A30: C6 | B30: Utilities - Electrical Room, water tank diesel storage etc | C30: LS | D30: 1 | E30: =1000000/88 -> 11363.636 | F30: =D30*E30 -> 11363.636
A31: Total Carried Over to Summary | F31: =SUM(F25:F30) -> 780113.64
B35: Total Basic Infrastructure | F35: =F31+F10+F21 -> 2001841.4 | G35: =F35/300 -> 6672.8045

Sheet Core Equipment 
A1: S.No. | B1: Equipments | C1: Capacity | D1: Quantity | E1: Unit | F1: Unit Price in Euros | G1: Total Price in Euros
A2: 1 | B2: Tractors Large | C2: 75-90 HP | D2: 10 | E2: No. | F2: =1500000/88 -> 17045.455 | G2: =F2*D2 -> 170454.55
A3: 2 | B3: Tractors small | C3: 40-45 HP | D3: 5 | E3: lot | F3: =800000/88 -> 9090.9091 | G3: =F3*D3 -> 45454.545
A4: 3 | B4: Tube wells inclusiveof Boring and Pumps | C4: 30 cubic m / hour depth 60 m | D4: 60 | E4: =E2 -> No. | F4: =1200000/88 -> 13636.364 | G4: =F4*D4 -> 818181.82
A5: 4 | B5: Generators (diesel) | C5: 25 KVA | D5: 30 | E5: No. | F5: =300000/88 -> 3409.0909 | G5: =F5*D5 -> 102272.73
A6: 5 | B6: Solar Panels with invertor and battery | C6: 25 KVA | D6: 30 | E6: No. | F6: =800000/88 -> 9090.9091 | G6: =F6*D6 -> 272727.27
A7: 4 | B7: Ripper/ MB plough | C7: suitable for large tractor | D7: =D2 -> 10 | E7: No. | F7: =30000/88 -> 340.90909 | G7: =F7*D7 -> 3409.0909
A8: 5 | B8: Cultivator | C8: suitable for large tractor | D8: 10 | E8: =E4 -> No. | F8: =F7 -> 340.90909 | G8: =F8*D8 -> 3409.0909
A9: 6 | B9: Disc Plough | C9: suitable for large tractor | D9: 10 | E9: =E8 -> No. | F9: =F8 -> 340.90909 | G9: =F9*D9 -> 3409.0909
A10: 7 | B10: Rotavator | C10: suitable for large tractor | D10: 5 | E10: =E9 -> No. | F10: =130000/88 -> 1477.2727 | G10: =F10*D10 -> 7386.3636
A11: 8 | B11: Seed Coating machine (for seed treatment) | C11: 500 Kg | D11: 3 | E11: No | F11: =300000/88 -> 3409.0909 | G11: =F11*D11 -> 10227.273
A12: 9 | B12: Seed Drill with fertiliser applicator and/ or bund maker | C12: suitable for large tractor | D12: 10 | E12: =E10 -> No. | F12: =120000/88 -> 1363.6364 | G12: =F12*D12 -> 13636.364
A13: 10 | B13: Harvesters | C13: suitable for large tractor | D13: 10 | E13: =E12 -> No. | F13: =200000/88 -> 2272.7273 | G13: =D13*F13 -> 22727.273
A14: 11 | B14: Multipurpose trolley | C14: 100 cum | D14: 5 | E14: =E12 -> No. | F14: =250000/88 -> 2840.9091 | G14: =F14*D14 -> 14204.545
A15: 12 | B15: Diesel Tank - to be attached to tractor | C15: 5 KL | D15: 2 | E15: =E14 -> No. | F15: =300000/88 -> 3409.0909 | G15: =D15*F15 -> 6818.1818
A16: 13 | B16: Diesel Storage | C16: 10 KL | D16: 1 | E16: =E15 -> No. | F16: =500000/88 -> 5681.8182 | G16: =D16*F16 -> 5681.8182
A17: 14 | B17: Weigh Bridge | C17: 60 MT | D17: 1 | E17: =E16 -> No. | F17: =1200000/88 -> 13636.364 | G17: =D17*F17 -> 13636.364
A18: 15 | B18: Electric Generator/ transformer/ internal lines | C18: 60 KVA | D18: 2 | E18: =E17 -> No. | F18: =3200000/88 -> 36363.636 | G18: =D18*F18 -> 72727.273
A19: 16 | B19: underground Irrigation pipes including valves | C19: 300 mm main, 150 mm lateral | D19: 300 | E19: Ha | F19: =37500/88 -> 426.13636 | G19: =D19*F19 -> 127840.91
A20: 17 | B20: Sprinklers - Manual movement with one irrigation | C20: suitable | D20: 4000 | E20: No. | F20: =500/88 -> 5.6818182 | G20: =D20*F20 -> 22727.273
A21: 18 | B21: Pickup vehicles | D21: 4 | E21: No. | F21: =1000000/88 -> 11363.636 | G21: =D21*F21 -> 45454.545
A22: 19 | B22: MUV | C22: suitable | D22: 8 | E22: no. | F22: =1600000/88 -> 18181.818 | G22: =D22*F22 -> 145454.55
A23: 20 | B23: Sprayers (Kubota) | C23: suitable | D23: 3 | E23: no. | F23: =2400000/88 -> 27272.727 | G23: =D23*F23 -> 81818.182
A24: 21 | B24: Drip for Vegetables | C24: Distance 1.0 m | D24: 190 | E24: Ha | F24: =80000*2.5/88 -> 2272.7273 | G24: =D24*F24 -> 431818.18
A25: 22 | B25: Potato Planter | C25: Planter with fertiliser application | D25: 5 | E25: No. | F25: =180000/88 -> 2045.4545 | G25: =D25*F25 -> 10227.273
A26: 23 | B26: Groundnut desheller | C26: Deshelling machine | D26: 2 | E26: No. | F26: =2000000/88 -> 22727.273 | G26: =D26*F26 -> 45454.545
A27: 24 | B27: Potato Harvester | C27: Harvester with mud shaker | D27: 5 | E27: No | F27: =200000/88 -> 2272.7273 | G27: =D27*F27 -> 11363.636
A28: 25 | B28: Vegetable Pack house | C28: Vegetable pack house for round/ long vegetables 10 MT/ Hr | D28: 1 | E28: LS | F28: =12000000/88 -> 136363.64 | G28: =D28*F28 -> 136363.64
A29: 26 | B29: Combine Harvesters | D29: 2 | E29: LS | F29: =4000000/88 -> 45454.545 | G29: =F29*D29 -> 90909.091
A30: 27 | B30: Brick making machine | C30: 2000-3000 bricks per hour | D30: 1 | E30: LS | F30: =2400000/88 -> 27272.727 | G30: =F30*D30 -> 27272.727
A31: 28 | B31: Crates | D31: 5000 | E31: LS | F31: =400/88 -> 4.5454545 | G31: =F31*D31 -> 22727.273
A32: 29 | B32: Packing lines | D32: 4 | E32: LS | F32: =2500000/88 -> 28409.091 | G32: =F32*D32 -> 113636.36
A33: 30 | B33: Potato Chips Line | D33: 1 | E33: LS | F33: =350000 -> 350000 | G33: =F33*D33 -> 350000
A34: 31 | B34: Cold Storage | C34: 3000 MT | D34: 1 | E34: LS | F34: =(14000*3000)/88 -> 477272.73 | G34: =F34*D34 -> 477272.73
A35: 32 | B35: Workshop equipment and spares | C35: 5% of equipment cost | D35: 1 | E35: LS | F35: =(SUM(G2:G34))*0.05 -> 186335.23 | G35: =D35*F35 -> 186335.23
B36: Total Price (Rs. In Euros) | G36: =SUM(G2:G35) -> 3913039.8

Sheet Other Equipment
A1: S No | B1: Function Area | C1: Equipment Description | D1: Nos | E1: Unit Rate Rs | F1: Est Price Rs
F2: Base Price | G2: Excise | H2: VAT | I2: Total
A3: 1 | C3: Computer, printer and table | D3: 15 | E3: =50000/88 -> 568.18182 | F3: =D3*E3 -> 8522.7273 | I3: =H3+++G3+F3 -> 8522.7273
A4: 2 | C4: Almirah | D4: =D3 -> 15 | E4: =7000/88 -> 79.545455 | F4: =IF(D4=0,E4,E4*D4) -> 1193.1818 | I4: =H4+++G4+F4 -> 1193.1818
C5: Office Chairs | D5: =D4*3 -> 45 | E5: =4500/88 -> 51.136364 | F5: =IF(D5=0,E5,E5*D5) -> 2301.1364 | I5: =H5+++G5+F5 -> 2301.1364
C6: Office tables | D6: =D4 -> 15 | E6: =6000/88 -> 68.181818 | F6: =IF(D6=0,E6,E6*D6) -> 1022.7273 | I6: =H6+++G6+F6 -> 1022.7273
C7: Computer tables | D7: =D6 -> 15 | E7: =6000/88 -> 68.181818 | F7: =IF(D7=0,E7,E7*D7) -> 1022.7273 | I7: =H7+++G7+F7 -> 1022.7273
C8: Computer chairs | D8: =D7 -> 15 | E8: =4000/88 -> 45.454545 | F8: =IF(D8=0,E8,E8*D8) -> 681.81818 | I8: =H8+++G8+F8 -> 681.81818
A9: 3 | C9: Fire Extinguishers | D9: =D8 -> 15 | E9: =3000/88 -> 34.090909 | F9: =IF(D9=0,E9,E9*D9) -> 511.36364 | I9: =H9+++G9+F9 -> 511.36364
A10: Sub Total | F10: =SUBTOTAL(9,F3:F9) -> 15255.682 | G10: =SUBTOTAL(9,G3:G9) -> 0 | H10: =SUBTOTAL(9,H3:H9) -> 0 | I10: =H10+++G10+F10 -> 15255.682

Sheet Growing cost  assum
C1: Year 1 | D1: Year 2 | E1: Year 3 | F1: Year 4 | G1: Year 5 | H1: Year 6 | I1: Year 7 | J1: Year 8 | K1: Year 9 | L1: Year 10
A4: Groundnut
A5: Description | B5: Cost/ Ha | C5: 80 | D5: =C5 -> 80 | E5: =D5 -> 80 | F5: =E5 -> 80 | G5: =F5 -> 80 | H5: =G5 -> 80 | I5: =H5 -> 80 | J5: =I5 -> 80 | K5: =J5 -> 80 | L5: =K5 -> 80
A6: Land preparation | B6: 19.56 | C6: =$B6*C$5 -> 1564.8 | D6: =$B6*D$5 -> 1564.8 | E6: =$B6*E$5 -> 1564.8 | F6: =$B6*F$5 -> 1564.8 | G6: =$B6*G$5 -> 1564.8 | H6: =$B6*H$5 -> 1564.8 | I6: =$B6*I$5 -> 1564.8 | J6: =$B6*J$5 -> 1564.8 | ... L6: =$B6*L$5 -> 1564.8 | N6: =64000/2.5 -> 25600 | P6: Litre
A7: Seed Cost | B7: =100*120/88 -> 136.36364 | C7: =$B7*C$5 -> 10909.091 | D7: =$B7*D$5 -> 10909.091 | E7: =$B7*E$5 -> 10909.091 | F7: =$B7*F$5 -> 10909.091 | G7: =$B7*G$5 -> 10909.091 | H7: =$B7*H$5 -> 10909.091 | I7: =$B7*I$5 -> 10909.091 | J7: =$B7*J$5 -> 10909.091 | ... L7: =$B7*L$5 -> 10909.091 | O7: Diesel consumption per hour | P7: 10
A8: Seed treatment cost | B8: =1350*1.5*2.5/88 -> 57.528409 | C8: =$B8*C$5 -> 4602.2727 | D8: =$B8*D$5 -> 4602.2727 | E8: =$B8*E$5 -> 4602.2727 | F8: =$B8*F$5 -> 4602.2727 | G8: =$B8*G$5 -> 4602.2727 | H8: =$B8*H$5 -> 4602.2727 | I8: =$B8*I$5 -> 4602.2727 | J8: =$B8*J$5 -> 4602.2727 | ... L8: =$B8*L$5 -> 4602.2727 | O8: Diesel price | P8: =75/88 -> 0.85227273
A9: Sowing cost | B9: =B6 -> 19.56 | C9: =$B9*C$5 -> 1564.8 | D9: =$B9*D$5 -> 1564.8 | E9: =$B9*E$5 -> 1564.8 | F9: =$B9*F$5 -> 1564.8 | G9: =$B9*G$5 -> 1564.8 | H9: =$B9*H$5 -> 1564.8 | I9: =$B9*I$5 -> 1564.8 | J9: =$B9*J$5 -> 1564.8 | ... L9: =$B9*L$5 -> 1564.8 | O9: Diese; cost /hour | P9: =P8*P7 -> 8.5227273
A10: Fertiliser (basal application)* urea in two doses | B10: =Q17 -> 36.409091 | C10: =$B10*C$5 -> 2912.7273 | D10: =$B10*D$5 -> 2912.7273 | E10: =$B10*E$5 -> 2912.7273 | F10: =$B10*F$5 -> 2912.7273 | G10: =$B10*G$5 -> 2912.7273 | H10: =$B10*H$5 -> 2912.7273 | I10: =$B10*I$5 -> 2912.7273 | J10: =$B10*J$5 -> 2912.7273 | ... L10: =$B10*L$5 -> 2912.7273 | O10: Diesel cost / Ha/ hour | P10: =P9*25/33 -> 6.4566116
A11: Pre emergent Herbicide spray | B11: =500*1.5*2.5/88 -> 21.306818 | C11: =$B11*C$5 -> 1704.5455 | D11: =$B11*D$5 -> 1704.5455 | E11: =$B11*E$5 -> 1704.5455 | F11: =$B11*F$5 -> 1704.5455 | G11: =$B11*G$5 -> 1704.5455 | H11: =$B11*H$5 -> 1704.5455 | I11: =$B11*I$5 -> 1704.5455 | J11: =$B11*J$5 -> 1704.5455 | ... L11: =$B11*L$5 -> 1704.5455 | O11: No. of irrigations / season | P11: 5
A12: Fungicide and Insecticide spray | B12: =(2500*1.5*2.5)/88 -> 106.53409 | C12: =$B12*C$5 -> 8522.7273 | D12: =$B12*D$5 -> 8522.7273 | E12: =$B12*E$5 -> 8522.7273 | F12: =$B12*F$5 -> 8522.7273 | G12: =$B12*G$5 -> 8522.7273 | H12: =$B12*H$5 -> 8522.7273 | I12: =$B12*I$5 -> 8522.7273 | J12: =$B12*J$5 -> 8522.7273 | ... L12: =$B12*L$5 -> 8522.7273 | O12: Total diesel cost per season per Ha | P12: =P11*P10*2 -> 64.566116
A13: Diesel for irrigation | B13: =P12 -> 64.566116 | C13: =B13*C5 -> 5165.2893 | D13: =C13 -> 5165.2893 | E13: =D13 -> 5165.2893 | F13: =E13 -> 5165.2893 | G13: =F13 -> 5165.2893 | H13: =G13 -> 5165.2893 | I13: =H13 -> 5165.2893 | J13: =I13 -> 5165.2893 | K13: =J13 -> 5165.2893 | L13: =K13 -> 5165.2893
A14: Harvesting (incl labour) | B14: =1500*2.5/88 -> 42.613636 | C14: =$B14*C$5 -> 3409.0909 | D14: =$B14*D$5 -> 3409.0909 | E14: =$B14*E$5 -> 3409.0909 | F14: =$B14*F$5 -> 3409.0909 | G14: =$B14*G$5 -> 3409.0909 | H14: =$B14*H$5 -> 3409.0909 | I14: =$B14*I$5 -> 3409.0909 | J14: =$B14*J$5 -> 3409.0909 | ... L14: =$B14*L$5 -> 3409.0909 | N14: Fertiliser basal/ Ha | O14: QTY | P14: Price | Q14: Val/ Ha
A15: Total Cost | B15: =SUM(B6:B14) -> 504.4418 | C15: =SUM(C5:C14) -> 40435.344 | D15: =SUM(D5:D14) -> 40435.344 | E15: =SUM(E5:E14) -> 40435.344 | F15: =SUM(F5:F14) -> 40435.344 | G15: =SUM(G5:G14) -> 40435.344 | H15: =SUM(H5:H14) -> 40435.344 | I15: =SUM(I5:I14) -> 40435.344 | J15: =SUM(J5:J14) -> 40435.344 | ... L15: =SUM(L5:L14) -> 40435.344 | N15: DAP | O15: 100 | P15: =1200/50/88 -> 0.27272727 | Q15: =P15*O15 -> 27.272727
A16: Yield | C16: =700*1.5*2.5 -> 2625 | D16: =750*1.5*2.5 -> 2812.5 | E16: =775*1.5*2.5 -> 2906.25 | F16: =850*1.5*2.5 -> 3187.5 | G16: =1000*1.5*2.5 -> 3750 | H16: =G16 -> 3750 | I16: =H16 -> 3750 | J16: =I16 -> 3750 | K16: =J16 -> 3750 | L16: =K16 -> 3750 | N16: Urea in two doses | O16: =40*1.5*2.5 -> 150 | P16: =268/50/88 -> 0.060909091 | Q16: =P16*O16 -> 9.1363636
A17: Price / Kg | C17: 0.24 | D17: =C17 -> 0.24 | E17: =D17 -> 0.24 | F17: =E17 -> 0.24 | G17: =F17 -> 0.24 | H17: =G17 -> 0.24 | I17: =H17 -> 0.24 | J17: =I17 -> 0.24 | K17: =J17 -> 0.24 | L17: =K17 -> 0.24 | Q17: =SUM(Q15:Q16) -> 36.409091
A18: Realisation | C18: =C17*C16*C5 -> 50400 | D18: =D17*D16*D5 -> 54000 | E18: =E17*E16*E5 -> 55800 | F18: =F17*F16*F5 -> 61200 | G18: =G17*G16*G5 -> 72000 | H18: =H17*H16*H5 -> 72000 | I18: =I17*I16*I5 -> 72000 | J18: =J17*J16*J5 -> 72000 | ... L18: =L17*L16*L5 -> 72000
A20: Operating margin | C20: =C18-C15 -> 9964.6562 | D20: =D18-D15 -> 13564.656 | E20: =E18-E15 -> 15364.656 | F20: =F18-F15 -> 20764.656 | G20: =G18-G15 -> 31564.656 | H20: =H18-H15 -> 31564.656 | I20: =I18-I15 -> 31564.656 | J20: =J18-J15 -> 31564.656 | ... L20: =L18-L15 -> 31564.656
A22: Cowpea
A23: Description | C23: 40 | D23: =C23 -> 40 | E23: =D23 -> 40 | F23: =E23 -> 40 | G23: =F23 -> 40 | H23: =G23 -> 40 | I23: =H23 -> 40 | J23: =I23 -> 40 | K23: =J23 -> 40 | L23: =K23 -> 40
A24: Land preparation | B24: =B42 -> 19.56 | C24: =C$23*$B24 -> 782.4 | D24: =D$23*$B24 -> 782.4 | E24: =E$23*$B24 -> 782.4 | F24: =F$23*$B24 -> 782.4 | G24: =G$23*$B24 -> 782.4 | H24: =H$23*$B24 -> 782.4 | I24: =I$23*$B24 -> 782.4 | J24: =J$23*$B24 -> 782.4 | ... L24: =L$23*$B24 -> 782.4
A25: Seed Cost | B25: =30*100/88 -> 34.090909 | C25: =C$23*$B25 -> 1363.6364 | D25: =D$23*$B25 -> 1363.6364 | E25: =E$23*$B25 -> 1363.6364 | F25: =F$23*$B25 -> 1363.6364 | G25: =G$23*$B25 -> 1363.6364 | H25: =H$23*$B25 -> 1363.6364 | I25: =I$23*$B25 -> 1363.6364 | J25: =J$23*$B25 -> 1363.6364 | ... L25: =L$23*$B25 -> 1363.6364
A26: Seed treatment cost | B26: =35 -> 35 | C26: =C$23*$B26 -> 1400 | D26: =D$23*$B26 -> 1400 | E26: =E$23*$B26 -> 1400 | F26: =F$23*$B26 -> 1400 | G26: =G$23*$B26 -> 1400 | H26: =H$23*$B26 -> 1400 | I26: =I$23*$B26 -> 1400 | J26: =J$23*$B26 -> 1400 | ... L26: =L$23*$B26 -> 1400
A27: Sowing cost | B27: =B45 -> 56.818182 | C27: =C$23*$B27 -> 2272.7273 | D27: =D$23*$B27 -> 2272.7273 | E27: =E$23*$B27 -> 2272.7273 | F27: =F$23*$B27 -> 2272.7273 | G27: =G$23*$B27 -> 2272.7273 | H27: =H$23*$B27 -> 2272.7273 | I27: =I$23*$B27 -> 2272.7273 | J27: =J$23*$B27 -> 2272.7273 | ... L27: =L$23*$B27 -> 2272.7273
A28: Fertiliser (basal application)* urea in two doses | B28: =B10 -> 36.409091 | C28: =C$23*$B28 -> 1456.3636 | D28: =D$23*$B28 -> 1456.3636 | E28: =E$23*$B28 -> 1456.3636 | F28: =F$23*$B28 -> 1456.3636 | G28: =G$23*$B28 -> 1456.3636 | H28: =H$23*$B28 -> 1456.3636 | I28: =I$23*$B28 -> 1456.3636 | J28: =J$23*$B28 -> 1456.3636 | ... L28: =L$23*$B28 -> 1456.3636
A29: Post emergent Herbicide spray | B29: =10000/88 -> 113.63636 | C29: =C$23*$B29 -> 4545.4545 | D29: =D$23*$B29 -> 4545.4545 | E29: =E$23*$B29 -> 4545.4545 | F29: =F$23*$B29 -> 4545.4545 | G29: =G$23*$B29 -> 4545.4545 | H29: =H$23*$B29 -> 4545.4545 | I29: =I$23*$B29 -> 4545.4545 | J29: =J$23*$B29 -> 4545.4545 | ... L29: =L$23*$B29 -> 4545.4545
A30: Fungicide and Insecticide spray | B30: =34 -> 34 | C30: =C$23*$B30 -> 1360 | D30: =D$23*$B30 -> 1360 | E30: =E$23*$B30 -> 1360 | F30: =F$23*$B30 -> 1360 | G30: =G$23*$B30 -> 1360 | H30: =H$23*$B30 -> 1360 | I30: =I$23*$B30 -> 1360 | J30: =J$23*$B30 -> 1360 | ... L30: =L$23*$B30 -> 1360
A31: =A13 -> Diesel for irrigation | B31: =B13/2 -> 32.283058 | C31: =C$23*$B31 -> 1291.3223 | D31: =D$23*$B31 -> 1291.3223 | E31: =E$23*$B31 -> 1291.3223 | F31: =F$23*$B31 -> 1291.3223 | G31: =G$23*$B31 -> 1291.3223 | H31: =H$23*$B31 -> 1291.3223 | I31: =I$23*$B31 -> 1291.3223 | J31: =J$23*$B31 -> 1291.3223 | ... L31: =L$23*$B31 -> 1291.3223
A32: Harvesting (incl labour) | B32: =137 -> 137 | C32: =C$23*$B32 -> 5480 | D32: =D$23*$B32 -> 5480 | E32: =E$23*$B32 -> 5480 | F32: =F$23*$B32 -> 5480 | G32: =G$23*$B32 -> 5480 | H32: =H$23*$B32 -> 5480 | I32: =I$23*$B32 -> 5480 | J32: =J$23*$B32 -> 5480 | ... L32: =L$23*$B32 -> 5480
A33: Total Cost | B33: =SUM(B24:B32) -> 498.7976 | C33: =SUM(C24:C32) -> 19951.904 | D33: =SUM(D24:D32) -> 19951.904 | E33: =SUM(E24:E32) -> 19951.904 | F33: =SUM(F24:F32) -> 19951.904 | G33: =SUM(G24:G32) -> 19951.904 | H33: =SUM(H24:H32) -> 19951.904 | I33: =SUM(I24:I32) -> 19951.904 | ... L33: =SUM(L24:L32) -> 19951.904
A34: Yield | C34: 900 | D34: 1000 | E34: =1100 -> 1100 | F34: =E34 -> 1100 | G34: =F34 -> 1100 | H34: =G34 -> 1100 | I34: =H34 -> 1100 | J34: =I34 -> 1100 | K34: =J34 -> 1100 | L34: =K34 -> 1100
A35: Price / Kg | C35: 1.3 | D35: =C35 -> 1.3 | E35: =D35 -> 1.3 | F35: =E35 -> 1.3 | G35: =F35 -> 1.3 | H35: =G35 -> 1.3 | I35: =H35 -> 1.3 | J35: =I35 -> 1.3 | K35: =J35 -> 1.3 | L35: =K35 -> 1.3
A36: Realisation | C36: =C35*C34*C23 -> 46800 | D36: =D35*D34*D23 -> 52000 | E36: =E35*E34*E23 -> 57200 | F36: =F35*F34*F23 -> 57200 | G36: =G35*G34*G23 -> 57200 | H36: =H35*H34*H23 -> 57200 | I36: =I35*I34*I23 -> 57200 | J36: =J35*J34*J23 -> 57200 | ... L36: =L35*L34*L23 -> 57200
A38: Operating margin | C38: =C36-C33 -> 26848.096 | D38: =D36-D33 -> 32048.096 | E38: =E36-E33 -> 37248.096 | F38: =F36-F33 -> 37248.096 | G38: =G36-G33 -> 37248.096 | H38: =H36-H33 -> 37248.096 | I38: =I36-I33 -> 37248.096 | J38: =J36-J33 -> 37248.096 | ... L38: =L36-L33 -> 37248.096
A40: Wheat
A41: Description | B41: Cost / Ha | C41: 80 | D41: =C41 -> 80 | E41: =D41 -> 80 | F41: =E41 -> 80 | G41: =F41 -> 80 | H41: =G41 -> 80 | I41: =H41 -> 80 | J41: =I41 -> 80 | K41: =J41 -> 80 | L41: =K41 -> 80
A42: Land preparation | B42: =B60 -> 19.56 | C42: =$B42*C$41 -> 1564.8 | D42: =$B42*D$41 -> 1564.8 | E42: =$B42*E$41 -> 1564.8 | F42: =$B42*F$41 -> 1564.8 | G42: =$B42*G$41 -> 1564.8 | H42: =$B42*H$41 -> 1564.8 | I42: =$B42*I$41 -> 1564.8 | J42: =$B42*J$41 -> 1564.8 | ... L42: =$B42*L$41 -> 1564.8
A43: Seed Cost | B43: =100*75/88 -> 85.227273 | C43: =$B43*C$41 -> 6818.1818 | D43: =$B43*D$41 -> 6818.1818 | E43: =$B43*E$41 -> 6818.1818 | F43: =$B43*F$41 -> 6818.1818 | G43: =$B43*G$41 -> 6818.1818 | H43: =$B43*H$41 -> 6818.1818 | I43: =$B43*I$41 -> 6818.1818 | J43: =$B43*J$41 -> 6818.1818 | ... L43: =$B43*L$41 -> 6818.1818
A44: Seed treatment cost | C44: =$B44*C$41 -> 0 | D44: =$B44*D$41 -> 0 | E44: =$B44*E$41 -> 0 | F44: =$B44*F$41 -> 0 | G44: =$B44*G$41 -> 0 | H44: =$B44*H$41 -> 0 | I44: =$B44*I$41 -> 0 | J44: =$B44*J$41 -> 0 | ... L44: =$B44*L$41 -> 0
A45: Sowing cost | B45: =5000/88 -> 56.818182 | C45: =$B45*C$41 -> 4545.4545 | D45: =$B45*D$41 -> 4545.4545 | E45: =$B45*E$41 -> 4545.4545 | F45: =$B45*F$41 -> 4545.4545 | G45: =$B45*G$41 -> 4545.4545 | H45: =$B45*H$41 -> 4545.4545 | I45: =$B45*I$41 -> 4545.4545 | J45: =$B45*J$41 -> 4545.4545 | ... L45: =$B45*L$41 -> 4545.4545
A46: Fertiliser (basal application)* urea in two doses | B46: =10000/88 -> 113.63636 | C46: =$B46*C$41 -> 9090.9091 | D46: =$B46*D$41 -> 9090.9091 | E46: =$B46*E$41 -> 9090.9091 | F46: =$B46*F$41 -> 9090.9091 | G46: =$B46*G$41 -> 9090.9091 | H46: =$B46*H$41 -> 9090.9091 | I46: =$B46*I$41 -> 9090.9091 | J46: =$B46*J$41 -> 9090.9091 | ... L46: =$B46*L$41 -> 9090.9091
...

Sheet Fin Assumptions
A2: Debt Assumptions
A3: Long term Debt
A4: Moratorium Period | B4: 8 | C4: quarters
A5: Repayment period (years) | B5: 8
A6: Repayment period (Quarters) | B6: =B5*4 -> 32
A8: Rate of interest | B8: 0.06 | C8: p.a.
A10: Quarterly principal payment | B10: =B36/B6 -> 174106.27
A12: Working Capital Loan
A13: Eligibility | B13: 0
A14: margin Money | B14: 1
A15: Rate of interest | B15: 0.04
A16: Requirement
A17: Raw material | B17: 0 | C17: days
A18: Finished Products | B18: 0 | C18: days
A19: Debtors | B19: 30 | C19: days
A22: Income tax rate | B22: 0.05 | C22: p.a.
A24: Depreciation Rates | B24: Book Depr | C24: Tax Depr
A25: Plant & Machinery | B25: 0.1034 | C25: 0.15
A26: Office Furniture | B26: 0.0633 | C26: 0.1
A27: Miscellaneous Fixed Assets | B27: 0.1034 | C27: 0.15
A28: Buildings-Plant (technical) | B28: 0.0334 | C28: 0.05
A29: Buildings-Non technical | B29: 0.0163 | C29: 0.05
A32: Means of finance
A33: Components | B33: Euro | C33: Proportion (%)
A34: Equity | B34: ='Project Cost'!D21*0.3 -> 2387743.1 | C34: =1-C36-C35 -> 0.3 | D34: =B34*0.25 -> 596935.77
A35: Grant | C35: =B35/$B$37 -> 0 | D35: =B35*0.25 -> 0
A36: Debt | B36: =B37-B34 -> 5571400.6 | C36: =B36/$B$37 -> 0.7 | D36: =B36*0.25 -> 1392850.1
A37: Total | B37: ='Project Cost'!D21 -> 7959143.7 | C37: =B37/$B$37 -> 1
A41: Salaries
A42: GM | B42: 1 | C42: 90000 | D42: =C42*B42 -> 90000 | G42: Project Head | H42: 1 | I42: 150000 | J42: =I42*H42 -> 150000
A43: Sales Manager | B43: 1 | C43: 70000 | D43: =C43*B43 -> 70000 | G43: General Manager | H43: 1 | I43: 113636 | J43: =I43*H43 -> 113636
A44: Crop Manager | B44: 3 | C44: 25000 | D44: =C44*B44 -> 75000 | G44: Marketing Head | H44: 1 | I44: =I43 -> 113636 | J44: =I44*H44 -> 113636
A45: Field supervisors | B45: 3 | C45: 20455 | D45: =C45*B45 -> 61365 | G45: Sales Head | H45: 1 | I45: =I44 -> 113636 | J45: =I45*H45 -> 113636
G46: Accounts and Finance Head | H46: 1 | I46: =I45 -> 113636 | J46: =I46*H46 -> 113636
A47: Finance and Accounts | B47: 2 | C47: =1200000/88 -> 13636.364 | D47: =C47*B47 -> 27272.727 | G47: Marketing & Sales Support | H47: 2 | I47: 25000 | J47: =I47*H47 -> 50000
A48: Workshop Supervisor | B48: 1 | C48: =1200000/88 -> 13636.364 | D48: =C48*B48 -> 13636.364 | G48: Finance & Accounts Support | H48: 1 | I48: 25000 | J48: =I48*H48 -> 25000
A49: Warehouse Supervisor | B49: 1 | C49: =1200000/88 -> 13636.364 | D49: =C49*B49 -> 13636.364 | G49: Workshop Staff | H49: 2 | I49: 20000 | J49: =I49*H49 -> 40000
A50: Deshelling Supervisor | B50: 2 | C50: =1200000/88 -> 13636.364 | D50: =C50*B50 -> 27272.727 | G50: Warehouse Staff | H50: 2 | I50: 20000 | J50: =I50*H50 -> 40000
A51: Canteen Supervisor | B51: 1 | C51: =500000/88 -> 5681.8182 | D51: =C51*B51 -> 5681.8182 | G51: De-shelling Staff | H51: 2 | I51: 20000 | J51: =I51*H51 -> 40000
A52: Permant Labour (incl drivers) | B52: 65 | C52: 3000 | D52: =C52*B52 -> 195000 | G52: Canteen Staff | H52: 2 | I52: 12000 | J52: =I52*H52 -> 24000
...

Sheet Project Cost
B2: Cost of Project
B3: Particulars | C3: Unit | D3: Total
B4: Project Management Services | C4: Acre | D4: 1200000
B5: Central Facility | C5: Acre
B7: Civil Works
B8: Technical | D8: ='Basic Infrastructure'!F35 -> 2001841.4 | F8: =D8+D9+D13+D16+D18 -> 6380136.8
B9: Project Engineering Services | D9: 200000 | F9: =5%*F8 -> 319006.84
B10: Total | D10: =D8+D9 -> 2201841.4 | F10: =F8+F9 -> 6699143.7
B12: Plant Machinery & Equipments
B13: Plant & Machinery | D13: ='Core Equipment '!G36 -> 3913039.8
B15: Utilities & Other assets
B16: Total Utilities & other Assets | D16: ='Other Equipment'!I10 -> 15255.682
B18: R&D | C18: 0 | D18: 250000
B19: Contingencies | C19: 0.05 | D19: =5%*D20 -> 379006.84
B20: Sub-total | D20: =D10+D13+D16+D18+D4 -> 7580136.8
B21: Total Project Cost | D21: =D20+D19 -> 7959143.7
B26: Means of Finance
B27: Equity
B28: Grant
B29: Long Term Debt
B30: Total

Sheet P&L
B2: Profitability Statement
B3: Year | D3: Year 1 | E3: Year 2 | F3: Year 3 | G3: Year 4 | H3: Year 5 | I3: Year 6 | J3: Year 7 | K3: Year 8 | L3: Year 9 | M3: Year 10
B4: Groundnut | D4: ='Growing cost assum'!C18 -> 50400 | E4: ='Growing cost assum'!D18 -> 54000 | F4: ='Growing cost assum'!E18 -> 55800 | G4: ='Growing cost assum'!F18 -> 61200 | H4: ='Growing cost assum'!G18 -> 72000 | I4: ='Growing cost assum'!H18 -> 72000 | J4: ='Growing cost assum'!I18 -> 72000 | K4: ='Growing cost assum'!J18 -> 72000 | ... M4: ='Growing cost assum'!L18 -> 72000
B5: Cowpea | D5: ='Growing cost assum'!C36 -> 46800 | E5: ='Growing cost assum'!D36 -> 52000 | F5: ='Growing cost assum'!E36 -> 57200 | G5: ='Growing cost assum'!F36 -> 57200 | H5: ='Growing cost assum'!G36 -> 57200 | I5: ='Growing cost assum'!H36 -> 57200 | J5: ='Growing cost assum'!I36 -> 57200 | K5: ='Growing cost assum'!J36 -> 57200 | ... M5: ='Growing cost assum'!L36 -> 57200
B6: Wheat | D6: ='Growing cost assum'!C54 -> 54545.455 | E6: ='Growing cost assum'!D54 -> 58181.818 | F6: ='Growing cost assum'!E54 -> 61818.182 | G6: ='Growing cost assum'!F54 -> 65454.545 | H6: ='Growing cost assum'!G54 -> 72727.273 | I6: ='Growing cost assum'!H54 -> 72727.273 | J6: ='Growing cost assum'!I54 -> 72727.273 | K6: ='Growing cost assum'!J54 -> 72727.273 | ... M6: ='Growing cost assum'!L54 -> 72727.273
B7: Sesame | D7: ='Growing cost assum'!C72 -> 35200 | E7: ='Growing cost assum'!D72 -> 39600 | F7: ='Growing cost assum'!E72 -> 44000 | G7: ='Growing cost assum'!F72 -> 44000 | H7: ='Growing cost assum'!G72 -> 44000 | I7: ='Growing cost assum'!H72 -> 44000 | J7: ='Growing cost assum'!I72 -> 44000 | K7: ='Growing cost assum'!J72 -> 44000 | ... M7: ='Growing cost assum'!L72 -> 44000
B8: Okra | D8: ='Growing cost assum'!C92 -> 56000 | E8: ='Growing cost assum'!D92 -> 63000 | F8: ='Growing cost assum'!E92 -> 70000 | G8: ='Growing cost assum'!F92 -> 77000 | H8: ='Growing cost assum'!G92 -> 84000 | I8: ='Growing cost assum'!H92 -> 84000 | J8: ='Growing cost assum'!I92 -> 84000 | K8: ='Growing cost assum'!J92 -> 84000 | ... M8: ='Growing cost assum'!L92 -> 84000
B9: Sorghum for seed | D9: ='Growing cost assum'!C110 -> 37546.667 | E9: ='Growing cost assum'!D110 -> 41301.333 | F9: ='Growing cost assum'!E110 -> 45431.467 | G9: ='Growing cost assum'!F110 -> 49974.613 | H9: ='Growing cost assum'!G110 -> 54972.075 | I9: ='Growing cost assum'!H110 -> 54972.075 | J9: ='Growing cost assum'!I110 -> 54972.075 | K9: ='Growing cost assum'!J110 -> 54972.075 | ... M9: ='Growing cost assum'!L110 -> 54972.075
B10: Onion | D10: ='Growing cost assum'!C128 -> 2400000 | E10: ='Growing cost assum'!D128 -> 2640000 | F10: ='Growing cost assum'!E128 -> 2880000 | G10: ='Growing cost assum'!F128 -> 3120000 | H10: ='Growing cost assum'!G128 -> 3360000 | I10: ='Growing cost assum'!H128 -> 3600000 | J10: ='Growing cost assum'!I128 -> 3600000 | K10: ='Growing cost assum'!J128 -> 3600000 | ... M10: ='Growing cost assum'!L128 -> 3600000
B11: Aubergine | D11: ='Growing cost assum'!C147 -> 250000 | E11: ='Growing cost assum'!D147 -> 275000 | F11: ='Growing cost assum'!E147 -> 302500 | G11: ='Growing cost assum'!F147 -> 332750 | H11: ='Growing cost assum'!G147 -> 366025 | I11: ='Growing cost assum'!H147 -> 400000 | J11: ='Growing cost assum'!I147 -> 400000 | K11: ='Growing cost assum'!J147 -> 400000 | ... M11: ='Growing cost assum'!L147 -> 400000
B12: Tomato | D12: ='Growing cost assum'!C165 -> 500000 | E12: ='Growing cost assum'!D165 -> 580000 | F12: ='Growing cost assum'!E165 -> 660000 | G12: ='Growing cost assum'!F165 -> 740000 | H12: ='Growing cost assum'!G165 -> 820000 | I12: ='Growing cost assum'!H165 -> 900000 | J12: ='Growing cost assum'!I165 -> 900000 | K12: ='Growing cost assum'!J165 -> 900000 | ... M12: ='Growing cost assum'!L165 -> 900000
B13: Potato | D13: ='Growing cost assum'!C183 -> 320000 | E13: ='Growing cost assum'!D183 -> 400000 | F13: ='Growing cost assum'!E183 -> 480000 | G13: ='Growing cost assum'!F183 -> 560000 | H13: ='Growing cost assum'!G183 -> 600000 | I13: ='Growing cost assum'!H183 -> 600000 | J13: ='Growing cost assum'!I183 -> 600000 | K13: ='Growing cost assum'!J183 -> 600000 | ... M13: ='Growing cost assum'!L183 -> 600000
B14: Alfa Alfa
B16: Revenue | D16: =SUM(D4:D13) -> 3750492.1 | E16: =SUM(E4:E13) -> 4203083.2 | F16: =SUM(F4:F13) -> 4656749.6 | G16: =SUM(G4:G13) -> 5107579.2 | H16: =SUM(H4:H13) -> 5530924.3 | I16: =SUM(I4:I13) -> 5884899.3 | J16: =SUM(J4:J13) -> 5884899.3 | K16: =SUM(K4:K13) -> 5884899.3 | ... M16: =SUM(M4:M13) -> 5884899.3 | IT16: =SUM(A16:IS16) -> 52673325
B18: Variable Expenses
B19: Land preparation | D19: ='Growing cost assum'!C6+'Growing cost assum'!C24+'Growing cost assum'!C42+'Growing cost assum'!C60+'Growing cost assum'!C80+'Growing cost assum'!C98+'Growing cost assum'!C116+'Growing cost assum'!C135+'Growing cost assum'!C153+'Growing cost assum'!C171+'Growing cost assum'!C189 -> 19113.164 | E19: ='Growing cost assum'!D6+'Growing cost assum'!D24+'Growing cost assum'!D42+'Growing cost assum'!D60+'Growing cost assum'!D80+'Growing cost assum'!D98+'Growing cost assum'!D116+'Growing cost assum'!D135+'Growing cost assum'!D153+'Growing cost assum'!D171+'Growing cost assum'!D189 -> 19113.164 | F19: ='Growing cost assum'!E6+'Growing cost assum'!E24+'Growing cost assum'!E42+'Growing cost assum'!E60+'Growing cost assum'!E80+'Growing cost assum'!E98+'Growing cost assum'!E116+'Growing cost assum'!E135+'Growing cost assum'!E153+'Growing cost assum'!E171+'Growing cost assum'!E189 -> 19113.164 | G19: ='Growing cost assum'!F6+'Growing cost assum'!F24+'Growing cost assum'!F42+'Growing cost assum'!F60+'Growing cost assum'!F80+'Growing cost assum'!F98+'Growing cost assum'!F116+'Growing cost assum'!F135+'Growing cost assum'!F153+'Growing cost assum'!F171+'Growing cost assum'!F189 -> 19113.164 | H19: ='Growing cost assum'!G6+'Growing cost assum'!G24+'Growing cost assum'!G42+'Growing cost assum'!G60+'Growing cost assum'!G80+'Growing cost assum'!G98+'Growing cost assum'!G116+'Growing cost assum'!G135+'Growing cost assum'!G153+'Growing cost assum'!G171+'Growing cost assum'!G189 -> 19113.164 | I19: ='Growing cost assum'!H6+'Growing cost assum'!H24+'Growing cost assum'!H42+'Growing cost assum'!H60+'Growing cost assum'!H80+'Growing cost assum'!H98+'Growing cost assum'!H116+'Growing cost assum'!H135+'Growing cost assum'!H153+'Growing cost assum'!H171+'Growing cost assum'!H189 -> 19113.164 | J19: ='Growing cost assum'!I6+'Growing cost assum'!I24+'Growing cost assum'!I42+'Growing cost assum'!I60+'Growing cost assum'!I80+'Growing cost assum'!I98+'Growing cost assum'!I116+'Growing cost assum'!I135+'Growing cost assum'!I153+'Growing cost assum'!I171+'Growing cost assum'!I189 -> 19113.164 | K19: ='Growing cost assum'!J6+'Growing cost assum'!J24+'Growing cost assum'!J42+'Growing cost assum'!J60+'Growing cost assum'!J80+'Growing cost assum'!J98+'Growing cost assum'!J116+'Growing cost assum'!J135+'Growing cost assum'!J153+'Growing cost assum'!J171+'Growing cost assum'!J189 -> 19113.164 | ... M19: ='Growing cost assum'!L6+'Growing cost assum'!L24+'Growing cost assum'!L42+'Growing cost assum'!L60+'Growing cost assum'!L80+'Growing cost assum'!L98+'Growing cost assum'!L116+'Growing cost assum'!L135+'Growing cost assum'!L153+'Growing cost assum'!L171+'Growing cost assum'!L189 -> 19113.164
B20: Seed Cost | D20: ='Growing cost assum'!C7+'Growing cost assum'!C25+'Growing cost assum'!C43+'Growing cost assum'!C61+'Growing cost assum'!C81+'Growing cost assum'!C99+'Growing cost assum'!C117+'Growing cost assum'!C136+'Growing cost assum'!C154+'Growing cost assum'!C172+'Growing cost assum'!C190 -> 126216.91 | E20: ='Growing cost assum'!D7+'Growing cost assum'!D25+'Growing cost assum'!D43+'Growing cost assum'!D61+'Growing cost assum'!D81+'Growing cost assum'!D99+'Growing cost assum'!D117+'Growing cost assum'!D136+'Growing cost assum'!D154+'Growing cost assum'!D172+'Growing cost assum'!D190 -> 126216.91 | F20: ='Growing cost assum'!E7+'Growing cost assum'!E25+'Growing cost assum'!E43+'Growing cost assum'!E61+'Growing cost assum'!E81+'Growing cost assum'!E99+'Growing cost assum'!E117+'Growing cost assum'!E136+'Growing cost assum'!E154+'Growing cost assum'!E172+'Growing cost assum'!E190 -> 126216.91 | G20: ='Growing cost assum'!F7+'Growing cost assum'!F25+'Growing cost assum'!F43+'Growing cost assum'!F61+'Growing cost assum'!F81+'Growing cost assum'!F99+'Growing cost assum'!F117+'Growing cost assum'!F136+'Growing cost assum'!F154+'Growing cost assum'!F172+'Growing cost assum'!F190 -> 126216.91 | H20: ='Growing cost assum'!G7+'Growing cost assum'!G25+'Growing cost assum'!G43+'Growing cost assum'!G61+'Growing cost assum'!G81+'Growing cost assum'!G99+'Growing cost assum'!G117+'Growing cost assum'!G136+'Growing cost assum'!G154+'Growing cost assum'!G172+'Growing cost assum'!G190 -> 126216.91 | I20: ='Growing cost assum'!H7+'Growing cost assum'!H25+'Growing cost assum'!H43+'Growing cost assum'!H61+'Growing cost assum'!H81+'Growing cost assum'!H99+'Growing cost assum'!H117+'Growing cost assum'!H136+'Growing cost assum'!H154+'Growing cost assum'!H172+'Growing cost assum'!H190 -> 126216.91 | J20: ='Growing cost assum'!I7+'Growing cost assum'!I25+'Growing cost assum'!I43+'Growing cost assum'!I61+'Growing cost assum'!I81+'Growing cost assum'!I99+'Growing cost assum'!I117+'Growing cost assum'!I136+'Growing cost assum'!I154+'Growing cost assum'!I172+'Growing cost assum'!I190 -> 126216.91 | K20: ='Growing cost assum'!J7+'Growing cost assum'!J25+'Growing cost assum'!J43+'Growing cost assum'!J61+'Growing cost assum'!J81+'Growing cost assum'!J99+'Growing cost assum'!J117+'Growing cost assum'!J136+'Growing cost assum'!J154+'Growing cost assum'!J172+'Growing cost assum'!J190 -> 126216.91 | ... M20: ='Growing cost assum'!L7+'Growing cost assum'!L25+'Growing cost assum'!L43+'Growing cost assum'!L61+'Growing cost assum'!L81+'Growing cost assum'!L99+'Growing cost assum'!L117+'Growing cost assum'!L136+'Growing cost assum'!L154+'Growing cost assum'!L172+'Growing cost assum'!L190 -> 126216.91
B21: Seed treatment / Nursery cost | D21: ='Growing cost assum'!C8+'Growing cost assum'!C26+'Growing cost assum'!C44+'Growing cost assum'!C62+'Growing cost assum'!C82+'Growing cost assum'!C100+'Growing cost assum'!C118+'Growing cost assum'!C137+'Growing cost assum'!C155+'Growing cost assum'!C173+'Growing cost assum'!C191 -> 27223.864 | E21: ='Growing cost assum'!D8+'Growing cost assum'!D26+'Growing cost assum'!D44+'Growing cost assum'!D62+'Growing cost assum'!D82+'Growing cost assum'!D100+'Growing cost assum'!D118+'Growing cost assum'!D137+'Growing cost assum'!D155+'Growing cost assum'!D173+'Growing cost assum'!D191 -> 27223.864 | F21: ='Growing cost assum'!E8+'Growing cost assum'!E26+'Growing cost assum'!E44+'Growing cost assum'!E62+'Growing cost assum'!E82+'Growing cost assum'!E100+'Growing cost assum'!E118+'Growing cost assum'!E137+'Growing cost assum'!E155+'Growing cost assum'!E173+'Growing cost assum'!E191 -> 27223.864 | G21: ='Growing cost assum'!F8+'Growing cost assum'!F26+'Growing cost assum'!F44+'Growing cost assum'!F62+'Growing cost assum'!F82+'Growing cost assum'!F100+'Growing cost assum'!F118+'Growing cost assum'!F137+'Growing cost assum'!F155+'Growing cost assum'!F173+'Growing cost assum'!F191 -> 27223.864 | H21: ='Growing cost assum'!G8+'Growing cost assum'!G26+'Growing cost assum'!G44+'Growing cost assum'!G62+'Growing cost assum'!G82+'Growing cost assum'!G100+'Growing cost assum'!G118+'Growing cost assum'!G137+'Growing cost assum'!G155+'Growing cost assum'!G173+'Growing cost assum'!G191 -> 27223.864 | I21: ='Growing cost assum'!H8+'Growing cost assum'!H26+'Growing cost assum'!H44+'Growing cost assum'!H62+'Growing cost assum'!H82+'Growing cost assum'!H100+'Growing cost assum'!H118+'Growing cost assum'!H137+'Growing cost assum'!H155+'Growing cost assum'!H173+'Growing cost assum'!H191 -> 27223.864 | J21: ='Growing cost assum'!I8+'Growing cost assum'!I26+'Growing cost assum'!I44+'Growing cost assum'!I62+'Growing cost assum'!I82+'Growing cost assum'!I100+'Growing cost assum'!I118+'Growing cost assum'!I137+'Growing cost assum'!I155+'Growing cost assum'!I173+'Growing cost assum'!I191 -> 27223.864 | K21: ='Growing cost assum'!J8+'Growing cost assum'!J26+'Growing cost assum'!J44+'Growing cost assum'!J62+'Growing cost assum'!J82+'Growing cost assum'!J100+'Growing cost assum'!J118+'Growing cost assum'!J137+'Growing cost assum'!J155+'Growing cost assum'!J173+'Growing cost assum'!J191 -> 27223.864 | ... M21: ='Growing cost assum'!L8+'Growing cost assum'!L26+'Growing cost assum'!L44+'Growing cost assum'!L62+'Growing cost assum'!L82+'Growing cost assum'!L100+'Growing cost assum'!L118+'Growing cost assum'!L137+'Growing cost assum'!L155+'Growing cost assum'!L173+'Growing cost assum'!L191 -> 27223.864
B22: Sowing cost | D22: ='Growing cost assum'!C9+'Growing cost assum'!C27+'Growing cost assum'!C45+'Growing cost assum'!C63+'Growing cost assum'!C83+'Growing cost assum'!C101+'Growing cost assum'!C119+'Growing cost assum'!C138+'Growing cost assum'!C156+'Growing cost assum'!C174+'Growing cost assum'!C192 -> 60932.127 | E22: ='Growing cost assum'!D9+'Growing cost assum'!D27+'Growing cost assum'!D45+'Growing cost assum'!D63+'Growing cost assum'!D83+'Growing cost assum'!D101+'Growing cost assum'!D119+'Growing cost assum'!D138+'Growing cost assum'!D156+'Growing cost assum'!D174+'Growing cost assum'!D192 -> 60932.127 | F22: ='Growing cost assum'!E9+'Growing cost assum'!E27+'Growing cost assum'!E45+'Growing cost assum'!E63+'Growing cost assum'!E83+'Growing cost assum'!E101+'Growing cost assum'!E119+'Growing cost assum'!E138+'Growing cost assum'!E156+'Growing cost assum'!E174+'Growing cost assum'!E192 -> 60932.127 | G22: ='Growing cost assum'!F9+'Growing cost assum'!F27+'Growing cost assum'!F45+'Growing cost assum'!F63+'Growing cost assum'!F83+'Growing cost assum'!F101+'Growing cost assum'!F119+'Growing cost assum'!F138+'Growing cost assum'!F156+'Growing cost assum'!F174+'Growing cost assum'!F192 -> 60932.127 | H22: ='Growing cost assum'!G9+'Growing cost assum'!G27+'Growing cost assum'!G45+'Growing cost assum'!G63+'Growing cost assum'!G83+'Growing cost assum'!G101+'Growing cost assum'!G119+'Growing cost assum'!G138+'Growing cost assum'!G156+'Growing cost assum'!G174+'Growing cost assum'!G192 -> 60932.127 | I22: ='Growing cost assum'!H9+'Growing cost assum'!H27+'Growing cost assum'!H45+'Growing cost assum'!H63+'Growing cost assum'!H83+'Growing cost assum'!H101+'Growing cost assum'!H119+'Growing cost assum'!H138+'Growing cost assum'!H156+'Growing cost assum'!H174+'Growing cost assum'!H192 -> 60932.127 | J22: ='Growing cost assum'!I9+'Growing cost assum'!I27+'Growing cost assum'!I45+'Growing cost assum'!I63+'Growing cost assum'!I83+'Growing cost assum'!I101+'Growing cost assum'!I119+'Growing cost assum'!I138+'Growing cost assum'!I156+'Growing cost assum'!I174+'Growing cost assum'!I192 -> 60932.127 | K22: ='Growing cost assum'!J9+'Growing cost assum'!J27+'Growing cost assum'!J45+'Growing cost assum'!J63+'Growing cost assum'!J83+'Growing cost assum'!J101+'Growing cost assum'!J119+'Growing cost assum'!J138+'Growing cost assum'!J156+'Growing cost assum'!J174+'Growing cost assum'!J192 -> 60932.127 | ... M22: ='Growing cost assum'!L9+'Growing cost assum'!L27+'Growing cost assum'!L45+'Growing cost assum'!L63+'Growing cost assum'!L83+'Growing cost assum'!L101+'Growing cost assum'!L119+'Growing cost assum'!L138+'Growing cost assum'!L156+'Growing cost assum'!L174+'Growing cost assum'!L192 -> 60932.127
B23: Fertiliser (basal application)* urea in two doses | D23: ='Growing cost assum'!C10+'Growing cost assum'!C28+'Growing cost assum'!C46+'Growing cost assum'!C64+'Growing cost assum'!C84+'Growing cost assum'!C102+'Growing cost assum'!C120+'Growing cost assum'!C139+'Growing cost assum'!C157+'Growing cost assum'!C175+'Growing cost assum'!C193 -> 144760.91 | E23: ='Growing cost assum'!D10+'Growing cost assum'!D28+'Growing cost assum'!D46+'Growing cost assum'!D64+'Growing cost assum'!D84+'Growing cost assum'!D102+'Growing cost assum'!D120+'Growing cost assum'!D139+'Growing cost assum'!D157+'Growing cost assum'!D175+'Growing cost assum'!D193 -> 144760.91 | F23: ='Growing cost assum'!E10+'Growing cost assum'!E28+'Growing cost assum'!E46+'Growing cost assum'!E64+'Growing cost assum'!E84+'Growing cost assum'!E102+'Growing cost assum'!E120+'Growing cost assum'!E139+'Growing cost assum'!E157+'Growing cost assum'!E175+'Growing cost assum'!E193 -> 144760.91 | G23: ='Growing cost assum'!F10+'Growing cost assum'!F28+'Growing cost assum'!F46+'Growing cost assum'!F64+'Growing cost assum'!F84+'Growing cost assum'!F102+'Growing cost assum'!F120+'Growing cost assum'!F139+'Growing cost assum'!F157+'Growing cost assum'!F175+'Growing cost assum'!F193 -> 144760.91 | H23: ='Growing cost assum'!G10+'Growing cost assum'!G28+'Growing cost assum'!G46+'Growing cost assum'!G64+'Growing cost assum'!G84+'Growing cost assum'!G102+'Growing cost assum'!G120+'Growing cost assum'!G139+'Growing cost assum'!G157+'Growing cost assum'!G175+'Growing cost assum'!G193 -> 144760.91 | I23: ='Growing cost assum'!H10+'Growing cost assum'!H28+'Growing cost assum'!H46+'Growing cost assum'!H64+'Growing cost assum'!H84+'Growing cost assum'!H102+'Growing cost assum'!H120+'Growing cost assum'!H139+'Growing cost assum'!H157+'Growing cost assum'!H175+'Growing cost assum'!H193 -> 144760.91 | J23: ='Growing cost assum'!I10+'Growing cost assum'!I28+'Growing cost assum'!I46+'Growing cost assum'!I64+'Growing cost assum'!I84+'Growing cost assum'!I102+'Growing cost assum'!I120+'Growing cost assum'!I139+'Growing cost assum'!I157+'Growing cost assum'!I175+'Growing cost assum'!I193 -> 144760.91 | K23: ='Growing cost assum'!J10+'Growing cost assum'!J28+'Growing cost assum'!J46+'Growing cost assum'!J64+'Growing cost assum'!J84+'Growing cost assum'!J102+'Growing cost assum'!J120+'Growing cost assum'!J139+'Growing cost assum'!J157+'Growing cost assum'!J175+'Growing cost assum'!J193 -> 144760.91 | ... M23: ='Growing cost assum'!L10+'Growing cost assum'!L28+'Growing cost assum'!L46+'Growing cost assum'!L64+'Growing cost assum'!L84+'Growing cost assum'!L102+'Growing cost assum'!L120+'Growing cost assum'!L139+'Growing cost assum'!L157+'Growing cost assum'!L175+'Growing cost assum'!L193 -> 144760.91
B24: Pre emergent Herbicide spray | D24: ='Growing cost assum'!C11+'Growing cost assum'!C29+'Growing cost assum'!C47+'Growing cost assum'!C65+'Growing cost assum'!C85+'Growing cost assum'!C103+'Growing cost assum'!C121+'Growing cost assum'!C140+'Growing cost assum'!C158+'Growing cost assum'!C176+'Growing cost assum'!C194 -> 55142.045 | E24: ='Growing cost assum'!D11+'Growing cost assum'!D29+'Growing cost assum'!D47+'Growing cost assum'!D65+'Growing cost assum'!D85+'Growing cost assum'!D103+'Growing cost assum'!D121+'Growing cost assum'!D140+'Growing cost assum'!D158+'Growing cost assum'!D176+'Growing cost assum'!D194 -> 55142.045 | F24: ='Growing cost assum'!E11+'Growing cost assum'!E29+'Growing cost assum'!E47+'Growing cost assum'!E65+'Growing cost assum'!E85+'Growing cost assum'!E103+'Growing cost assum'!E121+'Growing cost assum'!E140+'Growing cost assum'!E158+'Growing cost assum'!E176+'Growing cost assum'!E194 -> 55142.045 | G24: ='Growing cost assum'!F11+'Growing cost assum'!F29+'Growing cost assum'!F47+'Growing cost assum'!F65+'Growing cost assum'!F85+'Growing cost assum'!F103+'Growing cost assum'!F121+'Growing cost assum'!F140+'Growing cost assum'!F158+'Growing cost assum'!F176+'Growing cost assum'!F194 -> 55142.045 | H24: ='Growing cost assum'!G11+'Growing cost assum'!G29+'Growing cost assum'!G47+'Growing cost assum'!G65+'Growing cost assum'!G85+'Growing cost assum'!G103+'Growing cost assum'!G121+'Growing cost assum'!G140+'Growing cost assum'!G158+'Growing cost assum'!G176+'Growing cost assum'!G194 -> 55142.045 | I24: ='Growing cost assum'!H11+'Growing cost assum'!H29+'Growing cost assum'!H47+'Growing cost assum'!H65+'Growing cost assum'!H85+'Growing cost assum'!H103+'Growing cost assum'!H121+'Growing cost assum'!H140+'Growing cost assum'!H158+'Growing cost assum'!H176+'Growing cost assum'!H194 -> 55142.045 | J24: ='Growing cost assum'!I11+'Growing cost assum'!I29+'Growing cost assum'!I47+'Growing cost assum'!I65+'Growing cost assum'!I85+'Growing cost assum'!I103+'Growing cost assum'!I121+'Growing cost assum'!I140+'Growing cost assum'!I158+'Growing cost assum'!I176+'Growing cost assum'!I194 -> 55142.045 | K24: ='Growing cost assum'!J11+'Growing cost assum'!J29+'Growing cost assum'!J47+'Growing cost assum'!J65+'Growing cost assum'!J85+'Growing cost assum'!J103+'Growing cost assum'!J121+'Growing cost assum'!J140+'Growing cost assum'!J158+'Growing cost assum'!J176+'Growing cost assum'!J194 -> 55142.045 | ... M24: ='Growing cost assum'!L11+'Growing cost assum'!L29+'Growing cost assum'!L47+'Growing cost assum'!L65+'Growing cost assum'!L85+'Growing cost assum'!L103+'Growing cost assum'!L121+'Growing cost assum'!L140+'Growing cost assum'!L158+'Growing cost assum'!L176+'Growing cost assum'!L194 -> 55142.045
B25: Fungicide and Insecticide spray | D25: ='Growing cost assum'!C12+'Growing cost assum'!C30+'Growing cost assum'!C48+'Growing cost assum'!C66+'Growing cost assum'!C86+'Growing cost assum'!C104+'Growing cost assum'!C122+'Growing cost assum'!C141+'Growing cost assum'!C159+'Growing cost assum'!C177+'Growing cost assum'!C195 -> 80678.182 | E25: ='Growing cost assum'!D12+'Growing cost assum'!D30+'Growing cost assum'!D48+'Growing cost assum'!D66+'Growing cost assum'!D86+'Growing cost assum'!D104+'Growing cost assum'!D122+'Growing cost assum'!D141+'Growing cost assum'!D159+'Growing cost assum'!D177+'Growing cost assum'!D195 -> 80678.182 | F25: ='Growing cost assum'!E12+'Growing cost assum'!E30+'Growing cost assum'!E48+'Growing cost assum'!E66+'Growing cost assum'!E86+'Growing cost assum'!E104+'Growing cost assum'!E122+'Growing cost assum'!E141+'Growing cost assum'!E159+'Growing cost assum'!E177+'Growing cost assum'!E195 -> 80678.182 | G25: ='Growing cost assum'!F12+'Growing cost assum'!F30+'Growing cost assum'!F48+'Growing cost assum'!F66+'Growing cost assum'!F86+'Growing cost assum'!F104+'Growing cost assum'!F122+'Growing cost assum'!F141+'Growing cost assum'!F159+'Growing cost assum'!F177+'Growing cost assum'!F195 -> 80678.182 | H25: ='Growing cost assum'!G12+'Growing cost assum'!G30+'Growing cost assum'!G48+'Growing cost assum'!G66+'Growing cost assum'!G86+'Growing cost assum'!G104+'Growing cost assum'!G122+'Growing cost assum'!G141+'Growing cost assum'!G159+'Growing cost assum'!G177+'Growing cost assum'!G195 -> 80678.182 | I25: ='Growing cost assum'!H12+'Growing cost assum'!H30+'Growing cost assum'!H48+'Growing cost assum'!H66+'Growing cost assum'!H86+'Growing cost assum'!H104+'Growing cost assum'!H122+'Growing cost assum'!H141+'Growing cost assum'!H159+'Growing cost assum'!H177+'Growing cost assum'!H195 -> 80678.182 | J25: ='Growing cost assum'!I12+'Growing cost assum'!I30+'Growing cost assum'!I48+'Growing cost assum'!I66+'Growing cost assum'!I86+'Growing cost assum'!I104+'Growing cost assum'!I122+'Growing cost assum'!I141+'Growing cost assum'!I159+'Growing cost assum'!I177+'Growing cost assum'!I195 -> 80678.182 | K25: ='Growing cost assum'!J12+'Growing cost assum'!J30+'Growing cost assum'!J48+'Growing cost assum'!J66+'Growing cost assum'!J86+'Growing cost assum'!J104+'Growing cost assum'!J122+'Growing cost assum'!J141+'Growing cost assum'!J159+'Growing cost assum'!J177+'Growing cost assum'!J195 -> 80678.182 | ... M25: ='Growing cost assum'!L12+'Growing cost assum'!L30+'Growing cost assum'!L48+'Growing cost assum'!L66+'Growing cost assum'!L86+'Growing cost assum'!L104+'Growing cost assum'!L122+'Growing cost assum'!L141+'Growing cost assum'!L159+'Growing cost assum'!L177+'Growing cost assum'!L195 -> 80678.182
B26: Diesel for irrigation | D26: ='Growing cost assum'!C13+'Growing cost assum'!C31+'Growing cost assum'!C49+'Growing cost assum'!C67+'Growing cost assum'!C87+'Growing cost assum'!C105+'Growing cost assum'!C123+'Growing cost assum'!C142+'Growing cost assum'!C160+'Growing cost assum'!C178+'Growing cost assum'!C196 -> 47553.182 | E26: ='Growing cost assum'!D13+'Growing cost assum'!D31+'Growing cost assum'!D49+'Growing cost assum'!D67+'Growing cost assum'!D87+'Growing cost assum'!D105+'Growing cost assum'!D123+'Growing cost assum'!D142+'Growing cost assum'!D160+'Growing cost assum'!D178+'Growing cost assum'!D196 -> 47553.182 | F26: ='Growing cost assum'!E13+'Growing cost assum'!E31+'Growing cost assum'!E49+'Growing cost assum'!E67+'Growing cost assum'!E87+'Growing cost assum'!E105+'Growing cost assum'!E123+'Growing cost assum'!E142+'Growing cost assum'!E160+'Growing cost assum'!E178+'Growing cost assum'!E196 -> 47553.182 | G26: ='Growing cost assum'!F13+'Growing cost assum'!F31+'Growing cost assum'!F49+'Growing cost assum'!F67+'Growing cost assum'!F87+'Growing cost assum'!F105+'Growing cost assum'!F123+'Growing cost assum'!F142+'Growing cost assum'!F160+'Growing cost assum'!F178+'Growing cost assum'!F196 -> 47553.182 | H26: ='Growing cost assum'!G13+'Growing cost assum'!G31+'Growing cost assum'!G49+'Growing cost assum'!G67+'Growing cost assum'!G87+'Growing cost assum'!G105+'Growing cost assum'!G123+'Growing cost assum'!G142+'Growing cost assum'!G160+'Growing cost assum'!G178+'Growing cost assum'!G196 -> 47553.182 | I26: ='Growing cost assum'!H13+'Growing cost assum'!H31+'Growing cost assum'!H49+'Growing cost assum'!H67+'Growing cost assum'!H87+'Growing cost assum'!H105+'Growing cost assum'!H123+'Growing cost assum'!H142+'Growing cost assum'!H160+'Growing cost assum'!H178+'Growing cost assum'!H196 -> 47553.182 | J26: ='Growing cost assum'!I13+'Growing cost assum'!I31+'Growing cost assum'!I49+'Growing cost assum'!I67+'Growing cost assum'!I87+'Growing cost assum'!I105+'Growing cost assum'!I123+'Growing cost assum'!I142+'Growing cost assum'!I160+'Growing cost assum'!I178+'Growing cost assum'!I196 -> 47553.182 | K26: ='Growing cost assum'!J13+'Growing cost assum'!J31+'Growing cost assum'!J49+'Growing cost assum'!J67+'Growing cost assum'!J87+'Growing cost assum'!J105+'Growing cost assum'!J123+'Growing cost assum'!J142+'Growing cost assum'!J160+'Growing cost assum'!J178+'Growing cost assum'!J196 -> 47553.182 | ... M26: ='Growing cost assum'!L13+'Growing cost assum'!L31+'Growing cost assum'!L49+'Growing cost assum'!L67+'Growing cost assum'!L87+'Growing cost assum'!L105+'Growing cost assum'!L123+'Growing cost assum'!L142+'Growing cost assum'!L160+'Growing cost assum'!L178+'Growing cost assum'!L196 -> 47553.182
B27: Harvesting (incl labour) | D27: ='Growing cost assum'!C14+'Growing cost assum'!C32+'Growing cost assum'!C50+'Growing cost assum'!C68+'Growing cost assum'!C88+'Growing cost assum'!C106+'Growing cost assum'!C124+'Growing cost assum'!C143+'Growing cost assum'!C161+'Growing cost assum'!C179+'Growing cost assum'!C197 -> 145291.36 | E27: ='Growing cost assum'!D14+'Growing cost assum'!D32+'Growing cost assum'!D50+'Growing cost assum'!D68+'Growing cost assum'!D88+'Growing cost assum'!D106+'Growing cost assum'!D124+'Growing cost assum'!D143+'Growing cost assum'!D161+'Growing cost assum'!D179+'Growing cost assum'!D197 -> 145291.36 | F27: ='Growing cost assum'!E14+'Growing cost assum'!E32+'Growing cost assum'!E50+'Growing cost assum'!E68+'Growing cost assum'!E88+'Growing cost assum'!E106+'Growing cost assum'!E124+'Growing cost assum'!E143+'Growing cost assum'!E161+'Growing cost assum'!E179+'Growing cost assum'!E197 -> 145291.36 | G27: ='Growing cost assum'!F14+'Growing cost assum'!F32+'Growing cost assum'!F50+'Growing cost assum'!F68+'Growing cost assum'!F88+'Growing cost assum'!F106+'Growing cost assum'!F124+'Growing cost assum'!F143+'Growing cost assum'!F161+'Growing cost assum'!F179+'Growing cost assum'!F197 -> 145291.36 | H27: ='Growing cost assum'!G14+'Growing cost assum'!G32+'Growing cost assum'!G50+'Growing cost assum'!G68+'Growing cost assum'!G88+'Growing cost assum'!G106+'Growing cost assum'!G124+'Growing cost assum'!G143+'Growing cost assum'!G161+'Growing cost assum'!G179+'Growing cost assum'!G197 -> 145291.36 | I27: ='Growing cost assum'!H14+'Growing cost assum'!H32+'Growing cost assum'!H50+'Growing cost assum'!H68+'Growing cost assum'!H88+'Growing cost assum'!H106+'Growing cost assum'!H124+'Growing cost assum'!H143+'Growing cost assum'!H161+'Growing cost assum'!H179+'Growing cost assum'!H197 -> 145291.36 | J27: ='Growing cost assum'!I14+'Growing cost assum'!I32+'Growing cost assum'!I50+'Growing cost assum'!I68+'Growing cost assum'!I88+'Growing cost assum'!I106+'Growing cost assum'!I124+'Growing cost assum'!I143+'Growing cost assum'!I161+'Growing cost assum'!I179+'Growing cost assum'!I197 -> 145291.36 | K27: ='Growing cost assum'!J14+'Growing cost assum'!J32+'Growing cost assum'!J50+'Growing cost assum'!J68+'Growing cost assum'!J88+'Growing cost assum'!J106+'Growing cost assum'!J124+'Growing cost assum'!J143+'Growing cost assum'!J161+'Growing cost assum'!J179+'Growing cost assum'!J197 -> 145291.36 | ... M27: ='Growing cost assum'!L14+'Growing cost assum'!L32+'Growing cost assum'!L50+'Growing cost assum'!L68+'Growing cost assum'!L88+'Growing cost assum'!L106+'Growing cost assum'!L124+'Growing cost assum'!L143+'Growing cost assum'!L161+'Growing cost assum'!L179+'Growing cost assum'!L197 -> 145291.36
B29: Total Variable Costs | D29: =SUM(D19:D27) -> 706911.75 | E29: =SUM(E19:E27) -> 706911.75 | F29: =SUM(F19:F27) -> 706911.75 | G29: =SUM(G19:G27) -> 706911.75 | H29: =SUM(H19:H27) -> 706911.75 | I29: =SUM(I19:I27) -> 706911.75 | J29: =SUM(J19:J27) -> 706911.75 | K29: =SUM(K19:K27) -> 706911.75 | ... M29: =SUM(M19:M27) -> 706911.75
B31: Fixed Expenses
B32: Salaries (Permanent) | D32: ='Fin Assumptions'!D53 -> 578865 | E32: =D32*1.05 -> 607808.25 | F32: =E32*1.05 -> 638198.66 | G32: =F32*1.05 -> 670108.6 | H32: =G32*1.05 -> 703614.03 | I32: =H32*1.05 -> 738794.73 | J32: =I32*1.05 -> 775734.46 | K32: =J32*1.05 -> 814521.19 | L32: =K32*1.05 -> 855247.25 | M32: =L32*1.05 -> 898009.61
B33: Maintenance | D33: =2%*'Project Cost'!$D$21 -> 159182.87 | E33: =2%*'Project Cost'!$D$21 -> 159182.87 | F33: =2%*'Project Cost'!$D$21 -> 159182.87 | G33: =3%*'Project Cost'!$D$21 -> 238774.31 | H33: =3%*'Project Cost'!$D$21 -> 238774.31 | I33: =3%*'Project Cost'!$D$21 -> 238774.31 | J33: =4%*'Project Cost'!$D$21 -> 318365.75 | K33: =4%*'Project Cost'!$D$21 -> 318365.75 | L33: =4%*'Project Cost'!$D$21 -> 318365.75 | M33: =4%*'Project Cost'!$D$21 -> 318365.75
B34: PMC | D34: 0 | E34: =300000 -> 300000 | F34: =E34+25000 -> 325000 | G34: =F34+25000 -> 350000 | H34: =G34+25000 -> 375000 | I34: =H34+25000 -> 400000 | J34: =I34+25000 -> 425000 | K34: =J34+25000 -> 450000 | L34: =K34+25000 -> 475000 | M34: =L34+25000 -> 500000
B35: R&D | D35: 25000 | E35: =D35*1.05 -> 26250 | F35: =E35*1.05 -> 27562.5 | G35: =F35*1.05 -> 28940.625 | H35: =G35*1.05 -> 30387.656 | I35: =H35*1.05 -> 31907.039 | J35: =I35*1.05 -> 33502.391 | K35: =J35*1.05 -> 35177.511 | L35: =K35*1.05 -> 36936.386 | M35: =L35*1.05 -> 38783.205
B36: Insurance | D36: =Dep.!C42*1% -> 52176.491 | E36: =Dep.!D42*1% -> 44540.018 | F36: =Dep.!E42*1% -> 38039.515 | G36: =Dep.!F42*1% -> 32505.063 | H36: =Dep.!G42*1% -> 27792.205 | I36: =Dep.!H42*1% -> 23778.13 | J36: =Dep.!I42*1% -> 20358.429 | K36: =Dep.!J42*1% -> 17444.332 | ... M36: =Dep.!L42*1% -> 12842.361
B38: Total Fixed Costs | D38: =SUM(D32:D36) -> 815224.36 | E38: =SUM(E32:E36) -> 1137781.1 | F38: =SUM(F32:F36) -> 1187983.6 | G38: =SUM(G32:G36) -> 1320328.6 | H38: =SUM(H32:H36) -> 1375568.2 | I38: =SUM(I32:I36) -> 1433254.2 | J38: =SUM(J32:J36) -> 1572961 | K38: =SUM(K32:K36) -> 1635508.8 | ... M38: =SUM(M32:M36) -> 1768000.9
B40: Total Expenses | D40: =D38+D29 -> 1522136.1 | E40: =E38+E29 -> 1844692.9 | F40: =F38+F29 -> 1894895.3 | G40: =G38+G29 -> 2027240.3 | H40: =H38+H29 -> 2082479.9 | I40: =I38+I29 -> 2140166 | J40: =J38+J29 -> 2279872.8 | K40: =K38+K29 -> 2342420.5 | ... M40: =M38+M29 -> 2474912.7
B42: EBITDA | D42: =D16-D40 -> 2228356 | E42: =E16-E40 -> 2358390.3 | F42: =F16-F40 -> 2761854.4 | G42: =G16-G40 -> 3080338.8 | H42: =H16-H40 -> 3448444.4 | I42: =I16-I40 -> 3744733.4 | J42: =J16-J40 -> 3605026.6 | K42: =K16-K40 -> 3542478.8 | ... M42: =M16-M40 -> 3409986.7
B43: Interest Long Term Debt (LTD) | D43: =Debt!D49 -> 334284.03 | E43: =Debt!E49 -> 334284.03 | F43: =Debt!F49 -> 318614.47 | G43: =Debt!G49 -> 276828.97 | H43: =Debt!H49 -> 235043.46 | I43: =Debt!I49 -> 193257.96 | J43: =Debt!J49 -> 151472.45 | K43: =Debt!K49 -> 109686.95 | ... M43: =Debt!M49 -> 26115.94
B44: Interest Working Capital borrowing | D44: =Debt!D71 -> 10001.312 | E44: =Debt!E71 -> 22416.443 | F44: =Debt!F71 -> 24835.998 | G44: =Debt!G71 -> 27240.422 | H44: =Debt!H71 -> 29498.263 | I44: =Debt!I71 -> 31386.13 | J44: =Debt!J71 -> 31386.13 | K44: =Debt!K71 -> 31386.13 | ... M44: =Debt!M71 -> 31386.13
B45: Depreciation | D45: =Dep.!C20 -> 471469.83 | E45: =Dep.!D20 -> 471469.83 | F45: =Dep.!E20 -> 471469.83 | G45: =Dep.!F20 -> 471469.83 | H45: =Dep.!G20 -> 471469.83 | I45: =Dep.!H20 -> 471469.83 | J45: =Dep.!I20 -> 471469.83 | K45: =Dep.!J20 -> 471469.83 | ... M45: =Dep.!L20 -> 471469.83
B46: PBT | D46: =D42-SUM(D43:D45) -> 1412600.8 | E46: =E42-SUM(E43:E45) -> 1530220 | F46: =F42-SUM(F43:F45) -> 1946934.1 | G46: =G42-SUM(G43:G45) -> 2304799.6 | H46: =H42-SUM(H43:H45) -> 2712432.9 | I46: =I42-SUM(I43:I45) -> 3048619.5 | J46: =J42-SUM(J43:J45) -> 2950698.2 | K46: =K42-SUM(K43:K45) -> 2929935.9 | ... M46: =M42-SUM(M43:M45) -> 2881014.8
B47: Tax | D47: =D58 -> 49341.925 | E47: =E58 -> 61902.121 | F47: =F58 -> 88417.681 | G47: =G58 -> 111141.21 | H47: =H58 -> 135630.84 | I47: =I58 -> 155934.09 | J47: =J58 -> 154009.89 | K47: =K58 -> 155499.8 | ... M47: =M58 -> 157034.21
B48: Net Profit (PAT) | D48: =D46-D47 -> 1363258.9 | E48: =E46-E47 -> 1468317.8 | F48: =F46-F47 -> 1858516.4 | G48: =G46-G47 -> 2193658.4 | H48: =H46-H47 -> 2576802 | I48: =I46-I47 -> 2892685.4 | J48: =J46-J47 -> 2796688.3 | K48: =K46-K47 -> 2774436.1 | ... M48: =M46-M47 -> 2723980.6
...

Sheet Debt
