Workbook

Sheet Hypothèses Nour 3Moissons
B3: Nombre de fermes 3Moissons | C3: 50 | D3: unités | I3: Utilisations d'électricité pour une ferme CAP 3Moissons
B4: Puissance photovoltaique | C4: 80 | D4: kWc | I4: Usages | J4: Surface | K4: Puissance kW | L4: Disponibilité | M4: Utilisations | N4: Stockage kWh
B5: Stockage en batteries | C5: 20 | D5: kWh | I5: Agroforesterie & haie vive | J5: 5 ha | K5: 2 | L5: 2h/24h | M5: Pompage solaire | N5: 0
B6: Courant électrique | C6: 400 | D6: V triphasé | I6: Verger pour arbre fruitier | J6: 5 ha | K6: 5 | L6: 2h/24h | M6: Pompage solaire | N6: 0
B7: Ensoleillement | C7: 2200 | D7: h/an | I7: Irrigation pour culture de contre-saison | J7: 15 ha | K7: 3 | L7: 4h/24h | M7: Pompage solaire | N7: 0
B8: Coefficient pertes | C8: 0.85 | I8: Irrigation pour culture fourragère | J8: 10 ha | K8: 10 | L8: 2h/24h | M8: Pompage solaire | N8: 0
B9: Ensoleillement équivalent | C9: =C7*C8 -> 1870 | D9: h équiv./an | I9: Hangar et aire de stockage | J9: 300 m² | K9: 5 | L9: 16h/24h | M9: Treuil, éclairage | N9: 2
B10: Surface panneaux PV | C10: =C4*1000/150 -> 533.33333 | D10: m² | I10: Magasin du groupement | J10: 100 m² | K10: 2 | L10: 16h/24h | M10: Treuil, éclairage | N10: 2
B11: Productible PV une CAP 3Moissons | C11: =C4*C7*C8 -> 149600 | D11: kWh/an
B12: Potentiel ventes surplus kWh hors 3Moissons | C12: =(C11-N37) -> 74100 | D12: kWh/an
B13: Coefficient vente surplus kWh PV | C13: 0.25 | D13: soit 6h/jour
I15: local et petit bureau | J15: 70 m² | K15: 3 | L15: 10h/24h | M15: IT, Eclairage, divers | N15: 2
B16: Investissement Nour Energie en € par ferme 3Moissons | I16: Pompage mutualisé 500m3 à 60 à 100m | K16: 35 | L16: 4h/24h | M16: Pompage triphasé | N16: 7
B17: Photovoltaïque 80kWc | C17: 106000 | I17: Protection périmétrique, sécurité, incendie | K17: 2 | L17: 24h/24 | M17: Surveillance | N17: 4
B18: Groupe diesel 70kVA (100Cv) | C18: 12000 | I18: Divers air comprimé, lavage, froid | K18: 8 | L18: 16h/24h | M18: Services techniques | N18: 1
B19: Batterie 20kWh Plomb gel | C19: 8000 | I19: Total électricité | K19: =SUM(K5:K18) -> 75 | N19: =SUM(N5:N18) -> 18
B20: Réseau 400V triphasé | C20: 7000 | I20: Stockage d'électricité | L20: Batterie Plomb Gel 20,5kWh
B21: Total CAPEX Nour 1 CAP 3Moissons | C21: =SUM(C17:C20) -> 133000
B22: Nombre de fermes CAP 3Moissons année 3 | C22: 50
B23: Total Nour pour 50 CAP 3Moissons | C23: =C21*C22 -> 6650000 | I23: Consommations d'électricité d'une ferme CAP 3Moissons
I24: Consommations d'électricité d'une ferme CAP 3Moissons | K24: Puissance kW | L24: H équiv./jour | M24: kWh Saison sèche | N24: kWh Saison humide
B25: Année | C25: 1 | D25: 2 | E25: 3 | F25: année n | I25: Agroforesterie & haie vive | K25: 2 | L25: 2 | M25: =K25*L25 -> 4 | N25: 0
B26: Nb annuel d'électrification ferme 3Moissons | C26: 10 | D26: 20 | E26: 20 | F26: 0 | I26: Verger | K26: 5 | L26: 1 | M26: =K26*L26 -> 5 | N26: 0
B27: Nb total fermes CAP 3Moissons électrifiées | C27: =C26 -> 10 | D27: =C26+D26 -> 30 | E27: =SUM(C26:E26) -> 50 | F27: =E27 -> 50 | I27: Irrigation pour culture de contre-saison | K27: 3 | L27: 4 | M27: =K27*L27 -> 12 | N27: 0
I28: Irrigation pour culture fourragère | K28: 5 | L28: 2 | M28: =K28*L28 -> 10 | N28: 0
B29: Prix de vente kWh Nour à 3Moissons | C29: 0.25 | D29: €/kWh | E29: =C29/2 -> 0.125 | F29: €/kWh | I29: Hangar et aire de stockage | K29: 5 | L29: 3 | M29: =K29*L29 -> 15 | N29: =M29*1.5 -> 22.5
B30: Prix de vente surplus kWh hors 3Moissons | C30: 0.25 | D30: €/kWh | E30: =C30/2 -> 0.125 | F30: €/kWh | I30: Magasin du groupement | K30: 2 | L30: 6 | M30: =K30*L30 -> 12 | N30: =M30 -> 12
B31: kWh vendus par CAP 3Moissons | C31: =N37 -> 75500 | D31: kWh/an | I31: local et petit bureau | K31: 3 | L31: 6 | M31: =K31*L31 -> 18 | N31: =M31 -> 18
I32: Pompage mutualisé 500m3 à 60/100m | K32: 35 | L32: 4 | M32: =K32*L32 -> 140 | N32: =M32/10 -> 14
B33: Services O&M vendus par CAP 3Moissons | C33: 1000 | D33: €/an | I33: Protection périmétrique, sécurité, incendie | K33: 1 | L33: 24 | M33: =K33*L33 -> 24 | N33: =M33 -> 24
B34: Upside CA ventes surplus kWh hors 3M | C34: =$C$22*C12*C13*$C$30 -> 231562.5 | D34: €/an | I34: Divers air comprimé, lavage, froid | K34: 8 | L34: 2 | M34: =K34*L34 -> 16 | N34: =M34 -> 16
L35: Total kWh /j | M35: =SUM(M25:M34) -> 256 | N35: =SUM(N25:N34) -> 106.5
L36: Total saison | M36: =M35*245 -> 62720 | N36: =N35*120 -> 12780
L37: Total Annuel kWh | N37: =M36+N36 -> 75500
B41: O&M | C41: 0.01 | D41: du CAPEX
B42: CAPEX Vieillissement | C42: 0.001 | D42: de 5 à 10 ans
B43: CAPEX Vieillissement | C43: 0.01 | D43: de 10 à 20 ans
B44: CAPEX Vieillissement | C44: 0.05 | D44: après 20 ans

Sheet Hypothèses Nour Haraz
B3: Haraz Goz Aïche | C3: 1 | D3: site
B4: Puissance photovoltaïque | C4: 3000 | D4: kWc
B5: Stockage en battetie | C5: 2000 | D5: kWh
B6: Groupe électrogènes diesel | C6: 1200 | D6: kVA
B7: Courant | C7: 15 kV et 400V | D7: 50Hz triphasés
B8: Ensoleillement | C8: 2200 | D8: h/an
B9: Coefficient pertes | C9: 0.85
B10: Net | C10: =C8*C9 -> 1870 | D10: h équiv./an
B11: Surface panneaux PV | C11: =C4*1000/$E$11 -> 20000 | D11: m² | E11: 150
B13: Investissement Nour Energie pour Haraz en €
B14: Photovoltaïque 3MWc | C14: 4800000 | D14: €
B15: 3Groupesdiesel 400kVA x 3 | C15: 330000 | D15: €
B16: Batterie 2MWh | C16: 1200000 | D16: €
B17: Réseau 15kV/400V triphasé | C17: 180000 | D17: €
B18: Tvx amont / Logistique | C18: 250000 | D18: €
B19: Total Nour pour Haraz | C19: =SUM(C14:C18) -> 6760000 | D19: €
B23: Amortissement CAPEX PV
B24: Durée | C24: 20 | D24: années
B25: Montant Nour pour Haraz | C25: =C19/12 -> 563333.33 | D25: €/an
B26: Coûts OPEX
B27: O&M | C27: 0.01 | D27: du CAPEX
B28: Montant | C28: =C19*C27 -> 67600 | D28: €/an Haraz
B29: Pièces de rechange | C29: 120000 | D29: €
B30: Durée | C30: 20 | D30: années
B31: Montant | C31: =C29/C30 -> 6000 | D31: €/an Haraz
B32: Supervision Nour O&M | C32: 12000 | D32: €/an Haraz
B33: Coût total annuel Haraz | C33: =C25+C28+C31+C32 -> 648933.33 | D33: €/an Haraz
B34: Fee Nour Energie | C34: 0.3 | D34: du coût complet
B35: Montant fee Nour sur Haraz | C35: =C33*C34 -> 194680 | D35: €/an Haraz
B36: Facturation cible vers Haraz | C36: =C33+C35 -> 843613.33 | D36: €/an Haraz
B37: Productible | C37: =C4*C10 -> 5610000 | D37: kWh/an
B38: Cost + fee facturé à Haraz | C38: =C36/C37 -> 0.15037671 | D38: €/kWh
B39: Consommation moyenne Haraz | C39: =C45 -> 4220000 | D39: kWh/an
B40: Prix equilibre sur conso moy Haraz | C40: =C36/C39 -> 0.19990837 | D40: €/kWh
B41: Potentiel max vente hors Haraz | C41: =C46*C38 -> 209023.62 | D41: €/an
B43: Consommation Terap Agro | C43: 220000 | D43: kWh/an
B44: Consommation Terap Industries | C44: 4000000 | D44: kWh/an
B45: Consommation totale Haraz | C45: =SUM(C43:C44) -> 4220000 | D45: kWh/an
B46: Commercialisable hors Haraz | C46: =C37-C39 -> 1390000 | D46: kWh/an
B47: Coefficient vente surplus kWh PV | C47: 0.25 | D47: soit 5h/j
...

Sheet VAN Nour  Baghara
B3: Année / Rubrique | C3: 1 | D3: 2 | E3: 3 | F3: 4 | G3: 5 | H3: 6 | I3: 7 | J3: 8 | K3: 9 | L3: 10 | M3: 11 | N3: 12 | O3: 13 | P3: 14 | Q3: 15 | R3: 16 | S3: 17 | T3: 18 | U3: 19 | V3: 20 | W3: 21
B4: Nour pour 3Moissons
B5: CAPEX Nour pour 3Moissons | C5: ='Hypothèses Nour 3Moissons'!C26*'Hypothèses Nour 3Moissons'!$C$21 -> 1330000 | D5: ='Hypothèses Nour 3Moissons'!D26*'Hypothèses Nour 3Moissons'!$C$21 -> 2660000 | E5: ='Hypothèses Nour 3Moissons'!E26*'Hypothèses Nour 3Moissons'!$C$21 -> 2660000 | F5: 0 | G5: 0 | H5: 0 | I5: 0 | J5: 0 | K5: 0 | L5: 0 | M5: 0 | N5: 0 | O5: 0 | P5: 0 | Q5: 0 | R5: 0 | S5: 0 | T5: 0 | U5: 0 | V5: 0 | W5: 0
B6: Cumul CAPEX pour 3Moissons | C6: =C5 -> 1330000 | D6: =C5+D5 -> 3990000 | E6: =D6+E5 -> 6650000 | F6: =E6+F5 -> 6650000 | G6: =F6+G5 -> 6650000 | H6: =G6+H5 -> 6650000 | I6: =H6+I5 -> 6650000 | J6: =I6+J5 -> 6650000 | K6: =J6+K5 -> 6650000 | L6: =K6+L5 -> 6650000 | ... W6: =V6+W5 -> 6650000
B7: Delta BFR (stock+clients-fournisseurs)) | C7: 0 | D7: 0 | E7: 250000 | F7: 120000 | G7: 60000 | H7: 0 | I7: 0 | J7: 0 | K7: 0 | L7: 0 | M7: 0 | N7: 0 | O7: 0 | P7: 0 | Q7: 0 | R7: 0 | S7: 0 | T7: 0 | U7: 0 | V7: 0 | W7: 0
B8: kWh vendus à 3Moissons | C8: ='Hypothèses Nour 3Moissons'!C26*'Hypothèses Nour 3Moissons'!$N$37 -> 755000 | D8: =C8+'Hypothèses Nour 3Moissons'!D26*'Hypothèses Nour 3Moissons'!$N$37 -> 2265000 | E8: =D8+'Hypothèses Nour 3Moissons'!E26*'Hypothèses Nour 3Moissons'!$N$37 -> 3775000 | F8: =$E$8 -> 3775000 | G8: =$E$8 -> 3775000 | H8: =$E$8 -> 3775000 | I8: =$E$8 -> 3775000 | J8: =$E$8 -> 3775000 | K8: =$E$8 -> 3775000 | L8: =$E$8 -> 3775000 | M8: =$E$8 -> 3775000 | ... W8: =$E$8 -> 3775000
B9: Chiffres d'affaires kWh 3Moissons | C9: ='Hypothèses Nour 3Moissons'!$C$29*'VAN Nour Baghara'!C8 -> 188750 | D9: ='Hypothèses Nour 3Moissons'!$C$29*'VAN Nour Baghara'!D8 -> 566250 | E9: ='Hypothèses Nour 3Moissons'!$C$29*'VAN Nour Baghara'!E8 -> 943750 | F9: ='Hypothèses Nour 3Moissons'!$C$29*'VAN Nour Baghara'!F8 -> 943750 | G9: ='Hypothèses Nour 3Moissons'!$C$29*'VAN Nour Baghara'!G8 -> 943750 | H9: ='Hypothèses Nour 3Moissons'!$C$29*'VAN Nour Baghara'!H8 -> 943750 | I9: ='Hypothèses Nour 3Moissons'!$C$29*'VAN Nour Baghara'!I8 -> 943750 | J9: ='Hypothèses Nour 3Moissons'!$C$29*'VAN Nour Baghara'!J8 -> 943750 | ... W9: ='Hypothèses Nour 3Moissons'!$C$29*'VAN Nour Baghara'!W8 -> 943750
B10: Chiffres d'affaires O&M | C10: ='Hypothèses Nour 3Moissons'!C27*'Hypothèses Nour 3Moissons'!$C$33 -> 10000 | D10: ='Hypothèses Nour 3Moissons'!D27*'Hypothèses Nour 3Moissons'!$C$33 -> 30000 | E10: ='Hypothèses Nour 3Moissons'!E27*'Hypothèses Nour 3Moissons'!$C$33 -> 50000 | F10: =$E$10 -> 50000 | G10: =$E$10 -> 50000 | H10: =$E$10 -> 50000 | I10: =$E$10 -> 50000 | J10: =$E$10 -> 50000 | K10: =$E$10 -> 50000 | L10: =$E$10 -> 50000 | M10: =$E$10 -> 50000 | ... W10: =$E$10 -> 50000
B11: CA total Nour pour 3Moissons en € | C11: =SUM(C9:C10) -> 198750 | D11: =SUM(D9:D10) -> 596250 | E11: =SUM(E9:E10) -> 993750 | F11: =SUM(F9:F10) -> 993750 | G11: =SUM(G9:G10) -> 993750 | H11: =SUM(H9:H10) -> 993750 | I11: =SUM(I9:I10) -> 993750 | J11: =SUM(J9:J10) -> 993750 | ... W11: =SUM(W9:W10) -> 993750
B13: Nour pour Haraz
B14: CAPEX Nour pour Haraz | C14: ='Hypothèses Nour Haraz'!$C$19/2 -> 3380000 | D14: ='Hypothèses Nour Haraz'!$C$19/2 -> 3380000 | E14: 0 | F14: 0 | G14: 0 | H14: 0 | I14: 0 | J14: 0 | K14: 0 | L14: 0 | M14: 0 | N14: 0 | O14: 0 | P14: 0 | Q14: 0 | R14: 0 | S14: 0 | T14: 0 | U14: 0 | V14: 0 | W14: 0
B15: Cumul CAPEX pour Haraz | C15: =C14 -> 3380000 | D15: =C14+D14 -> 6760000 | E15: =D15+E14 -> 6760000 | F15: =E15+F14 -> 6760000 | G15: =F15+G14 -> 6760000 | H15: =G15+H14 -> 6760000 | I15: =H15+I14 -> 6760000 | J15: =I15+J14 -> 6760000 | K15: =J15+K14 -> 6760000 | L15: =K15+L14 -> 6760000 | ... W15: =V15+W14 -> 6760000
B16: kWh vendus à Haraz | C16: ='Hypothèses Nour Haraz'!$C$45/2 -> 2110000 | D16: ='Hypothèses Nour Haraz'!$C$45/2 -> 2110000 | E16: ='Hypothèses Nour Haraz'!$C$45 -> 4220000 | F16: ='Hypothèses Nour Haraz'!$C$45 -> 4220000 | G16: ='Hypothèses Nour Haraz'!$C$45 -> 4220000 | H16: ='Hypothèses Nour Haraz'!$C$45 -> 4220000 | I16: ='Hypothèses Nour Haraz'!$C$45 -> 4220000 | J16: ='Hypothèses Nour Haraz'!$C$45 -> 4220000 | K16: ='Hypothèses Nour Haraz'!$C$45 -> 4220000 | L16: ='Hypothèses Nour Haraz'!$C$45 -> 4220000 | ... W16: ='Hypothèses Nour Haraz'!$C$45 -> 4220000
B17: Chiffres d'affaires kWh Haraz | C17: =C16*'Hypothèses Nour Haraz'!$C$49 -> 527500 | D17: =D16*'Hypothèses Nour Haraz'!$C$49 -> 527500 | E17: =E16*'Hypothèses Nour Haraz'!$C$49 -> 1055000 | F17: =F16*'Hypothèses Nour Haraz'!$C$49 -> 1055000 | G17: =G16*'Hypothèses Nour Haraz'!$C$49 -> 1055000 | H17: =H16*'Hypothèses Nour Haraz'!$C$49 -> 1055000 | I17: =I16*'Hypothèses Nour Haraz'!$C$49 -> 1055000 | J17: =J16*'Hypothèses Nour Haraz'!$C$49 -> 1055000 | ... W17: =W16*'Hypothèses Nour Haraz'!$C$49 -> 1055000
B18: Chiffres d'affaires O&M Haraz | C18: ='Hypothèses Nour Haraz'!C52/2 -> 5000 | D18: ='Hypothèses Nour Haraz'!$C$52 -> 10000 | E18: ='Hypothèses Nour Haraz'!$C$52 -> 10000 | F18: ='Hypothèses Nour Haraz'!$C$52 -> 10000 | G18: ='Hypothèses Nour Haraz'!$C$52 -> 10000 | H18: ='Hypothèses Nour Haraz'!$C$52 -> 10000 | I18: ='Hypothèses Nour Haraz'!$C$52 -> 10000 | J18: ='Hypothèses Nour Haraz'!$C$52 -> 10000 | K18: ='Hypothèses Nour Haraz'!$C$52 -> 10000 | ... W18: ='Hypothèses Nour Haraz'!$C$52 -> 10000
B19: CA total Nour pour Haraz en € | C19: =SUM(C17:C18) -> 532500 | D19: =SUM(D17:D18) -> 537500 | E19: =SUM(E17:E18) -> 1065000 | F19: =SUM(F17:F18) -> 1065000 | G19: =SUM(G17:G18) -> 1065000 | H19: =SUM(H17:H18) -> 1065000 | I19: =SUM(I17:I18) -> 1065000 | J19: =SUM(J17:J18) -> 1065000 | ... W19: =SUM(W17:W18) -> 1065000
B21: Nour pour Baghara (3M + Haraz)
B22: CA Nour kW pour Baghara en € | C22: =C11+C19 -> 731250 | D22: =D11+D19 -> 1133750 | E22: =E11+E19 -> 2058750 | F22: =F11+F19 -> 2058750 | G22: =G11+G19 -> 2058750 | H22: =H11+H19 -> 2058750 | I22: =I11+I19 -> 2058750 | J22: =J11+J19 -> 2058750 | ... W22: =W11+W19 -> 2058750
B23: O&M vendus pour Baghara | C23: =(C6+C15)*'Hypothèses Nour 3Moissons'!$C$41 -> 47100 | D23: =(D6+D15)*'Hypothèses Nour 3Moissons'!$C$41 -> 107500 | E23: =(E6+E15)*'Hypothèses Nour 3Moissons'!$C$41 -> 134100 | F23: =(F6+F15)*'Hypothèses Nour 3Moissons'!$C$41 -> 134100 | G23: =(G6+G15)*'Hypothèses Nour 3Moissons'!$C$41 -> 134100 | H23: =(H6+H15)*'Hypothèses Nour 3Moissons'!$C$41 -> 134100 | I23: =(I6+I15)*'Hypothèses Nour 3Moissons'!$C$41 -> 134100 | J23: =(J6+J15)*'Hypothèses Nour 3Moissons'!$C$41 -> 134100 | ... W23: =(W6+W15)*'Hypothèses Nour 3Moissons'!$C$41 -> 134100
B24: CA total Nour pour Baghara | C24: =SUM(C22:C23) -> 778350 | D24: =SUM(D22:D23) -> 1241250 | E24: =SUM(E22:E23) -> 2192850 | F24: =SUM(F22:F23) -> 2192850 | G24: =SUM(G22:G23) -> 2192850 | H24: =SUM(H22:H23) -> 2192850 | I24: =SUM(I22:I23) -> 2192850 | J24: =SUM(J22:J23) -> 2192850 | ... W24: =SUM(W22:W23) -> 2192850
B26: Upside CA surplus kWh hors Baghara | F26: ='Hypothèses Nour 3Moissons'!$C$3*'Hypothèses Nour 3Moissons'!$C$12*'Hypothèses Nour 3Moissons'!$C$13*'Hypothèses Nour 3Moissons'!$C$30 +'Hypothèses Nour Haraz'!$C$46*'Hypothèses Nour Haraz'!$C$47*'Hypothèses Nour Haraz'!$C$50 -> 318437.5 | G26: ='Hypothèses Nour 3Moissons'!$C$3*'Hypothèses Nour 3Moissons'!$C$12*'Hypothèses Nour 3Moissons'!$C$13*'Hypothèses Nour 3Moissons'!$C$30 +'Hypothèses Nour Haraz'!$C$46*'Hypothèses Nour Haraz'!$C$47*'Hypothèses Nour Haraz'!$C$50 -> 318437.5 | H26: ='Hypothèses Nour 3Moissons'!$C$3*'Hypothèses Nour 3Moissons'!$C$12*'Hypothèses Nour 3Moissons'!$C$13*'Hypothèses Nour 3Moissons'!$C$30 +'Hypothèses Nour Haraz'!$C$46*'Hypothèses Nour Haraz'!$C$47*'Hypothèses Nour Haraz'!$C$50 -> 318437.5 | I26: ='Hypothèses Nour 3Moissons'!$C$3*'Hypothèses Nour 3Moissons'!$C$12*'Hypothèses Nour 3Moissons'!$C$13*'Hypothèses Nour 3Moissons'!$C$30 +'Hypothèses Nour Haraz'!$C$46*'Hypothèses Nour Haraz'!$C$47*'Hypothèses Nour Haraz'!$C$50 -> 318437.5 | J26: ='Hypothèses Nour 3Moissons'!$C$3*'Hypothèses Nour 3Moissons'!$C$12*'Hypothèses Nour 3Moissons'!$C$13*'Hypothèses Nour 3Moissons'!$C$30 +'Hypothèses Nour Haraz'!$C$46*'Hypothèses Nour Haraz'!$C$47*'Hypothèses Nour Haraz'!$C$50 -> 318437.5 | K26: ='Hypothèses Nour 3Moissons'!$C$3*'Hypothèses Nour 3Moissons'!$C$12*'Hypothèses Nour 3Moissons'!$C$13*'Hypothèses Nour 3Moissons'!$C$30 +'Hypothèses Nour Haraz'!$C$46*'Hypothèses Nour Haraz'!$C$47*'Hypothèses Nour Haraz'!$C$50 -> 318437.5 | L26: ='Hypothèses Nour 3Moissons'!$C$3*'Hypothèses Nour 3Moissons'!$C$12*'Hypothèses Nour 3Moissons'!$C$13*'Hypothèses Nour 3Moissons'!$C$30 +'Hypothèses Nour Haraz'!$C$46*'Hypothèses Nour Haraz'!$C$47*'Hypothèses Nour Haraz'!$C$50 -> 318437.5 | M26: ='Hypothèses Nour 3Moissons'!$C$3*'Hypothèses Nour 3Moissons'!$C$12*'Hypothèses Nour 3Moissons'!$C$13*'Hypothèses Nour 3Moissons'!$C$30 +'Hypothèses Nour Haraz'!$C$46*'Hypothèses Nour Haraz'!$C$47*'Hypothèses Nour Haraz'!$C$50 -> 318437.5 | ... W26: ='Hypothèses Nour 3Moissons'!$C$3*'Hypothèses Nour 3Moissons'!$C$12*'Hypothèses Nour 3Moissons'!$C$13*'Hypothèses Nour 3Moissons'!$C$30 +'Hypothèses Nour Haraz'!$C$46*'Hypothèses Nour Haraz'!$C$47*'Hypothèses Nour Haraz'!$C$50 -> 318437.5
B29: CAPEX vieillisement | H29: ='Hypothèses Nour 3Moissons'!$C$42*('VAN Nour Baghara'!H6+'VAN Nour Baghara'!H15) -> 13410 | I29: ='Hypothèses Nour 3Moissons'!$C$42*('VAN Nour Baghara'!I6+'VAN Nour Baghara'!I15) -> 13410 | J29: ='Hypothèses Nour 3Moissons'!$C$42*('VAN Nour Baghara'!J6+'VAN Nour Baghara'!J15) -> 13410 | K29: ='Hypothèses Nour 3Moissons'!$C$42*('VAN Nour Baghara'!K6+'VAN Nour Baghara'!K15) -> 13410 | L29: ='Hypothèses Nour 3Moissons'!$C$42*('VAN Nour Baghara'!L6+'VAN Nour Baghara'!L15) -> 13410 | M29: ='Hypothèses Nour 3Moissons'!$C$43*('VAN Nour Baghara'!M6+'VAN Nour Baghara'!M15) -> 134100 | N29: ='Hypothèses Nour 3Moissons'!$C$43*('VAN Nour Baghara'!N6+'VAN Nour Baghara'!N15) -> 134100 | O29: ='Hypothèses Nour 3Moissons'!$C$43*('VAN Nour Baghara'!O6+'VAN Nour Baghara'!O15) -> 134100 | P29: ='Hypothèses Nour 3Moissons'!$C$43*('VAN Nour Baghara'!P6+'VAN Nour Baghara'!P15) -> 134100 | Q29: ='Hypothèses Nour 3Moissons'!$C$43*('VAN Nour Baghara'!Q6+'VAN Nour Baghara'!Q15) -> 134100 | R29: ='Hypothèses Nour 3Moissons'!$C$43*('VAN Nour Baghara'!R6+'VAN Nour Baghara'!R15) -> 134100 | S29: ='Hypothèses Nour 3Moissons'!$C$43*('VAN Nour Baghara'!S6+'VAN Nour Baghara'!S15) -> 134100 | T29: ='Hypothèses Nour 3Moissons'!$C$43*('VAN Nour Baghara'!T6+'VAN Nour Baghara'!T15) -> 134100 | ... V29: ='Hypothèses Nour 3Moissons'!$C$43*('VAN Nour Baghara'!V6+'VAN Nour Baghara'!V15) -> 134100 | W29: ='Hypothèses Nour 3Moissons'!$C$44*('VAN Nour Baghara'!W6+'VAN Nour Baghara'!W15) -> 670500
B30: CAPEX annuel pour Baghara | C30: =C5+C14+C29 -> 4710000 | D30: =D5+D14+D29 -> 6040000 | E30: =E5+E14+E29 -> 2660000 | F30: =F5+F14+F29 -> 0 | G30: =G5+G14+G29 -> 0 | H30: =H5+H14+H29 -> 13410 | I30: =I5+I14+I29 -> 13410 | J30: =J5+J14+J29 -> 13410 | ... W30: =W5+W14+W29 -> 670500
B32: Impôts et taxes | C32: 0.025
B33: Impôts et taxes annuel | C33: =C24*$C$32 -> 19458.75 | D33: =D24*$C$32 -> 31031.25 | E33: =E24*$C$32 -> 54821.25 | F33: =F24*$C$32 -> 54821.25 | G33: =G24*$C$32 -> 54821.25 | H33: =H24*$C$32 -> 54821.25 | I33: =I24*$C$32 -> 54821.25 | J33: =J24*$C$32 -> 54821.25 | ... W33: =W24*$C$32 -> 54821.25
B34: Cash net généré | C34: =C24-C30-C7-C33 -> -3951108.8 | D34: =D24-D30-D7-D33 -> -4829781.2 | E34: =E24-E30-E7-E33 -> -771971.25 | F34: =F24-F30-F7-F33 -> 2018028.8 | G34: =G24-G30-G7-G33 -> 2078028.8 | H34: =H24-H30-H7-H33 -> 2124618.8 | I34: =I24-I30-I7-I33 -> 2124618.8 | J34: =J24-J30-J7-J33 -> 2124618.8 | ... W34: =W24-W30-W7-W33 -> 1467528.8
B35: CMPC (WACC) et coeffactualisation | C35: 0.06 | D35: =1/(1+C35) -> 0.94339623
B36: Coeff actualisation | C36: 1 | D36: =C36*$D$35 -> 0.94339623 | E36: =D36*$D$35 -> 0.88999644 | F36: =E36*$D$35 -> 0.83961928 | G36: =F36*$D$35 -> 0.79209366 | H36: =G36*$D$35 -> 0.74725817 | I36: =H36*$D$35 -> 0.70496054 | J36: =I36*$D$35 -> 0.66505711 | K36: =J36*$D$35 -> 0.62741237 | ... W36: =V36*$D$35 -> 0.31180473
B37: Cash net actualisé | C37: =C34*C36 -> -3951108.8 | D37: =D34*D36 -> -4556397.4 | E37: =E34*E36 -> -687051.66 | F37: =F34*F36 -> 1694375.9 | G37: =G34*G36 -> 1645993.4 | H37: =H34*H36 -> 1587638.7 | I37: =I34*I36 -> 1497772.4 | J37: =J34*J36 -> 1412992.8 | ... W37: =W34*W36 -> 457582.4
B40: Sensibilité CAPEX +10% | C40: 1.1
B41: Cash net généré 110% CAPEX | C41: =C24-$C$40*C30-C7-C33 -> -4422108.8 | D41: =D24-$C$40*D30-D7-D33 -> -5433781.3 | E41: =E24-$C$40*E30-E7-E33 -> -1037971.3 | F41: =F24-$C$40*F30-F7-F33 -> 2018028.8 | G41: =G24-$C$40*G30-G7-G33 -> 2078028.8 | H41: =H24-$C$40*H30-H7-H33 -> 2123277.8 | I41: =I24-$C$40*I30-I7-I33 -> 2123277.8 | J41: =J24-$C$40*J30-J7-J33 -> 2123277.8 | ... W41: =W24-$C$40*W30-W7-W33 -> 1400478.8
B42: Cash net actualisé 110% CAPEX | C42: =C41*C36 -> -4422108.8 | D42: =D41*D36 -> -5126208.7 | E42: =E41*E36 -> -923790.72 | F42: =F41*F36 -> 1694375.9 | G42: =G41*G36 -> 1645993.4 | H42: =H41*H36 -> 1586636.7 | I42: =I41*I36 -> 1496827 | J42: =J41*J36 -> 1412101 | ... W42: =W41*W36 -> 436675.89
B45: Sensibilité Chiffres d'affaires -10% | C45: =1-10% -> 0.9
B46: Cash net généré 90% CA | C46: =$C$45*C24-C30-C7-C45*C33 -> -4026997.9 | D46: =$C$45*D24-D30-D7-D45*D33 -> -4922875 | E46: =$C$45*E24-E30-E7-E45*E33 -> -936435 | F46: =$C$45*F24-F30-F7-F45*F33 -> 1853565 | G46: =$C$45*G24-G30-G7-G45*G33 -> 1913565 | H46: =$C$45*H24-H30-H7-H45*H33 -> 1960155 | I46: =$C$45*I24-I30-I7-I45*I33 -> 1960155 | J46: =$C$45*J24-J30-J7-J45*J33 -> 1960155 | ... W46: =$C$45*W24-W30-W7-W45*W33 -> 1303065
B47: Cash net actualisé 90% CA | C47: =C46*C36 -> -4026997.9 | D47: =D46*D36 -> -4644221.7 | E47: =E46*E36 -> -833423.82 | F47: =F46*F36 -> 1556288.9 | G47: =G46*G36 -> 1515722.7 | H47: =H46*H36 -> 1464741.8 | I47: =I46*I36 -> 1381831.9 | J47: =J46*J36 -> 1303615 | ... W47: =W46*W36 -> 406301.83
B49: Sensibilité taxes x 5 | C49: 5
B50: Cash net généré 500% Taxes | C50: =C24-C30-C7-$C$49*C33 -> -4028943.8 | D50: =D24-D30-D7-$C$49*D33 -> -4953906.2 | E50: =E24-E30-E7-$C$49*E33 -> -991256.25 | F50: =F24-F30-F7-$C$49*F33 -> 1798743.8 | G50: =G24-G30-G7-$C$49*G33 -> 1858743.8 | H50: =H24-H30-H7-$C$49*H33 -> 1905333.8 | I50: =I24-I30-I7-$C$49*I33 -> 1905333.8 | J50: =J24-J30-J7-$C$49*J33 -> 1905333.8 | ... W50: =W24-W30-W7-$C$49*W33 -> 1248243.8
B51: Cash net actualisé 500% Taxes | C51: =C50*C36 -> -4028943.8 | D51: =D50*D36 -> -4673496.5 | E51: =E50*E36 -> -882214.53 | F51: =F50*F36 -> 1510259.9 | G51: =G50*G36 -> 1472299.1 | H51: =H50*H36 -> 1423776.2 | I51: =I50*I36 -> 1343185.1 | J51: =J50*J36 -> 1267155.8 | ... W51: =W50*W36 -> 389208.3
B53: Sensibilités | C53: Aucune | D53: CAPEX+10% | E53: CA-10% | F53: Taxes x5
B54: VAN (NPV) projet Nour € | C54: =SUM(C37:W37) -> 10422332 | D54: =SUM(C42:V42) -> 8624305.4 | E54: =SUM(C47:W47) -> 8527387 | F54: =SUM(C51:W51) -> 7919089.1
...
