Workbook
Name clé_répartition: [1]BO!$E$44:$E$47
Name création_reprise: [1]BO!$E$12:$E$13
Name nom_projet: [1]param!$B$49:$B$54
Name type_amort_prêt: [1]BO!$B$4:$B$6
Name type_prêt: [1]BO!$C$4:$C$5

Sheet VAN des CAP
B2: VAN calculée sur les 10 premières années en MCFA
B4: Cashflow = EBITDA-CAPEX -D(BFR)-IS
B5: Taux de change MCFA/€ | C5: 655.957
B6: CMPC | C6: 0.02 | D6: =1/(1+C6) -> 0.98039216
B7: IMF Impôt minimum forfaitaire | C7: 0
B8: Bail 25 ans en usufruit sur le SMIC Agricole
B9: Production en début d'année 2
B10: C.A. constant 7 ans après la mise en service
B11: Prix suivent l'inflation
B12: 3 CAP en plus dans Haraz
B13: Année | D13: 1 | E13: 2 | F13: 3 | G13: 4 | H13: 5 | I13: 6 | J13: 7 | K13: 8 | L13: 9 | M13: 10 | N13: 11 | O13: 12
B14: CMPC | D14: 0 | E14: 0 | F14: 0 | G14: 0 | H14: 0 | I14: 0 | J14: 0 | K14: 0 | L14: =$C$6 -> 0.02 | M14: =$C$6 -> 0.02 | N14: =$C$6 -> 0.02 | O14: =$C$6 -> 0.02
B15: Taux actualisation 1 CAP | D15: 1 | E15: =1/(1+E14) -> 1 | F15: =E15*$E$15 -> 1 | G15: =F15*$E$15 -> 1 | H15: =G15*$E$15 -> 1 | I15: =H15*$E$15 -> 1 | J15: =I15*$E$15 -> 1 | K15: =J15*$E$15 -> 1 | L15: =K15*$D$6 -> 0.98039216 | M15: =L15*$D$6 -> 0.96116878 | N15: =M15*$D$6 -> 0.94232233 | O15: =N15*$D$6 -> 0.92384543
B17: 1 CAP
B18: Année | C18: Total | D18: 1 | E18: 2 | F18: 3 | G18: 4 | H18: 5 | I18: 6 | J18: 7 | K18: 8 | L18: 9 | M18: 10
B19: C.A. | D19: ='1 CAP'!D33 -> 0 | E19: ='1 CAP'!E33 -> 218.11174 | F19: ='1 CAP'!F33 -> 280.32446 | G19: ='1 CAP'!G33 -> 346.64505 | H19: ='1 CAP'!H33 -> 395.34724 | I19: ='1 CAP'!I33 -> 437.38346 | J19: ='1 CAP'!J33 -> 459.25263 | K19: =$J$19 -> 459.25263 | L19: =$J$19 -> 459.25263 | M19: =$J$19 -> 459.25263
B20: RN avant IS | D20: ='1 CAP'!D37 -> -26.395759 | E20: ='1 CAP'!E37 -> -13.186375 | F20: ='1 CAP'!F37 -> 31.820881 | G20: ='1 CAP'!G37 -> 46.550953 | H20: ='1 CAP'!H37 -> 84.411473 | I20: ='1 CAP'!I37 -> 109.2757 | J20: ='1 CAP'!J37 -> 118.07473 | K20: =$J$20 -> 118.07473 | L20: =$J$20 -> 118.07473 | M20: =$J$20 -> 118.07473
B21: IMF | D21: =D19*$C$7 -> 0 | E21: =E19*$C$7 -> 0 | F21: =F19*$C$7 -> 0 | G21: =G19*$C$7 -> 0 | H21: =H19*$C$7 -> 0 | I21: =I19*$C$7 -> 0 | J21: =J19*$C$7 -> 0 | K21: =K19*$C$7 -> 0 | ... M21: =M19*$C$7 -> 0
B22: CAPEX | D22: =Invest!$D$36/1000000 -> 248.3825 | E22: 0 | F22: 0 | G22: 0 | H22: 0 | I22: 0 | J22: 0 | K22: 0 | L22: 0 | M22: 0
B23: Cash flow net | D23: =D20-D21-D22 -> -274.77826 | E23: =E20-E21-E22 -> -13.186375 | F23: =F20-F21-F22 -> 31.820881 | G23: =G20-G21-G22 -> 46.550953 | H23: =H20-H21-H22 -> 84.411473 | I23: =I20-I21-I22 -> 109.2757 | J23: =J20-J21-J22 -> 118.07473 | K23: =K20-K21-K22 -> 118.07473 | ... M23: =M20-M21-M22 -> 118.07473
A24: AN à 10 | B24: CF net actualisé | D24: =D23*D15 -> -274.77826 | E24: =E23*E15 -> -13.186375 | F24: =F23*F15 -> 31.820881 | G24: =G23*G15 -> 46.550953 | H24: =H23*H15 -> 84.411473 | I24: =I23*I15 -> 109.2757 | J24: =J23*J15 -> 118.07473 | K24: =K23*K15 -> 118.07473 | ... M24: =M23*M15 -> 113.48974
B25: VAN à 10 ans d'1 CAP en MCFA | C25: =SUM(D24:M24) -> 449.49311
B26: VAN à 10 ans d'1 CAP en M€ | C26: =C25/$C$5 -> 0.68524783
B28: 10 premières CAP
B29: Année | C29: Total | D29: 1 | E29: 2 | F29: 3 | G29: 4 | H29: 5 | I29: 6 | J29: 7 | K29: 8 | L29: 9 | M29: 10
B30: C.A. | D30: =10*D19 -> 0 | E30: =10*E19 -> 2181.1174 | F30: =10*F19 -> 2803.2446 | G30: =10*G19 -> 3466.4505 | H30: =10*H19 -> 3953.4724 | I30: =10*I19 -> 4373.8346 | J30: =10*J19 -> 4592.5263 | K30: =10*K19 -> 4592.5263 | ... M30: =10*M19 -> 4592.5263
B31: RN avant IS | D31: =10*D20 -> -263.95759 | E31: =10*E20 -> -131.86375 | F31: =10*F20 -> 318.20881 | G31: =10*G20 -> 465.50953 | H31: =10*H20 -> 844.11473 | I31: =10*I20 -> 1092.757 | J31: =10*J20 -> 1180.7473 | K31: =10*K20 -> 1180.7473 | ... M31: =10*M20 -> 1180.7473
B32: IMF | D32: =10*D21 -> 0 | E32: =10*E21 -> 0 | F32: =10*F21 -> 0 | G32: =10*G21 -> 0 | H32: =10*H21 -> 0 | I32: =10*I21 -> 0 | J32: =10*J21 -> 0 | K32: =10*K21 -> 0 | ... M32: =10*M21 -> 0
B33: CAPEX | D33: =10*D22 -> 2483.825 | E33: =10*E22 -> 0 | F33: =10*F22 -> 0 | G33: =10*G22 -> 0 | H33: =10*H22 -> 0 | I33: =10*I22 -> 0 | J33: =10*J22 -> 0 | K33: =10*K22 -> 0 | ... M33: =10*M22 -> 0
B34: Cash flow net | D34: =10*D23 -> -2747.7826 | E34: =10*E23 -> -131.86375 | F34: =10*F23 -> 318.20881 | G34: =10*G23 -> 465.50953 | H34: =10*H23 -> 844.11473 | I34: =10*I23 -> 1092.757 | J34: =10*J23 -> 1180.7473 | K34: =10*K23 -> 1180.7473 | ... M34: =10*M23 -> 1180.7473
B35: CF net actualisé | D35: =10*D24 -> -2747.7826 | E35: =10*E24 -> -131.86375 | F35: =10*F24 -> 318.20881 | G35: =10*G24 -> 465.50953 | H35: =10*H24 -> 844.11473 | I35: =10*I24 -> 1092.757 | J35: =10*J24 -> 1180.7473 | K35: =10*K24 -> 1180.7473 | ... M35: =10*M24 -> 1134.8974
B36: VAN à 10 ans de 10 CAP en MCFA | C36: =SUM(D35:M35) -> 4494.9311
B37: VAN à 10 ans de 10 CAP en M€ | C37: =C36/$C$5 -> 6.8524783
B40: 50 premières CAP (étape 1)
B41: Année | C41: Total | D41: 1 | E41: 2 | F41: 3 | G41: 4 | H41: 5 | I41: 6 | J41: 7 | K41: 8 | L41: 9 | M41: 10 | N41: 11 | O41: 12
B42: C.A. | D42: ='50 CAP'!D33 -> 0 | E42: ='50 CAP'!E33 -> 2181.1174 | F42: ='50 CAP'!F33 -> 7165.4794 | G42: ='50 CAP'!G33 -> 13435.174 | H42: ='50 CAP'!H33 -> 16492.862 | I42: ='50 CAP'!I33 -> 19213.68 | J42: ='50 CAP'!J33 -> 21247.14 | K42: =$J$42 -> 21247.14 | L42: =$J$42 -> 21247.14 | M42: =$J$42 -> 21247.14 | N42: =$J$42 -> 21247.14 | O42: =$J$42 -> 21247.14
B43: RN avant IS | D43: ='50 CAP'!D37 -> -263.95759 | E43: ='50 CAP'!E37 -> -659.77893 | F43: ='50 CAP'!F37 -> -704.17742 | G43: ='50 CAP'!G37 -> 187.6175 | H43: ='50 CAP'!H37 -> 1466.6103 | I43: ='50 CAP'!I37 -> 2587.5637 | J43: ='50 CAP'!J37 -> 3796.4578 | K43: =$J$43 -> 3796.4578 | L43: =$J$43 -> 3796.4578 | M43: =$J$43 -> 3796.4578 | N43: =$J$43 -> 3796.4578 | O43: =$J$43 -> 3796.4578
B44: IMF | D44: =D42*$C$7 -> 0 | E44: =E42*$C$7 -> 0 | F44: =F42*$C$7 -> 0 | G44: =G42*$C$7 -> 0 | H44: =H42*$C$7 -> 0 | I44: =I42*$C$7 -> 0 | J44: =J42*$C$7 -> 0 | K44: =K42*$C$7 -> 0 | ... O44: =O42*$C$7 -> 0
B45: CAPEX | D45: =Invest!D20 -> 2483.825 | E45: =Invest!E20 -> 4967.65 | F45: =Invest!F20 -> 4967.65 | G45: =Invest!G22 -> 0 | H45: =Invest!H22 -> 0 | I45: =Invest!I22 -> 0 | J45: =Invest!J22 -> 0 | K45: =Invest!K22 -> 0 | L45: =Invest!L22 -> 0 | M45: =Invest!M22 -> 0 | N45: =Invest!N22 -> 0 | O45: =Invest!O22 -> 0
B46: Cash flow net | D46: =D43-D44-D45 -> -2747.7826 | E46: =E43-E44-E45 -> -5627.4289 | F46: =F43-F44-F45 -> -5671.8274 | G46: =G43-G44-G45 -> 187.6175 | H46: =H43-H44-H45 -> 1466.6103 | I46: =I43-I44-I45 -> 2587.5637 | J46: =J43-J44-J45 -> 3796.4578 | K46: =K43-K44-K45 -> 3796.4578 | ... O46: =O43-O44-O45 -> 3796.4578
...

Sheet 1 CAP
A1: BAGHARA CAP 3 MOISSONS | E1: PREVISIONS 7 ANS:
E2: en MCFA
B10: Date début simulation: | D10: 46023
B12: Année: | D12: 1 | E12: =1+D12 -> 2 | F12: =1+E12 -> 3 | G12: =1+F12 -> 4 | H12: =1+G12 -> 5 | I12: =1+H12 -> 6 | J12: =1+I12 -> 7
B13: Date début année: | D13: =D10 -> 46023 | E13: =[2]PL!E5 -> 46388 | F13: =[2]PL!F5 -> 46753 | G13: =[2]PL!G5 -> 47119 | H13: =[2]PL!H5 -> 47484 | I13: =[2]PL!I5 -> 47849 | J13: =[2]PL!J5 -> 48214
B15: Nb de CAP crées par année:
B17: Nb de CAP crées année 1 | C17: 1
B19: Nb de CAP crées année 2
B21: Nb de CAP crées année 3
B23: Total cumulé: | C23: =SUM(C17:C22) -> 1
B28: Prévisions pour total des CAP
B30: C.A. et Résultat:
B32: Année: | C32: Total 7 ans | D32: =D12 -> 1 | E32: =E12 -> 2 | F32: =F12 -> 3 | G32: =G12 -> 4 | H32: =H12 -> 5 | I32: =I12 -> 6 | J32: =J12 -> 7
B33: C.A. | C33: =SUM(D33:J33) -> 2137.0646 | D33: =[2]PL!D27 -> 0 | E33: =[2]PL!E27 -> 218.11174 | F33: =[2]PL!F27 -> 280.32446 | G33: =[2]PL!G27 -> 346.64505 | H33: =[2]PL!H27 -> 395.34724 | I33: =[2]PL!I27 -> 437.38346 | J33: =[2]PL!J27 -> 459.25263
B34: CA (en M€): | C34: =C33/656 -> 3.2577204 | D34: =D33/656 -> 0 | E34: =E33/656 -> 0.33248741 | F34: =F33/656 -> 0.42732387 | G34: =G33/656 -> 0.52842233 | H34: =H33/656 -> 0.60266347 | I34: =I33/656 -> 0.66674307 | J34: =J33/656 -> 0.70008023
B35: Achats matière | C35: =SUM(D35:J35) -> 856.91747 | D35: =[2]PL!D30 -> 0 | E35: =[2]PL!E30 -> 132.57599 | F35: =[2]PL!F30 -> 124.47599 | G35: =[2]PL!G30 -> 136.36815 | H35: =[2]PL!H30 -> 142.56436 | I35: =[2]PL!I30 -> 156.14982 | J35: =[2]PL!J30 -> 164.78315
B36: Taux marge / achats | D36: =[2]PL!D32 -> 0 | E36: =[2]PL!E32 -> 0.39216481 | F36: =[2]PL!F32 -> 0.55595743 | G36: =[2]PL!G32 -> 0.6066058 | H36: =[2]PL!H32 -> 0.63939456 | I36: =[2]PL!I32 -> 0.64299103 | J36: =[2]PL!J32 -> 0.6411928
B37: Résultat net (hors IS) | C37: =SUM(D37:J37) -> 350.5516 | D37: =[2]PL!D47 -> -26.395759 | E37: =[2]PL!E47 -> -13.186375 | F37: =[2]PL!F47 -> 31.820881 | G37: =[2]PL!G47 -> 46.550953 | H37: =[2]PL!H47 -> 84.411473 | I37: =[2]PL!I47 -> 109.2757 | J37: =[2]PL!J47 -> 118.07473
B57: Consomation électrique
B59: Consomation annuelle par CAP (kwh) | C59: 75500 | D59: au bout de 4 ans
B60: P.U. du kwh en euros | C60: =E61/15/75500 -> 0.16512141 | D60: PU ne tenant compte que du coût des investissements NOUR (hors faibles coûts salariaux):
B61: P.U. du kwh en CFA | C61: =657*C60 -> 108.48477 | E61: 187000 | F61: =CONCATENATE("( soit ",E61*656," CFA)") -> ( soit 122672000 CFA) | G61: par CAP amorti sur 15 ans
B63: Année | C63: Total 7 ans | D63: =D74 -> 1 | E63: =E74 -> 2 | F63: =F74 -> 3 | G63: =G74 -> 4 | H63: =H74 -> 5 | I63: =I74 -> 6 | J63: =J74 -> 7
B64: Consomation électrique en Mwh | C64: =SUM(D64:J64) -> 408.11813 | D64: =[2]PL!D144 -> 0 | E64: =[2]PL!E144 -> 41.653096 | F64: =[2]PL!F144 -> 53.533943 | G64: =[2]PL!G144 -> 66.199277 | H64: =[2]PL!H144 -> 75.5 | I64: =[2]PL!I144 -> 83.527714 | J64: =[2]PL!J144 -> 87.704099
B65: Puissance de crête necessaire sur 1 an en MWc (1 MWc => 1,8 GWh) | C65: MWc | D65: =D64/1800 -> 0 | E65: =E64/1800 -> 0.023140609 | F65: =F64/1800 -> 0.029741079 | G65: =G64/1800 -> 0.036777376 | H65: =H64/1800 -> 0.041944444 | I65: =I64/1800 -> 0.046404285 | J65: =J64/1800 -> 0.0487245
B66: Consomation électrique en MCFA | C66: =SUM(D66:J66) -> 44.274601 | D66: =[2]PL!D146 -> 0 | E66: =[2]PL!E146 -> 4.5187264 | F66: =[2]PL!F146 -> 5.8076174 | G66: =[2]PL!G146 -> 7.1816132 | H66: =[2]PL!H146 -> 8.1906 | I66: =[2]PL!I146 -> 9.0614847 | J66: =[2]PL!J146 -> 9.5145589
B67: Consomation électrique en M€ | C67: =SUM(D67:J67) -> 0.067491769 | D67: =D66/656 -> 0 | E67: =E66/656 -> 0.0068883025 | F67: =F66/656 -> 0.0088530753 | G67: =G66/656 -> 0.010947581 | H67: =H66/656 -> 0.012485671 | I67: =I66/656 -> 0.013813239 | J67: =J66/656 -> 0.014503901
B72: Investissements financés par emprunts:
B74: Année: | C74: Total 7 ans | D74: =D$12 -> 1 | E74: =E$12 -> 2 | F74: =F$12 -> 3 | G74: =G$12 -> 4 | H74: =H$12 -> 5 | I74: =I$12 -> 6 | J74: =J$12 -> 7
B75: Investissements de l'année | C75: =SUM(D75:J75) -> 248.3825 | D75: =[2]Invest!D20 -> 248.3825 | E75: =[2]Invest!E20 -> 0 | F75: =[2]Invest!F20 -> 0 | G75: =[2]Invest!G20 -> 0 | H75: =[2]Invest!H20 -> 0 | I75: =[2]Invest!I20 -> 0 | J75: =[2]Invest!J20 -> 0
B76: Investissements cumulés | D76: =[2]Invest!D21 -> 248.3825 | E76: =[2]Invest!E21 -> 248.3825 | F76: =[2]Invest!F21 -> 248.3825 | G76: =[2]Invest!G21 -> 248.3825 | H76: =[2]Invest!H21 -> 248.3825 | I76: =[2]Invest!I21 -> 248.3825 | J76: =[2]Invest!J21 -> 248.3825
B77: Investissements cumulés (en M€) | C77: =C75/656 -> 0.37863186
B78: Detail immos: | C78: =SUM(C79:C86) -> 248.3825
B79: =[3]invest!$H225 -> charges immobilisées | C79: =[3]invest!$I225*$C$23/1000000 -> 5
B80: =[3]invest!$H226 -> immos incorporelles | C80: =[3]invest!$I226*$C$23/1000000 -> 1.84
B81: =[3]invest!$H227 -> foncier
B82: =[3]invest!$H228 -> aménagements et const. | C82: =[3]invest!$I228*$C$23/1000000 -> 96
B83: =[3]invest!$J225 -> matériels et équipements | C83: =[3]invest!$L225*$C$23/1000000 -> 135.4
B84: =[3]invest!$J226 -> moyens roulants | C84: =[3]invest!$L226*$C$23/1000000 -> 4.8
B85: =[3]invest!$J227 -> matériels de bureau | C85: =[3]invest!$L227*$C$23/1000000 -> 3.5975
...

Sheet 50 CAP
A1: BAGHARA CAP 3 MOISSONS | E1: PREVISIONS 7 ANS:
E2: en MCFA
B10: Date début simulation: | D10: 46023
B12: Année: | D12: 1 | E12: =1+D12 -> 2 | F12: =1+E12 -> 3 | G12: =1+F12 -> 4 | H12: =1+G12 -> 5 | I12: =1+H12 -> 6 | J12: =1+I12 -> 7
B13: Date début année: | D13: =D10 -> 46023 | E13: =PL!E5 -> 46388 | F13: =PL!F5 -> 46753 | G13: =PL!G5 -> 47119 | H13: =PL!H5 -> 47484 | I13: =PL!I5 -> 47849 | J13: =PL!J5 -> 48214
B15: Nb de CAP crées par année:
B17: Nb de CAP crées année 1 | C17: 10
B19: Nb de CAP crées année 2 | C19: 20
B21: Nb de CAP crées année 3 | C21: 20
B23: Total cumulé: | C23: =SUM(C17:C22) -> 50
B28: Prévisions pour total des CAP
B30: C.A. et Résultat:
B32: Année: | C32: Total 7 ans | D32: =D12 -> 1 | E32: =E12 -> 2 | F32: =F12 -> 3 | G32: =G12 -> 4 | H32: =H12 -> 5 | I32: =I12 -> 6 | J32: =J12 -> 7
B33: C.A. | C33: =SUM(D33:J33) -> 79735.454 | D33: =PL!D27 -> 0 | E33: =PL!E27 -> 2181.1174 | F33: =PL!F27 -> 7165.4794 | G33: =PL!G27 -> 13435.174 | H33: =PL!H27 -> 16492.862 | I33: =PL!I27 -> 19213.68 | J33: =PL!J27 -> 21247.14
B34: CA (en M€): | C34: =C33/656 -> 121.54795 | D34: =D33/656 -> 0 | E34: =E33/656 -> 3.3248741 | F34: =F33/656 -> 10.922987 | G34: =G33/656 -> 20.480449 | H34: =H33/656 -> 25.141559 | I34: =I33/656 -> 29.289147 | J34: =J33/656 -> 32.388933
B35: Achats matière | C35: =SUM(D35:J35) -> 33131.551 | D35: =PL!D30 -> 0 | E35: =PL!E30 -> 1325.7599 | F35: =PL!F30 -> 3896.2798 | G35: =PL!G30 -> 6504.7212 | H35: =PL!H30 -> 6642.5265 | I35: =PL!I30 -> 7140.1485 | J35: =PL!J30 -> 7622.1151
B36: Taux marge / achats | D36: =PL!D32 -> 0 | E36: =PL!E32 -> 0.39216481 | F36: =PL!F32 -> 0.45624297 | G36: =PL!G32 -> 0.51584393 | H36: =PL!H32 -> 0.59724841 | I36: =PL!I32 -> 0.62838205 | J36: =PL!J32 -> 0.64126395
B37: Résultat net (hors IS) | C37: =SUM(D37:J37) -> 6410.3354 | D37: =PL!D47 -> -263.95759 | E37: =PL!E47 -> -659.77893 | F37: =PL!F47 -> -704.17742 | G37: =PL!G47 -> 187.6175 | H37: =PL!H47 -> 1466.6103 | I37: =PL!I47 -> 2587.5637 | J37: =PL!J47 -> 3796.4578
B57: Consomation électrique
B59: Consomation annuelle par CAP (kwh) | C59: 75500 | D59: au bout de 4 ans
B60: P.U. du kwh en euros | C60: =E61/15/75500 -> 0.16512141 | D60: PU ne tenant compte que du coût des investissements NOUR (hors faibles coûts salariaux):
B61: P.U. du kwh en CFA | C61: =657*C60 -> 108.48477 | E61: 187000 | F61: =CONCATENATE("( soit ",E61*656," CFA)") -> ( soit 122672000 CFA) | G61: par CAP, amorti sur 15 ans
B63: Année | C63: Total 7 ans | D63: =D74 -> 1 | E63: =E74 -> 2 | F63: =F74 -> 3 | G63: =G74 -> 4 | H63: =H74 -> 5 | I63: =I74 -> 6 | J63: =J74 -> 7
B64: Consomation électrique en Mwh | C64: =SUM(D64:J64) -> 15227.188 | D64: =PL!D144 -> 0 | E64: =PL!E144 -> 416.53096 | F64: =PL!F144 -> 1368.4013 | G64: =PL!G144 -> 2565.7335 | H64: =PL!H144 -> 3149.6644 | I64: =PL!I144 -> 3669.2627 | J64: =PL!J144 -> 4057.5953
B65: Puissance de crête necessaire sur 1 an en MWc (1 MWc => 1,8 GWh) | C65: MWc | D65: =D64/1800 -> 0 | E65: =E64/1800 -> 0.23140609 | F65: =F64/1800 -> 0.76022297 | G65: =G64/1800 -> 1.4254075 | H65: =H64/1800 -> 1.7498135 | I65: =I64/1800 -> 2.0384793 | J65: =J64/1800 -> 2.2542196
B66: Consomation électrique en MCFA | C66: =SUM(D66:J66) -> 1651.918 | D66: =PL!D146 -> 0 | E66: =PL!E146 -> 45.187264 | F66: =PL!F146 -> 148.4507 | G66: =PL!G146 -> 278.34301 | H66: =PL!H146 -> 341.69061 | I66: =PL!I146 -> 398.05911 | J66: =PL!J146 -> 440.18728
B67: Consomation électrique en M€ | C67: =SUM(D67:J67) -> 2.5181677 | D67: =D66/656 -> 0 | E67: =E66/656 -> 0.068883025 | F67: =F66/656 -> 0.2262968 | G67: =G66/656 -> 0.42430337 | H67: =H66/656 -> 0.52086983 | I67: =I66/656 -> 0.60679742 | J67: =J66/656 -> 0.6710172
B72: Investissements financés par emprunts:
B74: Année: | C74: Total 7 ans | D74: =D$12 -> 1 | E74: =E$12 -> 2 | F74: =F$12 -> 3 | G74: =G$12 -> 4 | H74: =H$12 -> 5 | I74: =I$12 -> 6 | J74: =J$12 -> 7
B75: Investissements de l'année | C75: =SUM(D75:J75) -> 12419.125 | D75: =Invest!D20 -> 2483.825 | E75: =Invest!E20 -> 4967.65 | F75: =Invest!F20 -> 4967.65 | G75: =Invest!G20 -> 0 | H75: =Invest!H20 -> 0 | I75: =Invest!I20 -> 0 | J75: =Invest!J20 -> 0
B76: Investissements cumulés | D76: =Invest!D21 -> 2483.825 | E76: =Invest!E21 -> 7451.475 | F76: =Invest!F21 -> 12419.125 | G76: =Invest!G21 -> 12419.125 | H76: =Invest!H21 -> 12419.125 | I76: =Invest!I21 -> 12419.125 | J76: =Invest!J21 -> 12419.125
B77: Investissements cumulés (en M€) | C77: =C75/656 -> 18.931593 | D77: =D76/656 -> 3.7863186 | E77: =E76/656 -> 11.358956 | F77: =F76/656 -> 18.931593
B78: Detail immos: | C78: =SUM(C79:C86) -> 12419.125 | D78: =SUM(D79:D86) -> 2483.825 | E78: =SUM(E79:E86) -> 4967.65 | F78: =SUM(F79:F86) -> 4967.65
B79: =[3]invest!$H225 -> charges immobilisées | C79: =[3]invest!$I225*$C$23/1000000 -> 250 | D79: =$C79*D$75/$C$75 -> 50 | E79: =$C79*E$75/$C$75 -> 100 | F79: =$C79*F$75/$C$75 -> 100
B80: =[3]invest!$H226 -> immos incorporelles | C80: =[3]invest!$I226*$C$23/1000000 -> 92 | D80: =$C80*D$75/$C$75 -> 18.4 | E80: =$C80*E$75/$C$75 -> 36.8 | F80: =$C80*F$75/$C$75 -> 36.8
B81: =[3]invest!$H227 -> foncier
B82: =[3]invest!$H228 -> aménagements et const. | C82: =[3]invest!$I228*$C$23/1000000 -> 4800 | D82: =$C82*D$75/$C$75 -> 960 | E82: =$C82*E$75/$C$75 -> 1920 | F82: =$C82*F$75/$C$75 -> 1920
B83: =[3]invest!$J225 -> matériels et équipements | C83: =[3]invest!$L225*$C$23/1000000 -> 6770 | D83: =$C83*D$75/$C$75 -> 1354 | E83: =$C83*E$75/$C$75 -> 2708 | F83: =$C83*F$75/$C$75 -> 2708
B84: =[3]invest!$J226 -> moyens roulants | C84: =[3]invest!$L226*$C$23/1000000 -> 240 | D84: =$C84*D$75/$C$75 -> 48 | E84: =$C84*E$75/$C$75 -> 96 | F84: =$C84*F$75/$C$75 -> 96
B85: =[3]invest!$J227 -> matériels de bureau | C85: =[3]invest!$L227*$C$23/1000000 -> 179.875 | D85: =$C85*D$75/$C$75 -> 35.975 | E85: =$C85*E$75/$C$75 -> 71.95 | F85: =$C85*F$75/$C$75 -> 71.95
...

Sheet PL
A1: BAGHARA CAP 3 MOISSONS | D1: Résultats 7 ans:
B3: Date début simulation: | D3: ='50 CAP'!D10 -> 46023
B4: Année: | D4: 1 | E4: =1+D4 -> 2 | F4: =1+E4 -> 3 | G4: =1+F4 -> 4 | H4: =1+G4 -> 5 | I4: =1+H4 -> 6 | J4: =1+I4 -> 7
B5: Date début année: | D5: =D3 -> 46023 | E5: =DATE(E53,"01","01") -> 46388 | F5: =DATE(F53,"01","01") -> 46753 | G5: =DATE(G53,"01","01") -> 47119 | H5: =DATE(H53,"01","01") -> 47484 | I5: =DATE(I53,"01","01") -> 47849 | J5: =DATE(J53,"01","01") -> 48214
B6: Taux inflation: | C6: 0.05 | I6: =C6 -> 0.05 | J6: =I6 -> 0.05
B10: Nb de CAP crées année 1 | C10: ='50 CAP'!C17 -> 10 | D10: =$C10 -> 10 | E10: =D10 -> 10 | F10: =E10 -> 10 | G10: =F10 -> 10 | H10: =G10 -> 10 | I10: =H10 -> 10 | J10: =I10 -> 10
B12: Nb de CAP crées année 2 | C12: ='50 CAP'!C19 -> 20 | E12: =$C12 -> 20 | F12: =E12 -> 20 | G12: =F12 -> 20 | H12: =G12 -> 20 | I12: =H12 -> 20 | J12: =I12 -> 20
B14: Nb de CAP crées année 3 | C14: ='50 CAP'!C21 -> 20 | F14: =$C14 -> 20 | G14: =F14 -> 20 | H14: =G14 -> 20 | I14: =H14 -> 20 | J14: =I14 -> 20
B16: Total cumulé: | C16: =SUM(C10:C15) -> 50 | D16: =SUM(D10:D15) -> 10 | E16: =SUM(E10:E15) -> 30 | F16: =SUM(F10:F15) -> 50 | G16: =SUM(G10:G15) -> 50 | H16: =SUM(H10:H15) -> 50 | I16: =SUM(I10:I15) -> 50 | J16: =SUM(J10:J15) -> 50
B21: I. CA et Résultat pour 50 CAP (en MCFA):
C24: Année: | D24: =YEAR($D$3) -> 2026 | E24: =D24+1 -> 2027 | F24: =E24+1 -> 2028 | G24: =F24+1 -> 2029 | H24: =G24+1 -> 2030 | I24: =H24+1 -> 2031 | J24: =I24+1 -> 2032
B25: Rubriques | C25: Total 7 ans | D25: =$D$54 -> Prévisions année: 1 | E25: =$E$54 -> Prévisions année: 2 | F25: =$F$54 -> Prévisions année: 3 | G25: =$G$54 -> Prévisions année: 4 | H25: =$H$54 -> Prévisions année: 5 | I25: =$I$54 -> Prévisions année: 6 | J25: =$J$54 -> Prévisions année: 7
B27: Chiffre d'affaires | C27: =SUM(D27:J27) -> 79735.454 | D27: =(D$10*D56+D$12*D83+D$14*D110)/1000000 -> 0 | E27: =(E$10*E56+E$12*E83+E$14*E110)/1000000 -> 2181.1174 | F27: =(F$10*F56+F$12*F83+F$14*F110)/1000000 -> 7165.4794 | G27: =(G$10*G56+G$12*G83+G$14*G110)/1000000 -> 13435.174 | H27: =(H$10*H56+H$12*H83+H$14*H110)/1000000 -> 16492.862 | I27: =(I$10*I56+I$12*I83+I$14*I110)/1000000 -> 19213.68 | J27: =(J$10*J56+J$12*J83+J$14*J110)/1000000 -> 21247.14
B28: Récap autres produit ou produits divers | C28: =SUM(D28:J28) -> 6422.4479 | D28: =(D$10*D57+D$12*D84+D$14*D111)/1000000 -> 0 | E28: =(E$10*E57+E$12*E84+E$14*E111)/1000000 -> 240.6907 | F28: =(F$10*F57+F$12*F84+F$14*F111)/1000000 -> 755.56468 | G28: =(G$10*G57+G$12*G84+G$14*G111)/1000000 -> 1319.6545 | H28: =(H$10*H57+H$12*H84+H$14*H111)/1000000 -> 1429.3664 | I28: =(I$10*I57+I$12*I84+I$14*I111)/1000000 -> 1479.7238 | J28: =(J$10*J57+J$12*J84+J$14*J111)/1000000 -> 1197.4478
B29: Total produit ou produits d'exploitation | C29: =SUM(D29:J29) -> 86157.902 | D29: =D27+D28 -> 0 | E29: =E27+E28 -> 2421.8081 | F29: =F27+F28 -> 7921.044 | G29: =G27+G28 -> 14754.829 | H29: =H27+H28 -> 17922.229 | I29: =I27+I28 -> 20693.404 | J29: =J27+J28 -> 22444.588
B30: Achats matières | C30: =SUM(D30:J30) -> 33131.551 | D30: =(D$10*D59+D$12*D86+D$14*D113)/1000000 -> 0 | E30: =(E$10*E59+E$12*E86+E$14*E113)/1000000 -> 1325.7599 | F30: =(F$10*F59+F$12*F86+F$14*F113)/1000000 -> 3896.2798 | G30: =(G$10*G59+G$12*G86+G$14*G113)/1000000 -> 6504.7212 | H30: =(H$10*H59+H$12*H86+H$14*H113)/1000000 -> 6642.5265 | I30: =(I$10*I59+I$12*I86+I$14*I113)/1000000 -> 7140.1485 | J30: =(J$10*J59+J$12*J86+J$14*J113)/1000000 -> 7622.1151
B31: Marge sur achats matières | C31: =SUM(D31:J31) -> 46603.903 | D31: =D27-D30 -> 0 | E31: =E27-E30 -> 855.35748 | F31: =F27-F30 -> 3269.1996 | G31: =G27-G30 -> 6930.4532 | H31: =H27-H30 -> 9850.3359 | I31: =I27-I30 -> 12073.532 | J31: =J27-J30 -> 13625.025
B32: Taux de marge / achats | D32: =IF(D27=0,0,D31/D27) -> 0 | E32: =IF(E27=0,0,E31/E27) -> 0.39216481 | F32: =IF(F27=0,0,F31/F27) -> 0.45624297 | G32: =IF(G27=0,0,G31/G27) -> 0.51584393 | H32: =IF(H27=0,0,H31/H27) -> 0.59724841 | I32: =IF(I27=0,0,I31/I27) -> 0.62838205 | J32: =IF(J27=0,0,J31/J27) -> 0.64126395
B33: Charges externes ponctuelles | C33: =SUM(D33:J33) -> 4208.7414 | D33: =(D$10*E62+D$12*D90+D$14*D117)/1000000 -> 0 | E33: =(E$10*F62+E$12*E90+E$14*E117)/1000000 -> 0 | F33: =(F$10*G62+J$12*F90+F$14*F117)/1000000 -> 230.74355 | G33: =(G$10*H62+G$12*G90+G$14*G117)/1000000 -> 650.58215 | H33: =(H$10*I62+H$12*H90+H$14*H117)/1000000 -> 944.9411 | I33: =(I$10*J62+I$12*I90+I$14*I117)/1000000 -> 1124.4417 | J33: =(J$10*K62+J$12*J90+J$14*J117)/1000000 -> 1258.0328
B34: Frais généraux et charges permanentes | C34: =SUM(D34:J34) -> 5771.4142 | D34: =(D$10*D63+D$12*D90+D$14*D117)/1000000 -> 0 | E34: =(E$10*E63+E$12*E90+E$14*E117)/1000000 -> 115.37177 | F34: =(F$10*F63+F$12*F90+F$14*F117)/1000000 -> 440.66285 | G34: =(G$10*G63+G$12*G90+G$14*G117)/1000000 -> 913.1334 | H34: =(H$10*H63+H$12*H90+H$14*H117)/1000000 -> 1244.6107 | I34: =(I$10*I63+I$12*I90+I$14*I117)/1000000 -> 1453.7885 | J34: =(J$10*J63+J$12*J90+J$14*J117)/1000000 -> 1603.847
B35: Leasings et locations longues durées | C35: =SUM(D35:J35) -> 3739.7701 | D35: =(D$10*D64+D$12*D91+D$14*D118)/1000000 -> 128.95759 | E35: =(E$10*E64+E$12*E91+E$14*E118)/1000000 -> 386.87277 | F35: =(F$10*F64+F$12*F91+F$14*F118)/1000000 -> 644.78795 | G35: =(G$10*G64+G$12*G91+G$14*G118)/1000000 -> 644.78795 | H35: =(H$10*H64+H$12*H91+H$14*H118)/1000000 -> 644.78795 | I35: =(I$10*I64+I$12*I91+I$14*I118)/1000000 -> 644.78795 | J35: =(J$10*J64+J$12*J91+J$14*J118)/1000000 -> 644.78795
B36: Impôts et taxes: | C36: =SUM(D36:J36) -> 3189.4182 | D36: =(D$10*D65+D$12*D92+D$14*D119)/1000000 -> 0 | E36: =(E$10*E65+E$12*E92+E$14*E119)/1000000 -> 87.244696 | F36: =(F$10*F65+F$12*F92+F$14*F119)/1000000 -> 286.61917 | G36: =(G$10*G65+G$12*G92+G$14*G119)/1000000 -> 537.40698 | H36: =(H$10*H65+H$12*H92+H$14*H119)/1000000 -> 659.7145 | I36: =(I$10*I65+I$12*I92+I$14*I119)/1000000 -> 768.54721 | J36: =(J$10*J65+J$12*J92+J$14*J119)/1000000 -> 849.88561
B37: TVA/charges non récupérables | C37: =SUM(D37:J37) -> 0 | D37: =(D$10*D66+D$12*D93+D$14*D120)/1000000 -> 0 | E37: =(E$10*E66+E$12*E93+E$14*E120)/1000000 -> 0 | F37: =(F$10*F66+F$12*F93+F$14*F120)/1000000 -> 0 | G37: =(G$10*G66+G$12*G93+G$14*G120)/1000000 -> 0 | H37: =(H$10*H66+H$12*H93+H$14*H120)/1000000 -> 0 | I37: =(I$10*I66+I$12*I93+I$14*I120)/1000000 -> 0 | J37: =(J$10*J66+J$12*J93+J$14*J120)/1000000 -> 0
B38: Dirigeants non salariés (rémun + CS) | C38: =SUM(D38:J38) -> 0 | D38: =(D$10*D67+D$12*D94+D$14*D121)/1000000 -> 0 | E38: =(E$10*E67+E$12*E94+E$14*E121)/1000000 -> 0 | F38: =(F$10*F67+F$12*F94+F$14*F121)/1000000 -> 0 | G38: =(G$10*G67+G$12*G94+G$14*G121)/1000000 -> 0 | H38: =(H$10*H67+H$12*H94+H$14*H121)/1000000 -> 0 | I38: =(I$10*I67+I$12*I94+I$14*I121)/1000000 -> 0 | J38: =(J$10*J67+J$12*J94+J$14*J121)/1000000 -> 0
B39: Autres salaires + charges sociales | C39: =SUM(D39:J39) -> 14755.314 | D39: =(D$10*D68+D$12*D95+D$14*D122)/1000000 -> 0 | E39: =(E$10*E68+E$12*E95+E$14*E122)/1000000 -> 273.108 | F39: =(F$10*F68+F$12*F95+F$14*F122)/1000000 -> 975.446 | G39: =(G$10*G68+G$12*G95+G$14*G122)/1000000 -> 2174.2294 | H39: =(H$10*H68+H$12*H95+H$14*H122)/1000000 -> 3201.9589 | I39: =(I$10*I68+I$12*I95+I$14*I122)/1000000 -> 3980.9518 | J39: =(J$10*J68+J$12*J95+J$14*J122)/1000000 -> 4149.6196
B40: Excédent brut d'exploitation (EBITDA): | C40: =SUM(D40:J40) -> 21361.693 | D40: =D31+D28-SUM(D33:D39) -> -128.95759 | E40: =E31+E28-SUM(E33:E39) -> 233.45094 | F40: =F31+F28-SUM(F33:F39) -> 1446.5048 | G40: =G31+G28-SUM(G33:G39) -> 3329.9678 | H40: =H31+H28-SUM(H33:H39) -> 4583.6892 | I40: =I31+I28-SUM(I33:I39) -> 5580.7384 | J40: =J31+J28-SUM(J33:J39) -> 6316.2998
B41: Dotation amortissements | C41: =SUM(D41:J41) -> 5918.91 | D41: =(D$10*D70+D$12*D97+D$14*D124)/1000000 -> 0 | E41: =(E$10*E70+E$12*E97+E$14*E124)/1000000 -> 257.85167 | F41: =(F$10*F70+F$12*F97+F$14*F124)/1000000 -> 773.555 | G41: =(G$10*G70+G$12*G97+G$14*G124)/1000000 -> 1289.2583 | H41: =(H$10*H70+H$12*H97+H$14*H124)/1000000 -> 1266.775 | I41: =(I$10*I70+I$12*I97+I$14*I124)/1000000 -> 1205.0133 | J41: =(J$10*J70+J$12*J97+J$14*J124)/1000000 -> 1126.4567
B42: Frais de direction | C42: =SUM(D42:J42) -> 6422.4479 | D42: =(D$10*D71+D$12*D98+D$14*D125)/1000000 -> 0 | E42: =(E$10*E71+E$12*E98+E$14*E125)/1000000 -> 240.6907 | F42: =(F$10*F71+F$12*F98+F$14*F125)/1000000 -> 755.56468 | G42: =(G$10*G71+G$12*G98+G$14*G125)/1000000 -> 1319.6545 | H42: =(H$10*H71+H$12*H98+H$14*H125)/1000000 -> 1429.3664 | I42: =(I$10*I71+I$12*I98+I$14*I125)/1000000 -> 1479.7238 | J42: =(J$10*J71+J$12*J98+J$14*J125)/1000000 -> 1197.4478
B43: Résultat d'exploitation (EBIT): | C43: =SUM(D43:J43) -> 9020.3355 | D43: =D40-D41-D42 -> -128.95759 | E43: =E40-E41-E42 -> -265.09143 | F43: =F40-F41-F42 -> -82.614916 | G43: =G40-G41-G42 -> 721.055 | H43: =H40-H41-H42 -> 1887.5478 | I43: =I40-I41-I42 -> 2896.0012 | J43: =J40-J41-J42 -> 3992.3953
B44: Charges d'emprunts | C44: =SUM(D44:J44) -> 2610 | D44: =(D$10*D73+D$12*D100+D$14*D127)/1000000 -> 135 | E44: =(E$10*E73+E$12*E100+E$14*E127)/1000000 -> 394.6875 | F44: =(F$10*F73+F$12*F100+F$14*F127)/1000000 -> 621.5625 | G44: =(G$10*G73+G$12*G100+G$14*G127)/1000000 -> 533.4375 | H44: =(H$10*H73+H$12*H100+H$14*H127)/1000000 -> 420.9375 | I44: =(I$10*I73+I$12*I100+I$14*I127)/1000000 -> 308.4375 | J44: =(J$10*J73+J$12*J100+J$14*J127)/1000000 -> 195.9375
B45: Autres charges financières | C45: =SUM(D45:J45) -> 0 | D45: =(D$10*D74+D$12*D101+D$14*D128)/1000000 -> 0 | E45: =(E$10*E74+E$12*E101+E$14*E128)/1000000 -> 0 | F45: =(F$10*F74+F$12*F101+F$14*F128)/1000000 -> 0 | G45: =(G$10*G74+G$12*G101+G$14*G128)/1000000 -> 0 | H45: =(H$10*H74+H$12*H101+H$14*H128)/1000000 -> 0 | I45: =(I$10*I74+I$12*I101+I$14*I128)/1000000 -> 0 | J45: =(J$10*J74+J$12*J101+J$14*J128)/1000000 -> 0
B46: Résultat financier: | C46: =SUM(D46:J46) -> -2610 | D46: =-D44-D45 -> -135 | E46: =-E44-E45 -> -394.6875 | F46: =-F44-F45 -> -621.5625 | G46: =-G44-G45 -> -533.4375 | H46: =-H44-H45 -> -420.9375 | I46: =-I44-I45 -> -308.4375 | J46: =-J44-J45 -> -195.9375
B47: Résultat brut: | C47: =SUM(D47:J47) -> 6410.3354 | D47: =D43+D46 -> -263.95759 | E47: =E43+E46 -> -659.77893 | F47: =F43+F46 -> -704.17742 | G47: =G43+G46 -> 187.6175 | H47: =H43+H46 -> 1466.6103 | I47: =I43+I46 -> 2587.5637 | J47: =J43+J46 -> 3796.4578
B51: Montants pour 1 CAP (en CFA):
D53: =YEAR($D$3) -> 2026 | E53: =D53+1 -> 2027 | F53: =E53+1 -> 2028 | G53: =F53+1 -> 2029 | H53: =G53+1 -> 2030 | I53: =H53+1 -> 2031 | J53: =I53+1 -> 2032
B54: Année 1: | C54: =D53 -> 2026 | D54: =CONCATENATE("Prévisions année: ", D4) -> Prévisions année: 1 | E54: =CONCATENATE("Prévisions année: ", E4) -> Prévisions année: 2 | F54: =CONCATENATE("Prévisions année: ", F4) -> Prévisions année: 3 | G54: =CONCATENATE("Prévisions année: ", G4) -> Prévisions année: 4 | H54: =CONCATENATE("Prévisions année: ", H4) -> Prévisions année: 5 | I54: =CONCATENATE("Prévisions année: ", I4) -> Prévisions année: 6 | J54: =CONCATENATE("Prévisions année: ", J4) -> Prévisions année: 7
B56: Chiffre d'affaires | C56: =SUM(D56:J56) -> 2.1370646e+09 | E56: =[3]CR!B20 -> 2.1811174e+08 | F56: =[3]CR!C20 -> 2.8032446e+08 | G56: =[3]CR!D20 -> 3.4664505e+08 | H56: =[3]CR!E20 -> 3.9534724e+08 | I56: =[1]CR!E20 -> 4.3738346e+08 | J56: =I56*(1+$C$6) -> 4.5925263e+08
B57: Récap autres produit ou produits divers | C57: =SUM(D57:J57) -> 1.4035044e+08 | E57: =[3]CR!B21 -> 24069070 | F57: =[3]CR!C21 -> 27418328 | G57: =[3]CR!D21 -> 28990652 | H57: =[3]CR!E21 -> 30118683 | I57: =[1]CR!E21 -> 29753710
B58: Total produit ou produits d'exploitation | C58: =SUM(D58:J58) -> 2.277415e+09 | D58: =SUM(D56:D57) -> 0 | E58: =SUM(E56:E57) -> 2.4218081e+08 | F58: =SUM(F56:F57) -> 3.0774278e+08 | G58: =SUM(G56:G57) -> 3.756357e+08 | H58: =SUM(H56:H57) -> 4.2546592e+08 | I58: =SUM(I56:I57) -> 4.6713717e+08 | J58: =SUM(J56:J57) -> 4.5925263e+08
B59: Achats matières | C59: =SUM(D59:J59) -> 8.5691747e+08 | E59: =[3]CR!B23 -> 1.3257599e+08 | F59: =[3]CR!C23 -> 1.2447599e+08 | G59: =[3]CR!D23 -> 1.3636815e+08 | H59: =[3]CR!E23 -> 1.4256436e+08 | I59: =[1]CR!E23 -> 1.5614982e+08 | J59: =J56-(J61*J56) -> 1.6478315e+08
...

Sheet Tréso
A2: BAGHARA CAP 3 MOISSONS | E2: TRESORERIE 5 ANS
B5: Date début année: | D5: =PL!D5 -> 46023 | E5: =PL!E5 -> 46388 | F5: =PL!F5 -> 46753 | G5: =PL!G5 -> 47119 | H5: =PL!H5 -> 47484
B7: Année: | D7: 1 | E7: =1+D7 -> 2 | F7: =1+E7 -> 3 | G7: =1+F7 -> 4 | H7: =1+G7 -> 5
B9: Nb de CAP crées année 1 | C9: =PL!C10 -> 10 | D9: =PL!D10 -> 10 | E9: =PL!E10 -> 10 | F9: =PL!F10 -> 10 | G9: =PL!G10 -> 10 | H9: =PL!H10 -> 10
B11: Nb de CAP crées année 2 | C11: =PL!C12 -> 20 | E11: =PL!E12 -> 20 | F11: =PL!F12 -> 20 | G11: =PL!G12 -> 20 | H11: =PL!H12 -> 20
B13: Nb de CAP crées année 3 | C13: =PL!C14 -> 20 | F13: =PL!F14 -> 20 | G13: =PL!G14 -> 20 | H13: =PL!H14 -> 20
B15: Total cumulé: | C15: =SUM(C9:C14) -> 50 | D15: =SUM(D9:D14) -> 10 | E15: =SUM(E9:E14) -> 30 | F15: =SUM(F9:F14) -> 50 | G15: =SUM(G9:G14) -> 50 | H15: =SUM(H9:H14) -> 50
B17: Trésorerie pour 50 CAP (en MCFA):
D19: année 1 | E19: année 2 | F19: année 3 | G19: année 4 | H19: année 5
B20: =[3]libel!$C$140 -> Tréso début de période | D20: =(D$9*D30+D$11*D35+D$13*D40) -> 0 | E20: =(E$9*E30+E$11*E35+E$13*E40) -> 131.85042 | F20: =(F$9*F30+F$11*F35+F$13*F40) -> 532.44506 | G20: =(G$9*G30+G$11*G35+G$13*G40) -> 1354.128 | H20: =(H$9*H30+H$11*H35+H$13*H40) -> 2836.6211
B21: Tréso fin de période | D21: =(D$9*D31+D$11*D36+D$13*D41) -> 131.85042 | E21: =(E$9*E31+E$11*E36+E$13*E41) -> 532.44506 | F21: =(F$9*F31+F$11*F36+F$13*F41) -> 1354.128 | G21: =(G$9*G31+G$11*G36+G$13*G41) -> 2836.6211 | H21: =(H$9*H31+H$11*H36+H$13*H41) -> 5557.8066
B25: Trésorerie pour 1 CAP
B28: Année 1:
D29: année 1 | E29: année 2 | F29: année 3 | G29: année 4 | H29: année 5
B30: =[3]libel!$C$140 -> Tréso début de période | D30: =[3]tréso!B$9/1000000 -> 0 | E30: =[3]tréso!C$9/1000000 -> 13.185042 | F30: =[3]tréso!D$9/1000000 -> 26.874423 | G30: =[3]tréso!E$9/1000000 -> 55.293875 | H30: =[1]tréso!$E$9/1000000 -> 119.32552
B31: Tréso fin de période | D31: =[3]tréso!B$39/1000000 -> 13.185042 | E31: =[3]tréso!C$39/1000000 -> 26.874423 | F31: =[3]tréso!D$39/1000000 -> 55.293875 | G31: =[3]tréso!E$39/1000000 -> 119.32552 | H31: =[1]tréso!$E$39/1000000 -> 206.54188
B33: Année 2:
E34: année 1 | F34: année 2 | G34: année 3 | H34: année 4
B35: =[3]libel!$C$140 -> Tréso début de période | E35: =D30 -> 0 | F35: =E30 -> 13.185042 | G35: =F30 -> 26.874423 | H35: =G30 -> 55.293875
B36: Tréso fin de période | E36: =D31 -> 13.185042 | F36: =E31 -> 26.874423 | G36: =F31 -> 55.293875 | H36: =G31 -> 119.32552
B38: Année 3:
F39: année 1 | G39: année 2 | H39: année 3
B40: =[3]libel!$C$140 -> Tréso début de période | F40: =E35 -> 0 | G40: =F35 -> 13.185042 | H40: =G35 -> 26.874423
B41: Tréso fin de période | F41: =E36 -> 13.185042 | G41: =F36 -> 26.874423 | H41: =G36 -> 55.293875

Sheet Invest
A1: BAGHARA CAP 3 MOISSONS | D1: INVESTISSEMENTS 7 ANS
B4: Année: | D4: 1 | E4: =1+D4 -> 2 | F4: =1+E4 -> 3 | G4: =1+F4 -> 4 | H4: =1+G4 -> 5 | I4: =1+H4 -> 6 | J4: =1+I4 -> 7
B9: Nb de CAP crées année 1 | C9: =PL!C10 -> 10 | D9: =$C9 -> 10 | E9: =D9 -> 10 | F9: =E9 -> 10 | G9: =F9 -> 10 | H9: =G9 -> 10 | I9: =H9 -> 10 | J9: =I9 -> 10
B11: Nb de CAP crées année 2 | C11: =PL!C12 -> 20 | E11: =$C11 -> 20 | F11: =E11 -> 20 | G11: =F11 -> 20 | H11: =G11 -> 20 | I11: =H11 -> 20 | J11: =I11 -> 20
B13: Nb de CAP crées année 3 | C13: =PL!C14 -> 20 | F13: =$C13 -> 20 | G13: =F13 -> 20 | H13: =G13 -> 20 | I13: =H13 -> 20 | J13: =I13 -> 20
B15: Total cumulé: | C15: =SUM(C9:C14) -> 50 | D15: =SUM(D9:D14) -> 10 | E15: =SUM(E9:E14) -> 30 | F15: =SUM(F9:F14) -> 50 | G15: =SUM(G9:G14) -> 50 | H15: =SUM(H9:H14) -> 50 | I15: =SUM(I9:I14) -> 50 | J15: =SUM(J9:J14) -> 50
B17: Prévisions immos pour 50 CAP (en MCFA):
B19: Année: | C19: Total 7 ans | D19: =D34 -> 1 | E19: =E34 -> 2 | F19: =F34 -> 3 | G19: =G34 -> 4 | H19: =H34 -> 5 | I19: =I34 -> 6 | J19: =J34 -> 7
B20: Total investissements: | C20: =SUM(D20:J20) -> 12419.125 | D20: =(D$9*D36+D$11*D47+D$13*D58)/1000000 -> 2483.825 | E20: =(E$9*E36+E$11*E47+E$13*E58)/1000000 -> 4967.65 | F20: =(F$9*F36+F$11*F47+F$13*F58)/1000000 -> 4967.65 | G20: =(G$9*G36+G$11*G47+G$13*G58)/1000000 -> 0 | H20: =(H$9*H36+H$11*H47+H$13*H58)/1000000 -> 0 | I20: =(I$9*I36+I$11*I47+I$13*I58)/1000000 -> 0 | J20: =(J$9*J36+J$11*J47+J$13*J58)/1000000 -> 0
B21: Investissement cumulé: | C21: =C20 -> 12419.125 | D21: =D20 -> 2483.825 | E21: =D21+E20 -> 7451.475 | F21: =E21+F20 -> 12419.125 | G21: =F21+G20 -> 12419.125 | H21: =G21+H20 -> 12419.125 | I21: =H21+I20 -> 12419.125 | J21: =I21+J20 -> 12419.125
B22: Total base amortissements: | C22: =SUM(D22:J22) -> 17419.125 | D22: =(D$9*D37+D$11*D48+D$13*D59)/1000000 -> 3483.825 | E22: =(E$9*E37+E$11*E48+E$13*E59)/1000000 -> 6967.65 | F22: =(F$9*F37+F$11*F48+F$13*F59)/1000000 -> 6967.65 | G22: =(G$9*G37+G$11*G48+G$13*G59)/1000000 -> 0 | H22: =(H$9*H37+H$11*H48+H$13*H59)/1000000 -> 0 | I22: =(I$9*I37+I$11*I48+I$13*I59)/1000000 -> 0 | J22: =(J$9*J37+J$11*J48+J$13*J59)/1000000 -> 0
B23: Base amortissements cumulés: | C23: =J23 -> 17419.125 | D23: =D22 -> 3483.825 | E23: =D23+E22 -> 10451.475 | F23: =E23+F22 -> 17419.125 | G23: =F23+G22 -> 17419.125 | H23: =G23+H22 -> 17419.125 | I23: =H23+I22 -> 17419.125 | J23: =I23+J22 -> 17419.125
B24: Total amortissement: | C24: =SUM(D24:J24) -> 5986.09 | D24: =(D$9*D38+D$11*D49+D$13*D60)/1000000 -> 0 | E24: =(E$9*E38+E$11*E49+E$13*E60)/1000000 -> 257.85167 | F24: =(F$9*F38+F$11*F49+F$13*F60)/1000000 -> 773.555 | G24: =(G$9*G38+G$11*G49+G$13*G60)/1000000 -> 1289.2583 | H24: =(H$9*H38+H$11*H49+H$13*H60)/1000000 -> 1266.775 | I24: =(I$9*I38+I$11*I49+I$13*I60)/1000000 -> 1221.8083 | J24: =(J$9*J38+J$11*J49+J$13*J60)/1000000 -> 1176.8417
B25: Amortissements cumulés: | C25: =J25 -> 5986.09 | D25: =D24 -> 0 | E25: =D25+E24 -> 257.85167 | F25: =E25+F24 -> 1031.4067 | G25: =F25+G24 -> 2320.665 | H25: =G25+H24 -> 3587.44 | I25: =H25+I24 -> 4809.2483 | J25: =I25+J24 -> 5986.09
B26: Total investissement TTC | C26: =SUM(D26:G26) -> 12419.125 | D26: =(D$9*D40+D$11*D51+D$13*D62)/1000000 -> 2483.825 | E26: =(E$9*E40+E$11*E51+E$13*E62)/1000000 -> 4967.65 | F26: =(F$9*F40+F$11*F51+F$13*F62)/1000000 -> 4967.65 | G26: =(G$9*G40+G$11*G51+G$13*G62)/1000000 -> 0 | H26: =(H$9*H40+H$11*H51+H$13*H62)/1000000 -> 0 | I26: =(I$9*I40+I$11*I51+I$13*I62)/1000000 -> 0 | J26: =(J$9*J40+J$11*J51+J$13*J62)/1000000 -> 0
B27: Total invest. corporels: | C27: =SUM(D27:J27) -> 12077.125 | D27: =(D$9*D41+D$11*D52+D$13*D63)/1000000 -> 2415.425 | E27: =(E$9*E41+E$11*E52+E$13*E63)/1000000 -> 4830.85 | F27: =(F$9*F41+F$11*F52+F$13*F63)/1000000 -> 4830.85 | G27: =(G$9*G41+G$11*G52+G$13*G63)/1000000 -> 0 | H27: =(H$9*H41+H$11*H52+H$13*H63)/1000000 -> 0 | I27: =(I$9*I41+I$11*I52+I$13*I63)/1000000 -> 0 | J27: =(J$9*J41+J$11*J52+J$13*J63)/1000000 -> 0
B28: Total invest. incorporels: | C28: =SUM(D28:J28) -> 342 | D28: =(D$9*D42+D$11*D53+D$13*D64)/1000000 -> 68.4 | E28: =(E$9*E42+E$11*E53+E$13*E64)/1000000 -> 136.8 | F28: =(F$9*F42+F$11*F53+F$13*F64)/1000000 -> 136.8 | G28: =(G$9*G42+G$11*G53+G$13*G64)/1000000 -> 0 | H28: =(H$9*H42+H$11*H53+H$13*H64)/1000000 -> 0 | I28: =(I$9*I42+I$11*I53+I$13*I64)/1000000 -> 0 | J28: =(J$9*J42+J$11*J53+J$13*J64)/1000000 -> 0
B31: Investissement pour 1 CAP (en CFA):
B34: Année 1: | D34: =PL!D4 -> 1 | E34: =PL!E4 -> 2 | F34: =PL!F4 -> 3 | G34: =PL!G4 -> 4 | H34: =PL!H$4 -> 5 | I34: =PL!I$4 -> 6 | J34: =PL!J$4 -> 7
B36: Total investissements: | D36: =[3]invest!R225 -> 2.483825e+08 | E36: =[3]invest!S225 -> 0 | F36: =[3]invest!T225 -> 0 | G36: =[3]invest!U225 -> 0 | H36: =G36 -> 0 | I36: =H36 -> 0 | J36: =I36 -> 0
B37: Total base amortissements: | D37: =[3]invest!R226 -> 348382500 | E37: =[3]invest!S226 -> 0 | F37: =[3]invest!T226 -> 0 | G37: =[3]invest!U226 -> 0 | H37: =G37 -> 0 | I37: =H37 -> 0 | J37: =I37 -> 0
B38: Total amortissement: | D38: =[3]invest!R227 -> 0 | E38: =[3]invest!S227 -> 25785167 | F38: =[3]invest!T227 -> 25785167 | G38: =[3]invest!U227 -> 25785167 | H38: =[1]invest!$U$227 -> 23536833 | I38: =H38 -> 23536833 | J38: =I38 -> 23536833
B39: Total investissement HT | D39: =[3]invest!R228 -> 2.483825e+08 | E39: =[3]invest!S228 -> 0 | F39: =[3]invest!T228 -> 0 | G39: =[3]invest!U228 -> 0 | H39: =G39 -> 0 | I39: =H39 -> 0 | J39: =I39 -> 0
B40: Total investissement TTC | D40: =[3]invest!R229 -> 2.483825e+08 | E40: =[3]invest!S229 -> 0 | F40: =[3]invest!T229 -> 0 | G40: =[3]invest!U229 -> 0 | H40: =G40 -> 0 | I40: =H40 -> 0 | J40: =I40 -> 0
B41: Total invest. corporels: | D41: =[3]invest!R230 -> 2.415425e+08 | E41: =[3]invest!S230 -> 0 | F41: =[3]invest!T230 -> 0 | G41: =[3]invest!U230 -> 0 | H41: =G41 -> 0 | I41: =H41 -> 0 | J41: =I41 -> 0
B42: Total invest. incorporels: | D42: =[3]invest!R231 -> 6840000 | E42: =[3]invest!S231 -> 0 | F42: =[3]invest!T231 -> 0 | G42: =[3]invest!U231 -> 0 | H42: =G42 -> 0 | I42: =H42 -> 0 | J42: =I42 -> 0
B45: Année 2: | E45: =D34 -> 1 | F45: =E34 -> 2 | G45: =F34 -> 3 | H45: =G34 -> 4 | I45: =H34 -> 5 | J45: =I34 -> 6
B47: =B36 -> Total investissements: | E47: =D36 -> 2.483825e+08 | F47: =E36 -> 0 | G47: =F36 -> 0 | H47: =G36 -> 0 | I47: =H36 -> 0 | J47: =I36 -> 0
B48: =B37 -> Total base amortissements: | E48: =D37 -> 348382500 | F48: =E37 -> 0 | G48: =F37 -> 0 | H48: =G37 -> 0 | I48: =H37 -> 0 | J48: =I37 -> 0
B49: =B38 -> Total amortissement: | E49: =D38 -> 0 | F49: =E38 -> 25785167 | G49: =F38 -> 25785167 | H49: =G38 -> 25785167 | I49: =H38 -> 23536833 | J49: =I38 -> 23536833
B50: =B39 -> Total investissement HT | E50: =D39 -> 2.483825e+08 | F50: =E39 -> 0 | G50: =F39 -> 0 | H50: =G39 -> 0 | I50: =H39 -> 0 | J50: =I39 -> 0
B51: =B40 -> Total investissement TTC | E51: =D40 -> 2.483825e+08 | F51: =E40 -> 0 | G51: =F40 -> 0 | H51: =G40 -> 0 | I51: =H40 -> 0 | J51: =I40 -> 0
B52: =B41 -> Total invest. corporels: | E52: =D41 -> 2.415425e+08 | F52: =E41 -> 0 | G52: =F41 -> 0 | H52: =G41 -> 0 | I52: =H41 -> 0 | J52: =I41 -> 0
B53: =B42 -> Total invest. incorporels: | E53: =D42 -> 6840000 | F53: =E42 -> 0 | G53: =F42 -> 0 | H53: =G42 -> 0 | I53: =H42 -> 0 | J53: =I42 -> 0
B56: Année 3: | F56: =E45 -> 1 | G56: =F45 -> 2 | H56: =G45 -> 3 | I56: =H45 -> 4 | J56: =I45 -> 5
B58: =B47 -> Total investissements: | F58: =E47 -> 2.483825e+08 | G58: =F47 -> 0 | H58: =G47 -> 0 | I58: =H47 -> 0 | J58: =I47 -> 0
B59: =B48 -> Total base amortissements: | F59: =E48 -> 348382500 | G59: =F48 -> 0 | H59: =G48 -> 0 | I59: =H48 -> 0 | J59: =I48 -> 0
B60: =B49 -> Total amortissement: | F60: =E49 -> 0 | G60: =F49 -> 25785167 | H60: =G49 -> 25785167 | I60: =H49 -> 25785167 | J60: =I49 -> 23536833
B61: =B50 -> Total investissement HT | F61: =E50 -> 2.483825e+08 | G61: =F50 -> 0 | H61: =G50 -> 0 | I61: =H50 -> 0 | J61: =I50 -> 0
B62: =B51 -> Total investissement TTC | F62: =E51 -> 2.483825e+08 | G62: =F51 -> 0 | H62: =G51 -> 0 | I62: =H51 -> 0 | J62: =I51 -> 0
...

Sheet Emprunts
A2: BAGHARA CAP 3 MOISSONS | E2: EMPRUNTS 7 ANS
C5: Date début année: | E5: =PL!D5 -> 46023 | F5: =PL!E5 -> 46388 | G5: =PL!F5 -> 46753 | H5: =PL!G5 -> 47119 | I5: =PL!H5 -> 47484 | J5: =PL!I5 -> 47849 | K5: =PL!J5 -> 48214
C7: Année: | E7: 1 | F7: =1+E7 -> 2 | G7: =1+F7 -> 3 | H7: =1+G7 -> 4 | I7: =1+H7 -> 5 | J7: =1+I7 -> 6 | K7: =1+J7 -> 7
C9: Nb de CAP crées année 1 | D9: =PL!C10 -> 10 | E9: =PL!D10 -> 10 | F9: =PL!E10 -> 10 | G9: =PL!F10 -> 10 | H9: =PL!G10 -> 10 | I9: =PL!H10 -> 10 | J9: =PL!I10 -> 10 | K9: =PL!J10 -> 10
C11: Nb de CAP crées année 2 | D11: =PL!C12 -> 20 | F11: =PL!E12 -> 20 | G11: =PL!F12 -> 20 | H11: =PL!G12 -> 20 | I11: =PL!H12 -> 20 | J11: =PL!I12 -> 20 | K11: =PL!J12 -> 20
C13: Nb de CAP crées année 3 | D13: =PL!C14 -> 20 | G13: =PL!F14 -> 20 | H13: =PL!G14 -> 20 | I13: =PL!H14 -> 20 | J13: =PL!I14 -> 20 | K13: =PL!J14 -> 20
C15: Total cumulé: | D15: =SUM(D9:D14) -> 50 | E15: =SUM(E9:E14) -> 10 | F15: =SUM(F9:F14) -> 30 | G15: =SUM(G9:G14) -> 50 | H15: =SUM(H9:H14) -> 50 | I15: =SUM(I9:I14) -> 50 | J15: =SUM(J9:J14) -> 50 | K15: =SUM(K9:K14) -> 50
C20: Prévisions pour 50 CAP (en MCFA):
E23: 2026 | F23: 2027 | G23: 2028 | H23: 2029 | I23: 2030 | J23: 2031 | K23: 2032
C24: rubriques | D24: Total 7 ans | E24: Prévisions année: 10 | F24: Prévisions année: 10 | G24: Prévisions année: 10 | H24: Prévisions année: 10 | I24: Prévisions année: 10 | J24: Prévisions année: 10 | K24: Prévisions année: 11
C25: Année: | E25: =E7 -> 1 | F25: =F7 -> 2 | G25: =G7 -> 3 | H25: =H7 -> 4 | I25: =I7 -> 5 | J25: =J7 -> 6 | K25: =K7 -> 7
C26: Total échéances à payer: | D26: =SUM(E26:K26) -> 12610 | E26: =(E$9*E184+E$11*E203+E$13*E220)/1000000 -> 135 | F26: =(F$9*F184+F$11*F203+F$13*F220)/1000000 -> 811.35417 | G26: =(G$9*G184+G$11*G203+G$13*G220)/1000000 -> 1871.5625 | H26: =(H$9*H184+H$11*H203+H$13*H220)/1000000 -> 2616.7708 | I26: =(I$9*I184+I$11*I203+I$13*I220)/1000000 -> 2504.2708 | J26: =(J$9*J184+J$11*J203+J$13*J220)/1000000 -> 2391.7708 | K26: =(K$9*K184+K$11*K203+K$13*K220)/1000000 -> 2279.2708
C27: Total capital souscrit | D27: =SUM(E27:K27) -> 12500 | E27: =(E$9*E185+E$11*E204+E$13*E221)/1000000 -> 2500 | F27: =(F$9*F185+F$11*F204+F$13*F221)/1000000 -> 5000 | G27: =(G$9*G185+G$11*G204+G$13*G221)/1000000 -> 5000 | H27: =(H$9*H185+H$11*H204+H$13*H221)/1000000 -> 0 | I27: =(I$9*I185+I$11*I204+I$13*I221)/1000000 -> 0 | J27: =(J$9*J185+J$11*J204+J$13*J221)/1000000 -> 0 | K27: =(K$9*K185+K$11*K204+K$13*K221)/1000000 -> 0
C28: Capital souscrit cumulé | D28: =K28 -> 12500 | E28: =E27 -> 2500 | F28: =E28+F27 -> 7500 | G28: =F28+G27 -> 12500 | H28: =G28+H27 -> 12500 | I28: =H28+I27 -> 12500 | J28: =I28+J27 -> 12500 | K28: =J28+K27 -> 12500
C29: Total capital remboursé | D29: =SUM(E29:K29) -> 10000 | E29: =(E$9*E186+E$11*E205+E$13*E222)/1000000 -> 2.6697988e-07 | F29: =(F$9*F186+F$11*F205+F$13*F222)/1000000 -> 416.66667 | G29: =(G$9*G186+G$11*G205+G$13*G222)/1000000 -> 1250 | H29: =(H$9*H186+H$11*H205+H$13*H222)/1000000 -> 2083.3333 | I29: =(I$9*I186+I$11*I205+I$13*I222)/1000000 -> 2083.3333 | J29: =(J$9*J186+J$11*J205+J$13*J222)/1000000 -> 2083.3333 | K29: =(K$9*K186+K$11*K205+K$13*K222)/1000000 -> 2083.3333
C30: Capital restant dû | D30: =K30 -> 2500 | E30: =(E$9*E187+E$11*E206+E$13*E223)/1000000 -> 2500 | F30: =(F$9*F187+F$11*F206+F$13*F223)/1000000 -> 7083.3333 | G30: =(G$9*G187+G$11*G206+G$13*G223)/1000000 -> 10833.333 | H30: =(H$9*H187+H$11*H206+H$13*H223)/1000000 -> 8750 | I30: =(I$9*I187+I$11*I206+I$13*I223)/1000000 -> 6666.6667 | J30: =(J$9*J187+J$11*J206+J$13*J223)/1000000 -> 4583.3334 | K30: =(K$9*K187+K$11*K206+K$13*K223)/1000000 -> 2500
C32: Total intérêts | D32: =SUM(E32:K32) -> 2610 | E32: =(E$9*E191+E$11*E210+E$13*E227)/1000000 -> 135 | F32: =(F$9*F191+F$11*F210+F$13*F227)/1000000 -> 394.6875 | G32: =(G$9*G191+G$11*G210+G$13*G227)/1000000 -> 621.5625 | H32: =(H$9*H191+H$11*H210+H$13*H227)/1000000 -> 533.4375 | I32: =(I$9*I191+I$11*I210+I$13*I227)/1000000 -> 420.9375 | J32: =(J$9*J191+J$11*J210+J$13*J227)/1000000 -> 308.4375 | K32: =(K$9*K191+K$11*K210+K$13*K227)/1000000 -> 195.9375
C38: Prévisions pour 1 CAP (en CFA):
C183: Année 1: | E183: =E7 -> 1 | F183: =F7 -> 2 | G183: =G7 -> 3 | H183: =H7 -> 4 | I183: =I7 -> 5 | J183: =J7 -> 6 | K183: =K7 -> 7
C184: Total échéances à payer: | E184: =[3]emprunts!S149 -> 13500000 | F184: =[1]emprunts!S149 -> 54135417 | G184: =[1]emprunts!T149 -> 51885417 | H184: =[1]emprunts!U149 -> 49635417 | I184: =[1]emprunts!V149 -> 47385417 | J184: =[1]emprunts!W149 -> 45135417 | K184: =[1]emprunts!X149 -> 42885417
C185: Total capital souscrit | E185: =[3]emprunts!S150 -> 250000000 | F185: 0 | G185: =[1]emprunts!T150 -> 0 | H185: =[1]emprunts!U150 -> 0 | I185: =[1]emprunts!V150 -> 0 | J185: =[1]emprunts!W150 -> 0 | K185: =[1]emprunts!X150 -> 0
C186: Total capital remboursé | E186: =[3]emprunts!S151 -> 0.026697988 | F186: =[1]emprunts!S151 -> 41666667 | G186: =[1]emprunts!T151 -> 41666667 | H186: =[1]emprunts!U151 -> 41666667 | I186: =[1]emprunts!V151 -> 41666667 | J186: =[1]emprunts!W151 -> 41666667 | K186: =[1]emprunts!X151 -> 41666667
C187: Total capital restant dû | E187: =[3]emprunts!S152 -> 2.5e+08 | F187: =[1]emprunts!S152 -> 2.0833333e+08 | G187: =[1]emprunts!T152 -> 1.6666667e+08 | H187: =[1]emprunts!U152 -> 1.25e+08 | I187: =[1]emprunts!V152 -> 83333334 | J187: =[1]emprunts!W152 -> 41666667 | K187: =[1]emprunts!X152 -> -2.9569492e-07
C190: dont capital restant dû à la reprise | E190: =[3]emprunts!S155 -> 0 | F190: 0 | G190: =[1]emprunts!T155 -> 0 | H190: =[1]emprunts!U155 -> 0 | I190: =[1]emprunts!V155 -> 0 | J190: =[1]emprunts!W155 -> 0 | K190: =[1]emprunts!X155 -> 0
C191: Total intérêts | E191: =[3]emprunts!S156 -> 13500000 | F191: =[1]emprunts!S156 -> 12468750 | G191: =[1]emprunts!T156 -> 10218750 | H191: =[1]emprunts!U156 -> 7968750.1 | I191: =[1]emprunts!V156 -> 5718750.1 | J191: =[1]emprunts!W156 -> 3468750 | K191: =[1]emprunts!X156 -> 1218750
C192: Total intérêts, assurances et frais | E192: =[3]emprunts!S157 -> 13500000 | F192: =[1]emprunts!S157 -> 12468750 | G192: =[1]emprunts!T157 -> 10218750 | H192: =[1]emprunts!U157 -> 7968750.1 | I192: =[1]emprunts!V157 -> 5718750.1 | J192: =[1]emprunts!W157 -> 3468750 | K192: =[1]emprunts!X157 -> 1218750
C193: Tot. Int.+frais+assur hors différé | E193: =[3]emprunts!S158 -> 13500000 | F193: =[1]emprunts!S158 -> 12468750 | G193: =[1]emprunts!T158 -> 10218750 | H193: =[1]emprunts!U158 -> 7968750.1 | I193: =[1]emprunts!V158 -> 5718750.1 | J193: =[1]emprunts!W158 -> 3468750 | K193: =[1]emprunts!X158 -> 1218750
C194: contrôle
C202: Année 2: | F202: =E183 -> 1 | G202: =F183 -> 2 | H202: =G183 -> 3 | I202: =H183 -> 4 | J202: =I183 -> 5 | K202: =J183 -> 6
C203: Total échéances à payer: | F203: =E184 -> 13500000 | G203: =F184 -> 54135417 | H203: =G184 -> 51885417 | I203: =H184 -> 49635417 | J203: =I184 -> 47385417 | K203: =J184 -> 45135417
C204: Total capital souscrit | F204: =E185 -> 250000000 | G204: =F185 -> 0 | H204: =G185 -> 0 | I204: =H185 -> 0 | J204: =I185 -> 0 | K204: =J185 -> 0
C205: Total capital remboursé | F205: =E186 -> 0.026697988 | G205: =F186 -> 41666667 | H205: =G186 -> 41666667 | I205: =H186 -> 41666667 | J205: =I186 -> 41666667 | K205: =J186 -> 41666667
C206: Total capital restant dû | F206: =E187 -> 2.5e+08 | G206: =F187 -> 2.0833333e+08 | H206: =G187 -> 1.6666667e+08 | I206: =H187 -> 1.25e+08 | J206: =I187 -> 83333334 | K206: =J187 -> 41666667
F207: =E188 -> 0 | G207: =F188 -> 0 | H207: =G188 -> 0 | I207: =H188 -> 0 | J207: =I188 -> 0 | K207: =J188 -> 0
F208: =E189 -> 0 | G208: =F189 -> 0 | H208: =G189 -> 0 | I208: =H189 -> 0 | J208: =I189 -> 0 | K208: =J189 -> 0
C209: dont capital restant dû à la reprise | F209: =E190 -> 0 | G209: =F190 -> 0 | H209: =G190 -> 0 | I209: =H190 -> 0 | J209: =I190 -> 0 | K209: =J190 -> 0
C210: Total intérêts | F210: =E191 -> 13500000 | G210: =F191 -> 12468750 | H210: =G191 -> 10218750 | I210: =H191 -> 7968750.1 | J210: =I191 -> 5718750.1 | K210: =J191 -> 3468750
C211: Total intérêts, assurances et frais | F211: =E192 -> 13500000 | G211: =F192 -> 12468750 | H211: =G192 -> 10218750 | I211: =H192 -> 7968750.1 | J211: =I192 -> 5718750.1 | K211: =J192 -> 3468750
C212: Tot. Int.+frais+assur hors différé | F212: =E193 -> 13500000 | G212: =F193 -> 12468750 | H212: =G193 -> 10218750 | I212: =H193 -> 7968750.1 | J212: =I193 -> 5718750.1 | K212: =J193 -> 3468750
C213: contrôle | F213: =E194 -> 0 | G213: =F194 -> 0 | H213: =G194 -> 0 | I213: =H194 -> 0 | J213: =I194 -> 0 | K213: =J194 -> 0
...
