Workbook

Sheet 00_Cover
B1: 3 Fermes Incubatrices · Financial Model L1 v11
B3: Built via xlsx_build/ framework (declarative TabSpec + procedural helpers)
B5: MODEL STATUS | C5: =IF('18_Validation'!M29=0,"ALL CHECKS PASS","CHECKS FAILING") -> ALL CHECKS PASS | D5: ='18_Validation'!M29&" total fails" -> 0 total fails
B7: Check | C7: Description | D7: Fails
B8: L1 | C8: S&U balance | D8: ='18_Validation'!M6 -> 0
B9: L2 | C9: CWIP zero at COD | D9: ='18_Validation'!M7 -> 0
B10: L3 | C10: Book NBV ≥ 0 | D10: ='18_Validation'!M8 -> 0
B11: L4 | C11: DTL ≥ 0 | D11: ='18_Validation'!M9 -> 0
B12: L5 | C12: Debt ≥ 0 | D12: ='18_Validation'!M10 -> 0
B13: L6 | C13: BS balance | D13: ='18_Validation'!M13 -> 0
B14: L7 | C14: Cash floor ≥ 0 | D14: ='18_Validation'!M14 -> 0
B15: L8 | C15: NOL ≥ 0 | D15: ='18_Validation'!M17 -> 0
B16: L9 | C16: DTL closing ≥ 0 | D16: ='18_Validation'!M18 -> 0
B17: L11 | C17: CFS reconciliation | D17: ='18_Validation'!M21 -> 0
B18: L12 | C18: IS EBITDA arithmetic | D18: ='18_Validation'!M24 -> 0
B19: L13 | C19: IS pre-tax consistency | D19: ='18_Validation'!M25 -> 0
B20: L14 | C20: Named range smoke test | D20: ='18_Validation'!M26 -> 0
B22: KPI SNAPSHOT — steady-state (Y6)
B23: Revenue SS | D23: =REV_TOTAL_Y6 -> 1567503
B24: OpEx SS (farming) | D24: =-IS_OPEX_Y6 -> 578623.98
B25: EBITDA SS | D25: =IS_EBITDA_Y6 -> 988879.02
B26: CFADS SS | D26: =CFADS_Y6 -> 988879.02
B27: Debt outstanding Y6 | D27: =DEBT_CLOSE_Y6 -> 1877540.9
B28: Total CAPEX | D28: =CAPEX_TOTAL_YM1+CAPEX_TOTAL_Y0+CAPEX_TOTAL_Y1+CAPEX_TOTAL_Y2+CAPEX_TOTAL_Y3+CAPEX_TOTAL_Y4+CAPEX_TOTAL_Y5+CAPEX_TOTAL_Y6 -> 5566792.4
B30: Note: Senior debt not yet sized — DSCR and returns are indicative only

Sheet 01_Assumptions
B1: 01 — Assumptions
B3: Parameter | C3: Unit | D3: Value
B4: Engine inputs (computed parameters)
B5: Farmers per cooperative farm (filière A) | C5: persons | D5: 40
B6: Water technicians per farm (filière B) | C6: persons | D6: 4
B7: Energy technicians per farm (filière C) | C7: persons | D7: 2
B8: Mechanisation operators per farm (filière D) | C8: persons | D8: 6
B9: Number of cooperative farms — Phase A wave | C9: UOFs | D9: 10
B10: Number of cooperative farms — full programme | C10: UOFs | D10: 50
B11: Bootstrap cohort — number of trainees | C11: persons | D11: 120
B12: Calendar days per month | C12: days | D12: 25
B13: International specialist trainers | C13: persons | D13: 3
B14: International specialist — annual cost | C14: €/yr | D14: 40000
B15: Total beds — Phase A | C15: beds | D15: 135
B16: Resident trainees — Phase A | C16: persons | D16: 135
... B27: USD source — diesel price | C27: USD/L | D27: 1
B29: Programme structure
B30: Number of incubator farms | C30: count | D30: 3
B31: Surface area per farm | C31: ha | D31: 100
B32: Project life (Y-1 → Y6) | C32: years | D32: 8
B33: Commissioning year (COD) | C33: year | D33: 1
B34: Gate evaluation year | C34: year | D34: 2
B35: Training start year | C35: year | D35: 1
B36: Training stop year | C36: year | D36: 2
B37: EUR / USD exchange rate | C37: EUR/USD | D37: 1.1
B39: Training throughput
B40: Simultaneous training slots per farm | C40: persons | D40: 90
B41: Staggered cohorts per farm | C41: cohorts | D41: 2
B42: Trainees per cohort | C42: persons | D42: 45
B43: Annual throughput at steady state | C43: persons/yr | D43: 270
B44: Filière A share — farmers | C44: % | D44: 0.76923077
B45: Filière B share — water technicians | C45: % | D45: 0.076923077
B46: Filière C share — energy technicians | C46: % | D46: 0.038461538
B47: Filière D share — mechanisation operators | C47: % | D47: 0.11538462
B48: Programme target — filière A graduates | C48: persons | D48: 520
B49: Programme target — filière B graduates | C49: persons | D49: 40
B50: Programme target — filière C graduates | C50: persons | D50: 20
B51: Programme target — filière D graduates | C51: persons | D51: 60
B52: Programme target — total graduates | C52: persons | D52: 640
B54: Cost per trainee by filière
...

Sheet 02_Timeline
B1: 02 — Timeline / Programme state
D3: Total | E3: Y-1 | F3: Y0 | G3: Y1 | H3: Y2 | I3: Y3 | J3: Y4 | K3: Y5 | L3: Y6
E4: -1 | F4: 0 | G4: 1 | H4: 2 | I4: 3 | J4: 4 | K4: 5 | L4: 6
B7: Programme phase
B8: Pre-programme (Y-1) | C8: flag | D8: =SUM(E8:L8) -> 1 | E8: =IF(E$4=-1,1,0) -> 1 | F8: =IF(F$4=-1,1,0) -> 0 | G8: =IF(G$4=-1,1,0) -> 0 | H8: =IF(H$4=-1,1,0) -> 0 | I8: =IF(I$4=-1,1,0) -> 0 | J8: =IF(J$4=-1,1,0) -> 0 | K8: =IF(K$4=-1,1,0) -> 0 | L8: =IF(L$4=-1,1,0) -> 0
B9: Construction (Y0) | C9: flag | D9: =SUM(E9:L9) -> 1 | E9: =IF(E$4=0,1,0) -> 0 | F9: =IF(F$4=0,1,0) -> 1 | G9: =IF(G$4=0,1,0) -> 0 | H9: =IF(H$4=0,1,0) -> 0 | I9: =IF(I$4=0,1,0) -> 0 | J9: =IF(J$4=0,1,0) -> 0 | K9: =IF(K$4=0,1,0) -> 0 | L9: =IF(L$4=0,1,0) -> 0
B10: Phase A — training (Y1-Y2) | C10: flag | D10: =SUM(E10:L10) -> 2 | E10: =IF(AND(E$4>=ASM_A06_TRAINING_START_YEAR,E$4<=ASM_A07_TRAINING_STOP_YEAR),1,0) -> 0 | F10: =IF(AND(F$4>=ASM_A06_TRAINING_START_YEAR,F$4<=ASM_A07_TRAINING_STOP_YEAR),1,0) -> 0 | G10: =IF(AND(G$4>=ASM_A06_TRAINING_START_YEAR,G$4<=ASM_A07_TRAINING_STOP_YEAR),1,0) -> 1 | H10: =IF(AND(H$4>=ASM_A06_TRAINING_START_YEAR,H$4<=ASM_A07_TRAINING_STOP_YEAR),1,0) -> 1 | I10: =IF(AND(I$4>=ASM_A06_TRAINING_START_YEAR,I$4<=ASM_A07_TRAINING_STOP_YEAR),1,0) -> 0 | J10: =IF(AND(J$4>=ASM_A06_TRAINING_START_YEAR,J$4<=ASM_A07_TRAINING_STOP_YEAR),1,0) -> 0 | K10: =IF(AND(K$4>=ASM_A06_TRAINING_START_YEAR,K$4<=ASM_A07_TRAINING_STOP_YEAR),1,0) -> 0 | L10: =IF(AND(L$4>=ASM_A06_TRAINING_START_YEAR,L$4<=ASM_A07_TRAINING_STOP_YEAR),1,0) -> 0
B11: Deployment support (Y3+) | C11: flag | D11: =SUM(E11:L11) -> 4 | E11: =IF(E$4>ASM_A07_TRAINING_STOP_YEAR,1,0) -> 0 | F11: =IF(F$4>ASM_A07_TRAINING_STOP_YEAR,1,0) -> 0 | G11: =IF(G$4>ASM_A07_TRAINING_STOP_YEAR,1,0) -> 0 | H11: =IF(H$4>ASM_A07_TRAINING_STOP_YEAR,1,0) -> 0 | I11: =IF(I$4>ASM_A07_TRAINING_STOP_YEAR,1,0) -> 1 | J11: =IF(J$4>ASM_A07_TRAINING_STOP_YEAR,1,0) -> 1 | K11: =IF(K$4>ASM_A07_TRAINING_STOP_YEAR,1,0) -> 1 | L11: =IF(L$4>ASM_A07_TRAINING_STOP_YEAR,1,0) -> 1
B12: Post-commissioning operations (Y1+) | C12: flag | D12: =SUM(E12:L12) -> 6 | E12: =IF(E$4>=ASM_A04_COD_YEAR,1,0) -> 0 | F12: =IF(F$4>=ASM_A04_COD_YEAR,1,0) -> 0 | G12: =IF(G$4>=ASM_A04_COD_YEAR,1,0) -> 1 | H12: =IF(H$4>=ASM_A04_COD_YEAR,1,0) -> 1 | I12: =IF(I$4>=ASM_A04_COD_YEAR,1,0) -> 1 | J12: =IF(J$4>=ASM_A04_COD_YEAR,1,0) -> 1 | K12: =IF(K$4>=ASM_A04_COD_YEAR,1,0) -> 1 | L12: =IF(L$4>=ASM_A04_COD_YEAR,1,0) -> 1
B14: O2 — Production & operations
B15: Farms operational | C15: count | D15: =SUM(E15:L15) -> 18 | E15: =IF(E$4>=ASM_A04_COD_YEAR,ASM_A01_N_FARMS,0) -> 0 | F15: =IF(F$4>=ASM_A04_COD_YEAR,ASM_A01_N_FARMS,0) -> 0 | G15: =IF(G$4>=ASM_A04_COD_YEAR,ASM_A01_N_FARMS,0) -> 3 | H15: =IF(H$4>=ASM_A04_COD_YEAR,ASM_A01_N_FARMS,0) -> 3 | I15: =IF(I$4>=ASM_A04_COD_YEAR,ASM_A01_N_FARMS,0) -> 3 | J15: =IF(J$4>=ASM_A04_COD_YEAR,ASM_A01_N_FARMS,0) -> 3 | K15: =IF(K$4>=ASM_A04_COD_YEAR,ASM_A01_N_FARMS,0) -> 3 | L15: =IF(L$4>=ASM_A04_COD_YEAR,ASM_A01_N_FARMS,0) -> 3
B16: Farms in construction | C16: count | D16: =SUM(E16:L16) -> 3 | E16: =IF(E$4=0,ASM_A01_N_FARMS,0) -> 0 | F16: =IF(F$4=0,ASM_A01_N_FARMS,0) -> 3 | G16: =IF(G$4=0,ASM_A01_N_FARMS,0) -> 0 | H16: =IF(H$4=0,ASM_A01_N_FARMS,0) -> 0 | I16: =IF(I$4=0,ASM_A01_N_FARMS,0) -> 0 | J16: =IF(J$4=0,ASM_A01_N_FARMS,0) -> 0 | K16: =IF(K$4=0,ASM_A01_N_FARMS,0) -> 0 | L16: =IF(L$4=0,ASM_A01_N_FARMS,0) -> 0
B17: Production flag | C17: % SS | D17: =SUM(E17:L17) -> 5.15 | E17: =IF(E$4<ASM_A04_COD_YEAR,0,IF(E$4=ASM_A04_COD_YEAR,ASM_E20_RAMP_Y1_PCT,IF(E$4=ASM_A04_COD_YEAR+1,ASM_E21_RAMP_Y2_PCT,1))) -> 0 | F17: =IF(F$4<ASM_A04_COD_YEAR,0,IF(F$4=ASM_A04_COD_YEAR,ASM_E20_RAMP_Y1_PCT,IF(F$4=ASM_A04_COD_YEAR+1,ASM_E21_RAMP_Y2_PCT,1))) -> 0 | G17: =IF(G$4<ASM_A04_COD_YEAR,0,IF(G$4=ASM_A04_COD_YEAR,ASM_E20_RAMP_Y1_PCT,IF(G$4=ASM_A04_COD_YEAR+1,ASM_E21_RAMP_Y2_PCT,1))) -> 0.4 | H17: =IF(H$4<ASM_A04_COD_YEAR,0,IF(H$4=ASM_A04_COD_YEAR,ASM_E20_RAMP_Y1_PCT,IF(H$4=ASM_A04_COD_YEAR+1,ASM_E21_RAMP_Y2_PCT,1))) -> 0.75 | I17: =IF(I$4<ASM_A04_COD_YEAR,0,IF(I$4=ASM_A04_COD_YEAR,ASM_E20_RAMP_Y1_PCT,IF(I$4=ASM_A04_COD_YEAR+1,ASM_E21_RAMP_Y2_PCT,1))) -> 1 | J17: =IF(J$4<ASM_A04_COD_YEAR,0,IF(J$4=ASM_A04_COD_YEAR,ASM_E20_RAMP_Y1_PCT,IF(J$4=ASM_A04_COD_YEAR+1,ASM_E21_RAMP_Y2_PCT,1))) -> 1 | K17: =IF(K$4<ASM_A04_COD_YEAR,0,IF(K$4=ASM_A04_COD_YEAR,ASM_E20_RAMP_Y1_PCT,IF(K$4=ASM_A04_COD_YEAR+1,ASM_E21_RAMP_Y2_PCT,1))) -> 1 | L17: =IF(L$4<ASM_A04_COD_YEAR,0,IF(L$4=ASM_A04_COD_YEAR,ASM_E20_RAMP_Y1_PCT,IF(L$4=ASM_A04_COD_YEAR+1,ASM_E21_RAMP_Y2_PCT,1))) -> 1
B19: O1 — Training throughput (residents in year)
B20: Filière A — farmers | C20: persons | D20: =SUM(E20:L20) -> 416 | E20: =IF(AND(E$4>=ASM_A06_TRAINING_START_YEAR,E$4<=ASM_A07_TRAINING_STOP_YEAR),ROUND(ASM_B04_THROUGHPUT_ANNUAL*ASM_B05_PCT_FILIERE_A,0),0) -> 0 | F20: =IF(AND(F$4>=ASM_A06_TRAINING_START_YEAR,F$4<=ASM_A07_TRAINING_STOP_YEAR),ROUND(ASM_B04_THROUGHPUT_ANNUAL*ASM_B05_PCT_FILIERE_A,0),0) -> 0 | G20: =IF(AND(G$4>=ASM_A06_TRAINING_START_YEAR,G$4<=ASM_A07_TRAINING_STOP_YEAR),ROUND(ASM_B04_THROUGHPUT_ANNUAL*ASM_B05_PCT_FILIERE_A,0),0) -> 208 | H20: =IF(AND(H$4>=ASM_A06_TRAINING_START_YEAR,H$4<=ASM_A07_TRAINING_STOP_YEAR),ROUND(ASM_B04_THROUGHPUT_ANNUAL*ASM_B05_PCT_FILIERE_A,0),0) -> 208 | I20: =IF(AND(I$4>=ASM_A06_TRAINING_START_YEAR,I$4<=ASM_A07_TRAINING_STOP_YEAR),ROUND(ASM_B04_THROUGHPUT_ANNUAL*ASM_B05_PCT_FILIERE_A,0),0) -> 0 | J20: =IF(AND(J$4>=ASM_A06_TRAINING_START_YEAR,J$4<=ASM_A07_TRAINING_STOP_YEAR),ROUND(ASM_B04_THROUGHPUT_ANNUAL*ASM_B05_PCT_FILIERE_A,0),0) -> 0 | K20: =IF(AND(K$4>=ASM_A06_TRAINING_START_YEAR,K$4<=ASM_A07_TRAINING_STOP_YEAR),ROUND(ASM_B04_THROUGHPUT_ANNUAL*ASM_B05_PCT_FILIERE_A,0),0) -> 0 | L20: =IF(AND(L$4>=ASM_A06_TRAINING_START_YEAR,L$4<=ASM_A07_TRAINING_STOP_YEAR),ROUND(ASM_B04_THROUGHPUT_ANNUAL*ASM_B05_PCT_FILIERE_A,0),0) -> 0
B21: Filière B — water technicians | C21: persons | D21: =SUM(E21:L21) -> 42 | E21: =IF(AND(E$4>=ASM_A06_TRAINING_START_YEAR,E$4<=ASM_A07_TRAINING_STOP_YEAR),ROUND(ASM_B04_THROUGHPUT_ANNUAL*ASM_B06_PCT_FILIERE_B,0),0) -> 0 | F21: =IF(AND(F$4>=ASM_A06_TRAINING_START_YEAR,F$4<=ASM_A07_TRAINING_STOP_YEAR),ROUND(ASM_B04_THROUGHPUT_ANNUAL*ASM_B06_PCT_FILIERE_B,0),0) -> 0 | G21: =IF(AND(G$4>=ASM_A06_TRAINING_START_YEAR,G$4<=ASM_A07_TRAINING_STOP_YEAR),ROUND(ASM_B04_THROUGHPUT_ANNUAL*ASM_B06_PCT_FILIERE_B,0),0) -> 21 | H21: =IF(AND(H$4>=ASM_A06_TRAINING_START_YEAR,H$4<=ASM_A07_TRAINING_STOP_YEAR),ROUND(ASM_B04_THROUGHPUT_ANNUAL*ASM_B06_PCT_FILIERE_B,0),0) -> 21 | I21: =IF(AND(I$4>=ASM_A06_TRAINING_START_YEAR,I$4<=ASM_A07_TRAINING_STOP_YEAR),ROUND(ASM_B04_THROUGHPUT_ANNUAL*ASM_B06_PCT_FILIERE_B,0),0) -> 0 | J21: =IF(AND(J$4>=ASM_A06_TRAINING_START_YEAR,J$4<=ASM_A07_TRAINING_STOP_YEAR),ROUND(ASM_B04_THROUGHPUT_ANNUAL*ASM_B06_PCT_FILIERE_B,0),0) -> 0 | K21: =IF(AND(K$4>=ASM_A06_TRAINING_START_YEAR,K$4<=ASM_A07_TRAINING_STOP_YEAR),ROUND(ASM_B04_THROUGHPUT_ANNUAL*ASM_B06_PCT_FILIERE_B,0),0) -> 0 | L21: =IF(AND(L$4>=ASM_A06_TRAINING_START_YEAR,L$4<=ASM_A07_TRAINING_STOP_YEAR),ROUND(ASM_B04_THROUGHPUT_ANNUAL*ASM_B06_PCT_FILIERE_B,0),0) -> 0
B22: Filière C — energy technicians | C22: persons | D22: =SUM(E22:L22) -> 20 | E22: =IF(AND(E$4>=ASM_A06_TRAINING_START_YEAR,E$4<=ASM_A07_TRAINING_STOP_YEAR),ROUND(ASM_B04_THROUGHPUT_ANNUAL*ASM_B07_PCT_FILIERE_C,0),0) -> 0 | F22: =IF(AND(F$4>=ASM_A06_TRAINING_START_YEAR,F$4<=ASM_A07_TRAINING_STOP_YEAR),ROUND(ASM_B04_THROUGHPUT_ANNUAL*ASM_B07_PCT_FILIERE_C,0),0) -> 0 | G22: =IF(AND(G$4>=ASM_A06_TRAINING_START_YEAR,G$4<=ASM_A07_TRAINING_STOP_YEAR),ROUND(ASM_B04_THROUGHPUT_ANNUAL*ASM_B07_PCT_FILIERE_C,0),0) -> 10 | H22: =IF(AND(H$4>=ASM_A06_TRAINING_START_YEAR,H$4<=ASM_A07_TRAINING_STOP_YEAR),ROUND(ASM_B04_THROUGHPUT_ANNUAL*ASM_B07_PCT_FILIERE_C,0),0) -> 10 | I22: =IF(AND(I$4>=ASM_A06_TRAINING_START_YEAR,I$4<=ASM_A07_TRAINING_STOP_YEAR),ROUND(ASM_B04_THROUGHPUT_ANNUAL*ASM_B07_PCT_FILIERE_C,0),0) -> 0 | J22: =IF(AND(J$4>=ASM_A06_TRAINING_START_YEAR,J$4<=ASM_A07_TRAINING_STOP_YEAR),ROUND(ASM_B04_THROUGHPUT_ANNUAL*ASM_B07_PCT_FILIERE_C,0),0) -> 0 | K22: =IF(AND(K$4>=ASM_A06_TRAINING_START_YEAR,K$4<=ASM_A07_TRAINING_STOP_YEAR),ROUND(ASM_B04_THROUGHPUT_ANNUAL*ASM_B07_PCT_FILIERE_C,0),0) -> 0 | L22: =IF(AND(L$4>=ASM_A06_TRAINING_START_YEAR,L$4<=ASM_A07_TRAINING_STOP_YEAR),ROUND(ASM_B04_THROUGHPUT_ANNUAL*ASM_B07_PCT_FILIERE_C,0),0) -> 0
B23: Filière D — mechanisation operators | C23: persons | D23: =SUM(E23:L23) -> 62 | E23: =IF(AND(E$4>=ASM_A06_TRAINING_START_YEAR,E$4<=ASM_A07_TRAINING_STOP_YEAR),ASM_B04_THROUGHPUT_ANNUAL-ROUND(ASM_B04_THROUGHPUT_ANNUAL*ASM_B05_PCT_FILIERE_A,0)-ROUND(ASM_B04_THROUGHPUT_ANNUAL*ASM_B06_PCT_FILIERE_B,0)-ROUND(ASM_B04_THROUGHPUT_ANNUAL*ASM_B07_PCT_FILIERE_C,0),0) -> 0 | F23: =IF(AND(F$4>=ASM_A06_TRAINING_START_YEAR,F$4<=ASM_A07_TRAINING_STOP_YEAR),ASM_B04_THROUGHPUT_ANNUAL-ROUND(ASM_B04_THROUGHPUT_ANNUAL*ASM_B05_PCT_FILIERE_A,0)-ROUND(ASM_B04_THROUGHPUT_ANNUAL*ASM_B06_PCT_FILIERE_B,0)-ROUND(ASM_B04_THROUGHPUT_ANNUAL*ASM_B07_PCT_FILIERE_C,0),0) -> 0 | G23: =IF(AND(G$4>=ASM_A06_TRAINING_START_YEAR,G$4<=ASM_A07_TRAINING_STOP_YEAR),ASM_B04_THROUGHPUT_ANNUAL-ROUND(ASM_B04_THROUGHPUT_ANNUAL*ASM_B05_PCT_FILIERE_A,0)-ROUND(ASM_B04_THROUGHPUT_ANNUAL*ASM_B06_PCT_FILIERE_B,0)-ROUND(ASM_B04_THROUGHPUT_ANNUAL*ASM_B07_PCT_FILIERE_C,0),0) -> 31 | H23: =IF(AND(H$4>=ASM_A06_TRAINING_START_YEAR,H$4<=ASM_A07_TRAINING_STOP_YEAR),ASM_B04_THROUGHPUT_ANNUAL-ROUND(ASM_B04_THROUGHPUT_ANNUAL*ASM_B05_PCT_FILIERE_A,0)-ROUND(ASM_B04_THROUGHPUT_ANNUAL*ASM_B06_PCT_FILIERE_B,0)-ROUND(ASM_B04_THROUGHPUT_ANNUAL*ASM_B07_PCT_FILIERE_C,0),0) -> 31 | I23: =IF(AND(I$4>=ASM_A06_TRAINING_START_YEAR,I$4<=ASM_A07_TRAINING_STOP_YEAR),ASM_B04_THROUGHPUT_ANNUAL-ROUND(ASM_B04_THROUGHPUT_ANNUAL*ASM_B05_PCT_FILIERE_A,0)-ROUND(ASM_B04_THROUGHPUT_ANNUAL*ASM_B06_PCT_FILIERE_B,0)-ROUND(ASM_B04_THROUGHPUT_ANNUAL*ASM_B07_PCT_FILIERE_C,0),0) -> 0 | J23: =IF(AND(J$4>=ASM_A06_TRAINING_START_YEAR,J$4<=ASM_A07_TRAINING_STOP_YEAR),ASM_B04_THROUGHPUT_ANNUAL-ROUND(ASM_B04_THROUGHPUT_ANNUAL*ASM_B05_PCT_FILIERE_A,0)-ROUND(ASM_B04_THROUGHPUT_ANNUAL*ASM_B06_PCT_FILIERE_B,0)-ROUND(ASM_B04_THROUGHPUT_ANNUAL*ASM_B07_PCT_FILIERE_C,0),0) -> 0 | K23: =IF(AND(K$4>=ASM_A06_TRAINING_START_YEAR,K$4<=ASM_A07_TRAINING_STOP_YEAR),ASM_B04_THROUGHPUT_ANNUAL-ROUND(ASM_B04_THROUGHPUT_ANNUAL*ASM_B05_PCT_FILIERE_A,0)-ROUND(ASM_B04_THROUGHPUT_ANNUAL*ASM_B06_PCT_FILIERE_B,0)-ROUND(ASM_B04_THROUGHPUT_ANNUAL*ASM_B07_PCT_FILIERE_C,0),0) -> 0 | L23: =IF(AND(L$4>=ASM_A06_TRAINING_START_YEAR,L$4<=ASM_A07_TRAINING_STOP_YEAR),ASM_B04_THROUGHPUT_ANNUAL-ROUND(ASM_B04_THROUGHPUT_ANNUAL*ASM_B05_PCT_FILIERE_A,0)-ROUND(ASM_B04_THROUGHPUT_ANNUAL*ASM_B06_PCT_FILIERE_B,0)-ROUND(ASM_B04_THROUGHPUT_ANNUAL*ASM_B07_PCT_FILIERE_C,0),0) -> 0
B25: O1 — Cumulative certified (programme running total)
B26: Cumulative certified A — farmers | C26: persons | D26: =SUM(E26:L26) -> 2704 | E26: =IF(E$4>=ASM_A06_TRAINING_START_YEAR,MIN(ROUND(ASM_B04_THROUGHPUT_ANNUAL*ASM_B05_PCT_FILIERE_A,0)*(E$4-ASM_A06_TRAINING_START_YEAR+1),ASM_B09_TARGET_CERTIFIED_A),0) -> 0 | F26: =IF(F$4>=ASM_A06_TRAINING_START_YEAR,MIN(ROUND(ASM_B04_THROUGHPUT_ANNUAL*ASM_B05_PCT_FILIERE_A,0)*(F$4-ASM_A06_TRAINING_START_YEAR+1),ASM_B09_TARGET_CERTIFIED_A),0) -> 0 | G26: =IF(G$4>=ASM_A06_TRAINING_START_YEAR,MIN(ROUND(ASM_B04_THROUGHPUT_ANNUAL*ASM_B05_PCT_FILIERE_A,0)*(G$4-ASM_A06_TRAINING_START_YEAR+1),ASM_B09_TARGET_CERTIFIED_A),0) -> 208 | H26: =IF(H$4>=ASM_A06_TRAINING_START_YEAR,MIN(ROUND(ASM_B04_THROUGHPUT_ANNUAL*ASM_B05_PCT_FILIERE_A,0)*(H$4-ASM_A06_TRAINING_START_YEAR+1),ASM_B09_TARGET_CERTIFIED_A),0) -> 416 | I26: =IF(I$4>=ASM_A06_TRAINING_START_YEAR,MIN(ROUND(ASM_B04_THROUGHPUT_ANNUAL*ASM_B05_PCT_FILIERE_A,0)*(I$4-ASM_A06_TRAINING_START_YEAR+1),ASM_B09_TARGET_CERTIFIED_A),0) -> 520 | J26: =IF(J$4>=ASM_A06_TRAINING_START_YEAR,MIN(ROUND(ASM_B04_THROUGHPUT_ANNUAL*ASM_B05_PCT_FILIERE_A,0)*(J$4-ASM_A06_TRAINING_START_YEAR+1),ASM_B09_TARGET_CERTIFIED_A),0) -> 520 | K26: =IF(K$4>=ASM_A06_TRAINING_START_YEAR,MIN(ROUND(ASM_B04_THROUGHPUT_ANNUAL*ASM_B05_PCT_FILIERE_A,0)*(K$4-ASM_A06_TRAINING_START_YEAR+1),ASM_B09_TARGET_CERTIFIED_A),0) -> 520 | L26: =IF(L$4>=ASM_A06_TRAINING_START_YEAR,MIN(ROUND(ASM_B04_THROUGHPUT_ANNUAL*ASM_B05_PCT_FILIERE_A,0)*(L$4-ASM_A06_TRAINING_START_YEAR+1),ASM_B09_TARGET_CERTIFIED_A),0) -> 520
B27: Cumulative certified B — water technicians | C27: persons | D27: =SUM(E27:L27) -> 221 | E27: =IF(E$4>=ASM_A06_TRAINING_START_YEAR,MIN(ROUND(ASM_B04_THROUGHPUT_ANNUAL*ASM_B06_PCT_FILIERE_B,0)*(E$4-ASM_A06_TRAINING_START_YEAR+1),ASM_B10_TARGET_CERTIFIED_B),0) -> 0 | F27: =IF(F$4>=ASM_A06_TRAINING_START_YEAR,MIN(ROUND(ASM_B04_THROUGHPUT_ANNUAL*ASM_B06_PCT_FILIERE_B,0)*(F$4-ASM_A06_TRAINING_START_YEAR+1),ASM_B10_TARGET_CERTIFIED_B),0) -> 0 | G27: =IF(G$4>=ASM_A06_TRAINING_START_YEAR,MIN(ROUND(ASM_B04_THROUGHPUT_ANNUAL*ASM_B06_PCT_FILIERE_B,0)*(G$4-ASM_A06_TRAINING_START_YEAR+1),ASM_B10_TARGET_CERTIFIED_B),0) -> 21 | H27: =IF(H$4>=ASM_A06_TRAINING_START_YEAR,MIN(ROUND(ASM_B04_THROUGHPUT_ANNUAL*ASM_B06_PCT_FILIERE_B,0)*(H$4-ASM_A06_TRAINING_START_YEAR+1),ASM_B10_TARGET_CERTIFIED_B),0) -> 40 | I27: =IF(I$4>=ASM_A06_TRAINING_START_YEAR,MIN(ROUND(ASM_B04_THROUGHPUT_ANNUAL*ASM_B06_PCT_FILIERE_B,0)*(I$4-ASM_A06_TRAINING_START_YEAR+1),ASM_B10_TARGET_CERTIFIED_B),0) -> 40 | J27: =IF(J$4>=ASM_A06_TRAINING_START_YEAR,MIN(ROUND(ASM_B04_THROUGHPUT_ANNUAL*ASM_B06_PCT_FILIERE_B,0)*(J$4-ASM_A06_TRAINING_START_YEAR+1),ASM_B10_TARGET_CERTIFIED_B),0) -> 40 | K27: =IF(K$4>=ASM_A06_TRAINING_START_YEAR,MIN(ROUND(ASM_B04_THROUGHPUT_ANNUAL*ASM_B06_PCT_FILIERE_B,0)*(K$4-ASM_A06_TRAINING_START_YEAR+1),ASM_B10_TARGET_CERTIFIED_B),0) -> 40 | L27: =IF(L$4>=ASM_A06_TRAINING_START_YEAR,MIN(ROUND(ASM_B04_THROUGHPUT_ANNUAL*ASM_B06_PCT_FILIERE_B,0)*(L$4-ASM_A06_TRAINING_START_YEAR+1),ASM_B10_TARGET_CERTIFIED_B),0) -> 40
B28: Cumulative certified C — energy technicians | C28: persons | D28: =SUM(E28:L28) -> 110 | E28: =IF(E$4>=ASM_A06_TRAINING_START_YEAR,MIN(ROUND(ASM_B04_THROUGHPUT_ANNUAL*ASM_B07_PCT_FILIERE_C,0)*(E$4-ASM_A06_TRAINING_START_YEAR+1),ASM_B11_TARGET_CERTIFIED_C),0) -> 0 | F28: =IF(F$4>=ASM_A06_TRAINING_START_YEAR,MIN(ROUND(ASM_B04_THROUGHPUT_ANNUAL*ASM_B07_PCT_FILIERE_C,0)*(F$4-ASM_A06_TRAINING_START_YEAR+1),ASM_B11_TARGET_CERTIFIED_C),0) -> 0 | G28: =IF(G$4>=ASM_A06_TRAINING_START_YEAR,MIN(ROUND(ASM_B04_THROUGHPUT_ANNUAL*ASM_B07_PCT_FILIERE_C,0)*(G$4-ASM_A06_TRAINING_START_YEAR+1),ASM_B11_TARGET_CERTIFIED_C),0) -> 10 | H28: =IF(H$4>=ASM_A06_TRAINING_START_YEAR,MIN(ROUND(ASM_B04_THROUGHPUT_ANNUAL*ASM_B07_PCT_FILIERE_C,0)*(H$4-ASM_A06_TRAINING_START_YEAR+1),ASM_B11_TARGET_CERTIFIED_C),0) -> 20 | I28: =IF(I$4>=ASM_A06_TRAINING_START_YEAR,MIN(ROUND(ASM_B04_THROUGHPUT_ANNUAL*ASM_B07_PCT_FILIERE_C,0)*(I$4-ASM_A06_TRAINING_START_YEAR+1),ASM_B11_TARGET_CERTIFIED_C),0) -> 20 | J28: =IF(J$4>=ASM_A06_TRAINING_START_YEAR,MIN(ROUND(ASM_B04_THROUGHPUT_ANNUAL*ASM_B07_PCT_FILIERE_C,0)*(J$4-ASM_A06_TRAINING_START_YEAR+1),ASM_B11_TARGET_CERTIFIED_C),0) -> 20 | K28: =IF(K$4>=ASM_A06_TRAINING_START_YEAR,MIN(ROUND(ASM_B04_THROUGHPUT_ANNUAL*ASM_B07_PCT_FILIERE_C,0)*(K$4-ASM_A06_TRAINING_START_YEAR+1),ASM_B11_TARGET_CERTIFIED_C),0) -> 20 | L28: =IF(L$4>=ASM_A06_TRAINING_START_YEAR,MIN(ROUND(ASM_B04_THROUGHPUT_ANNUAL*ASM_B07_PCT_FILIERE_C,0)*(L$4-ASM_A06_TRAINING_START_YEAR+1),ASM_B11_TARGET_CERTIFIED_C),0) -> 20
B29: Cumulative certified D — mechanisation operators | C29: persons | D29: =SUM(E29:L29) -> 331 | E29: =IF(E$4>=ASM_A06_TRAINING_START_YEAR,MIN((ASM_B04_THROUGHPUT_ANNUAL-ROUND(ASM_B04_THROUGHPUT_ANNUAL*ASM_B05_PCT_FILIERE_A,0)-ROUND(ASM_B04_THROUGHPUT_ANNUAL*ASM_B06_PCT_FILIERE_B,0)-ROUND(ASM_B04_THROUGHPUT_ANNUAL*ASM_B07_PCT_FILIERE_C,0))*(E$4-ASM_A06_TRAINING_START_YEAR+1),ASM_B12_TARGET_CERTIFIED_D),0) -> 0 | F29: =IF(F$4>=ASM_A06_TRAINING_START_YEAR,MIN((ASM_B04_THROUGHPUT_ANNUAL-ROUND(ASM_B04_THROUGHPUT_ANNUAL*ASM_B05_PCT_FILIERE_A,0)-ROUND(ASM_B04_THROUGHPUT_ANNUAL*ASM_B06_PCT_FILIERE_B,0)-ROUND(ASM_B04_THROUGHPUT_ANNUAL*ASM_B07_PCT_FILIERE_C,0))*(F$4-ASM_A06_TRAINING_START_YEAR+1),ASM_B12_TARGET_CERTIFIED_D),0) -> 0 | G29: =IF(G$4>=ASM_A06_TRAINING_START_YEAR,MIN((ASM_B04_THROUGHPUT_ANNUAL-ROUND(ASM_B04_THROUGHPUT_ANNUAL*ASM_B05_PCT_FILIERE_A,0)-ROUND(ASM_B04_THROUGHPUT_ANNUAL*ASM_B06_PCT_FILIERE_B,0)-ROUND(ASM_B04_THROUGHPUT_ANNUAL*ASM_B07_PCT_FILIERE_C,0))*(G$4-ASM_A06_TRAINING_START_YEAR+1),ASM_B12_TARGET_CERTIFIED_D),0) -> 31 | H29: =IF(H$4>=ASM_A06_TRAINING_START_YEAR,MIN((ASM_B04_THROUGHPUT_ANNUAL-ROUND(ASM_B04_THROUGHPUT_ANNUAL*ASM_B05_PCT_FILIERE_A,0)-ROUND(ASM_B04_THROUGHPUT_ANNUAL*ASM_B06_PCT_FILIERE_B,0)-ROUND(ASM_B04_THROUGHPUT_ANNUAL*ASM_B07_PCT_FILIERE_C,0))*(H$4-ASM_A06_TRAINING_START_YEAR+1),ASM_B12_TARGET_CERTIFIED_D),0) -> 60 | I29: =IF(I$4>=ASM_A06_TRAINING_START_YEAR,MIN((ASM_B04_THROUGHPUT_ANNUAL-ROUND(ASM_B04_THROUGHPUT_ANNUAL*ASM_B05_PCT_FILIERE_A,0)-ROUND(ASM_B04_THROUGHPUT_ANNUAL*ASM_B06_PCT_FILIERE_B,0)-ROUND(ASM_B04_THROUGHPUT_ANNUAL*ASM_B07_PCT_FILIERE_C,0))*(I$4-ASM_A06_TRAINING_START_YEAR+1),ASM_B12_TARGET_CERTIFIED_D),0) -> 60 | J29: =IF(J$4>=ASM_A06_TRAINING_START_YEAR,MIN((ASM_B04_THROUGHPUT_ANNUAL-ROUND(ASM_B04_THROUGHPUT_ANNUAL*ASM_B05_PCT_FILIERE_A,0)-ROUND(ASM_B04_THROUGHPUT_ANNUAL*ASM_B06_PCT_FILIERE_B,0)-ROUND(ASM_B04_THROUGHPUT_ANNUAL*ASM_B07_PCT_FILIERE_C,0))*(J$4-ASM_A06_TRAINING_START_YEAR+1),ASM_B12_TARGET_CERTIFIED_D),0) -> 60 | K29: =IF(K$4>=ASM_A06_TRAINING_START_YEAR,MIN((ASM_B04_THROUGHPUT_ANNUAL-ROUND(ASM_B04_THROUGHPUT_ANNUAL*ASM_B05_PCT_FILIERE_A,0)-ROUND(ASM_B04_THROUGHPUT_ANNUAL*ASM_B06_PCT_FILIERE_B,0)-ROUND(ASM_B04_THROUGHPUT_ANNUAL*ASM_B07_PCT_FILIERE_C,0))*(K$4-ASM_A06_TRAINING_START_YEAR+1),ASM_B12_TARGET_CERTIFIED_D),0) -> 60 | L29: =IF(L$4>=ASM_A06_TRAINING_START_YEAR,MIN((ASM_B04_THROUGHPUT_ANNUAL-ROUND(ASM_B04_THROUGHPUT_ANNUAL*ASM_B05_PCT_FILIERE_A,0)-ROUND(ASM_B04_THROUGHPUT_ANNUAL*ASM_B06_PCT_FILIERE_B,0)-ROUND(ASM_B04_THROUGHPUT_ANNUAL*ASM_B07_PCT_FILIERE_C,0))*(L$4-ASM_A06_TRAINING_START_YEAR+1),ASM_B12_TARGET_CERTIFIED_D),0) -> 60

Sheet 03_Training
B1: 03 — Training / Human capital [€] ← feeds CAPEX · OpEx · Revenue
D3: Total | E3: Y-1 | F3: Y0 | G3: Y1 | H3: Y2 | I3: Y3 | J3: Y4 | K3: Y5 | L3: Y6
E4: -1 | F4: 0 | G4: 1 | H4: 2 | I4: 3 | J4: 4 | K4: 5 | L4: 6
B6: Summary
B7: 1. Training infrastructure (one-time CAP) | C7: € | D7: =SUM(E7:L7) -> 1488000 | E7: =E38 -> 628000 | F7: =F38 -> 860000 | G7: =G38 -> 0 | H7: =H38 -> 0 | I7: =I38 -> 0 | J7: =J38 -> 0 | K7: =K38 -> 0 | L7: =L38 -> 0
B8: 2. Recurring training (annual OPEX, net of work offset) | C8: € | D8: =SUM(E8:L8) -> 1359700 | E8: =E61 -> 0 | F8: =F61 -> 0 | G8: =G61 -> 679850 | H8: =H61 -> 679850 | I8: =I61 -> 0 | J8: =J61 -> 0 | K8: =K61 -> 0 | L8: =L61 -> 0
B9: 3. Training revenue (= 0; grant-funded) | C9: € | D9: =SUM(E9:L9) -> 0 | E9: =0 -> 0 | F9: =0 -> 0 | G9: =0 -> 0 | H9: =0 -> 0 | I9: =0 -> 0 | J9: =0 -> 0 | K9: =0 -> 0 | L9: =0 -> 0
B10: TOTAL TRAINING PROGRAMME COST | C10: € | D10: =SUM(E10:L10) -> 2847700 | E10: =E7+E8-E9 -> 628000 | F10: =F7+F8-F9 -> 860000 | G10: =G7+G8-G9 -> 679850 | H10: =H7+H8-H9 -> 679850 | I10: =I7+I8-I9 -> 0 | J10: =J7+J8-J9 -> 0 | K10: =K7+K8-K9 -> 0 | L10: =L7+L8-L9 -> 0
B12: Training infrastructure — one-time CAP build
B13: Curriculum, certification & expert support
B14: Curriculum design + certification partner | C14: € | D14: =SUM(E14:L14) -> 220000 | E14: =E$98*FLAG_PREPROG_YM1 -> 220000 | F14: =F$98*FLAG_PREPROG_Y0 -> 0 | G14: =G$98*FLAG_PREPROG_Y1 -> 0 | H14: =H$98*FLAG_PREPROG_Y2 -> 0 | I14: =I$98*FLAG_PREPROG_Y3 -> 0 | J14: =J$98*FLAG_PREPROG_Y4 -> 0 | K14: =K$98*FLAG_PREPROG_Y5 -> 0 | L14: =L$98*FLAG_PREPROG_Y6 -> 0
B15: Train-the-Trainer (programme team) | C15: € | D15: =SUM(E15:L15) -> 288000 | E15: =E$124*E$88*E$89*FLAG_PREPROG_YM1 -> 288000 | F15: =F$124*F$88*F$89*FLAG_PREPROG_Y0 -> 0 | G15: =G$124*G$88*G$89*FLAG_PREPROG_Y1 -> 0 | H15: =H$124*H$88*H$89*FLAG_PREPROG_Y2 -> 0 | I15: =I$124*I$88*I$89*FLAG_PREPROG_Y3 -> 0 | J15: =J$124*J$88*J$89*FLAG_PREPROG_Y4 -> 0 | K15: =K$124*K$88*K$89*FLAG_PREPROG_Y5 -> 0 | L15: =L$124*L$88*L$89*FLAG_PREPROG_Y6 -> 0
B16: International specialist experts (one-time) | C16: € | D16: =SUM(E16:L16) -> 120000 | E16: =E$125*FLAG_PREPROG_YM1 -> 120000 | F16: =F$125*FLAG_PREPROG_Y0 -> 0 | G16: =G$125*FLAG_PREPROG_Y1 -> 0 | H16: =H$125*FLAG_PREPROG_Y2 -> 0 | I16: =I$125*FLAG_PREPROG_Y3 -> 0 | J16: =J$125*FLAG_PREPROG_Y4 -> 0 | K16: =K$125*FLAG_PREPROG_Y5 -> 0 | L16: =L$125*FLAG_PREPROG_Y6 -> 0
B17: Curriculum materials (per filière) | C17: € | D17: =SUM(E17:L17) -> 50000 | E17: =E$100*E$101*FLAG_CONSTRUCT_YM1 -> 0 | F17: =F$100*F$101*FLAG_CONSTRUCT_Y0 -> 50000 | G17: =G$100*G$101*FLAG_CONSTRUCT_Y1 -> 0 | H17: =H$100*H$101*FLAG_CONSTRUCT_Y2 -> 0 | I17: =I$100*I$101*FLAG_CONSTRUCT_Y3 -> 0 | J17: =J$100*J$101*FLAG_CONSTRUCT_Y4 -> 0 | K17: =K$100*K$101*FLAG_CONSTRUCT_Y5 -> 0 | L17: =L$100*L$101*FLAG_CONSTRUCT_Y6 -> 0
B18: Subtotal — Curriculum & certification | C18: € | D18: =SUM(D14:D17) -> 678000 | E18: =SUM(E14:E17) -> 628000 | F18: =SUM(F14:F17) -> 50000 | G18: =SUM(G14:G17) -> 0 | H18: =SUM(H14:H17) -> 0 | I18: =SUM(I14:I17) -> 0 | J18: =SUM(J14:J17) -> 0 | K18: =SUM(K14:K17) -> 0 | L18: =SUM(L14:L17) -> 0
B20: Pedagogical plateaux & classroom
B21: Classroom equipment (3 farms) | C21: € | D21: =SUM(E21:L21) -> 135000 | E21: =E$65*E$99*FLAG_CONSTRUCT_YM1 -> 0 | F21: =F$65*F$99*FLAG_CONSTRUCT_Y0 -> 135000 | G21: =G$65*G$99*FLAG_CONSTRUCT_Y1 -> 0 | H21: =H$65*H$99*FLAG_CONSTRUCT_Y2 -> 0 | I21: =I$65*I$99*FLAG_CONSTRUCT_Y3 -> 0 | J21: =J$65*J$99*FLAG_CONSTRUCT_Y4 -> 0 | K21: =K$65*K$99*FLAG_CONSTRUCT_Y5 -> 0 | L21: =L$65*L$99*FLAG_CONSTRUCT_Y6 -> 0
B22: Plateau eau — pumping bench + irrigation lab + drilling station (filière B) | C22: € | D22: =ASM_G02A_PLATEAU_EAU_EUR -> 60000 | E22: =ASM_G02A_PLATEAU_EAU_EUR*FLAG_CONSTRUCT_YM1 -> 0 | F22: =ASM_G02A_PLATEAU_EAU_EUR*FLAG_CONSTRUCT_Y0 -> 60000 | G22: =ASM_G02A_PLATEAU_EAU_EUR*FLAG_CONSTRUCT_Y1 -> 0 | H22: =ASM_G02A_PLATEAU_EAU_EUR*FLAG_CONSTRUCT_Y2 -> 0 | I22: =ASM_G02A_PLATEAU_EAU_EUR*FLAG_CONSTRUCT_Y3 -> 0 | J22: =ASM_G02A_PLATEAU_EAU_EUR*FLAG_CONSTRUCT_Y4 -> 0 | K22: =ASM_G02A_PLATEAU_EAU_EUR*FLAG_CONSTRUCT_Y5 -> 0 | L22: =ASM_G02A_PLATEAU_EAU_EUR*FLAG_CONSTRUCT_Y6 -> 0
B23: Plateau PV — array + hybrid inverters + BESS + SCADA (filière C) | C23: € | D23: =ASM_G02B_PLATEAU_PV_EUR -> 50000 | E23: =ASM_G02B_PLATEAU_PV_EUR*FLAG_CONSTRUCT_YM1 -> 0 | F23: =ASM_G02B_PLATEAU_PV_EUR*FLAG_CONSTRUCT_Y0 -> 50000 | G23: =ASM_G02B_PLATEAU_PV_EUR*FLAG_CONSTRUCT_Y1 -> 0 | H23: =ASM_G02B_PLATEAU_PV_EUR*FLAG_CONSTRUCT_Y2 -> 0 | I23: =ASM_G02B_PLATEAU_PV_EUR*FLAG_CONSTRUCT_Y3 -> 0 | J23: =ASM_G02B_PLATEAU_PV_EUR*FLAG_CONSTRUCT_Y4 -> 0 | K23: =ASM_G02B_PLATEAU_PV_EUR*FLAG_CONSTRUCT_Y5 -> 0 | L23: =ASM_G02B_PLATEAU_PV_EUR*FLAG_CONSTRUCT_Y6 -> 0
B24: Atelier méca — workshop + lifting + tractor + diagnostic (filière D) | C24: € | D24: =ASM_G02C_ATELIER_MECA_EUR -> 60000 | E24: =ASM_G02C_ATELIER_MECA_EUR*FLAG_CONSTRUCT_YM1 -> 0 | F24: =ASM_G02C_ATELIER_MECA_EUR*FLAG_CONSTRUCT_Y0 -> 60000 | G24: =ASM_G02C_ATELIER_MECA_EUR*FLAG_CONSTRUCT_Y1 -> 0 | H24: =ASM_G02C_ATELIER_MECA_EUR*FLAG_CONSTRUCT_Y2 -> 0 | I24: =ASM_G02C_ATELIER_MECA_EUR*FLAG_CONSTRUCT_Y3 -> 0 | J24: =ASM_G02C_ATELIER_MECA_EUR*FLAG_CONSTRUCT_Y4 -> 0 | K24: =ASM_G02C_ATELIER_MECA_EUR*FLAG_CONSTRUCT_Y5 -> 0 | L24: =ASM_G02C_ATELIER_MECA_EUR*FLAG_CONSTRUCT_Y6 -> 0
B25: Classroom / IT / comms — multipurpose rooms + workstations + technical library | C25: € | D25: =ASM_G02D_CLASSROOM_IT_EUR -> 40000 | E25: =ASM_G02D_CLASSROOM_IT_EUR*FLAG_CONSTRUCT_YM1 -> 0 | F25: =ASM_G02D_CLASSROOM_IT_EUR*FLAG_CONSTRUCT_Y0 -> 40000 | G25: =ASM_G02D_CLASSROOM_IT_EUR*FLAG_CONSTRUCT_Y1 -> 0 | H25: =ASM_G02D_CLASSROOM_IT_EUR*FLAG_CONSTRUCT_Y2 -> 0 | I25: =ASM_G02D_CLASSROOM_IT_EUR*FLAG_CONSTRUCT_Y3 -> 0 | J25: =ASM_G02D_CLASSROOM_IT_EUR*FLAG_CONSTRUCT_Y4 -> 0 | K25: =ASM_G02D_CLASSROOM_IT_EUR*FLAG_CONSTRUCT_Y5 -> 0 | L25: =ASM_G02D_CLASSROOM_IT_EUR*FLAG_CONSTRUCT_Y6 -> 0
B26: Subtotal — Pedagogical plateaux & classroom | C26: € | D26: =SUM(D21:D25) -> 345000 | E26: =SUM(E21:E25) -> 0 | F26: =SUM(F21:F25) -> 345000 | G26: =SUM(G21:G25) -> 0 | H26: =SUM(H21:H25) -> 0 | I26: =SUM(I21:I25) -> 0 | J26: =SUM(J21:J25) -> 0 | K26: =SUM(K21:K25) -> 0 | L26: =SUM(L21:L25) -> 0
B28: Accommodation
B29: Trainee dormitories | C29: € | D29: =SUM(E29:L29) -> 297000 | E29: =E$126*E$65*E$94*FLAG_CONSTRUCT_YM1 -> 0 | F29: =F$126*F$65*F$94*FLAG_CONSTRUCT_Y0 -> 297000 | G29: =G$126*G$65*G$94*FLAG_CONSTRUCT_Y1 -> 0 | H29: =H$126*H$65*H$94*FLAG_CONSTRUCT_Y2 -> 0 | I29: =I$126*I$65*I$94*FLAG_CONSTRUCT_Y3 -> 0 | J29: =J$126*J$65*J$94*FLAG_CONSTRUCT_Y4 -> 0 | K29: =K$126*K$65*K$94*FLAG_CONSTRUCT_Y5 -> 0 | L29: =L$126*L$65*L$94*FLAG_CONSTRUCT_Y6 -> 0
B30: Refectory & common areas | C30: € | D30: =SUM(E30:L30) -> 48000 | E30: =E$65*E$95*FLAG_CONSTRUCT_YM1 -> 0 | F30: =F$65*F$95*FLAG_CONSTRUCT_Y0 -> 48000 | G30: =G$65*G$95*FLAG_CONSTRUCT_Y1 -> 0 | H30: =H$65*H$95*FLAG_CONSTRUCT_Y2 -> 0 | I30: =I$65*I$95*FLAG_CONSTRUCT_Y3 -> 0 | J30: =J$65*J$95*FLAG_CONSTRUCT_Y4 -> 0 | K30: =K$65*K$95*FLAG_CONSTRUCT_Y5 -> 0 | L30: =L$65*L$95*FLAG_CONSTRUCT_Y6 -> 0
B31: Family housing | C31: € | D31: =SUM(E31:L31) -> 40000 | E31: =E$127*E$97*FLAG_CONSTRUCT_YM1 -> 0 | F31: =F$127*F$97*FLAG_CONSTRUCT_Y0 -> 40000 | G31: =G$127*G$97*FLAG_CONSTRUCT_Y1 -> 0 | H31: =H$127*H$97*FLAG_CONSTRUCT_Y2 -> 0 | I31: =I$127*I$97*FLAG_CONSTRUCT_Y3 -> 0 | J31: =J$127*J$97*FLAG_CONSTRUCT_Y4 -> 0 | K31: =K$127*K$97*FLAG_CONSTRUCT_Y5 -> 0 | L31: =L$127*L$97*FLAG_CONSTRUCT_Y6 -> 0
B32: Subtotal — Accommodation | C32: € | D32: =SUM(D29:D31) -> 385000 | E32: =SUM(E29:E31) -> 0 | F32: =SUM(F29:F31) -> 385000 | G32: =SUM(G29:G31) -> 0 | H32: =SUM(H29:H31) -> 0 | I32: =SUM(I29:I31) -> 0 | J32: =SUM(J29:J31) -> 0 | K32: =SUM(K29:K31) -> 0 | L32: =SUM(L29:L31) -> 0
B34: Monitoring & communications
B35: Monitoring equipment | C35: € | D35: =SUM(E35:L35) -> 60000 | E35: =E$103*FLAG_CONSTRUCT_YM1 -> 0 | F35: =F$103*FLAG_CONSTRUCT_Y0 -> 60000 | G35: =G$103*FLAG_CONSTRUCT_Y1 -> 0 | H35: =H$103*FLAG_CONSTRUCT_Y2 -> 0 | I35: =I$103*FLAG_CONSTRUCT_Y3 -> 0 | J35: =J$103*FLAG_CONSTRUCT_Y4 -> 0 | K35: =K$103*FLAG_CONSTRUCT_Y5 -> 0 | L35: =L$103*FLAG_CONSTRUCT_Y6 -> 0
B36: Communication materials | C36: € | D36: =SUM(E36:L36) -> 20000 | E36: =E$106*FLAG_CONSTRUCT_YM1 -> 0 | F36: =F$106*FLAG_CONSTRUCT_Y0 -> 20000 | G36: =G$106*FLAG_CONSTRUCT_Y1 -> 0 | H36: =H$106*FLAG_CONSTRUCT_Y2 -> 0 | I36: =I$106*FLAG_CONSTRUCT_Y3 -> 0 | J36: =J$106*FLAG_CONSTRUCT_Y4 -> 0 | K36: =K$106*FLAG_CONSTRUCT_Y5 -> 0 | L36: =L$106*FLAG_CONSTRUCT_Y6 -> 0
B37: Subtotal — Monitoring & communications | C37: € | D37: =SUM(D35:D36) -> 80000 | E37: =SUM(E35:E36) -> 0 | F37: =SUM(F35:F36) -> 80000 | G37: =SUM(G35:G36) -> 0 | H37: =SUM(H35:H36) -> 0 | I37: =SUM(I35:I36) -> 0 | J37: =SUM(J35:J36) -> 0 | K37: =SUM(K35:K36) -> 0 | L37: =SUM(L35:L36) -> 0
B38: TOTAL TRAINING INFRASTRUCTURE | C38: € | D38: =D18+D26+D32+D37 -> 1488000 | E38: =E18+E26+E32+E37 -> 628000 | F38: =F18+F26+F32+F37 -> 860000 | G38: =G18+G26+G32+G37 -> 0 | H38: =H18+H26+H32+H37 -> 0 | I38: =I18+I26+I32+I37 -> 0 | J38: =J18+J26+J32+J37 -> 0 | K38: =K18+K26+K32+K37 -> 0 | L38: =L18+L26+L32+L37 -> 0
B40: Recurring training — annual OPEX
B41: Trainers — filière + specialist
B42: Filière trainers | C42: €/yr | D42: =SUM(E42:L42) -> 480000 | E42: =E$82*E$84*IF(AND(E$4>=ASM_A04_COD_YEAR,E$4<ASM_A04_COD_YEAR+ASM_D06_YEARS_TRAINERS_ACTIVE),1,0) -> 0 | F42: =F$82*F$84*IF(AND(F$4>=ASM_A04_COD_YEAR,F$4<ASM_A04_COD_YEAR+ASM_D06_YEARS_TRAINERS_ACTIVE),1,0) -> 0 | G42: =G$82*G$84*IF(AND(G$4>=ASM_A04_COD_YEAR,G$4<ASM_A04_COD_YEAR+ASM_D06_YEARS_TRAINERS_ACTIVE),1,0) -> 240000 | H42: =H$82*H$84*IF(AND(H$4>=ASM_A04_COD_YEAR,H$4<ASM_A04_COD_YEAR+ASM_D06_YEARS_TRAINERS_ACTIVE),1,0) -> 240000 | I42: =I$82*I$84*IF(AND(I$4>=ASM_A04_COD_YEAR,I$4<ASM_A04_COD_YEAR+ASM_D06_YEARS_TRAINERS_ACTIVE),1,0) -> 0 | J42: =J$82*J$84*IF(AND(J$4>=ASM_A04_COD_YEAR,J$4<ASM_A04_COD_YEAR+ASM_D06_YEARS_TRAINERS_ACTIVE),1,0) -> 0 | K42: =K$82*K$84*IF(AND(K$4>=ASM_A04_COD_YEAR,K$4<ASM_A04_COD_YEAR+ASM_D06_YEARS_TRAINERS_ACTIVE),1,0) -> 0 | L42: =L$82*L$84*IF(AND(L$4>=ASM_A04_COD_YEAR,L$4<ASM_A04_COD_YEAR+ASM_D06_YEARS_TRAINERS_ACTIVE),1,0) -> 0
B43: Specialist trainers | C43: €/yr | D43: =SUM(E43:L43) -> 320000 | E43: =E$83*E$85*IF(AND(E$4>=ASM_A04_COD_YEAR,E$4<ASM_A04_COD_YEAR+ASM_D07_YEARS_SPECIALIST_ACTIVE),1,0) -> 0 | F43: =F$83*F$85*IF(AND(F$4>=ASM_A04_COD_YEAR,F$4<ASM_A04_COD_YEAR+ASM_D07_YEARS_SPECIALIST_ACTIVE),1,0) -> 0 | G43: =G$83*G$85*IF(AND(G$4>=ASM_A04_COD_YEAR,G$4<ASM_A04_COD_YEAR+ASM_D07_YEARS_SPECIALIST_ACTIVE),1,0) -> 160000 | H43: =H$83*H$85*IF(AND(H$4>=ASM_A04_COD_YEAR,H$4<ASM_A04_COD_YEAR+ASM_D07_YEARS_SPECIALIST_ACTIVE),1,0) -> 160000 | I43: =I$83*I$85*IF(AND(I$4>=ASM_A04_COD_YEAR,I$4<ASM_A04_COD_YEAR+ASM_D07_YEARS_SPECIALIST_ACTIVE),1,0) -> 0 | J43: =J$83*J$85*IF(AND(J$4>=ASM_A04_COD_YEAR,J$4<ASM_A04_COD_YEAR+ASM_D07_YEARS_SPECIALIST_ACTIVE),1,0) -> 0 | K43: =K$83*K$85*IF(AND(K$4>=ASM_A04_COD_YEAR,K$4<ASM_A04_COD_YEAR+ASM_D07_YEARS_SPECIALIST_ACTIVE),1,0) -> 0 | L43: =L$83*L$85*IF(AND(L$4>=ASM_A04_COD_YEAR,L$4<ASM_A04_COD_YEAR+ASM_D07_YEARS_SPECIALIST_ACTIVE),1,0) -> 0
B44: Subtotal — Trainers | C44: € | D44: =SUM(D42:D43) -> 800000 | E44: =SUM(E42:E43) -> 0 | F44: =SUM(F42:F43) -> 0 | G44: =SUM(G42:G43) -> 400000 | H44: =SUM(H42:H43) -> 400000 | I44: =SUM(I42:I43) -> 0 | J44: =SUM(J42:J43) -> 0 | K44: =SUM(K42:K43) -> 0 | L44: =SUM(L42:L43) -> 0
B46: Trainee stipends — net of productive-work credit
B47: Filière A — stipends paid | C47: €/yr | D47: =SUM(E47:L47) -> 873600 | E47: =E$148*E$136*FLAG_VALIDATION_YM1 -> 0 | F47: =F$148*F$136*FLAG_VALIDATION_Y0 -> 0 | G47: =G$148*G$136*FLAG_VALIDATION_Y1 -> 436800 | H47: =H$148*H$136*FLAG_VALIDATION_Y2 -> 436800 | I47: =I$148*I$136*FLAG_VALIDATION_Y3 -> 0 | J47: =J$148*J$136*FLAG_VALIDATION_Y4 -> 0 | K47: =K$148*K$136*FLAG_VALIDATION_Y5 -> 0 | L47: =L$148*L$136*FLAG_VALIDATION_Y6 -> 0
B48: Filière A — productive-work credit (notional) | C48: €/yr | D48: =SUM(E48:L48) -> -520000 | E48: =-E$148*E$140*FLAG_VALIDATION_YM1 -> 0 | F48: =-F$148*F$140*FLAG_VALIDATION_Y0 -> 0 | G48: =-G$148*G$140*FLAG_VALIDATION_Y1 -> -260000 | H48: =-H$148*H$140*FLAG_VALIDATION_Y2 -> -260000 | I48: =-I$148*I$140*FLAG_VALIDATION_Y3 -> 0 | J48: =-J$148*J$140*FLAG_VALIDATION_Y4 -> 0 | K48: =-K$148*K$140*FLAG_VALIDATION_Y5 -> 0 | L48: =-L$148*L$140*FLAG_VALIDATION_Y6 -> 0
...

Sheet 04_Genetics
B1: 04 — Block 3 Genetics (animal + plant) [€] ← feeds 05_CAPEX · 07_Revenue · 08_OpEx · 06_S&U
D3: Total | E3: Y-1 | F3: Y0 | G3: Y1 | H3: Y2 | I3: Y3 | J3: Y4 | K3: Y5 | L3: Y6
E4: -1 | F4: 0 | G4: 1 | H4: 2 | I4: 3 | J4: 4 | K4: 5 | L4: 6
B6: Summary
B7: 1. Animal genetics — hardware | C7: € | D7: =SUM(E7:L7) -> 298401 | E7: =E20 -> 0 | F7: =F20 -> 298401 | G7: =G20 -> 0 | H7: =H20 -> 0 | I7: =I20 -> 0 | J7: =J20 -> 0 | K7: =K20 -> 0 | L7: =L20 -> 0
B8: 2. Animal genetics — operations (pre-op + recurring) | C8: € | D8: =SUM(E8:L8) -> 388360 | E8: =E26+E34 -> 0 | F8: =F26+F34 -> 104800 | G8: =G26+G34 -> 141780 | H8: =H26+H34 -> 141780 | I8: =I26+I34 -> 0 | J8: =J26+J34 -> 0 | K8: =K26+K34 -> 0 | L8: =L26+L34 -> 0
B9: 3. Plant genetics — hardware | C9: € | D9: =SUM(E9:L9) -> 200000 | E9: =E40 -> 0 | F9: =F40 -> 200000 | G9: =G40 -> 0 | H9: =H40 -> 0 | I9: =I40 -> 0 | J9: =J40 -> 0 | K9: =K40 -> 0 | L9: =L40 -> 0
B10: 4. Plant genetics — operations (pre-op + recurring) | C10: € | D10: =SUM(E10:L10) -> 291000 | E10: =E48+E55 -> 0 | F10: =F48+F55 -> 73000 | G10: =G48+G55 -> 109000 | H10: =H48+H55 -> 109000 | I10: =I48+I55 -> 0 | J10: =J48+J55 -> 0 | K10: =K48+K55 -> 0 | L10: =L48+L55 -> 0
B11: 5. Genetics programme revenue (= 0; grant-funded) | C11: € | D11: =SUM(E11:L11) -> 0 | E11: =0 -> 0 | F11: =0 -> 0 | G11: =0 -> 0 | H11: =0 -> 0 | I11: =0 -> 0 | J11: =0 -> 0 | K11: =0 -> 0 | L11: =0 -> 0
B12: TOTAL GENETICS PROGRAMME COST | C12: € | D12: =SUM(E12:L12) -> 1177761 | E12: =E7+E8+E9+E10-E11 -> 0 | F12: =F7+F8+F9+F10-F11 -> 676201 | G12: =G7+G8+G9+G10-G11 -> 250780 | H12: =H7+H8+H9+H10-H11 -> 250780 | I12: =I7+I8+I9+I10-I11 -> 0 | J12: =J7+J8+J9+J10-J11 -> 0 | K12: =K7+K8+K9+K10-K11 -> 0 | L12: =L7+L8+L9+L10-L11 -> 0
B14: Animal genetics
B15: Hardware (one-time, Y0)
B16: Veterinary centre (standalone building) | C16: € | D16: =SUM(E16:L16) -> 125000 | E16: =$F$59*FLAG_CONSTRUCT_YM1 -> 0 | F16: =$F$59*FLAG_CONSTRUCT_Y0 -> 125000 | G16: =$F$59*FLAG_CONSTRUCT_Y1 -> 0 | H16: =$F$59*FLAG_CONSTRUCT_Y2 -> 0 | I16: =$F$59*FLAG_CONSTRUCT_Y3 -> 0 | J16: =$F$59*FLAG_CONSTRUCT_Y4 -> 0 | K16: =$F$59*FLAG_CONSTRUCT_Y5 -> 0 | L16: =$F$59*FLAG_CONSTRUCT_Y6 -> 0
B17: Animal equipment (pharma + lab + restraint) | C17: € | D17: =SUM(E17:L17) -> 150000 | E17: =$F$60*FLAG_CONSTRUCT_YM1 -> 0 | F17: =$F$60*FLAG_CONSTRUCT_Y0 -> 150000 | G17: =$F$60*FLAG_CONSTRUCT_Y1 -> 0 | H17: =$F$60*FLAG_CONSTRUCT_Y2 -> 0 | I17: =$F$60*FLAG_CONSTRUCT_Y3 -> 0 | J17: =$F$60*FLAG_CONSTRUCT_Y4 -> 0 | K17: =$F$60*FLAG_CONSTRUCT_Y5 -> 0 | L17: =$F$60*FLAG_CONSTRUCT_Y6 -> 0
B18: Identification system per farm (PREMIUM tier) | C18: € | D18: =SUM(E18:L18) -> 15000 | E18: =ASM_A01_N_FARMS*$F$61*FLAG_CONSTRUCT_YM1 -> 0 | F18: =ASM_A01_N_FARMS*$F$61*FLAG_CONSTRUCT_Y0 -> 15000 | G18: =ASM_A01_N_FARMS*$F$61*FLAG_CONSTRUCT_Y1 -> 0 | H18: =ASM_A01_N_FARMS*$F$61*FLAG_CONSTRUCT_Y2 -> 0 | I18: =ASM_A01_N_FARMS*$F$61*FLAG_CONSTRUCT_Y3 -> 0 | J18: =ASM_A01_N_FARMS*$F$61*FLAG_CONSTRUCT_Y4 -> 0 | K18: =ASM_A01_N_FARMS*$F$61*FLAG_CONSTRUCT_Y5 -> 0 | L18: =ASM_A01_N_FARMS*$F$61*FLAG_CONSTRUCT_Y6 -> 0
B19: AI hardware (shared — tank + ultrasound) | C19: € | D19: =SUM(E19:L19) -> 8401 | E19: =$F$62*FLAG_CONSTRUCT_YM1 -> 0 | F19: =$F$62*FLAG_CONSTRUCT_Y0 -> 8401 | G19: =$F$62*FLAG_CONSTRUCT_Y1 -> 0 | H19: =$F$62*FLAG_CONSTRUCT_Y2 -> 0 | I19: =$F$62*FLAG_CONSTRUCT_Y3 -> 0 | J19: =$F$62*FLAG_CONSTRUCT_Y4 -> 0 | K19: =$F$62*FLAG_CONSTRUCT_Y5 -> 0 | L19: =$F$62*FLAG_CONSTRUCT_Y6 -> 0
B20: Subtotal — Animal genetics hardware | C20: € | D20: =SUM(D16:D19) -> 298401 | E20: =SUM(E16:E19) -> 0 | F20: =SUM(F16:F19) -> 298401 | G20: =SUM(G16:G19) -> 0 | H20: =SUM(H16:H19) -> 0 | I20: =SUM(I16:I19) -> 0 | J20: =SUM(J16:J19) -> 0 | K20: =SUM(K16:K19) -> 0 | L20: =SUM(L16:L19) -> 0
B22: Pre-op (one-time Y0 expense)
B23: Partner support per farm (PREMIUM, pre-op) | C23: € | D23: =SUM(E23:L23) -> 72000 | E23: =ASM_A01_N_FARMS*$F$63*FLAG_CONSTRUCT_YM1 -> 0 | F23: =ASM_A01_N_FARMS*$F$63*FLAG_CONSTRUCT_Y0 -> 72000 | G23: =ASM_A01_N_FARMS*$F$63*FLAG_CONSTRUCT_Y1 -> 0 | H23: =ASM_A01_N_FARMS*$F$63*FLAG_CONSTRUCT_Y2 -> 0 | I23: =ASM_A01_N_FARMS*$F$63*FLAG_CONSTRUCT_Y3 -> 0 | J23: =ASM_A01_N_FARMS*$F$63*FLAG_CONSTRUCT_Y4 -> 0 | K23: =ASM_A01_N_FARMS*$F$63*FLAG_CONSTRUCT_Y5 -> 0 | L23: =ASM_A01_N_FARMS*$F$63*FLAG_CONSTRUCT_Y6 -> 0
B24: Inseminator training (3 months, pre-op) | C24: € | D24: =SUM(E24:L24) -> 25300 | E24: =$F$64*FLAG_CONSTRUCT_YM1 -> 0 | F24: =$F$64*FLAG_CONSTRUCT_Y0 -> 25300 | G24: =$F$64*FLAG_CONSTRUCT_Y1 -> 0 | H24: =$F$64*FLAG_CONSTRUCT_Y2 -> 0 | I24: =$F$64*FLAG_CONSTRUCT_Y3 -> 0 | J24: =$F$64*FLAG_CONSTRUCT_Y4 -> 0 | K24: =$F$64*FLAG_CONSTRUCT_Y5 -> 0 | L24: =$F$64*FLAG_CONSTRUCT_Y6 -> 0
B25: Initial AI doses (working capital) | C25: € | D25: =SUM(E25:L25) -> 7500 | E25: =$F$65*$F$66*FLAG_CONSTRUCT_YM1 -> 0 | F25: =$F$65*$F$66*FLAG_CONSTRUCT_Y0 -> 7500 | G25: =$F$65*$F$66*FLAG_CONSTRUCT_Y1 -> 0 | H25: =$F$65*$F$66*FLAG_CONSTRUCT_Y2 -> 0 | I25: =$F$65*$F$66*FLAG_CONSTRUCT_Y3 -> 0 | J25: =$F$65*$F$66*FLAG_CONSTRUCT_Y4 -> 0 | K25: =$F$65*$F$66*FLAG_CONSTRUCT_Y5 -> 0 | L25: =$F$65*$F$66*FLAG_CONSTRUCT_Y6 -> 0
B26: Subtotal — Animal genetics pre-op | C26: € | D26: =SUM(D23:D25) -> 104800 | E26: =SUM(E23:E25) -> 0 | F26: =SUM(F23:F25) -> 104800 | G26: =SUM(G23:G25) -> 0 | H26: =SUM(H23:H25) -> 0 | I26: =SUM(I23:I25) -> 0 | J26: =SUM(J23:J25) -> 0 | K26: =SUM(K23:K25) -> 0 | L26: =SUM(L23:L25) -> 0
B28: Recurring (annual, post-commissioning)
B29: Herd-management software per farm | C29: €/yr | D29: =SUM(E29:L29) -> 4560 | E29: =ASM_A01_N_FARMS*$F$67*FLAG_VALIDATION_YM1 -> 0 | F29: =ASM_A01_N_FARMS*$F$67*FLAG_VALIDATION_Y0 -> 0 | G29: =ASM_A01_N_FARMS*$F$67*FLAG_VALIDATION_Y1 -> 2280 | H29: =ASM_A01_N_FARMS*$F$67*FLAG_VALIDATION_Y2 -> 2280 | I29: =ASM_A01_N_FARMS*$F$67*FLAG_VALIDATION_Y3 -> 0 | J29: =ASM_A01_N_FARMS*$F$67*FLAG_VALIDATION_Y4 -> 0 | K29: =ASM_A01_N_FARMS*$F$67*FLAG_VALIDATION_Y5 -> 0 | L29: =ASM_A01_N_FARMS*$F$67*FLAG_VALIDATION_Y6 -> 0
B30: Local inseminator salary | C30: €/yr | D30: =SUM(E30:L30) -> 13000 | E30: =$F$68*FLAG_VALIDATION_YM1 -> 0 | F30: =$F$68*FLAG_VALIDATION_Y0 -> 0 | G30: =$F$68*FLAG_VALIDATION_Y1 -> 6500 | H30: =$F$68*FLAG_VALIDATION_Y2 -> 6500 | I30: =$F$68*FLAG_VALIDATION_Y3 -> 0 | J30: =$F$68*FLAG_VALIDATION_Y4 -> 0 | K30: =$F$68*FLAG_VALIDATION_Y5 -> 0 | L30: =$F$68*FLAG_VALIDATION_Y6 -> 0
B31: Veterinary inputs across herd (vaccines, prophylaxis) | C31: €/yr | D31: =SUM(E31:L31) -> 36000 | E31: =$F$69*$F$70*FLAG_VALIDATION_YM1 -> 0 | F31: =$F$69*$F$70*FLAG_VALIDATION_Y0 -> 0 | G31: =$F$69*$F$70*FLAG_VALIDATION_Y1 -> 18000 | H31: =$F$69*$F$70*FLAG_VALIDATION_Y2 -> 18000 | I31: =$F$69*$F$70*FLAG_VALIDATION_Y3 -> 0 | J31: =$F$69*$F$70*FLAG_VALIDATION_Y4 -> 0 | K31: =$F$69*$F$70*FLAG_VALIDATION_Y5 -> 0 | L31: =$F$69*$F$70*FLAG_VALIDATION_Y6 -> 0
B32: Programme management (Y1+Y2) | C32: €/yr | D32: =SUM(E32:L32) -> 158700 | E32: =$F$71*FLAG_VALIDATION_YM1 -> 0 | F32: =$F$71*FLAG_VALIDATION_Y0 -> 0 | G32: =$F$71*FLAG_VALIDATION_Y1 -> 79350 | H32: =$F$71*FLAG_VALIDATION_Y2 -> 79350 | I32: =$F$71*FLAG_VALIDATION_Y3 -> 0 | J32: =$F$71*FLAG_VALIDATION_Y4 -> 0 | K32: =$F$71*FLAG_VALIDATION_Y5 -> 0 | L32: =$F$71*FLAG_VALIDATION_Y6 -> 0
B33: Consumables (Y1+Y2) | C33: €/yr | D33: =SUM(E33:L33) -> 71300 | E33: =$F$72*FLAG_VALIDATION_YM1 -> 0 | F33: =$F$72*FLAG_VALIDATION_Y0 -> 0 | G33: =$F$72*FLAG_VALIDATION_Y1 -> 35650 | H33: =$F$72*FLAG_VALIDATION_Y2 -> 35650 | I33: =$F$72*FLAG_VALIDATION_Y3 -> 0 | J33: =$F$72*FLAG_VALIDATION_Y4 -> 0 | K33: =$F$72*FLAG_VALIDATION_Y5 -> 0 | L33: =$F$72*FLAG_VALIDATION_Y6 -> 0
B34: Subtotal — Animal genetics recurring | C34: € | D34: =SUM(D29:D33) -> 283560 | E34: =SUM(E29:E33) -> 0 | F34: =SUM(F29:F33) -> 0 | G34: =SUM(G29:G33) -> 141780 | H34: =SUM(H29:H33) -> 141780 | I34: =SUM(I29:I33) -> 0 | J34: =SUM(J29:J33) -> 0 | K34: =SUM(K29:K33) -> 0 | L34: =SUM(L29:L33) -> 0
B36: Plant genetics
B37: Hardware (one-time, Y0)
B38: Plant centre building (500 m² covered) | C38: € | D38: =SUM(E38:L38) -> 125000 | E38: =$F$75*FLAG_CONSTRUCT_YM1 -> 0 | F38: =$F$75*FLAG_CONSTRUCT_Y0 -> 125000 | G38: =$F$75*FLAG_CONSTRUCT_Y1 -> 0 | H38: =$F$75*FLAG_CONSTRUCT_Y2 -> 0 | I38: =$F$75*FLAG_CONSTRUCT_Y3 -> 0 | J38: =$F$75*FLAG_CONSTRUCT_Y4 -> 0 | K38: =$F$75*FLAG_CONSTRUCT_Y5 -> 0 | L38: =$F$75*FLAG_CONSTRUCT_Y6 -> 0
B39: Plant equipment (germinators + drip + greenhouse + tools) | C39: € | D39: =SUM(E39:L39) -> 75000 | E39: =$F$76*FLAG_CONSTRUCT_YM1 -> 0 | F39: =$F$76*FLAG_CONSTRUCT_Y0 -> 75000 | G39: =$F$76*FLAG_CONSTRUCT_Y1 -> 0 | H39: =$F$76*FLAG_CONSTRUCT_Y2 -> 0 | I39: =$F$76*FLAG_CONSTRUCT_Y3 -> 0 | J39: =$F$76*FLAG_CONSTRUCT_Y4 -> 0 | K39: =$F$76*FLAG_CONSTRUCT_Y5 -> 0 | L39: =$F$76*FLAG_CONSTRUCT_Y6 -> 0
B40: Subtotal — Plant genetics hardware | C40: € | D40: =SUM(D38:D39) -> 200000 | E40: =SUM(E38:E39) -> 0 | F40: =SUM(F38:F39) -> 200000 | G40: =SUM(G38:G39) -> 0 | H40: =SUM(H38:H39) -> 0 | I40: =SUM(I38:I39) -> 0 | J40: =SUM(J38:J39) -> 0 | K40: =SUM(K38:K39) -> 0 | L40: =SUM(L38:L39) -> 0
B42: Pre-op (one-time Y0 expense)
B43: Nursery operator training (3 months, pre-op) | C43: € | D43: =SUM(E43:L43) -> 17000 | E43: =$F$77*FLAG_CONSTRUCT_YM1 -> 0 | F43: =$F$77*FLAG_CONSTRUCT_Y0 -> 17000 | G43: =$F$77*FLAG_CONSTRUCT_Y1 -> 0 | H43: =$F$77*FLAG_CONSTRUCT_Y2 -> 0 | I43: =$F$77*FLAG_CONSTRUCT_Y3 -> 0 | J43: =$F$77*FLAG_CONSTRUCT_Y4 -> 0 | K43: =$F$77*FLAG_CONSTRUCT_Y5 -> 0 | L43: =$F$77*FLAG_CONSTRUCT_Y6 -> 0
B44: Plant partner support (pre-op) | C44: € | D44: =SUM(E44:L44) -> 24000 | E44: =$F$78*FLAG_CONSTRUCT_YM1 -> 0 | F44: =$F$78*FLAG_CONSTRUCT_Y0 -> 24000 | G44: =$F$78*FLAG_CONSTRUCT_Y1 -> 0 | H44: =$F$78*FLAG_CONSTRUCT_Y2 -> 0 | I44: =$F$78*FLAG_CONSTRUCT_Y3 -> 0 | J44: =$F$78*FLAG_CONSTRUCT_Y4 -> 0 | K44: =$F$78*FLAG_CONSTRUCT_Y5 -> 0 | L44: =$F$78*FLAG_CONSTRUCT_Y6 -> 0
B45: Imported G0 seeds (working capital) | C45: € | D45: =SUM(E45:L45) -> 8000 | E45: =$F$79*FLAG_CONSTRUCT_YM1 -> 0 | F45: =$F$79*FLAG_CONSTRUCT_Y0 -> 8000 | G45: =$F$79*FLAG_CONSTRUCT_Y1 -> 0 | H45: =$F$79*FLAG_CONSTRUCT_Y2 -> 0 | I45: =$F$79*FLAG_CONSTRUCT_Y3 -> 0 | J45: =$F$79*FLAG_CONSTRUCT_Y4 -> 0 | K45: =$F$79*FLAG_CONSTRUCT_Y5 -> 0 | L45: =$F$79*FLAG_CONSTRUCT_Y6 -> 0
B46: Mother trees (acacia / faidherbia / fruit) | C46: € | D46: =SUM(E46:L46) -> 18000 | E46: =$F$80*FLAG_CONSTRUCT_YM1 -> 0 | F46: =$F$80*FLAG_CONSTRUCT_Y0 -> 18000 | G46: =$F$80*FLAG_CONSTRUCT_Y1 -> 0 | H46: =$F$80*FLAG_CONSTRUCT_Y2 -> 0 | I46: =$F$80*FLAG_CONSTRUCT_Y3 -> 0 | J46: =$F$80*FLAG_CONSTRUCT_Y4 -> 0 | K46: =$F$80*FLAG_CONSTRUCT_Y5 -> 0 | L46: =$F$80*FLAG_CONSTRUCT_Y6 -> 0
B47: Acacia senegal mother nursery (gum arabic) | C47: € | D47: =SUM(E47:L47) -> 6000 | E47: =$F$81*FLAG_CONSTRUCT_YM1 -> 0 | F47: =$F$81*FLAG_CONSTRUCT_Y0 -> 6000 | G47: =$F$81*FLAG_CONSTRUCT_Y1 -> 0 | H47: =$F$81*FLAG_CONSTRUCT_Y2 -> 0 | I47: =$F$81*FLAG_CONSTRUCT_Y3 -> 0 | J47: =$F$81*FLAG_CONSTRUCT_Y4 -> 0 | K47: =$F$81*FLAG_CONSTRUCT_Y5 -> 0 | L47: =$F$81*FLAG_CONSTRUCT_Y6 -> 0
...

Sheet 05_CAPEX
B1: 05 — CAPEX / Capital Investments [€]
D3: Total | E3: Y-1 | F3: Y0 | G3: Y1 | H3: Y2 | I3: Y3 | J3: Y4 | K3: Y5 | L3: Y6
E4: -1 | F4: 0 | G4: 1 | H4: 2 | I4: 3 | J4: 4 | K4: 5 | L4: 6
B6: Summary
B7: 1. The three farms — production assets | C7: € | D7: =SUM(E7:L7) -> 2701585.8 | E7: =E36 -> 0 | F7: =F36 -> 2701585.8 | G7: =G36 -> 0 | H7: =H36 -> 0 | I7: =I36 -> 0 | J7: =J36 -> 0 | K7: =K36 -> 0 | L7: =L36 -> 0
B8: 2. Building the workforce — training cohorts | C8: € | D8: =SUM(E8:L8) -> 1488000 | E8: =E54 -> 628000 | F8: =F54 -> 860000 | G8: =G54 -> 0 | H8: =H54 -> 0 | I8: =I54 -> 0 | J8: =J54 -> 0 | K8: =K54 -> 0 | L8: =L54 -> 0
B9: 3. Genetics platform — animal + plant | C9: € | D9: =SUM(E9:L9) -> 498401 | E9: =E68 -> 0 | F9: =F68 -> 498401 | G9: =G68 -> 0 | H9: =H68 -> 0 | I9: =I68 -> 0 | J9: =J68 -> 0 | K9: =K68 -> 0 | L9: =L68 -> 0
B10: 4. Development & structuring costs | C10: € | D10: =SUM(E10:L10) -> 334147.18 | E10: =E79 -> 0 | F10: =F79 -> 334147.18 | G10: =G79 -> 0 | H10: =H79 -> 0 | I10: =I79 -> 0 | J10: =J79 -> 0 | K10: =K79 -> 0 | L10: =L79 -> 0
B11: 5. Reserves (working capital, DSRA/MMR, contingency) | C11: € | D11: =SUM(E11:L11) -> 544658.36 | E11: =E86 -> 0 | F11: =F86 -> 544658.36 | G11: =G86 -> 0 | H11: =H86 -> 0 | I11: =I86 -> 0 | J11: =J86 -> 0 | K11: =K86 -> 0 | L11: =L86 -> 0
B12: TOTAL CAPITAL INVESTED | C12: € | D12: =SUM(E12:L12) -> 5566792.4 | E12: =E7+E8+E9+E10+E11 -> 628000 | F12: =F7+F8+F9+F10+F11 -> 4938792.4 | G12: =G7+G8+G9+G10+G11 -> 0 | H12: =H7+H8+H9+H10+H11 -> 0 | I12: =I7+I8+I9+I10+I11 -> 0 | J12: =J7+J8+J9+J10+J11 -> 0 | K12: =K7+K8+K9+K10+K11 -> 0 | L12: =L7+L8+L9+L10+L11 -> 0
B14: The three farms — physical CAPEX (Y0 build)
B15: Land & infrastructure
B16: Foncier — land (in-kind, 100 ha/farm) | C16: € | D16: =SUM(E16:L16) -> 448909.09 | E16: =ASM_A01_N_FARMS*E$103*FLAG_CONSTRUCT_YM1 -> 0 | F16: =ASM_A01_N_FARMS*F$103*FLAG_CONSTRUCT_Y0 -> 448909.09 | G16: =ASM_A01_N_FARMS*G$103*FLAG_CONSTRUCT_Y1 -> 0 | H16: =ASM_A01_N_FARMS*H$103*FLAG_CONSTRUCT_Y2 -> 0 | I16: =ASM_A01_N_FARMS*I$103*FLAG_CONSTRUCT_Y3 -> 0 | J16: =ASM_A01_N_FARMS*J$103*FLAG_CONSTRUCT_Y4 -> 0 | K16: =ASM_A01_N_FARMS*K$103*FLAG_CONSTRUCT_Y5 -> 0 | L16: =ASM_A01_N_FARMS*L$103*FLAG_CONSTRUCT_Y6 -> 0
B17: Aménagements — clearing, topography, fencing, VRD | C17: € | D17: =ASM_A01_N_FARMS*ASM_I01A_AMENAGEMENTS_PER_FARM_EUR -> 163767 | E17: =ASM_A01_N_FARMS*ASM_I01A_AMENAGEMENTS_PER_FARM_EUR*FLAG_CONSTRUCT_YM1 -> 0 | F17: =ASM_A01_N_FARMS*ASM_I01A_AMENAGEMENTS_PER_FARM_EUR*FLAG_CONSTRUCT_Y0 -> 163767 | G17: =ASM_A01_N_FARMS*ASM_I01A_AMENAGEMENTS_PER_FARM_EUR*FLAG_CONSTRUCT_Y1 -> 0 | H17: =ASM_A01_N_FARMS*ASM_I01A_AMENAGEMENTS_PER_FARM_EUR*FLAG_CONSTRUCT_Y2 -> 0 | I17: =ASM_A01_N_FARMS*ASM_I01A_AMENAGEMENTS_PER_FARM_EUR*FLAG_CONSTRUCT_Y3 -> 0 | J17: =ASM_A01_N_FARMS*ASM_I01A_AMENAGEMENTS_PER_FARM_EUR*FLAG_CONSTRUCT_Y4 -> 0 | K17: =ASM_A01_N_FARMS*ASM_I01A_AMENAGEMENTS_PER_FARM_EUR*FLAG_CONSTRUCT_Y5 -> 0 | L17: =ASM_A01_N_FARMS*ASM_I01A_AMENAGEMENTS_PER_FARM_EUR*FLAG_CONSTRUCT_Y6 -> 0
B18: Buildings — coop office, storage, warehouse, livestock buildings | C18: € | D18: =SUM(E18:L18) -> 315859.09 | E18: =ASM_A01_N_FARMS*E$100*FLAG_CONSTRUCT_YM1 -> 0 | F18: =ASM_A01_N_FARMS*F$100*FLAG_CONSTRUCT_Y0 -> 315859.09 | G18: =ASM_A01_N_FARMS*G$100*FLAG_CONSTRUCT_Y1 -> 0 | H18: =ASM_A01_N_FARMS*H$100*FLAG_CONSTRUCT_Y2 -> 0 | I18: =ASM_A01_N_FARMS*I$100*FLAG_CONSTRUCT_Y3 -> 0 | J18: =ASM_A01_N_FARMS*J$100*FLAG_CONSTRUCT_Y4 -> 0 | K18: =ASM_A01_N_FARMS*K$100*FLAG_CONSTRUCT_Y5 -> 0 | L18: =ASM_A01_N_FARMS*L$100*FLAG_CONSTRUCT_Y6 -> 0
B19: Agroforestry — 30,000 trees/farm × €0.50 | C19: € | D19: =ASM_A01_N_FARMS*ASM_I05_TREES_PER_FARM*ASM_I06_COST_PER_TREE_EUR -> 45000 | E19: =ASM_A01_N_FARMS*ASM_I05_TREES_PER_FARM*ASM_I06_COST_PER_TREE_EUR*FLAG_CONSTRUCT_YM1 -> 0 | F19: =ASM_A01_N_FARMS*ASM_I05_TREES_PER_FARM*ASM_I06_COST_PER_TREE_EUR*FLAG_CONSTRUCT_Y0 -> 45000 | G19: =ASM_A01_N_FARMS*ASM_I05_TREES_PER_FARM*ASM_I06_COST_PER_TREE_EUR*FLAG_CONSTRUCT_Y1 -> 0 | H19: =ASM_A01_N_FARMS*ASM_I05_TREES_PER_FARM*ASM_I06_COST_PER_TREE_EUR*FLAG_CONSTRUCT_Y2 -> 0 | I19: =ASM_A01_N_FARMS*ASM_I05_TREES_PER_FARM*ASM_I06_COST_PER_TREE_EUR*FLAG_CONSTRUCT_Y3 -> 0 | J19: =ASM_A01_N_FARMS*ASM_I05_TREES_PER_FARM*ASM_I06_COST_PER_TREE_EUR*FLAG_CONSTRUCT_Y4 -> 0 | K19: =ASM_A01_N_FARMS*ASM_I05_TREES_PER_FARM*ASM_I06_COST_PER_TREE_EUR*FLAG_CONSTRUCT_Y5 -> 0 | L19: =ASM_A01_N_FARMS*ASM_I05_TREES_PER_FARM*ASM_I06_COST_PER_TREE_EUR*FLAG_CONSTRUCT_Y6 -> 0
B20: Subtotal — Land & infrastructure | C20: € | D20: =SUM(D16:D19) -> 973535.18 | E20: =SUM(E16:E19) -> 0 | F20: =SUM(F16:F19) -> 973535.18 | G20: =SUM(G16:G19) -> 0 | H20: =SUM(H16:H19) -> 0 | I20: =SUM(I16:I19) -> 0 | J20: =SUM(J16:J19) -> 0 | K20: =SUM(K16:K19) -> 0 | L20: =SUM(L16:L19) -> 0
B22: Livestock
B23: Dairy — infra (building + milking + cooling) | C23: € | D23: =ASM_A01_N_FARMS*ASM_I03A_DAIRY_INFRA_PER_FARM_EUR -> 130365 | E23: =ASM_A01_N_FARMS*ASM_I03A_DAIRY_INFRA_PER_FARM_EUR*FLAG_CONSTRUCT_YM1 -> 0 | F23: =ASM_A01_N_FARMS*ASM_I03A_DAIRY_INFRA_PER_FARM_EUR*FLAG_CONSTRUCT_Y0 -> 130365 | G23: =ASM_A01_N_FARMS*ASM_I03A_DAIRY_INFRA_PER_FARM_EUR*FLAG_CONSTRUCT_Y1 -> 0 | H23: =ASM_A01_N_FARMS*ASM_I03A_DAIRY_INFRA_PER_FARM_EUR*FLAG_CONSTRUCT_Y2 -> 0 | I23: =ASM_A01_N_FARMS*ASM_I03A_DAIRY_INFRA_PER_FARM_EUR*FLAG_CONSTRUCT_Y3 -> 0 | J23: =ASM_A01_N_FARMS*ASM_I03A_DAIRY_INFRA_PER_FARM_EUR*FLAG_CONSTRUCT_Y4 -> 0 | K23: =ASM_A01_N_FARMS*ASM_I03A_DAIRY_INFRA_PER_FARM_EUR*FLAG_CONSTRUCT_Y5 -> 0 | L23: =ASM_A01_N_FARMS*ASM_I03A_DAIRY_INFRA_PER_FARM_EUR*FLAG_CONSTRUCT_Y6 -> 0
B24: Herd — 30 cows (in-kind, Haraz) | C24: € | D24: =ASM_A01_N_FARMS*ASM_I03B_DAIRY_HERD_INKIND_PER_FARM_EUR -> 204546 | E24: =ASM_A01_N_FARMS*ASM_I03B_DAIRY_HERD_INKIND_PER_FARM_EUR*FLAG_CONSTRUCT_YM1 -> 0 | F24: =ASM_A01_N_FARMS*ASM_I03B_DAIRY_HERD_INKIND_PER_FARM_EUR*FLAG_CONSTRUCT_Y0 -> 204546 | G24: =ASM_A01_N_FARMS*ASM_I03B_DAIRY_HERD_INKIND_PER_FARM_EUR*FLAG_CONSTRUCT_Y1 -> 0 | H24: =ASM_A01_N_FARMS*ASM_I03B_DAIRY_HERD_INKIND_PER_FARM_EUR*FLAG_CONSTRUCT_Y2 -> 0 | I24: =ASM_A01_N_FARMS*ASM_I03B_DAIRY_HERD_INKIND_PER_FARM_EUR*FLAG_CONSTRUCT_Y3 -> 0 | J24: =ASM_A01_N_FARMS*ASM_I03B_DAIRY_HERD_INKIND_PER_FARM_EUR*FLAG_CONSTRUCT_Y4 -> 0 | K24: =ASM_A01_N_FARMS*ASM_I03B_DAIRY_HERD_INKIND_PER_FARM_EUR*FLAG_CONSTRUCT_Y5 -> 0 | L24: =ASM_A01_N_FARMS*ASM_I03B_DAIRY_HERD_INKIND_PER_FARM_EUR*FLAG_CONSTRUCT_Y6 -> 0
B25: Feedlot — open pens (30 finished/yr) | C25: € | D25: =SUM(E25:L25) -> 23593.636 | E25: =ASM_A01_N_FARMS*E$102*FLAG_CONSTRUCT_YM1 -> 0 | F25: =ASM_A01_N_FARMS*F$102*FLAG_CONSTRUCT_Y0 -> 23593.636 | G25: =ASM_A01_N_FARMS*G$102*FLAG_CONSTRUCT_Y1 -> 0 | H25: =ASM_A01_N_FARMS*H$102*FLAG_CONSTRUCT_Y2 -> 0 | I25: =ASM_A01_N_FARMS*I$102*FLAG_CONSTRUCT_Y3 -> 0 | J25: =ASM_A01_N_FARMS*J$102*FLAG_CONSTRUCT_Y4 -> 0 | K25: =ASM_A01_N_FARMS*K$102*FLAG_CONSTRUCT_Y5 -> 0 | L25: =ASM_A01_N_FARMS*L$102*FLAG_CONSTRUCT_Y6 -> 0
B26: Subtotal — Livestock | C26: € | D26: =SUM(D23:D25) -> 358504.64 | E26: =SUM(E23:E25) -> 0 | F26: =SUM(F23:F25) -> 358504.64 | G26: =SUM(G23:G25) -> 0 | H26: =SUM(H23:H25) -> 0 | I26: =SUM(I23:I25) -> 0 | J26: =SUM(J23:J25) -> 0 | K26: =SUM(K23:K25) -> 0 | L26: =SUM(L23:L25) -> 0
B28: Power, water & equipment
B29: Irrigation infra — drip 20ha + sprinkler 10ha + piping | C29: € | D29: =ASM_A01_N_FARMS*ASM_I01B_IRRIGATION_PER_FARM_EUR -> 553506 | E29: =ASM_A01_N_FARMS*ASM_I01B_IRRIGATION_PER_FARM_EUR*FLAG_CONSTRUCT_YM1 -> 0 | F29: =ASM_A01_N_FARMS*ASM_I01B_IRRIGATION_PER_FARM_EUR*FLAG_CONSTRUCT_Y0 -> 553506 | G29: =ASM_A01_N_FARMS*ASM_I01B_IRRIGATION_PER_FARM_EUR*FLAG_CONSTRUCT_Y1 -> 0 | H29: =ASM_A01_N_FARMS*ASM_I01B_IRRIGATION_PER_FARM_EUR*FLAG_CONSTRUCT_Y2 -> 0 | I29: =ASM_A01_N_FARMS*ASM_I01B_IRRIGATION_PER_FARM_EUR*FLAG_CONSTRUCT_Y3 -> 0 | J29: =ASM_A01_N_FARMS*ASM_I01B_IRRIGATION_PER_FARM_EUR*FLAG_CONSTRUCT_Y4 -> 0 | K29: =ASM_A01_N_FARMS*ASM_I01B_IRRIGATION_PER_FARM_EUR*FLAG_CONSTRUCT_Y5 -> 0 | L29: =ASM_A01_N_FARMS*ASM_I01B_IRRIGATION_PER_FARM_EUR*FLAG_CONSTRUCT_Y6 -> 0
B30: Water station — wells, pumps, storage, treatment (to confirm) | C30: € | D30: =ASM_A01_N_FARMS*ASM_I07_UOF_WATER_PER_FARM_EUR -> 486000 | E30: =ASM_A01_N_FARMS*ASM_I07_UOF_WATER_PER_FARM_EUR*FLAG_CONSTRUCT_YM1 -> 0 | F30: =ASM_A01_N_FARMS*ASM_I07_UOF_WATER_PER_FARM_EUR*FLAG_CONSTRUCT_Y0 -> 486000 | G30: =ASM_A01_N_FARMS*ASM_I07_UOF_WATER_PER_FARM_EUR*FLAG_CONSTRUCT_Y1 -> 0 | H30: =ASM_A01_N_FARMS*ASM_I07_UOF_WATER_PER_FARM_EUR*FLAG_CONSTRUCT_Y2 -> 0 | I30: =ASM_A01_N_FARMS*ASM_I07_UOF_WATER_PER_FARM_EUR*FLAG_CONSTRUCT_Y3 -> 0 | J30: =ASM_A01_N_FARMS*ASM_I07_UOF_WATER_PER_FARM_EUR*FLAG_CONSTRUCT_Y4 -> 0 | K30: =ASM_A01_N_FARMS*ASM_I07_UOF_WATER_PER_FARM_EUR*FLAG_CONSTRUCT_Y5 -> 0 | L30: =ASM_A01_N_FARMS*ASM_I07_UOF_WATER_PER_FARM_EUR*FLAG_CONSTRUCT_Y6 -> 0
B31: Power station — solar PV + BESS + inverter + 400V (to confirm) | C31: € | D31: =ASM_A01_N_FARMS*ASM_I08_UOF_ENERGY_PER_FARM_EUR -> 70035 | E31: =ASM_A01_N_FARMS*ASM_I08_UOF_ENERGY_PER_FARM_EUR*FLAG_CONSTRUCT_YM1 -> 0 | F31: =ASM_A01_N_FARMS*ASM_I08_UOF_ENERGY_PER_FARM_EUR*FLAG_CONSTRUCT_Y0 -> 70035 | G31: =ASM_A01_N_FARMS*ASM_I08_UOF_ENERGY_PER_FARM_EUR*FLAG_CONSTRUCT_Y1 -> 0 | H31: =ASM_A01_N_FARMS*ASM_I08_UOF_ENERGY_PER_FARM_EUR*FLAG_CONSTRUCT_Y2 -> 0 | I31: =ASM_A01_N_FARMS*ASM_I08_UOF_ENERGY_PER_FARM_EUR*FLAG_CONSTRUCT_Y3 -> 0 | J31: =ASM_A01_N_FARMS*ASM_I08_UOF_ENERGY_PER_FARM_EUR*FLAG_CONSTRUCT_Y4 -> 0 | K31: =ASM_A01_N_FARMS*ASM_I08_UOF_ENERGY_PER_FARM_EUR*FLAG_CONSTRUCT_Y5 -> 0 | L31: =ASM_A01_N_FARMS*ASM_I08_UOF_ENERGY_PER_FARM_EUR*FLAG_CONSTRUCT_Y6 -> 0
B32: Mechanisation — tractors, implements (shared pool, to confirm) | C32: € | D32: =ASM_I09_UOF_MECHANIZATION_PROGRAMME_EUR -> 180000 | E32: =ASM_I09_UOF_MECHANIZATION_PROGRAMME_EUR*FLAG_CONSTRUCT_YM1 -> 0 | F32: =ASM_I09_UOF_MECHANIZATION_PROGRAMME_EUR*FLAG_CONSTRUCT_Y0 -> 180000 | G32: =ASM_I09_UOF_MECHANIZATION_PROGRAMME_EUR*FLAG_CONSTRUCT_Y1 -> 0 | H32: =ASM_I09_UOF_MECHANIZATION_PROGRAMME_EUR*FLAG_CONSTRUCT_Y2 -> 0 | I32: =ASM_I09_UOF_MECHANIZATION_PROGRAMME_EUR*FLAG_CONSTRUCT_Y3 -> 0 | J32: =ASM_I09_UOF_MECHANIZATION_PROGRAMME_EUR*FLAG_CONSTRUCT_Y4 -> 0 | K32: =ASM_I09_UOF_MECHANIZATION_PROGRAMME_EUR*FLAG_CONSTRUCT_Y5 -> 0 | L32: =ASM_I09_UOF_MECHANIZATION_PROGRAMME_EUR*FLAG_CONSTRUCT_Y6 -> 0
B33: Monitoring — piezometers (4/farm) | C33: € | D33: =ASM_H08_N_PIEZOMETERS_PER_FARM*ASM_A01_N_FARMS*ASM_H09_COST_PER_PIEZOMETER_EUR -> 65460 | E33: =ASM_H08_N_PIEZOMETERS_PER_FARM*ASM_A01_N_FARMS*ASM_H09_COST_PER_PIEZOMETER_EUR*FLAG_CONSTRUCT_YM1 -> 0 | F33: =ASM_H08_N_PIEZOMETERS_PER_FARM*ASM_A01_N_FARMS*ASM_H09_COST_PER_PIEZOMETER_EUR*FLAG_CONSTRUCT_Y0 -> 65460 | G33: =ASM_H08_N_PIEZOMETERS_PER_FARM*ASM_A01_N_FARMS*ASM_H09_COST_PER_PIEZOMETER_EUR*FLAG_CONSTRUCT_Y1 -> 0 | H33: =ASM_H08_N_PIEZOMETERS_PER_FARM*ASM_A01_N_FARMS*ASM_H09_COST_PER_PIEZOMETER_EUR*FLAG_CONSTRUCT_Y2 -> 0 | I33: =ASM_H08_N_PIEZOMETERS_PER_FARM*ASM_A01_N_FARMS*ASM_H09_COST_PER_PIEZOMETER_EUR*FLAG_CONSTRUCT_Y3 -> 0 | J33: =ASM_H08_N_PIEZOMETERS_PER_FARM*ASM_A01_N_FARMS*ASM_H09_COST_PER_PIEZOMETER_EUR*FLAG_CONSTRUCT_Y4 -> 0 | K33: =ASM_H08_N_PIEZOMETERS_PER_FARM*ASM_A01_N_FARMS*ASM_H09_COST_PER_PIEZOMETER_EUR*FLAG_CONSTRUCT_Y5 -> 0 | L33: =ASM_H08_N_PIEZOMETERS_PER_FARM*ASM_A01_N_FARMS*ASM_H09_COST_PER_PIEZOMETER_EUR*FLAG_CONSTRUCT_Y6 -> 0
B34: Telemetry & SCADA (programme lump) | C34: € | D34: =ASM_H10_COST_TELEMETRY_LUMP_EUR -> 14545 | E34: =ASM_H10_COST_TELEMETRY_LUMP_EUR*FLAG_CONSTRUCT_YM1 -> 0 | F34: =ASM_H10_COST_TELEMETRY_LUMP_EUR*FLAG_CONSTRUCT_Y0 -> 14545 | G34: =ASM_H10_COST_TELEMETRY_LUMP_EUR*FLAG_CONSTRUCT_Y1 -> 0 | H34: =ASM_H10_COST_TELEMETRY_LUMP_EUR*FLAG_CONSTRUCT_Y2 -> 0 | I34: =ASM_H10_COST_TELEMETRY_LUMP_EUR*FLAG_CONSTRUCT_Y3 -> 0 | J34: =ASM_H10_COST_TELEMETRY_LUMP_EUR*FLAG_CONSTRUCT_Y4 -> 0 | K34: =ASM_H10_COST_TELEMETRY_LUMP_EUR*FLAG_CONSTRUCT_Y5 -> 0 | L34: =ASM_H10_COST_TELEMETRY_LUMP_EUR*FLAG_CONSTRUCT_Y6 -> 0
B35: Subtotal — Power, water & equipment | C35: € | D35: =SUM(D29:D34) -> 1369546 | E35: =SUM(E29:E34) -> 0 | F35: =SUM(F29:F34) -> 1369546 | G35: =SUM(G29:G34) -> 0 | H35: =SUM(H29:H34) -> 0 | I35: =SUM(I29:I34) -> 0 | J35: =SUM(J29:J34) -> 0 | K35: =SUM(K29:K34) -> 0 | L35: =SUM(L29:L34) -> 0
B36: TOTAL — THE THREE FARMS | C36: € | D36: =D20+D26+D35 -> 2701585.8 | E36: =E20+E26+E35 -> 0 | F36: =F20+F26+F35 -> 2701585.8 | G36: =G20+G26+G35 -> 0 | H36: =H20+H26+H35 -> 0 | I36: =I20+I26+I35 -> 0 | J36: =J20+J26+J35 -> 0 | K36: =K20+K26+K35 -> 0 | L36: =L20+L26+L35 -> 0
B38: Training infrastructure — one-time setup
B39: Curriculum & certification
B40: Curriculum & certification | C40: € | D40: =SUM(E40:L40) -> 678000 | E40: =TRAIN_CAP_CURRICULUM_YM1 -> 628000 | F40: =TRAIN_CAP_CURRICULUM_Y0 -> 50000 | G40: =TRAIN_CAP_CURRICULUM_Y1 -> 0 | H40: =TRAIN_CAP_CURRICULUM_Y2 -> 0 | I40: =TRAIN_CAP_CURRICULUM_Y3 -> 0 | J40: =TRAIN_CAP_CURRICULUM_Y4 -> 0 | K40: =TRAIN_CAP_CURRICULUM_Y5 -> 0 | L40: =TRAIN_CAP_CURRICULUM_Y6 -> 0
B41: Subtotal — Curriculum & certification | C41: € | D41: =SUM(D40) -> 678000 | E41: =SUM(E40) -> 628000 | F41: =SUM(F40) -> 50000 | G41: =SUM(G40) -> 0 | H41: =SUM(H40) -> 0 | I41: =SUM(I40) -> 0 | J41: =SUM(J40) -> 0 | K41: =SUM(K40) -> 0 | L41: =SUM(L40) -> 0
B43: Pedagogical plateaux & classroom
B44: Pedagogical plateaux & classroom | C44: € | D44: =SUM(E44:L44) -> 345000 | E44: =TRAIN_CAP_PLATEAUX_YM1 -> 0 | F44: =TRAIN_CAP_PLATEAUX_Y0 -> 345000 | G44: =TRAIN_CAP_PLATEAUX_Y1 -> 0 | H44: =TRAIN_CAP_PLATEAUX_Y2 -> 0 | I44: =TRAIN_CAP_PLATEAUX_Y3 -> 0 | J44: =TRAIN_CAP_PLATEAUX_Y4 -> 0 | K44: =TRAIN_CAP_PLATEAUX_Y5 -> 0 | L44: =TRAIN_CAP_PLATEAUX_Y6 -> 0
B45: Subtotal — Pedagogical plateaux & classroom | C45: € | D45: =SUM(D44) -> 345000 | E45: =SUM(E44) -> 0 | F45: =SUM(F44) -> 345000 | G45: =SUM(G44) -> 0 | H45: =SUM(H44) -> 0 | I45: =SUM(I44) -> 0 | J45: =SUM(J44) -> 0 | K45: =SUM(K44) -> 0 | L45: =SUM(L44) -> 0
B47: Accommodation
B48: Accommodation | C48: € | D48: =SUM(E48:L48) -> 385000 | E48: =TRAIN_CAP_ACCOMMODATION_YM1 -> 0 | F48: =TRAIN_CAP_ACCOMMODATION_Y0 -> 385000 | G48: =TRAIN_CAP_ACCOMMODATION_Y1 -> 0 | H48: =TRAIN_CAP_ACCOMMODATION_Y2 -> 0 | I48: =TRAIN_CAP_ACCOMMODATION_Y3 -> 0 | J48: =TRAIN_CAP_ACCOMMODATION_Y4 -> 0 | K48: =TRAIN_CAP_ACCOMMODATION_Y5 -> 0 | L48: =TRAIN_CAP_ACCOMMODATION_Y6 -> 0
...

Sheet 06_S&U
B1: 06 — Sources & Uses [€]
D3: Total | E3: Y-1 | F3: Y0 | G3: Y1 | H3: Y2 | I3: Y3 | J3: Y4 | K3: Y5 | L3: Y6
E4: -1 | F4: 0 | G4: 1 | H4: 2 | I4: 3 | J4: 4 | K4: 5 | L4: 6
B6: Summary
B7: USES BY PURPOSE | C7: €
