Workbook
Name Début_Prêt: '[1]Plan d''amortissement'!$D$9
Name Dernière_Ligne: IF('CA Agriculture'!Valeurs_Entrées,Ligne_EnTête+'CA Agriculture'!Nbre_de_Paiements,Ligne_EnTête)
Name Dernière_Ligne: IF('Matière 1é & fourni Agriculture'!Valeurs_Entrées,Ligne_EnTête+'Matière 1é & fourni Agriculture'!Nbre_de_Paiements,Ligne_EnTête)
Name Dernière_Ligne: IF(Valeurs_Entrées,Ligne_EnTête+Nbre_de_Paiements,Ligne_EnTête)
Name Durée_Prêt: '[1]Plan d''amortissement'!$D$7
Name Ent: #REF!
Name Ligne_EnTête: ROW('[1]Plan d''amortissement'!$17:$17)
Name Montant_Prêt: '[1]Plan d''amortissement'!$D$5
Name Nbre_de_Paiements: MATCH(0.01,Solde_Final,-1)+1
Name Nbre_de_Paiements: MATCH(0.01,Solde_Final,-1)+1
Name Nbre_de_Paiements: MATCH(0.01,Solde_Final,-1)+1
Name Nbre_Pmt: #REF!
Name Nbre_Pmt_Par_An: #REF!
Name Nbre_Pmt_Par_An: #REF!
Name Pmt_Mensuel_Programmé: #REF!
Name Pmt_Mensuel_Programmé: #REF!
Name Pmt_Programmé: #REF!
Name Pmt_Programmé: #REF!
Name Pmt_Supplémentaire: #REF!
Name Pmt_Supplémentaire: #REF!
Name Pmt_Total: #REF!
Name Pmt_Total: #REF!
Name Pmts_Supplémentaires_Programmés: #REF!
Name Pmts_Supplémentaires_Programmés: #REF!
Name Princ: #REF!
Name Princ: #REF!
Name Solde_Départ: #REF!
Name Solde_Départ: #REF!
Name Solde_Final: '[1]Plan d''amortissement'!$I$18:$I$497
Name Taux_Intérêt: '[1]Plan d''amortissement'!$D$6
Name Valeurs_Entrées: IF(Montant_Prêt*Taux_Intérêt*Durée_Prêt*Début_Prêt>0,1,0)
Name Valeurs_Entrées: IF(Montant_Prêt*Taux_Intérêt*Durée_Prêt*Début_Prêt>0,1,0)
Name Valeurs_Entrées: IF(Montant_Prêt*Taux_Intérêt*Durée_Prêt*Début_Prêt>0,1,0)

Sheet Amenag, Infrastr et Equipemt 
B3: AMENAGEMENTS & CONSTRUCTIONS - Bureau cooperative pour 10 unités de 100 ha | J3: EQUIPEMENTS & INFRASTRUCTURES COMMUNES POUR 10 UNITES DE 100 HA
B4: Nature | C4: Fonction | D4: Superficie | E4: Coût unitaire | F4: Nombre | G4: Cout total | J4: LIBELLE | K4: FONCTION | L4: Coût unitaire | M4: Nombre | N4: Cout total
B5: Foncier | C5: Bureau de gestion pour les 10 CAP | D5: 1 Ha | E5: 1000000 | F5: 0 | G5: =+F5*E5 -> 0 | J5: INFRASTRUCTURES | K5: Tank de stockage et unité de maintenance | L5: 4000000 | M5: 1 | N5: =+M5*L5 -> 4000000
B6: Aménagement | C6: VRD & réseau Eau, Electricité | D6: 350 m² | E6: 3500000 | F6: 1 | G6: =+F6*E6 -> 3500000 | J6: EQUIPEMENTS | K6: Moissonneuses-batteuses | L6: 30000000 | M6: 1 | N6: =+M6*L6 -> 30000000
B7: Construction | C7: Bureau CAP | D7: 100 m² | E7: 18500000 | F7: 1 | G7: =SUM(E7)*F7 -> 18500000 | J7: EQUIPEMENTS | K7: Décorticeur d’arachide | L7: 15000000 | M7: 1 | N7: =+M7*L7 -> 15000000
B8: Entrepots | C8: Premier stockage | D8: 2000 m² | E8: 125000000 | F8: 0 | G8: =SUM(E8)*F8 -> 0 | J8: EQUIPEMENTS | K8: Planteur de pommes de terre | L8: 1500000 | M8: 2 | N8: =+M8*L8 -> 3000000
F9: TOTAL | G9: =+SUM(G2:G8) -> 22000000 | J9: EQUIPEMENTS | K9: Récolteuse de pommes de terre | L9: 1700000 | M9: 2 | N9: =+M9*L9 -> 3400000
M10: TOTAL | N10: =+SUM(N5:N7) -> 49000000
C11: valeur de prise en compte pour une unité coopérative 1/10 de la charge globale | F11: TOTAL | G11: =SUM(G9)/10 -> 2200000 | K11: valeur de prise en compte pour une unité coopérative 1/10 de la charge globale | M11: TOTAL | N11: =SUM(N10)/10 -> 4900000
B18: AMENAGEMENTS & CONSTRUCTIONS - CAP de 100 ha | J18: EQUIPEMENTS & INFRASTRUCTURES POUR L'UNITE DE 100 HA
B19: Nature | C19: Fonction | D19: Superficie | E19: Coût unitaire | F19: Nombre | G19: Cout total | J19: LIBELLE | K19: FONCTION | L19: Coût unitaire | M19: Nombre | N19: Cout total
B20: Foncier | C20: Mise à disposition du site d'exploitation (5 ha par coopérateur / 20 personnes) | D20: 100 Ha | E20: 1000000 | G20: =+F20*E20 -> 0 | J20: EQUIPEMENTS | K20: Tracteurs de grande taille 75 à 90 CV | L20: 12000000 | M20: 1 | N20: =+M20*L20 -> 12000000
B21: Cartographie | C21: Délimitation et levé topographique du terrain | D21: 100 Ha | E21: 67000 | F21: 100 | G21: =+F21*E21 -> 6700000 | J21: EQUIPEMENTS | K21: Tracteurs de petite taille 40 à 45 HP | L21: 7000000 | M21: 1 | N21: =+M21*L21 -> 7000000
B22: Cloture | C22: Clôture du site grillage et piquets métalliques | D22: 4000 ml | E22: 8500 | F22: 4000 | G22: =+F22*E22 -> 34000000 | J22: EQUIPEMENTS | K22: Charrue Ripper/ Cultivateur / Charrue à disques / Rotavator | L22: 2000000 | M22: 2 | N22: =+M22*L22 -> 4000000
B23: Aménagement | C23: Aménagement hydroagricole (agroforesterie & haie vive) | D23: 5 Ha | E23: 1500000 | F23: 5 | G23: =+F23*E23 -> 7500000 | J23: EQUIPEMENTS | K23: Recoltant cueilleur / moissonneurs mixte | L23: 3000000 | M23: 1 | N23: =+M23*L23 -> 3000000
B24: Aménagement | C24: Aménagement hydroagricole (verger pour arbre fruitier) | D24: 5 Ha | E24: 2500000 | F24: 5 | G24: =+F24*E24 -> 12500000 | J24: EQUIPEMENTS | K24: Semoir à céréale / semoir petit grain mixte | L24: 3000000 | M24: 1 | N24: =+M24*L24 -> 3000000
B25: Aménagement | C25: Aménagement hydroagricole (irrigation pour culture de contre-saison) | D25: 15 Ha | E25: 4000000 | F25: 15 | G25: =+F25*E25 -> 60000000 | J25: INFRASTRUCTURES | K25: Puits tubulaires, y compris forage et pompes | L25: 10000000 | M25: 4 | N25: =+M25*L25 -> 40000000
B26: Aménagement | C26: Aménagement hydroagricole (irrigation pour culture fourragère) | D26: 10 Ha | E26: 3500000 | F26: 10 | G26: =+F26*E26 -> 35000000 | J26: INFRASTRUCTURES | K26: Panneaux solaires avec onduleur et batterie 25 KVA | L26: 6000000 | M26: 4 | N26: =+M26*L26 -> 24000000
B27: Aménagement | C27: Défrichage - débroussaillage, enlèvement de la masse racinaire | D27: 60 Ha | E27: 325000 | F27: 60 | G27: =+F27*E27 -> 19500000 | N27: =+M27*L27 -> 0
B28: Construction | C28: Première préparation (hangar et aire de stockage) | D28: 300 m² | E28: 65000 | F28: 200 | G28: =+F28*E28 -> 13000000
B29: Construction | C29: Magasin du groupement | D29: 100 m² | E29: 85000 | F29: 100 | G29: =+F29*E29 -> 8500000
B30: Construction | C30: local et petit bureau | D30: 70 m² | E30: 90000 | F30: 70 | G30: =+F30*E30 -> 6300000
F32: TOTAL | G32: =+SUM(G19:G31) -> 203000000 | M32: TOTAL | N32: =+SUM(N20:N30) -> 93000000
B36: AMENAGEMENTS & CONSTRUCTIONS - Volet élevage | J36: EQUIPEMENTS & INFRASTRUCTURES VOLET ELEVAGE
B37: Nature | C37: Fonction | D37: Superficie | E37: Coût unitaire | F37: Nombre | G37: Cout total | J37: LIBELLE | K37: FONCTION | L37: Coût unitaire | M37: Nombre | N37: Cout total
B38: Foncier | C38: Site d'élevage sous 4 formes (laitière, ambouche, pondeuse et chaire) | D38: 5 Ha | E38: 1000000 | G38: =+F38*E38 -> 0 | J38: INFRASTRUCTURES | K38: Aérateur et humidificateur d'air | L38: 5000000 | M38: 1 | N38: =+M38*L38 -> 5000000
B39: Aménagement | C39: VRD & réseau Eau, électricité | D39: FF | E39: 1500000 | F39: 4 | G39: =+F39*E39 -> 6000000 | J39: INFRASTRUCTURES | K39: Equipement réseau Eau & électricité | L39: 2500000 | M39: 4 | N39: =SUM(L39*M39) -> 10000000
B40: Construction | C40: Bâtiment d'élevage pour vache laitière | D40: 300 m² | E40: 65000 | F40: 300 | G40: =+F40*E40 -> 19500000 | J40: EQUIPEMENTS | K40: Equipements d'élevage pour vache laitière | L40: 8500000 | M40: 1 | N40: =+M40*L40 -> 8500000
B41: Construction | C41: Bâtiment d'élevage pour bovin d'ambouche | D41: 200 m² | E41: 45000 | F41: 200 | G41: =+F41*E41 -> 9000000 | J41: EQUIPEMENTS | K41: Equipements d'élevage pour bovin d'ambouche | L41: 5500000 | M41: 1 | N41: =+M41*L41 -> 5500000
B42: Construction | C42: Bâtiment d'élevage pour poule pondeuse | D42: 100 m² | E42: 65000 | F42: 100 | G42: =+F42*E42 -> 6500000 | J42: EQUIPEMENTS | K42: Equipements d'élevage pour poule pondeuse | L42: 3000000 | M42: 1 | N42: =SUM(L42*M42) -> 3000000
B43: Construction | C43: Bâtiment d'élevage pour poulet de chair | D43: 500 m² | E43: 45000 | F43: 100 | G43: =+F43*E43 -> 4500000 | J43: EQUIPEMENTS | K43: Equipements d'élevage pour poulet de chair | L43: 2000000 | M43: 1 | N43: =+M43*L43 -> 2000000
B44: Local | C44: locale pour équipement d'élevage | D44: 70 m² | E44: 90000 | F44: 70 | G44: =+F44*E44 -> 6300000 | J44: EQUIPEMENTS | K44: Divers équipement d'élevage | L44: 3000000 | M44: 1 | N44: =+M44*L44 -> 3000000
J45: INSTALLATION | K45: Déplacement de techniciens formation | L45: 5500000 | M45: 1 | N45: =SUM(L45*M45) -> 5500000
F46: TOTAL | G46: =+SUM(G37:G45) -> 51800000 | N46: =+M46*L46 -> 0
M47: TOTAL | N47: =+SUM(N38:N45) -> 42500000
C53: TOTAUX AMENAGEMENTS & CONSTRUCTIONS | K53: TOTAUX EQUIPEMENTS INDUSTRIELS
C54: Unité | D54: Montant | K54: Unité | L54: Montant
C55: CHARGES BUREAU DES COOPERATIVES 1/10 | D55: =SUM(G11) -> 2200000 | K55: EQUIPEMENTS & INFRASTRUCTURES COMMUNES POUR 10 UNITES DE 100 HA | L55: =SUM(N11) -> 4900000
C56: AMENAGEMENTS & CONSTRUCTION CAP 100 HA | D56: =+G32 -> 203000000 | K56: EQUIPEMENTS & INFRASTRUCTURES POUR L'UNITE DE 100 HA | L56: =+N32 -> 93000000
C57: AMENAGEMENTS & CONSTRUCTION VOLET ELEVAGE | D57: =+G46 -> 51800000 | K57: EQUIPEMENTS & INFRASTRUCTURES VOLET ELEVAGE | L57: =+N47 -> 42500000
...

Sheet Mat bureau & Mat roulants
C4: MATERIELS DE BUREAU - DIRECTION | I4: MOYENS ROULANTS - DIRECTION | O4: INFORMATIQUE DIRECTION GENERALE
C5: Désignation | D5: Unité | E5: Prix unitaire | F5: Prix total | I5: Désignation | J5: Unité | K5: Prix unitaire | L5: Prix total | O5: Désignation | P5: Unité | Q5: Prix unitaire | R5: Prix total
C6: Table de réunion | D6: 3 | E6: 250000 | F6: =+E6*D6 -> 750000 | I6: Véhicule Prado | J6: 0 | K6: 25000000 | L6: =+K6*J6 -> 0 | O6: Micro-ordinateurs | P6: 6 | Q6: 450000 | R6: =+Q6*P6 -> 2700000
C7: Chaise | D7: 12 | E7: 70000 | F7: =+E7*D7 -> 840000 | I7: Véhicule Pick Up (double cabine) | J7: 1 | K7: 19000000 | L7: =+K7*J7 -> 19000000 | O7: Imprimantes | P7: 3 | Q7: 250000 | R7: =+Q7*P7 -> 750000
C8: Bureau direction | D8: 1 | E8: 450000 | F8: =+E8*D8 -> 450000 | I8: Moto | J8: 4 | K8: 500000 | L8: =+K8*J8 -> 2000000 | O8: Autre scanner/photocopieurs | P8: 1 | Q8: 750000 | R8: =+Q8*P8 -> 750000
C9: Fauteuil direction | D9: 3 | E9: 150000 | F9: =+E9*D9 -> 450000 | I9: Camion de transport | J9: 0 | K9: 85000000 | L9: =+K9*J9 -> 0 | Q9: TOTAUX | R9: =+SUM(R5:R7) -> 3450000
C10: Bureau assistante | D10: 1 | E10: 150000 | F10: =+E10*D10 -> 150000 | I10: Porte - charge Manitou | J10: 0 | K10: 22000000 | L10: =+K10*J10 -> 0 | O10: La coopérative 1/10 de la charge globale | R10: =SUM(R9)/10 -> 345000
C11: Fauteuil | D11: 1 | E11: 70000 | F11: =+E11*D11 -> 70000 | K11: TOTAUX | L11: =SUM(L5:L10) -> 21000000
C12: Autre bureau | D12: 4 | E12: 150000 | F12: =+E12*D12 -> 600000 | I12: La coopérative 1/10 de la charge globale | L12: =SUM(L11)/10 -> 2100000
C13: Fauteuil | D13: 12 | E13: 70000 | F13: =+E13*D13 -> 840000
C14: Armoires | D14: 5 | E14: 175000 | F14: =+E14*D14 -> 875000
C15: Banc d'attente | D15: 3 | E15: 200000 | F15: =+E15*D15 -> 600000
C16: Autres matériels | D16: 1 | E16: 150000 | F16: =+E16*D16 -> 150000
E17: TOTAUX | F17: =+SUM(F5:F16) -> 5775000
C18: La coopérative 1/10 de la charge globale | F18: =SUM(F17)/10 -> 577500
C23: MATERIELS DE BUREAU - UNITE AGRICOLE | I23: MOYENS ROULANTS - UNITE AGRICOLE | O23: INFORMATIQUE UNITE AGRICOLE
C24: Désignation | D24: Unité | E24: Prix unitaire | F24: Prix total | I24: Désignation | J24: Unité | K24: Prix unitaire | L24: Prix total | O24: Désignation | P24: Unité | Q24: Prix unitaire | R24: Prix total
C25: Table de réunion | D25: 1 | E25: 250000 | F25: =+E25*D25 -> 250000 | I25: Véhicule Pick Up (double cabine) | J25: 0 | K25: 19000000 | L25: =+K25*J25 -> 0 | O25: Micro-ordinateurs | P25: 1 | Q25: 450000 | R25: =+Q25*P25 -> 450000
C26: Chaise | D26: 8 | E26: 70000 | F26: =+E26*D26 -> 560000 | I26: Camionnette de transport | J26: 0 | K26: 25000000 | L26: =+K26*J26 -> 0 | O26: Imprimantes | P26: 1 | Q26: 250000 | R26: =+Q26*P26 -> 250000
C27: Bureau Chef d'unité | D27: 1 | E27: 250000 | F27: =+E27*D27 -> 250000 | I27: Porte - charge tricycle | J27: 1 | K27: 850000 | L27: =+K27*J27 -> 850000 | O27: Autres photocopieurs | P27: 0 | Q27: 500000 | R27: =+Q27*P27 -> 0
C28: Fauteuil | D28: 3 | E28: 150000 | F28: =+E28*D28 -> 450000 | I28: Moto | J28: 1 | K28: 500000 | L28: =+K28*J28 -> 500000
C29: Bureau assistante | D29: 0 | E29: 150000 | F29: =+E29*D29 -> 0 | Q29: TOTAUX | R29: =+SUM(R25:R27) -> 700000
C30: Fauteuil | D30: 0 | E30: 70000 | F30: =+E30*D30 -> 0 | K30: TOTAUX | L30: =+SUM(L25:L28) -> 1350000
C31: Autre bureau | D31: 0 | E31: 150000 | F31: =+E31*D31 -> 0
C32: Fauteuil | D32: 0 | E32: 70000 | F32: =+E32*D32 -> 0
C33: Armoires | D33: 0 | E33: 175000 | F33: =+E33*D33 -> 0
C34: Banc d'attente | D34: 0 | E34: 200000 | F34: =+E34*D34 -> 0
C35: Autres matériels | D35: 0 | E35: 300000 | F35: =+E35*D35 -> 0
E37: TOTAUX | F37: =+SUM(F25:F36) -> 1510000
C42: MATERIELS DE BUREAU - UNITE ELEVAGE | I42: MOYENS ROULANTS - UNITE ELEVAGE | O42: INFORMATIQUE UNITE ELEVAGE
C43: Désignation | D43: Unité | E43: Prix unitaire | F43: Prix total | I43: Désignation | J43: Unité | K43: Prix unitaire | L43: Prix total | O43: Désignation | P43: Unité | Q43: Prix unitaire | R43: Prix total
C44: Table de réunion | D44: 1 | E44: 250000 | F44: =+E44*D44 -> 250000 | I44: Véhicule Pick Up (double cabine) | J44: 0 | K44: 19000000 | L44: =+K44*J44 -> 0 | O44: Micro-ordinateurs | P44: 1 | Q44: 450000 | R44: =+Q44*P44 -> 450000
C45: Chaise | D45: 8 | E45: 70000 | F45: =+E45*D45 -> 560000 | I45: Camionnette de transport | J45: 0 | K45: 25000000 | L45: =+K45*J45 -> 0 | O45: Imprimantes | P45: 1 | Q45: 250000 | R45: =+Q45*P45 -> 250000
C46: Bureau Chef d'unité | D46: 1 | E46: 250000 | F46: =+E46*D46 -> 250000 | I46: Porte - charge tricycle | J46: 1 | K46: 850000 | L46: =+K46*J46 -> 850000 | O46: Autres photocopieurs | P46: 0 | Q46: 500000 | R46: =+Q46*P46 -> 0
C47: Fauteuil | D47: 3 | E47: 150000 | F47: =+E47*D47 -> 450000 | I47: Moto | J47: 1 | K47: 500000 | L47: =+K47*J47 -> 500000
C48: Bureau assistante | D48: 0 | E48: 150000 | F48: =+E48*D48 -> 0 | Q48: TOTAUX | R48: =+SUM(R44:R46) -> 700000
C49: Fauteuil | D49: 0 | E49: 70000 | F49: =+E49*D49 -> 0 | K49: TOTAUX | L49: =+SUM(L44:L47) -> 1350000
C50: Autre bureau | D50: 0 | E50: 150000 | F50: =+E50*D50 -> 0
C51: Fauteuil | D51: 0 | E51: 70000 | F51: =+E51*D51 -> 0
C52: Armoires | D52: 0 | E52: 175000 | F52: =+E52*D52 -> 0
...

Sheet Salaires & Avantages
B6: DIRECTION
B7: POSTE | C7: Effectif à terme | D7: Base de rémunération | F7: 2026 | G7: 2027 | H7: 2028 | I7: 2029 | J7: 2030
B8: Directeur | D8: Salaire | E8: 550000 | F8: =SUM(E8)*6 -> 3300000 | G8: =+E8*12 -> 6600000 | H8: =+G8*1.1 -> 7260000 | I8: =+H8*1.05 -> 7623000 | J8: =+I8*1 -> 7623000
C9: 1 | D9: Avantage | E9: 50000 | F9: =SUM(E9)*6 -> 300000 | G9: =+E9*12 -> 600000 | H9: =+G9*1.05 -> 630000 | I9: =+H9*1.05 -> 661500 | J9: =+I9*1 -> 661500
D10: Ch Sociale | E10: =+E8*20% -> 110000 | F10: =SUM(E10)*6 -> 660000 | G10: =+G8*20% -> 1320000 | H10: =+H8*20% -> 1452000 | I10: =+I8*20% -> 1524600 | J10: =+J8*20% -> 1524600
B11: Assistante de direction | D11: Salaire | E11: 150000 | F11: =SUM(E11)*6 -> 900000 | G11: =+E11*12 -> 1800000 | H11: =+G11*1.1 -> 1980000 | I11: =+H11*1.05 -> 2079000 | J11: =+I11*1 -> 2079000
C12: 1 | D12: Avantage | E12: 25000 | F12: =SUM(E12)*6 -> 150000 | G12: =+E12*12 -> 300000 | H12: =+G12*1.05 -> 315000 | I12: =+H12*1.05 -> 330750 | J12: =+I12*1 -> 330750
D13: Ch Sociale | E13: =+E11*20% -> 30000 | F13: =SUM(E13)*6 -> 180000 | G13: =+G11*20% -> 360000 | H13: =+H11*20% -> 396000 | I13: =+I11*20% -> 415800 | J13: =+J11*20% -> 415800
B14: Conseiller Action Solidaire (partiel) | D14: Salaire | E14: 150000 | I14: =SUM(E14)*12 -> 1800000 | J14: =+I14*1 -> 1800000
C15: 1 | D15: Avantage | E15: 25000 | I15: =SUM(E15)*12 -> 300000 | J15: =+I15*1 -> 300000
D16: Ch Sociale | E16: =+E14*20% -> 30000 | G16: =+G14*20% -> 0 | I16: =+I14*20% -> 360000 | J16: =+J14*20% -> 360000
B17: Chef département administration compta finances | D17: Salaire | E17: 350000 | G17: =+E17*6 -> 2100000 | H17: =+E17*12*1.1 -> 4620000 | I17: =+H17*1.05 -> 4851000 | J17: =+I17*1 -> 4851000
C18: 1 | D18: Avantage | E18: 25000 | G18: =+E18*6 -> 150000 | H18: =+E18*12*1.05 -> 315000 | I18: =+H18*1.05 -> 330750 | J18: =+I18*1 -> 330750
D19: Ch Sociale | E19: =+E17*20% -> 70000 | G19: =+G17*20% -> 420000 | H19: =+H17*20% -> 924000 | I19: =+I17*20% -> 970200 | J19: =+J17*20% -> 970200
B20: Comptable | D20: Salaire | E20: 250000 | F20: =SUM(E20)*12 -> 3000000 | G20: =+E20*12 -> 3000000 | H20: =+E20*12*1.1 -> 3300000 | I20: =+H20*1.05 -> 3465000 | J20: =+I20*1 -> 3465000
C21: 1 | D21: Avantage | E21: 25000 | F21: =SUM(E21)*6 -> 150000 | G21: =+E21*12 -> 300000 | H21: =+E21*1.05*12 -> 315000 | I21: =+H21*1.05 -> 330750 | J21: =+I21*1 -> 330750
D22: Ch Sociale | E22: =+E20*20% -> 50000 | F22: =SUM(F20)*0.2 -> 600000 | G22: =+G20*20% -> 600000 | H22: =+H20*20% -> 660000 | I22: =+I20*20% -> 693000 | J22: =+J20*20% -> 693000
B23: Resp Ressources humaines & Matériels | D23: Salaire | E23: 200000 | G23: =+E23*6 -> 1200000 | H23: =+E23*12*1.1 -> 2640000 | I23: =+H23*1.05 -> 2772000 | J23: =+I23*1 -> 2772000
C24: 1 | D24: Avantage | E24: 25000 | G24: =+E24*6 -> 150000 | H24: =+E24*12*1.05 -> 315000 | I24: =+H24*1.05 -> 330750 | J24: =+I24*1 -> 330750
D25: Ch Sociale | E25: =+E23*20% -> 40000 | G25: =+G23*20% -> 240000 | H25: =+H23*20% -> 528000 | I25: =+I23*20% -> 554400 | J25: =+J23*20% -> 554400
B26: Chef de département production | D26: Salaire | E26: 250000 | G26: =+E26*6 -> 1500000 | H26: =+E26*12 -> 3000000 | I26: =+H26*1.05 -> 3150000 | J26: =+I26*1 -> 3150000
C27: 1 | D27: Avantage | E27: 25000 | G27: =+E27*6 -> 150000 | H27: =+E27*12 -> 300000 | I27: =+H27*1.05 -> 315000 | J27: =+I27*1 -> 315000
D28: Ch Sociale | E28: =+E26*20% -> 50000 | G28: =+G26*20% -> 300000 | H28: =+H26*20% -> 600000 | I28: =+I26*20% -> 630000 | J28: =+J26*20% -> 630000
B29: Responsable approvisionnement | D29: Salaire | E29: 200000 | H29: =+E29*12*1.1 -> 2640000 | I29: =+H29*1.05 -> 2772000 | J29: =+I29*1 -> 2772000
C30: 1 | D30: Avantage | E30: 25000 | H30: =+E30*12*1.05 -> 315000 | I30: =+H30*1.05 -> 330750 | J30: =+I30*1 -> 330750
D31: Ch Sociale | E31: =+E29*20% -> 40000 | H31: =+H29*20% -> 528000 | I31: =+I29*20% -> 554400 | J31: =+J29*20% -> 554400
B32: Responsable Maintenance technique | D32: Salaire | E32: 200000 | H32: =+E32*12 -> 2400000 | I32: =+H32*1.05 -> 2520000 | J32: =+I32*1 -> 2520000
C33: 1 | D33: Avantage | E33: 25000 | H33: =+E33*12 -> 300000 | I33: =+H33*1.05 -> 315000 | J33: =+I33*1 -> 315000
D34: Ch Sociale | E34: =+E32*20% -> 40000 | G34: =+G32*20% -> 0 | H34: =+H32*20% -> 480000 | I34: =+I32*20% -> 504000 | J34: =+J32*20% -> 504000
B35: Chauffeur | D35: Salaire | E35: 120000 | F35: =SUM(E35)*C36*12 -> 1440000 | G35: =+E35*12*C36 -> 1440000 | H35: =+E35*12*C36*1.1 -> 1584000 | I35: =+H35*1.05 -> 1663200 | J35: =+I35*1 -> 1663200
C36: 1 | D36: Avantage | E36: 15000 | F36: =SUM(E36)*12 -> 180000 | G36: =+E36*12*C36 -> 180000 | H36: =+E36*12*C36*1.05 -> 189000 | I36: =+H36*1.05 -> 198450 | J36: =+I36*1 -> 198450
D37: Ch Sociale | E37: =+E35*20% -> 24000 | F37: =SUM(F35)*0.2 -> 288000 | G37: =+G35*20% -> 288000 | H37: =+H35*20% -> 316800 | I37: =+I35*20% -> 332640 | J37: =+J35*20% -> 332640
B38: Planton coursier | D38: Salaire | E38: 90000 | G38: =+E38*12*C39 -> 1080000 | H38: =+E38*12*C39*1.5 -> 1620000 | I38: =+H38*1.05 -> 1701000 | J38: =+I38*1 -> 1701000
C39: 1 | D39: Avantage | E39: 15000 | G39: =+E39*C39*12 -> 180000 | H39: =+E39*C39*12*1.05 -> 189000 | I39: =+H39*1.05 -> 198450 | J39: =+I39*1 -> 198450
D40: Ch Sociale | E40: =+E38*20% -> 18000 | G40: =+G38*20% -> 216000 | H40: =+H38*20% -> 324000 | I40: =+I38*20% -> 340200 | J40: =+J38*20% -> 340200
B41: Nettoyage ménage & jardinier | D41: Salaire | E41: 75000 | G41: =+E41*C42*12 -> 1800000 | H41: =+E41*12*C42*1.1 -> 1980000 | I41: =+H41*1.05 -> 2079000 | J41: =+I41*1 -> 2079000
C42: 2 | D42: Avantage | E42: 10000 | G42: =+E42*C42*12 -> 240000 | H42: =+E42*C42*12*1.05 -> 252000 | I42: =+H42*1.05 -> 264600 | J42: =+I42*1 -> 264600
D43: Ch Sociale | E43: =+E41*20% -> 15000 | G43: =+G41*20% -> 360000 | H43: =+H41*20% -> 396000 | I43: =+I41*20% -> 415800 | J43: =+J41*20% -> 415800
B44: Gardien/ Sécurité | D44: Salaire | E44: 70000 | F44: =SUM(E44)*12 -> 840000 | G44: =+E44*C45*12 -> 1680000 | H44: =+E44*12*C45*1.1 -> 1848000 | I44: =+H44*1.05 -> 1940400 | J44: =+I44*1 -> 1940400
C45: 2 | D45: Avantage | E45: 10000 | F45: =SUM(E45)*12 -> 120000 | G45: =+E45*12*C45 -> 240000 | H45: =+E45*12*C45*1.05 -> 252000 | I45: =+H45*1.05 -> 264600 | J45: =+I45*1 -> 264600
...

Sheet Exploitation
E5: CHARGE D'EXPLOITATION DIRECTION
E6: Désignation | F6: 2026 | G6: 2027 | H6: 2028 | I6: 2029 | J6: 2030
E7: Frais de téléphone | F7: =1000*10*6 -> 60000 | G7: =SUM(F7)*2 -> 120000 | H7: =+G7*1.1 -> 132000 | I7: =+H7*1.1 -> 145200 | J7: =+I7*1.1 -> 159720
E8: Connexion internet | F8: =5500*12 -> 66000 | G8: =SUM(F8)*2 -> 132000 | H8: =+G8*1.1 -> 145200 | I8: =+H8*1.1 -> 159720 | J8: =+I8*1.1 -> 175692
E9: Frais de carburant | F9: =50*500*15*6 -> 2250000 | G9: =SUM(F9)*1.2 -> 2700000 | H9: =+G9*1.1 -> 2970000 | I9: =+H9*1.1 -> 3267000 | J9: =+I9*1.1 -> 3593700
E10: Fournitures de bureau | F10: =50000*6 -> 300000 | G10: =SUM(F10)*2 -> 600000 | H10: =+G10*1.1 -> 660000 | I10: =+H10*1.1 -> 726000 | J10: =+I10*1.1 -> 798600
E11: Achat de petits matériels | F11: 150000 | G11: =SUM(F11)*2 -> 300000 | H11: =+G11*1.1 -> 330000 | I11: =+H11*1.1 -> 363000 | J11: =+I11*1.1 -> 399300
E12: Frais de transport | F12: =10*500*30*6 -> 900000 | G12: =SUM(F12)*2 -> 1800000 | H12: =+G12*1.1 -> 1980000 | I12: =+H12*1.1 -> 2178000 | J12: =+I12*1.1 -> 2395800
E13: Voyages et déplacements | F13: 600000 | G13: =SUM(F13)*2 -> 1200000 | H13: =+G13*1.1 -> 1320000 | I13: =+H13*1.1 -> 1452000 | J13: =+I13*1.1 -> 1597200
E14: Loyers et charges locatives | F14: =+(3000*2)+(12000*3) -> 42000 | G14: =SUM(F14)*2 -> 84000 | H14: =+G14*1.1 -> 92400 | I14: =+H14*1.1 -> 101640 | J14: =+I14*1.1 -> 111804
E15: Entretien (locaux, matériel) | F15: =2000*120 -> 240000 | G15: =SUM(F15)*2 -> 480000 | H15: =+G15*1.1 -> 528000 | I15: =+H15*1.1 -> 580800 | J15: =+I15*1.1 -> 638880
E16: Documentation | F16: 150000 | G16: =SUM(F16)*2 -> 300000 | H16: =+G16*1.1 -> 330000 | I16: =+H16*1.1 -> 363000 | J16: =+I16*1.1 -> 399300
E17: Marketing Com/RP -R&D | F17: 500000 | G17: =SUM(F17)*2 -> 1000000 | H17: =+G17*1.1 -> 1100000 | I17: =+H17*1.1 -> 1210000 | J17: =+I17*1.1 -> 1331000
E18: Frais de formation | F18: 500000 | G18: =SUM(F18)*2 -> 1000000 | H18: =+G18*1.1 -> 1100000 | I18: =+H18*1.1 -> 1210000 | J18: =+I18*1.1 -> 1331000
E19: Redevances diverses | F19: 150000 | G19: =SUM(F19)*2 -> 300000 | H19: =+G19*1.1 -> 330000 | I19: =+H19*1.1 -> 363000 | J19: =+I19*1.1 -> 399300
E20: Assistance contrats int, Assurances diverses | F20: 250000 | G20: =SUM(F20)*2 -> 500000 | H20: =+G20*1.1 -> 550000 | I20: =+H20*1.1 -> 605000 | J20: =+I20*1.1 -> 665500
E21: Assurances locaux et moyens roulants | F21: 100000 | G21: =SUM(F21)*2 -> 200000 | H21: =+G21*1.1 -> 220000 | I21: =+H21*1.1 -> 242000 | J21: =+I21*1.1 -> 266200
E22: Autres charges externes | F22: 200000 | G22: =SUM(F22)*2 -> 400000 | H22: =+G22*1.1 -> 440000 | I22: =+H22*1.1 -> 484000 | J22: =+I22*1.1 -> 532400
J23: =+I23*1.1 -> 0
E24: TOTAL | F24: =SUM(F7:F22) -> 6458000 | G24: =SUM(G7:G22) -> 11116000 | H24: =SUM(H7:H22) -> 12227600 | I24: =SUM(I7:I22) -> 13450360 | J24: =SUM(J7:J22) -> 14795396
E25: La coopérative 1/10 de la charge globale | F25: =SUM(F24)/10 -> 645800 | G25: =SUM(G24)/10 -> 1111600 | H25: =SUM(H24)/10 -> 1222760 | I25: =SUM(I24)/10 -> 1345036 | J25: =SUM(J24)/10 -> 1479539.6
E29: CHARGE D'EXPLOITATION UNITE AGRICULTURE
E30: Désignation | F30: 2026 | G30: 2027 | H30: 2028 | I30: 2029 | J30: 2030
E31: Frais de téléphone | F31: =SUM(F7)/2 -> 30000 | G31: =SUM(F31)*2 -> 60000 | H31: =+G31*1.1 -> 66000 | I31: =+H31*1.1 -> 72600 | J31: =+I31*1.1 -> 79860
E32: Connexion internet | F32: =SUM(F8)/2 -> 33000 | G32: =SUM(F32)*2 -> 66000 | H32: =SUM(G32)*1.1 -> 72600 | I32: =+H32*1.1 -> 79860 | J32: =+I32*1.1 -> 87846
E33: Eau & Electricité | F33: 500000 | G33: =SUM(F33) -> 500000 | H33: =SUM(F33)*1.1 -> 550000 | I33: =SUM(F33)*1.1 -> 550000 | J33: =SUM(I33)*1.1 -> 605000
E34: Frais de carburant | F34: =50*500*15*6 -> 2250000 | G34: =SUM(F34)*2 -> 4500000 | H34: =+G34*1.1 -> 4950000 | I34: =+H34*1.1 -> 5445000 | J34: =+I34*1.1 -> 5989500
E35: Fournitures de bureau | F35: =SUM(F10)/2 -> 150000 | G35: =SUM(F35)*2 -> 300000 | H35: =+G35*1.1 -> 330000 | I35: =+H35*1.1 -> 363000 | J35: =+I35*1.1 -> 399300
E36: Achat de petits matériels | F36: =SUM(F11)/2 -> 75000 | G36: =SUM(F36)*2 -> 150000 | H36: =+G36*1.1 -> 165000 | I36: =+H36*1.1 -> 181500 | J36: =+I36*1.1 -> 199650
E37: Frais de transport | F37: =SUM(F12)/4 -> 225000 | G37: =SUM(F37)*2 -> 450000 | H37: =SUM(G37)*1.1 -> 495000 | I37: =+H37*1.1 -> 544500 | J37: =+I37*1.1 -> 598950
E38: Voyages et déplacements | F38: 0 | G38: 250000 | H38: =SUM(G38)*1.1 -> 275000 | I38: =+H38*1.1 -> 302500 | J38: =+I38*1.1 -> 332750
E39: Loyers et charges locatives | F39: 0 | G39: 0 | H39: 0 | I39: 0 | J39: 0
E40: Entretien (locaux, matériel) | F40: =SUM(F15)/2 -> 120000 | G40: =SUM(F40)*2 -> 240000 | H40: =SUM(G40)*1.1 -> 264000 | I40: =+H40*1.1 -> 290400 | J40: =+I40*1.1 -> 319440
E41: Documentation | F41: =SUM(F16)/2 -> 75000 | G41: =SUM(F41*2) -> 150000 | H41: =+G41*1.1 -> 165000 | I41: =+H41*1.1 -> 181500 | J41: =+I41*1.1 -> 199650
E42: Frais de formation | F42: =SUM(F18)/4 -> 125000 | G42: =SUM(F42)*2 -> 250000 | H42: =+G42*1.1 -> 275000 | I42: =+H42*1.1 -> 302500 | J42: =+I42*1.1 -> 332750
E43: Redevances diverses | F43: 0 | G43: 0 | H43: =+G43*1.1 -> 0 | I43: =+H43*1.1 -> 0 | J43: =+I43*1.1 -> 0
E44: Assistance extérieure | F44: =+'CA Elevage'!C220 -> 0 | G44: 0 | H44: =SUM(G44)*1.3 -> 0 | I44: =SUM(H44)*2 -> 0 | J44: =SUM(I44)*1.3 -> 0
E45: Assurances locaux et moyens roulants | F45: =SUM(F21)/2 -> 50000 | G45: =SUM(F45)*2 -> 100000 | H45: =SUM(G45)*1.1 -> 110000 | I45: =+H45*1.1 -> 121000 | J45: =+I45*1.1 -> 133100
E46: Autres charges externes | F46: =SUM(F22)/2 -> 100000 | G46: =SUM(F46)*2 -> 200000 | H46: =+G46*1.1 -> 220000 | I46: =+H46*1.1 -> 242000 | J46: =+I46*1.1 -> 266200
E48: TOTAL | F48: =SUM(F31:F47) -> 3733000 | G48: =SUM(G31:G47) -> 7216000 | H48: =SUM(H31:H47) -> 7937600 | I48: =SUM(I31:I47) -> 8676360 | J48: =SUM(J31:J47) -> 9543996
...

Sheet Diverses charges immobilisées
C5: CHARGES IMMOBILISEES
C6: Désignation | D6: Unité | E6: Montant Unit. | F6: Montant total
C7: Constitution cooperative | D7: 1 | E7: 250000 | F7: =+E7*D7 -> 250000
C8: Charge enregistrement au programme Baghara | D8: 1 | E8: 150000 | F8: =+E8*D8 -> 150000
C9: Charge enregistrement au projet 3Moissons | D9: 1 | E9: 450000 | F9: =+E9*D9 -> 450000
C10: Etudes & montage du projet coopératif | D10: 1 | E10: 1650000 | F10: =+E10*D10 -> 1650000
C11: Missions et Etudes techniques sur site | D11: 2 | E11: 750000 | F11: =+E11*D11 -> 1500000
C12: Missions à l'extérieur | D12: 0 | E12: 5000000 | F12: =+E12*D12 -> 0
C13: Communication publicité | D13: 0 | E13: 1000000 | F13: =+E13*D13 -> 0
C14: Agréments divers | D14: 1 | E14: 1000000 | F14: =+E14*D14 -> 1000000
E16: TOTAL | F16: =+SUM(F7:F14) -> 5000000
C21: IMMOBILISATIONS INCORPORELLES - TOTAL DU GROUPE HARAZ
C22: Désignation | D22: Unité | E22: Montant Unit. | F22: Montant total
C23: Marque et dépôt (forfait) | D23: 0 | E23: 5000000 | F23: =+E23*D23 -> 0
C24: Logiciel de Gestion commerciale 1/10 | D24: 1 | E24: 3000000 | F24: =SUM(E24)/10 -> 300000
C25: Suite de Gestion collaborative / ERP Formation 1/10 | D25: 1 | E25: 6000000 | F25: =SUM(E25)/10 -> 600000
C26: Site Internet / Intranet global 1/10 | D26: 1 | E26: 4000000 | F26: =SUM(E26)/10 -> 400000
C27: manuel de procédures 1/10 | D27: 4 | E27: 300000 | F27: =SUM(D27*E27)/10 -> 120000
C28: manuel technique de production industrie 1/10 | D28: 4 | E28: 300000 | F28: =SUM(D28*E28)/10 -> 120000
C29: Kompass 1/10 | D29: 1 | E29: 800000 | F29: =SUM(D29*E29)/10 -> 80000
C30: Formations administration & management 1/10 | D30: 4 | E30: 350000 | F30: =SUM(D30*E30)/10 -> 140000
C31: Autre formation HACCP & Normes 1/10 | D31: 4 | E31: 200000 | F31: =SUM(D31*E31)/10 -> 80000
E33: TOTAL | F33: =+SUM(F23:F31) -> 1840000
C40: IMMOBILISATIONS CORPORELLES - TOTAL DU GROUPE HARAZ
C41: Désignation | F41: Montant total
C42: TOTAUX AMENAGEMENT & INFRASTRUCTURES | F42: =+'Amenag, Infrastr et Equipemt '!D59 -> 257000000
C43: TOTAUX EQUIPEMENTS INDUSTRIELS | F43: =+'Amenag, Infrastr et Equipemt '!L59 -> 140400000
C44: TOTAUX MOYENS ROULANTS | F44: =+'Mat bureau & Mat roulants'!L68 -> 4800000
C45: TOTAUX MATERIELS INFORMATIQUES & REPROGRAPHIE | F45: =SUM('Mat bureau & Mat roulants'!R68) -> 1745000
C46: TOTAUX MATERIELS DE BUREAU | F46: =+'Mat bureau & Mat roulants'!F68 -> 3597500
E48: TOTAL | F48: =+SUM(F42:F47) -> 407542500
C54: TOTAL DES INVESTISSEMENTS DE BASE
C55: Désignation | F55: Prix total
C56: =+C5 -> CHARGES IMMOBILISEES | F56: =+F16 -> 5000000
C57: =+C21 -> IMMOBILISATIONS INCORPORELLES - TOTAL DU GROUPE HARAZ | F57: =+F33 -> 1840000
C58: =+C40 -> IMMOBILISATIONS CORPORELLES - TOTAL DU GROUPE HARAZ | F58: =+F48 -> 407542500
E60: TOTAL | F60: =+SUM(F56:F59) -> 414382500

Sheet Amort technique
C2: TABLEAU D'AMORTISSEMENTS TECHNIQUES
C3: Investissement | D3: Montant initial | E3: Durée | F3: 2026 | G3: 2027 | H3: 2028 | I3: 2029 | J3: 2030
C4: Charges immobilisées | D4: =+'Diverses charges immobilisées'!F16 -> 5000000 | E4: 3 | G4: =+D4/E4 -> 1666666.7 | H4: =+G4 -> 1666666.7 | I4: =+H4 -> 1666666.7
C5: Immobilisations incorporelles | D5: =+'Diverses charges immobilisées'!F33 -> 1840000 | E5: 10 | G5: =+D5/E5 -> 184000 | H5: =+G5 -> 184000 | I5: =+H5 -> 184000 | J5: =+I5 -> 184000
C6: Fonciers | D6: 100000000 | E6: 30 | G6: =SUM(D6)/30 -> 3333333.3 | H6: =+G6 -> 3333333.3 | I6: =+H6 -> 3333333.3 | J6: =+I6 -> 3333333.3
C7: Aménagements et constructions | D7: =SUM('Amenag, Infrastr et Equipemt '!D59) -> 257000000 | E7: 20 | G7: =+D7/E7 -> 12850000 | H7: =+G7 -> 12850000 | I7: =+H7 -> 12850000 | J7: =+I7 -> 12850000
C8: Matériels et équipements industriels | D8: =+'Amenag, Infrastr et Equipemt '!L59 -> 140400000 | E8: 10 | G8: =+D8/E8 -> 14040000 | H8: =+G8 -> 14040000 | I8: =+H8 -> 14040000 | J8: =+I8 -> 14040000
C9: Moyens roulants | D9: =+'Mat bureau & Mat roulants'!L68 -> 4800000 | E9: 5 | G9: =+D9/E9 -> 960000 | H9: =+G9 -> 960000 | I9: =+H9 -> 960000 | J9: =+I9 -> 960000
C10: Matériels de bureau | D10: =+'Mat bureau & Mat roulants'!F68 -> 3597500 | E10: 5 | G10: =+D10/E10 -> 719500 | H10: =+G10 -> 719500 | I10: =+H10 -> 719500 | J10: =+I10 -> 719500
C11: Informatiques et reproduction | D11: =+'Mat bureau & Mat roulants'!R68 -> 1745000 | E11: 3 | G11: =+D11/E11 -> 581666.67 | H11: =+G11 -> 581666.67 | I11: =+H11 -> 581666.67 | J11: =+I11 -> 581666.67
D13: =SUM(D4:D12) -> 514382500 | E13: TOTAUX | F13: =+SUM(F4:F12) -> 0 | G13: =+SUM(G4:G12) -> 34335167 | H13: =+SUM(H4:H12) -> 34335167 | I13: =+SUM(I4:I12) -> 34335167 | J13: =+SUM(J4:J12) -> 32668500

Sheet Coûts de product° Agricole
D2: Coûts de production agricoles en €
D4: Year 1 | E4: Year 2 | F4: Year 3 | G4: Year 4 | H4: Year 5 | I4: Year 6 | J4: Year 7 | K4: Year 8 | L4: Year 9 | M4: Year 10
B6: Arachide (Groundnut)
A7: 1 | B7: Description | C7: Coût/ Ha € | D7: 20 | E7: =D7 -> 20 | F7: =E7 -> 20 | G7: =F7 -> 20 | H7: =G7 -> 20 | I7: =H7 -> 20 | J7: =I7 -> 20 | K7: =J7 -> 20 | L7: =K7 -> 20 | M7: =L7 -> 20
B8: Préparation du sol | C8: 19.56 | D8: =$C8*D$7 -> 391.2 | E8: =$C8*E$7 -> 391.2 | F8: =$C8*F$7 -> 391.2 | G8: =$C8*G$7 -> 391.2 | H8: =$C8*H$7 -> 391.2 | I8: =$C8*I$7 -> 391.2 | J8: =$C8*J$7 -> 391.2 | K8: =$C8*K$7 -> 391.2 | ... M8: =$C8*M$7 -> 391.2 | O8: =64000/2.5 -> 25600 | Q8: Litre
B9: Coût des semences | C9: =100*120/88 -> 136.36364 | D9: =$C9*D$7 -> 2727.2727 | E9: =$C9*E$7 -> 2727.2727 | F9: =$C9*F$7 -> 2727.2727 | G9: =$C9*G$7 -> 2727.2727 | H9: =$C9*H$7 -> 2727.2727 | I9: =$C9*I$7 -> 2727.2727 | J9: =$C9*J$7 -> 2727.2727 | K9: =$C9*K$7 -> 2727.2727 | ... M9: =$C9*M$7 -> 2727.2727 | P9: Diesel consumption per hour | Q9: 10
B10: Coût du traitement des semences | C10: =1350*1.5*2.5/88 -> 57.528409 | D10: =$C10*D$7 -> 1150.5682 | E10: =$C10*E$7 -> 1150.5682 | F10: =$C10*F$7 -> 1150.5682 | G10: =$C10*G$7 -> 1150.5682 | H10: =$C10*H$7 -> 1150.5682 | I10: =$C10*I$7 -> 1150.5682 | J10: =$C10*J$7 -> 1150.5682 | K10: =$C10*K$7 -> 1150.5682 | ... M10: =$C10*M$7 -> 1150.5682 | P10: Diesel’s price | Q10: =75/88 -> 0.85227273
B11: Coût du semis | C11: =C8 -> 19.56 | D11: =$C11*D$7 -> 391.2 | E11: =$C11*E$7 -> 391.2 | F11: =$C11*F$7 -> 391.2 | G11: =$C11*G$7 -> 391.2 | H11: =$C11*H$7 -> 391.2 | I11: =$C11*I$7 -> 391.2 | J11: =$C11*J$7 -> 391.2 | K11: =$C11*K$7 -> 391.2 | ... M11: =$C11*M$7 -> 391.2 | P11: Diesel; cost /hour | Q11: =Q10*Q9 -> 8.5227273
B12: Engrais urée en 2 doses | C12: =R19 -> 36.409091 | D12: =$C12*D$7 -> 728.18182 | E12: =$C12*E$7 -> 728.18182 | F12: =$C12*F$7 -> 728.18182 | G12: =$C12*G$7 -> 728.18182 | H12: =$C12*H$7 -> 728.18182 | I12: =$C12*I$7 -> 728.18182 | J12: =$C12*J$7 -> 728.18182 | K12: =$C12*K$7 -> 728.18182 | ... M12: =$C12*M$7 -> 728.18182 | P12: Diesel cost / Ha/ hour | Q12: =Q11*25/33 -> 6.4566116
B13: Pulvérisation d’herbicide de prélevée | C13: =500*1.5*2.5/88 -> 21.306818 | D13: =$C13*D$7 -> 426.13636 | E13: =$C13*E$7 -> 426.13636 | F13: =$C13*F$7 -> 426.13636 | G13: =$C13*G$7 -> 426.13636 | H13: =$C13*H$7 -> 426.13636 | I13: =$C13*I$7 -> 426.13636 | J13: =$C13*J$7 -> 426.13636 | K13: =$C13*K$7 -> 426.13636 | ... M13: =$C13*M$7 -> 426.13636 | P13: No. of irrigations / season | Q13: 5
B14: Pulvérisation de fongicide et d’insecticide | C14: =(2500*1.5*2.5)/88 -> 106.53409 | D14: =$C14*D$7 -> 2130.6818 | E14: =$C14*E$7 -> 2130.6818 | F14: =$C14*F$7 -> 2130.6818 | G14: =$C14*G$7 -> 2130.6818 | H14: =$C14*H$7 -> 2130.6818 | I14: =$C14*I$7 -> 2130.6818 | J14: =$C14*J$7 -> 2130.6818 | K14: =$C14*K$7 -> 2130.6818 | ... M14: =$C14*M$7 -> 2130.6818 | P14: Total diesel cost per season per Ha | Q14: =Q13*Q12*2 -> 64.566116
B15: Gazole pour l’irrigation | C15: =Q14 -> 64.566116 | D15: =C15*D7 -> 1291.3223 | E15: =D15 -> 1291.3223 | F15: =E15 -> 1291.3223 | G15: =F15 -> 1291.3223 | H15: =G15 -> 1291.3223 | I15: =H15 -> 1291.3223 | J15: =I15 -> 1291.3223 | K15: =J15 -> 1291.3223 | L15: =K15 -> 1291.3223 | M15: =L15 -> 1291.3223
B16: Récolte (y compris la main-d’œuvre) | C16: =1500*2.5/88 -> 42.613636 | D16: =$C16*D$7 -> 852.27273 | E16: =$C16*E$7 -> 852.27273 | F16: =$C16*F$7 -> 852.27273 | G16: =$C16*G$7 -> 852.27273 | H16: =$C16*H$7 -> 852.27273 | I16: =$C16*I$7 -> 852.27273 | J16: =$C16*J$7 -> 852.27273 | K16: =$C16*K$7 -> 852.27273 | ... M16: =$C16*M$7 -> 852.27273 | O16: Fertiliser basal/ Ha | P16: QTY | Q16: Price | R16: Val/ Ha
B17: Coût total | C17: =SUM(C8:C16) -> 504.4418 | D17: =SUM(D7:D16) -> 10108.836 | E17: =SUM(E7:E16) -> 10108.836 | F17: =SUM(F7:F16) -> 10108.836 | G17: =SUM(G7:G16) -> 10108.836 | H17: =SUM(H7:H16) -> 10108.836 | I17: =SUM(I7:I16) -> 10108.836 | J17: =SUM(J7:J16) -> 10108.836 | K17: =SUM(K7:K16) -> 10108.836 | ... M17: =SUM(M7:M16) -> 10108.836 | O17: DAP | P17: 100 | Q17: =1200/50/88 -> 0.27272727 | R17: =Q17*P17 -> 27.272727
B18: Rendement | D18: =700*1.5*2.5 -> 2625 | E18: =750*1.5*2.5 -> 2812.5 | F18: =775*1.5*2.5 -> 2906.25 | G18: =850*1.5*2.5 -> 3187.5 | H18: =1000*1.5*2.5 -> 3750 | I18: =H18 -> 3750 | J18: =I18 -> 3750 | K18: =J18 -> 3750 | L18: =K18 -> 3750 | M18: =L18 -> 3750 | O18: Urea in two doses | P18: =40*1.5*2.5 -> 150 | Q18: =268/50/88 -> 0.060909091 | R18: =Q18*P18 -> 9.1363636
B19: Prix / kg | D19: 0.5 | E19: 0.5 | F19: =E19 -> 0.5 | G19: =F19 -> 0.5 | H19: =G19 -> 0.5 | I19: =H19 -> 0.5 | J19: =I19 -> 0.5 | K19: =J19 -> 0.5 | L19: =K19 -> 0.5 | M19: =L19 -> 0.5 | R19: =SUM(R17:R18) -> 36.409091
B20: Réalisation | D20: =D19*D18*D7 -> 26250 | E20: =E19*E18*E7 -> 28125 | F20: =F19*F18*F7 -> 29062.5 | G20: =G19*G18*G7 -> 31875 | H20: =H19*H18*H7 -> 37500 | I20: =I19*I18*I7 -> 37500 | J20: =J19*J18*J7 -> 37500 | K20: =K19*K18*K7 -> 37500 | ... M20: =M19*M18*M7 -> 37500
B22: Marge opérationnelle | D22: =D20-D17 -> 16141.164 | E22: =E20-E17 -> 18016.164 | F22: =F20-F17 -> 18953.664 | G22: =G20-G17 -> 21766.164 | H22: =H20-H17 -> 27391.164 | I22: =I20-I17 -> 27391.164 | J22: =J20-J17 -> 27391.164 | K22: =K20-K17 -> 27391.164 | ... M22: =M20-M17 -> 27391.164
A24: 2 | B24: Niébé (Cowpea)
B25: Description | C25: Coût/ Ha € | D25: 10 | E25: =D25 -> 10 | F25: =E25 -> 10 | G25: =F25 -> 10 | H25: =G25 -> 10 | I25: =H25 -> 10 | J25: =I25 -> 10 | K25: =J25 -> 10 | L25: =K25 -> 10 | M25: =L25 -> 10
B26: Préparation du sol | C26: =C44 -> 19.56 | D26: =D$25*$C26 -> 195.6 | E26: =E$25*$C26 -> 195.6 | F26: =F$25*$C26 -> 195.6 | G26: =G$25*$C26 -> 195.6 | H26: =H$25*$C26 -> 195.6 | I26: =I$25*$C26 -> 195.6 | J26: =J$25*$C26 -> 195.6 | K26: =K$25*$C26 -> 195.6 | ... M26: =M$25*$C26 -> 195.6
B27: Coût des semences | C27: =30*100/88 -> 34.090909 | D27: =D$25*$C27 -> 340.90909 | E27: =E$25*$C27 -> 340.90909 | F27: =F$25*$C27 -> 340.90909 | G27: =G$25*$C27 -> 340.90909 | H27: =H$25*$C27 -> 340.90909 | I27: =I$25*$C27 -> 340.90909 | J27: =J$25*$C27 -> 340.90909 | K27: =K$25*$C27 -> 340.90909 | ... M27: =M$25*$C27 -> 340.90909
B28: Coût du traitement des semences | C28: =35 -> 35 | D28: =D$25*$C28 -> 350 | E28: =E$25*$C28 -> 350 | F28: =F$25*$C28 -> 350 | G28: =G$25*$C28 -> 350 | H28: =H$25*$C28 -> 350 | I28: =I$25*$C28 -> 350 | J28: =J$25*$C28 -> 350 | K28: =K$25*$C28 -> 350 | ... M28: =M$25*$C28 -> 350
B29: Coût du semis | C29: =C47 -> 56.818182 | D29: =D$25*$C29 -> 568.18182 | E29: =E$25*$C29 -> 568.18182 | F29: =F$25*$C29 -> 568.18182 | G29: =G$25*$C29 -> 568.18182 | H29: =H$25*$C29 -> 568.18182 | I29: =I$25*$C29 -> 568.18182 | J29: =J$25*$C29 -> 568.18182 | K29: =K$25*$C29 -> 568.18182 | ... M29: =M$25*$C29 -> 568.18182
B30: Engrais urée en 2 doses | C30: =C12 -> 36.409091 | D30: =D$25*$C30 -> 364.09091 | E30: =E$25*$C30 -> 364.09091 | F30: =F$25*$C30 -> 364.09091 | G30: =G$25*$C30 -> 364.09091 | H30: =H$25*$C30 -> 364.09091 | I30: =I$25*$C30 -> 364.09091 | J30: =J$25*$C30 -> 364.09091 | K30: =K$25*$C30 -> 364.09091 | ... M30: =M$25*$C30 -> 364.09091
B31: Pulvérisation d’herbicide de prélevée | C31: =10000/88 -> 113.63636 | D31: =D$25*$C31 -> 1136.3636 | E31: =E$25*$C31 -> 1136.3636 | F31: =F$25*$C31 -> 1136.3636 | G31: =G$25*$C31 -> 1136.3636 | H31: =H$25*$C31 -> 1136.3636 | I31: =I$25*$C31 -> 1136.3636 | J31: =J$25*$C31 -> 1136.3636 | K31: =K$25*$C31 -> 1136.3636 | ... M31: =M$25*$C31 -> 1136.3636
B32: Pulvérisation de fongicide et d’insecticide | C32: =34 -> 34 | D32: =D$25*$C32 -> 340 | E32: =E$25*$C32 -> 340 | F32: =F$25*$C32 -> 340 | G32: =G$25*$C32 -> 340 | H32: =H$25*$C32 -> 340 | I32: =I$25*$C32 -> 340 | J32: =J$25*$C32 -> 340 | K32: =K$25*$C32 -> 340 | ... M32: =M$25*$C32 -> 340
B33: Gazole pour l’irrigation | C33: =C15/2 -> 32.283058 | D33: =D$25*$C33 -> 322.83058 | E33: =E$25*$C33 -> 322.83058 | F33: =F$25*$C33 -> 322.83058 | G33: =G$25*$C33 -> 322.83058 | H33: =H$25*$C33 -> 322.83058 | I33: =I$25*$C33 -> 322.83058 | J33: =J$25*$C33 -> 322.83058 | K33: =K$25*$C33 -> 322.83058 | ... M33: =M$25*$C33 -> 322.83058
B34: Récolte (y compris la main-d’œuvre) | C34: =137 -> 137 | D34: =D$25*$C34 -> 1370 | E34: =E$25*$C34 -> 1370 | F34: =F$25*$C34 -> 1370 | G34: =G$25*$C34 -> 1370 | H34: =H$25*$C34 -> 1370 | I34: =I$25*$C34 -> 1370 | J34: =J$25*$C34 -> 1370 | K34: =K$25*$C34 -> 1370 | ... M34: =M$25*$C34 -> 1370
B35: Coût total | C35: =SUM(C26:C34) -> 498.7976 | D35: =SUM(D26:D34) -> 4987.976 | E35: =SUM(E26:E34) -> 4987.976 | F35: =SUM(F26:F34) -> 4987.976 | G35: =SUM(G26:G34) -> 4987.976 | H35: =SUM(H26:H34) -> 4987.976 | I35: =SUM(I26:I34) -> 4987.976 | J35: =SUM(J26:J34) -> 4987.976 | ... M35: =SUM(M26:M34) -> 4987.976
B36: Rendement | D36: 900 | E36: 1000 | F36: =1100 -> 1100 | G36: =F36 -> 1100 | H36: =G36 -> 1100 | I36: =H36 -> 1100 | J36: =I36 -> 1100 | K36: =J36 -> 1100 | L36: =K36 -> 1100 | M36: =L36 -> 1100
B37: Prix / kg | D37: 1.3 | E37: =D37 -> 1.3 | F37: =E37 -> 1.3 | G37: =F37 -> 1.3 | H37: =G37 -> 1.3 | I37: =H37 -> 1.3 | J37: =I37 -> 1.3 | K37: =J37 -> 1.3 | L37: =K37 -> 1.3 | M37: =L37 -> 1.3
B38: Réalisation | D38: =D37*D36*D25 -> 11700 | E38: =E37*E36*E25 -> 13000 | F38: =F37*F36*F25 -> 14300 | G38: =G37*G36*G25 -> 14300 | H38: =H37*H36*H25 -> 14300 | I38: =I37*I36*I25 -> 14300 | J38: =J37*J36*J25 -> 14300 | K38: =K37*K36*K25 -> 14300 | ... M38: =M37*M36*M25 -> 14300
B40: Marge opérationnelle | D40: =D38-D35 -> 6712.024 | E40: =E38-E35 -> 8012.024 | F40: =F38-F35 -> 9312.024 | G40: =G38-G35 -> 9312.024 | H40: =H38-H35 -> 9312.024 | I40: =I38-I35 -> 9312.024 | J40: =J38-J35 -> 9312.024 | K40: =K38-K35 -> 9312.024 | ... M40: =M38-M35 -> 9312.024
A42: 3 | B42: Céréale, blé, mais (Wheat, corne, )
B43: Description | C43: Coût/ Ha € | D43: 20 | E43: =D43 -> 20 | F43: =E43 -> 20 | G43: =F43 -> 20 | H43: =G43 -> 20 | I43: =H43 -> 20 | J43: =I43 -> 20 | K43: =J43 -> 20 | L43: =K43 -> 20 | M43: =L43 -> 20
B44: Préparation du sol | C44: =C62 -> 19.56 | D44: =$C44*D$43 -> 391.2 | E44: =$C44*E$43 -> 391.2 | F44: =$C44*F$43 -> 391.2 | G44: =$C44*G$43 -> 391.2 | H44: =$C44*H$43 -> 391.2 | I44: =$C44*I$43 -> 391.2 | J44: =$C44*J$43 -> 391.2 | K44: =$C44*K$43 -> 391.2 | ... M44: =$C44*M$43 -> 391.2
B45: Coût des semences | C45: =100*75/88 -> 85.227273 | D45: =$C45*D$43 -> 1704.5455 | E45: =$C45*E$43 -> 1704.5455 | F45: =$C45*F$43 -> 1704.5455 | G45: =$C45*G$43 -> 1704.5455 | H45: =$C45*H$43 -> 1704.5455 | I45: =$C45*I$43 -> 1704.5455 | J45: =$C45*J$43 -> 1704.5455 | K45: =$C45*K$43 -> 1704.5455 | ... M45: =$C45*M$43 -> 1704.5455
B46: Coût du traitement des semences | D46: =$C46*D$43 -> 0 | E46: =$C46*E$43 -> 0 | F46: =$C46*F$43 -> 0 | G46: =$C46*G$43 -> 0 | H46: =$C46*H$43 -> 0 | I46: =$C46*I$43 -> 0 | J46: =$C46*J$43 -> 0 | K46: =$C46*K$43 -> 0 | ... M46: =$C46*M$43 -> 0
B47: Coût du semis | C47: =5000/88 -> 56.818182 | D47: =$C47*D$43 -> 1136.3636 | E47: =$C47*E$43 -> 1136.3636 | F47: =$C47*F$43 -> 1136.3636 | G47: =$C47*G$43 -> 1136.3636 | H47: =$C47*H$43 -> 1136.3636 | I47: =$C47*I$43 -> 1136.3636 | J47: =$C47*J$43 -> 1136.3636 | K47: =$C47*K$43 -> 1136.3636 | ... M47: =$C47*M$43 -> 1136.3636
...

Sheet Matière 1é & fourni Agriculture
C3: 1 Arachide (Groundnut) | K3: 2 Niébé (Cowpea) | T3: 3 Céréale, blé, mais (Wheat, corne) | AB3: 4 Sesame | AI3: 5 Gombo - avec goutte-à-goutte | AP3: 6 Sorgho pour graine | AW3: 7 Oignon - avec goutte-à-goutte | BD3: 8 Aubergine - avec goutte-à-goutte et paillage | BK3: 9 Tomate - avec goutte-à-goutte et paillage | BR3: 10 Pomme de terre en hiver avec irrigation | BY3: 11 Luzerne (Alfa Alfa) en irrigation | CF3: 12 Verget pour arbre fruitiers | CN3: 13 Agroforesterie & haie vive
C4: Arachide (Groundnut) | K4: Niébé (Cowpea) | T4: Céréale, blé, mais (Wheat, corne, ) | AB4: Sesame | AI4: Gombo - avec goutte-à-goutte (Okra - with drip) | AP4: Sorgho pour graine (Sorghum for Seed) | AW4: Oignon - avec goutte-à-goutte (Onion - with drip) | BD4: Aubergine - avec goutte-à-goutte et paillage | BK4: Tomate - avec goutte-à-goutte et paillage | BR4: Pomme de terre en hiver avec irrigation | BY4: Luzerne (Alfa Alfa) en irrigation | CF4: Verget pour arbre fruitiers | CN4: Agroforesterie & haie vive
C5: Matière première | D5: Octobre | E5: Novembre | F5: Décembre | G5: Total vendu | K5: Matière première | L5: Octobre | M5: Novembre | N5: Décembre | O5: Total vendu | T5: Matière première | U5: Octobre | V5: Novembre | W5: Décembre | X5: Total vendu | AB5: Matière première | AC5: Octobre | AD5: Novembre | AE5: Décembre | AF5: Total vendu | AI5: Matière première | AJ5: Octobre | AK5: Novembre | AL5: Décembre | AM5: Total vendu | AP5: Matière première | AQ5: Octobre | AR5: Novembre | AS5: Décembre | AT5: Total vendu | AW5: Matière première | AX5: Octobre | AY5: Novembre | AZ5: Décembre | BA5: Total vendu | BD5: Matière première | BE5: Octobre | BF5: Novembre | BG5: Décembre | BH5: Total vendu | BK5: Matière première | BL5: Octobre | BM5: Novembre | BN5: Décembre | BO5: Total vendu | BR5: Matière première | BS5: Octobre | BT5: Novembre | BU5: Décembre | BV5: Total vendu | BY5: Matière première | BZ5: Octobre | CA5: Novembre | CB5: Décembre | CC5: Total vendu | CF5: Matière première | CG5: Octobre | CH5: Novembre | CI5: Décembre | CJ5: Total vendu | CN5: Matière première | CO5: Octobre | CP5: Novembre | CQ5: Décembre | CR5: Total vendu
C6: Superficie cultivée en pluviale | D6: =+'[2]Ca...'!C6+'[2]Ca...'!C11+'[2]Ca...'!C17 -> 0 | F6: 0 | G6: =+SUM(C6:F6) -> 0 | K6: Superficie cultivée en pluviale | L6: =+'[2]Ca...'!K6+'[2]Ca...'!K11+'[2]Ca...'!K17 -> 0 | O6: =+SUM(K6:N6) -> 0 | T6: Superficie cultivée en pluviale | X6: =+SUM(T6:W6) -> 0 | AB6: Superficie cultivée en pluviale | AE6: 0 | AF6: =+SUM(AB6:AE6) -> 0 | AI6: Superficie cultivée en irriguation | AL6: 0 | AM6: =+SUM(AI6:AL6) -> 0 | AP6: Superficie cultivée en irriguation | AS6: 0 | AT6: =+SUM(AP6:AS6) -> 0 | AW6: Superficie cultivée en irriguation | AZ6: 0 | BA6: =+SUM(AW6:AZ6) -> 0 | BD6: Superficie cultivée en irriguation | BG6: 0 | BH6: =+SUM(BD6:BG6) -> 0 | BK6: Superficie cultivée en irriguation | BN6: 0 | BO6: =+SUM(BK6:BN6) -> 0 | BR6: Superficie cultivée en irriguation | BU6: 0 | BV6: =+SUM(BR6:BU6) -> 0 | BY6: Superficie cultivée en irriguation | CB6: 0 | CC6: =+SUM(BY6:CB6) -> 0 | CF6: Superficie cultivée en irriguation | CI6: 0 | CJ6: =+SUM(CF6:CI6) -> 0 | CN6: Superficie cultivée en irriguation | CQ6: 0 | CR6: =+SUM(CN6:CQ6) -> 0
C7: Coût unitaire par hectare (504€/H) | E7: =SUM('Coûts de product° Agricole'!C17)*657 -> 331418.26 | F7: =SUM(E7) -> 331418.26 | K7: Coût unitaire par hectare (498€/H) | L7: =SUM('Coûts de product° Agricole'!C35)*657 -> 327710.03 | M7: =SUM(L7) -> 327710.03 | N7: =SUM(M7) -> 327710.03 | T7: Coût unitaire par hectare (688€/H) | U7: =SUM('Coûts de product° Agricole'!C53)*657 -> 452321.48 | V7: =SUM(U7) -> 452321.48 | W7: =SUM(V7) -> 452321.48 | AB7: Coût unitaire par hectare (233€/H) | AC7: =SUM('Coûts de product° Agricole'!C71)*657 -> 153373.3 | AE7: 0 | AI7: Coût unitaire par hectare (2245€/H) | AJ7: =SUM('Coûts de product° Agricole'!C91)*657 -> 1475365.4 | AL7: 0 | AP7: Coût unitaire par hectare (309€/H) | AQ7: =SUM('Coûts de product° Agricole'!C109)*657 -> 203562.87 | AS7: 0 | AW7: Coût unitaire par hectare (1364€/H) | AX7: =SUM('Coûts de product° Agricole'!C127)*657 -> 896757.49 | AZ7: 0 | BD7: Coût unitaire par hectare (4398€/H) | BE7: =SUM('Coûts de product° Agricole'!C145)*657 -> 2890070.4 | BG7: 0 | BK7: Coût unitaire par hectare (4725€/H) | BL7: =SUM('Coûts de product° Agricole'!C163)*657 -> 3104715.3 | BN7: 0 | BR7: Coût unitaire par hectare (1603€/H) | BS7: =SUM('Coûts de product° Agricole'!C181)*657 -> 1053822.6 | BU7: 0 | BY7: Coût unitaire par hectare (834€/H) | BZ7: =SUM('Coûts de product° Agricole'!C199)*657 -> 548466.59 | CB7: 0 | CF7: Coût unitaire par hectare (1900€/H) | CG7: =SUM(CE12)*CE13 -> 1250000 | CI7: 0 | CN7: Coût unitaire par hectare (914€/H) | CO7: =SUM(CM12)*CM13 -> 600000 | CQ7: 0
C8: Sous-total | D8: =+D7*D6 -> 0 | E8: =+E7*E6 -> 0 | F8: =+F7*F6 -> 0 | K8: Sous-total | L8: =+L7*L6 -> 0 | M8: =+M7*M6 -> 0 | N8: =+N7*N6 -> 0 | T8: Sous-total | U8: =+U7*U6 -> 0 | V8: =+V7*V6 -> 0 | W8: =+W7*W6 -> 0 | AB8: Sous-total | AC8: =+AC7*AC6 -> 0 | AD8: =+AD7*AD6 -> 0 | AE8: =+AE7*AE6 -> 0 | AI8: Sous-total | AJ8: =+AJ7*AJ6 -> 0 | AK8: =+AK7*AK6 -> 0 | AL8: =+AL7*AL6 -> 0 | AP8: Sous-total | AQ8: =+AQ7*AQ6 -> 0 | AR8: =+AR7*AR6 -> 0 | AS8: =+AS7*AS6 -> 0 | AW8: Sous-total | AX8: =+AX7*AX6 -> 0 | AY8: =+AY7*AY6 -> 0 | AZ8: =+AZ7*AZ6 -> 0 | BD8: Sous-total | BE8: =+BE7*BE6 -> 0 | BF8: =+BF7*BF6 -> 0 | BG8: =+BG7*BG6 -> 0 | BK8: Sous-total | BL8: =+BL7*BL6 -> 0 | BM8: =+BM7*BM6 -> 0 | BN8: =+BN7*BN6 -> 0 | BR8: Sous-total | BS8: =+BS7*BS6 -> 0 | BT8: =+BT7*BT6 -> 0 | BU8: =+BU7*BU6 -> 0 | BY8: Sous-total | BZ8: =+BZ7*BZ6 -> 0 | CA8: =+CA7*CA6 -> 0 | CB8: =+CB7*CB6 -> 0 | CF8: Sous-total | CG8: =+CG7*CG6 -> 0 | CH8: =+CH7*CH6 -> 0 | CI8: =+CI7*CI6 -> 0 | CN8: Sous-total | CO8: =+CO7*CO6 -> 0 | CP8: =+CP7*CP6 -> 0 | CQ8: =+CQ7*CQ6 -> 0
C9: Sous-total cumulé | D9: =+D8 -> 0 | E9: =+D9+E8 -> 0 | F9: =+E9+F8 -> 0 | K9: Sous-total cumulé | L9: =+L8 -> 0 | M9: =+L9+M8 -> 0 | N9: =+M9+N8 -> 0 | T9: Sous-total cumulé | U9: =+U8 -> 0 | V9: =+U9+V8 -> 0 | W9: =+V9+W8 -> 0 | AB9: Sous-total cumulé | AC9: =+AC8 -> 0 | AD9: =+AC9+AD8 -> 0 | AE9: =+AD9+AE8 -> 0 | AI9: Sous-total cumulé | AJ9: =+AJ8 -> 0 | AK9: =+AJ9+AK8 -> 0 | AL9: =+AK9+AL8 -> 0 | AP9: Sous-total cumulé | AQ9: =+AQ8 -> 0 | AR9: =+AQ9+AR8 -> 0 | AS9: =+AR9+AS8 -> 0 | AW9: Sous-total cumulé | AX9: =+AX8 -> 0 | AY9: =+AX9+AY8 -> 0 | AZ9: =+AY9+AZ8 -> 0 | BD9: Sous-total cumulé | BE9: =+BE8 -> 0 | BF9: =+BE9+BF8 -> 0 | BG9: =+BF9+BG8 -> 0 | BK9: Sous-total cumulé | BL9: =+BL8 -> 0 | BM9: =+BL9+BM8 -> 0 | BN9: =+BM9+BN8 -> 0 | BR9: Sous-total cumulé | BS9: =+BS8 -> 0 | BT9: =+BS9+BT8 -> 0 | BU9: =+BT9+BU8 -> 0 | BY9: Sous-total cumulé | BZ9: =+BZ8 -> 0 | CA9: =+BZ9+CA8 -> 0 | CB9: =+CA9+CB8 -> 0 | CF9: Sous-total cumulé | CG9: =+CG8 -> 0 | CH9: =+CG9+CH8 -> 0 | CI9: =+CH9+CI8 -> 0 | CN9: Sous-total cumulé | CO9: =+CO8 -> 0 | CP9: =+CO9+CP8 -> 0 | CQ9: =+CP9+CQ8 -> 0
D11: =+'[2]Ca...'!C11 -> 0 | E11: =+'[2]Ca...'!D11 -> 0 | F11: =+'[2]Ca...'!E11 -> 0 | L11: =+'[2]Ca...'!K11 -> 0 | M11: =+'[2]Ca...'!L11 -> 0 | N11: =+'[2]Ca...'!M11 -> 0 | W11: =+'[2]Ca...'!V11 -> 0
G12: =+SUM(C12:F12) -> 0 | O12: =+SUM(K12:N12) -> 0 | X12: =+SUM(T12:W12) -> 0 | AF12: =+SUM(AB12:AE12) -> 0 | AM12: =+SUM(AI12:AL12) -> 0 | AT12: =+SUM(AP12:AS12) -> 0 | BA12: =+SUM(AW12:AZ12) -> 0 | BH12: =+SUM(BD12:BG12) -> 0 | BO12: =+SUM(BK12:BN12) -> 0 | BV12: =+SUM(BR12:BU12) -> 0 | CC12: =+SUM(BY12:CB12) -> 0 | CE12: 500 | CF12: 500 pieds de fruitier à l'hectare | CJ12: =+SUM(CF12:CI12) -> 0 | CM12: 2000 | CN12: 2000 pieds d'acacia au kilometre | CR12: =+SUM(CN12:CQ12) -> 0
CE13: 2500 | CF13: Prix unitaire de la pepiniere 2500 Fr | CM13: 300 | CN13: Prix unitaire de la pepiniere 300 Fr
D14: =+D13*D12 -> 0 | E14: =+E13*E12 -> 0 | F14: =+F13*F12 -> 0 | L14: =+L13*L12 -> 0 | M14: =+M13*M12 -> 0 | N14: =+N13*N12 -> 0 | U14: =+U13*U12 -> 0 | V14: =+V13*V12 -> 0 | W14: =+W13*W12 -> 0 | AC14: =+AC13*AC12 -> 0 | AD14: =+AD13*AD12 -> 0 | AE14: =+AE13*AE12 -> 0 | AJ14: =+AJ13*AJ12 -> 0 | AK14: =+AK13*AK12 -> 0 | AL14: =+AL13*AL12 -> 0 | AQ14: =+AQ13*AQ12 -> 0 | AR14: =+AR13*AR12 -> 0 | AS14: =+AS13*AS12 -> 0 | AX14: =+AX13*AX12 -> 0 | AY14: =+AY13*AY12 -> 0 | AZ14: =+AZ13*AZ12 -> 0 | BE14: =+BE13*BE12 -> 0 | BF14: =+BF13*BF12 -> 0 | BG14: =+BG13*BG12 -> 0 | BL14: =+BL13*BL12 -> 0 | BM14: =+BM13*BM12 -> 0 | BN14: =+BN13*BN12 -> 0 | BS14: =+BS13*BS12 -> 0 | BT14: =+BT13*BT12 -> 0 | BU14: =+BU13*BU12 -> 0 | BZ14: =+BZ13*BZ12 -> 0 | CA14: =+CA13*CA12 -> 0 | CB14: =+CB13*CB12 -> 0 | CG14: =+CG13*CG12 -> 0 | CH14: =+CH13*CH12 -> 0 | CI14: =+CI13*CI12 -> 0 | CO14: =+CO13*CO12 -> 0 | CP14: =+CP13*CP12 -> 0 | CQ14: =+CQ13*CQ12 -> 0
D15: =+D14 -> 0 | E15: =+D15+E14 -> 0 | F15: =+E15+F14 -> 0 | L15: =+L14 -> 0 | M15: =+L15+M14 -> 0 | N15: =+M15+N14 -> 0 | U15: =+U14 -> 0 | V15: =+U15+V14 -> 0 | W15: =+V15+W14 -> 0 | AC15: =+AC14 -> 0 | AD15: =+AC15+AD14 -> 0 | AE15: =+AD15+AE14 -> 0 | AJ15: =+AJ14 -> 0 | AK15: =+AJ15+AK14 -> 0 | AL15: =+AK15+AL14 -> 0 | AQ15: =+AQ14 -> 0 | AR15: =+AQ15+AR14 -> 0 | AS15: =+AR15+AS14 -> 0 | AX15: =+AX14 -> 0 | AY15: =+AX15+AY14 -> 0 | AZ15: =+AY15+AZ14 -> 0 | BE15: =+BE14 -> 0 | BF15: =+BE15+BF14 -> 0 | BG15: =+BF15+BG14 -> 0 | BL15: =+BL14 -> 0 | BM15: =+BL15+BM14 -> 0 | BN15: =+BM15+BN14 -> 0 | BS15: =+BS14 -> 0 | BT15: =+BS15+BT14 -> 0 | BU15: =+BT15+BU14 -> 0 | BZ15: =+BZ14 -> 0 | CA15: =+BZ15+CA14 -> 0 | CB15: =+CA15+CB14 -> 0 | CG15: =+CG14 -> 0 | CH15: =+CG15+CH14 -> 0 | CI15: =+CH15+CI14 -> 0 | CO15: =+CO14 -> 0 | CP15: =+CO15+CP14 -> 0 | CQ15: =+CP15+CQ14 -> 0
D17: =+'[2]Ca...'!C17 -> 0 | E17: =+'[2]Ca...'!D17 -> 0 | F17: =+'[2]Ca...'!E17 -> 0 | L17: =+'[2]Ca...'!K17 -> 0 | M17: =+'[2]Ca...'!L17 -> 0 | N17: =+'[2]Ca...'!M17 -> 0 | W17: =+'[2]Ca...'!V28 -> 0
F18: 0 | G18: =+SUM(C18:F18) -> 0 | N18: 0 | O18: =+SUM(K18:N18) -> 0 | W18: 0 | X18: =+SUM(T18:W18) -> 0 | AE18: 0 | AF18: =+SUM(AB18:AE18) -> 0 | AL18: 0 | AM18: =+SUM(AI18:AL18) -> 0 | AS18: 0 | AT18: =+SUM(AP18:AS18) -> 0 | AZ18: 0 | BA18: =+SUM(AW18:AZ18) -> 0 | BG18: 0 | BH18: =+SUM(BD18:BG18) -> 0 | BN18: 0 | BO18: =+SUM(BK18:BN18) -> 0 | BU18: 0 | BV18: =+SUM(BR18:BU18) -> 0 | CB18: 0 | CC18: =+SUM(BY18:CB18) -> 0 | CI18: 0 | CJ18: =+SUM(CF18:CI18) -> 0 | CQ18: 0 | CR18: =+SUM(CN18:CQ18) -> 0
F19: 0 | N19: 0 | W19: 0 | AE19: 0 | AL19: 0 | AS19: 0 | AZ19: 0 | BG19: 0 | BN19: 0 | BU19: 0 | CB19: 0 | CI19: 0 | CQ19: 0
D20: =+D19*D18 -> 0 | F20: =+F19*F18 -> 0 | L20: =+L19*L18 -> 0 | N20: =+N19*N18 -> 0 | U20: =+U19*U18 -> 0 | W20: =+W19*W18 -> 0 | AC20: =+AC19*AC18 -> 0 | AE20: =+AE19*AE18 -> 0 | AJ20: =+AJ19*AJ18 -> 0 | AL20: =+AL19*AL18 -> 0 | AQ20: =+AQ19*AQ18 -> 0 | AS20: =+AS19*AS18 -> 0 | AX20: =+AX19*AX18 -> 0 | AZ20: =+AZ19*AZ18 -> 0 | BE20: =+BE19*BE18 -> 0 | BG20: =+BG19*BG18 -> 0 | BL20: =+BL19*BL18 -> 0 | BN20: =+BN19*BN18 -> 0 | BS20: =+BS19*BS18 -> 0 | BU20: =+BU19*BU18 -> 0 | BZ20: =+BZ19*BZ18 -> 0 | CB20: =+CB19*CB18 -> 0 | CG20: =+CG19*CG18 -> 0 | CI20: =+CI19*CI18 -> 0 | CO20: =+CO19*CO18 -> 0 | CQ20: =+CQ19*CQ18 -> 0
D21: =+D20 -> 0 | E21: =+D21+E20 -> 0 | F21: =+E21+F20 -> 0 | L21: =+L20 -> 0 | M21: =+L21+M20 -> 0 | N21: =+M21+N20 -> 0 | U21: =+U20 -> 0 | V21: =+U21+V20 -> 0 | W21: =+V21+W20 -> 0 | AC21: =+AC20 -> 0 | AD21: =+AC21+AD20 -> 0 | AE21: =+AD21+AE20 -> 0 | AJ21: =+AJ20 -> 0 | AK21: =+AJ21+AK20 -> 0 | AL21: =+AK21+AL20 -> 0 | AQ21: =+AQ20 -> 0 | AR21: =+AQ21+AR20 -> 0 | AS21: =+AR21+AS20 -> 0 | AX21: =+AX20 -> 0 | AY21: =+AX21+AY20 -> 0 | AZ21: =+AY21+AZ20 -> 0 | BE21: =+BE20 -> 0 | BF21: =+BE21+BF20 -> 0 | BG21: =+BF21+BG20 -> 0 | BL21: =+BL20 -> 0 | BM21: =+BL21+BM20 -> 0 | BN21: =+BM21+BN20 -> 0 | BS21: =+BS20 -> 0 | BT21: =+BS21+BT20 -> 0 | BU21: =+BT21+BU20 -> 0 | BZ21: =+BZ20 -> 0 | CA21: =+BZ21+CA20 -> 0 | CB21: =+CA21+CB20 -> 0 | CG21: =+CG20 -> 0 | CH21: =+CG21+CH20 -> 0 | CI21: =+CH21+CI20 -> 0 | CO21: =+CO20 -> 0 | CP21: =+CO21+CP20 -> 0 | CQ21: =+CP21+CQ20 -> 0
C23: Totaux | D23: =+D8+D14+D20 -> 0 | E23: =+E20+E14+E8 -> 0 | F23: =+F20+F14+F8 -> 0 | G23: =+SUM(G6:G22) -> 0 | K23: Totaux | L23: =+L8+L14+L20 -> 0 | M23: =+M20+M14+M8 -> 0 | N23: =+N20+N14+N8 -> 0 | O23: =+SUM(O6:O22) -> 0 | T23: Totaux | U23: =+U8+U14+U20 -> 0 | V23: =+V20+V14+V8 -> 0 | W23: =+W20+W14+W8 -> 0 | X23: =+SUM(X6:X22) -> 0 | AB23: Totaux | AC23: =+AC8+AC14+AC20 -> 0 | AD23: =+AD20+AD14+AD8 -> 0 | AE23: =+AE20+AE14+AE8 -> 0 | AF23: =+SUM(AF6:AF22) -> 0 | AI23: Totaux | AJ23: =+AJ8+AJ14+AJ20 -> 0 | AK23: =+AK20+AK14+AK8 -> 0 | AL23: =+AL20+AL14+AL8 -> 0 | AM23: =+SUM(AM6:AM22) -> 0 | AP23: Totaux | AQ23: =+AQ8+AQ14+AQ20 -> 0 | AR23: =+AR20+AR14+AR8 -> 0 | AS23: =+AS20+AS14+AS8 -> 0 | AT23: =+SUM(AT6:AT22) -> 0 | AW23: Totaux | AX23: =+AX8+AX14+AX20 -> 0 | AY23: =+AY20+AY14+AY8 -> 0 | AZ23: =+AZ20+AZ14+AZ8 -> 0 | BA23: =+SUM(BA6:BA22) -> 0 | BD23: Totaux | BE23: =+BE8+BE14+BE20 -> 0 | BF23: =+BF20+BF14+BF8 -> 0 | BG23: =+BG20+BG14+BG8 -> 0 | BH23: =+SUM(BH6:BH22) -> 0 | BK23: Totaux | BL23: =+BL8+BL14+BL20 -> 0 | BM23: =+BM20+BM14+BM8 -> 0 | BN23: =+BN20+BN14+BN8 -> 0 | BO23: =+SUM(BO6:BO22) -> 0 | BR23: Totaux | BS23: =+BS8+BS14+BS20 -> 0 | BT23: =+BT20+BT14+BT8 -> 0 | BU23: =+BU20+BU14+BU8 -> 0 | BV23: =+SUM(BV6:BV22) -> 0 | BY23: Totaux | BZ23: =+BZ8+BZ14+BZ20 -> 0 | CA23: =+CA20+CA14+CA8 -> 0 | CB23: =+CB20+CB14+CB8 -> 0 | CC23: =+SUM(CC6:CC22) -> 0 | CF23: Totaux | CG23: =+CG8+CG14+CG20 -> 0 | CH23: =+CH20+CH14+CH8 -> 0 | CI23: =+CI20+CI14+CI8 -> 0 | CJ23: =+SUM(CJ6:CJ22) -> 0 | CN23: Totaux | CO23: =+CO8+CO14+CO20 -> 0 | CP23: =+CP20+CP14+CP8 -> 0 | CQ23: =+CQ20+CQ14+CQ8 -> 0 | CR23: =+SUM(CR6:CR22) -> 0
C24: Totaux cumulés | D24: =+D23 -> 0 | E24: =+D24+E23 -> 0 | F24: =+E24+F23 -> 0 | K24: Totaux cumulés | L24: =+L23 -> 0 | M24: =+L24+M23 -> 0 | N24: =+M24+N23 -> 0 | T24: Totaux cumulés | U24: =+U23 -> 0 | V24: =+U24+V23 -> 0 | W24: =+V24+W23 -> 0 | AB24: Totaux cumulés | AC24: =+AC23 -> 0 | AD24: =+AC24+AD23 -> 0 | AE24: =+AD24+AE23 -> 0 | AI24: Totaux cumulés | AJ24: =+AJ23 -> 0 | AK24: =+AJ24+AK23 -> 0 | AL24: =+AK24+AL23 -> 0 | AP24: Totaux cumulés | AQ24: =+AQ23 -> 0 | AR24: =+AQ24+AR23 -> 0 | AS24: =+AR24+AS23 -> 0 | AW24: Totaux cumulés | AX24: =+AX23 -> 0 | AY24: =+AX24+AY23 -> 0 | AZ24: =+AY24+AZ23 -> 0 | BD24: Totaux cumulés | BE24: =+BE23 -> 0 | BF24: =+BE24+BF23 -> 0 | BG24: =+BF24+BG23 -> 0 | BK24: Totaux cumulés | BL24: =+BL23 -> 0 | BM24: =+BL24+BM23 -> 0 | BN24: =+BM24+BN23 -> 0 | BR24: Totaux cumulés | BS24: =+BS23 -> 0 | BT24: =+BS24+BT23 -> 0 | BU24: =+BT24+BU23 -> 0 | BY24: Totaux cumulés | BZ24: =+BZ23 -> 0 | CA24: =+BZ24+CA23 -> 0 | CB24: =+CA24+CB23 -> 0 | CF24: Totaux cumulés | CG24: =+CG23 -> 0 | CH24: =+CG24+CH23 -> 0 | CI24: =+CH24+CI23 -> 0 | CN24: Totaux cumulés | CO24: =+CO23 -> 0 | CP24: =+CO24+CP23 -> 0 | CQ24: =+CP24+CQ23 -> 0
C27: Arachide (Groundnut) 2026 | K27: Niébé (Cowpea) 2026 | T27: Céréale, blé, mais (Wheat, corne, ) 2026 | Y27: Total acheté | AB27: Sesame 2026 | AG27: Total acheté | AI27: Gombo - avec goutte-à-goutte (Okra - with drip) 2026 | AN27: Total acheté | AP27: Sorgho pour graine (Sorghum for Seed) 2026 | AU27: Total acheté | AW27: Oignon - avec goutte-à-goutte (Onion - with drip) 2026 | BB27: Total acheté | BD27: Aubergine - avec goutte-à-goutte et paillage 2026 | BI27: Total acheté | BK27: Tomate - avec goutte-à-goutte et paillage 2026 | BP27: Total acheté | BR27: Pomme de terre en hiver avec irrigation 2026 | BW27: Total acheté | BY27: Luzerne (Alfa Alfa) en irrigation 2026 | CD27: Total acheté | CF27: Verget pour arbre fruitiers 2026 | CK27: Total acheté | CN27: Verget pour arbre fruitiers 2026 | CS27: Total acheté
C28: Matière première | D28: 1er trimestre | E28: 2ème trimestre | F28: 3ème trimestre | G28: 4ème trimestre | H28: Total Acheté | K28: Matière première | L28: 1er trimestre | M28: 2ème trimestre | N28: 3ème trimestre | O28: 4ème trimestre | P28: Total Acheté | T28: Achat de production | U28: 1er trimestre | V28: 2ème trimestre | W28: 3ème trimestre | X28: 4ème trimestre | Y28: Total Acheté | AB28: Achat de production | AC28: 1er trimestre | AD28: 2ème trimestre | AE28: 3ème trimestre | AF28: 4ème trimestre | AG28: Total acheté | AI28: Achat de production | AJ28: 1er trimestre | AK28: 2ème trimestre | AL28: 3ème trimestre | AM28: 4ème trimestre | AN28: Total acheté | AP28: Achat de production | AQ28: 1er trimestre | AR28: 2ème trimestre | AS28: 3ème trimestre | AT28: 4ème trimestre | AU28: Total acheté | AW28: Achat de production | AX28: 1er trimestre | AY28: 2ème trimestre | AZ28: 3ème trimestre | BA28: 4ème trimestre | BB28: Total acheté | BD28: Achat de production | BE28: 1er trimestre | BF28: 2ème trimestre | BG28: 3ème trimestre | BH28: 4ème trimestre | BI28: Total acheté | BK28: Achat de production | BL28: 1er trimestre | BM28: 2ème trimestre | BN28: 3ème trimestre | BO28: 4ème trimestre | BP28: Total acheté | BR28: Achat de production | BS28: 1er trimestre | BT28: 2ème trimestre | BU28: 3ème trimestre | BV28: 4ème trimestre | BW28: Total acheté | BY28: Achat de production | BZ28: 1er trimestre | CA28: 2ème trimestre | CB28: 3ème trimestre | CC28: 4ème trimestre | CD28: Total acheté | CF28: Achat de production | CG28: 1er trimestre | CH28: 2ème trimestre | CI28: 3ème trimestre | CJ28: 4ème trimestre | CK28: Total acheté | CN28: Achat de production | CO28: 1er trimestre | CP28: 2ème trimestre | CQ28: 3ème trimestre | CR28: 4ème trimestre | CS28: Total acheté
