Workbook
Name EuroDollarRatio: #REF!
Name LempiraDollarFx: [1]Assumptions!$D$32
Name QuanzaDollarFx: #REF!
Name QuanzaFx: #REF!
Name Scenarios: #REF!
Name Tax: [1]Assumptions!$D$33
Name taxholiday: #REF!
Name Update: "1.8.18"
Name wacc: #REF!

Sheet Cover
C3: Cattle Integration, Baghara, Chad
C5: Financial Model
C9: Submitted to
C10: Mr. Amir Artine
C12: Last Update
C13: =TODAY() -> 45763
C26: Disclaimer:
C27: Except for statements of historical fact, information contained herein constitutes forward-looking statements. Such forward-looking statements necessarily involve known and unknown risks and uncertainties, which may cause actual performance and financial results in future periods to differ materially from any projections of future performance or result expressed or implied by such forward-looking statements.
C28: All rights reserved. No part of this financial model may be reproduced, distributed, or transmitted in any form or by any means, without the prior written permission of the publisher.

Sheet Data Input
B1: Company/Project: | C1: =Cover!$C$10 -> Mr. Amir Artine | D1: =Cover!$C$3 -> Cattle Integration, Baghara, Chad | G1: Last Update: | H1: =Cover!$C$13 -> 45763
B3: Operation - Annual Distribution (Before Inflation) | C3: 2018 | D3: 2019 | E3: 2020 | F3: 2021 | G3: 2022 | H3: 2023 | I3: 2024 | J3: 2025 | K3: 2026 | L3: 2027 | M3: 2028 | N3: 2029 | O3: 2030 | P3: 2031 | Q3: 2032 | R3: 2033 | S3: 2034 | T3: 2035 | U3: 2036 | V3: 2037
C4: 0 | D4: 1 | E4: 2 | F4: 3 | G4: 4 | H4: 5 | I4: 6 | J4: 7 | K4: 8 | L4: 9 | M4: 10 | N4: 11 | O4: 12 | P4: 13 | Q4: 14 | R4: 15 | S4: 16 | T4: 17 | U4: 18 | V4: 19
B5: Total Revenues | D5: =Revenues!C23 -> 9047287.3 | E5: =Revenues!D23 -> 16863223 | F5: =Revenues!E23 -> 19790786 | G5: =Revenues!F23 -> 22734686 | H5: =Revenues!G23 -> 27021648 | I5: =Revenues!H23 -> 31835737 | J5: =Revenues!I23 -> 34497379 | K5: =Revenues!J23 -> 35816607 | ... O5: =Revenues!N23 -> 37105101 | P5: =O5 -> 37105101 | Q5: =P5 -> 37105101 | R5: =Q5 -> 37105101 | S5: =R5 -> 37105101 | T5: =S5 -> 37105101 | U5: =T5 -> 37105101 | V5: =U5 -> 37105101
B6: Total Cost of Goods Sold (COGS) | D6: =OPEX!H110 -> 6987857.2 | E6: =OPEX!I110 -> 11350188 | F6: =OPEX!J110 -> 12096703 | G6: =OPEX!K110 -> 12620686 | H6: =OPEX!L110 -> 13489559 | I6: =OPEX!M110 -> 14246266 | J6: =OPEX!N110 -> 14487410 | K6: =OPEX!O110 -> 14616737 | ... O6: =OPEX!S110 -> 14702408 | P6: =O6 -> 14702408 | Q6: =P6 -> 14702408 | R6: =Q6 -> 14702408 | S6: =R6 -> 14702408 | T6: =S6 -> 14702408 | U6: =T6 -> 14702408 | V6: =U6 -> 14702408
B7: Total Sales, General & Administration (SG&A) | D7: =OPEX!H111 -> 2294976.8 | E7: =OPEX!I111 -> 2409450.5 | F7: =OPEX!J111 -> 2413590.9 | G7: =OPEX!K111 -> 2417969.5 | H7: =OPEX!L111 -> 2424097.1 | I7: =OPEX!M111 -> 2052614.8 | J7: =OPEX!N111 -> 2056397.7 | K7: =OPEX!O111 -> 2058277.3 | ... O7: =OPEX!S111 -> 2060090.5 | P7: =O7 -> 2060090.5 | Q7: =P7 -> 2060090.5 | R7: =Q7 -> 2060090.5 | S7: =R7 -> 2060090.5 | T7: =S7 -> 2060090.5 | U7: =T7 -> 2060090.5 | V7: =U7 -> 2060090.5
B10: CAPEX | D10: 2018 | E10: 2019 | F10: 2020 | G10: 2021 | H10: 2022
C11: Depreciation | D11: 0 | E11: 1 | F11: 2 | G11: 3 | H11: 4 | I11: Reinvestment*
B12: Establishment cost | C12: 20 | D12: =CAPEX!E249 -> 37124290 | E12: =CAPEX!F249 -> 13382679 | F12: =CAPEX!G249 -> 0 | G12: =CAPEX!H249 -> 0 | H12: =CAPEX!I249 -> 0 | I12: 0
B13: Total | D13: =SUM(D12:D12) -> 37124290 | E13: =SUM(E12:E12) -> 13382679 | F13: =SUM(F12:F12) -> 0 | G13: =SUM(G12:G12) -> 0 | H13: =SUM(H12:H12) -> 0
I14: * 1-Yes; 2-No
B16: Financial Assumptions
B17: Item | C17: Unit | D17: Amount | E17: Comments
B18: CAPEX Loan Terms
B19: Loan Interest Rate | C19: % | D19: 0.06
B20: Term | C20: Years | D20: 13
B21: Grace | C21: Years | D21: 3 | E21: Incl. Year 0
B22: Loan/Equity | C22: % Equity | D22: =Dashboard!C103 -> 0.33333333
B23: No. of Payments | C23: Payments/Year | D23: 4
B24: Interest During Construction (IDC) | C24: Yes/No | D24: 1 | E24: 1=Yes; 0=No
B25: Debt Service Reserve Account (DSRA) | C25: Yes/No | D25: 1 | E25: 1=Yes; 0=No
B26: Fees | C26: % CAPEX | D26: 0.02 | E26: Management/Commitment/Commission
B27: Working Capital Loan Terms
B28: Raise Working Capital? | C28: Yes/No | D28: 1 | E28: 1=Yes; 0=No
B29: Loan Interest Rate | C29: % | D29: 0.1
B30: Term | C30: Years | D30: 1
B31: Grace | C31: Years | D31: 0
B32: Loan/Equity | C32: % Equity | D32: 0
B33: Taxes
B34: Tax Holiday | C34: Years | D34: 5
B35: Corporate Tax | C35: % | D35: 0.35
B36: Financial Statement Assumptions
B37: Minimum Cash | C37: Currency | D37: 0
B38: Inflation Rate | C38: % | D38: 0.03
B39: Equity Interest Rate | C39: % | D39: 0.1
B40: WACC | C40: % | D40: =D39*D22+D19*(1-D35)*(1-D22) -> 0.059333333
B41: Terminal Growth Rate | C41: % | D41: 0.02
B42: Minimum Debt Service Coverage Ratio (DSCR) | C42: Ratio | D42: 1.2
B43: Working Capital Drivers
D44: 1 | E44: 2 | F44: 3 | G44: 4 | H44: 5 | I44: 6 | J44: 7 | K44: 8 | L44: 9 | M44: 10 | N44: 11 | O44: 12
...

Sheet Dashboard
B1: Company/Project: | C1: =Cover!$C$10 -> Mr. Amir Artine | D1: =Cover!$C$3 -> Cattle Integration, Baghara, Chad | G1: Last Update: | H1: =Cover!$C$13 -> 45763
B4: Main Financial Results
C5: Equity | D5: Firm
B6: NPV (20 Years; WACC) | C6: =Fin.Statements!C105/1000 -> 115391.96 | D6: =Fin.Statements!D105/1000 -> 97128.474
B7: IRR (20 Years) | C7: =Fin.Statements!C106 -> 0.2905722 | D7: =Fin.Statements!D106 -> 0.16573041
B8: Return Period | C8: =Fin.Statements!C107 -> 6.9 | D8: =Fin.Statements!D107 -> 8.6
B9: Discounted Return Period | C9: =Fin.Statements!C108 -> 7.5 | D9: =Fin.Statements!D108 -> 10.1
B10: Real Revenues (Year 12) | C10: ='Data Input'!O5/1000 -> 37105.101
B11: Real EBITDA (Year 12) | C11: =('Data Input'!O5-SUM('Data Input'!O6:O7))/1000 -> 20342.603
B12: % EBITDA | C12: =C11/C10 -> 0.54824275
B13: Total Capital Requirements | C13: =C23/1000 -> 54721.415
B14: ROI (Year 12) | C14: =Q43 -> 0.90716364
B17: Sources and Uses | AB17: Sources and Uses
B18: Item | C18: Amount | D18: % | E18: Year 0 | F18: Year 1 | G18: Year 2 | H18: Year 3 | I18: Year 4 | J18: Year 5 | K18: Year 6 | L18: Year 7 | M18: Year 8 | N18: Year 9 | O18: Year 10 | P18: Year 11 | Q18: Year 12 | R18: Year 13 | S18: Year 14 | T18: Year 15 | U18: Year 16 | V18: Year 17 | W18: Year 18 | X18: Year 19 | Y18: Year 20 | AB18: Item | AC18: Amount | AD18: % | AE18: Year 0 | AF18: Year 1 | AG18: Year 2 | AH18: Year 3 | AI18: Year 4
B19: Sources | AB19: Sources
B20: Establishment Equity | C20: =SUM(E20:Y20) -> 18240472 | D20: =C20/$C$23 -> 0.33333333 | E20: ='CAPEX Financing'!C18+'WC Financing'!C23 -> 13407347 | F20: ='CAPEX Financing'!D18+'WC Financing'!D23 -> 4833124.7 | G20: ='CAPEX Financing'!E18+'WC Financing'!E23 -> 2.718339e-138 | H20: ='CAPEX Financing'!F18+'WC Financing'!F23 -> 2.8769344e-138 | I20: ='CAPEX Financing'!G18+'WC Financing'!G23 -> 0 | J20: ='CAPEX Financing'!H18+'WC Financing'!H23 -> 0 | K20: ='CAPEX Financing'!I18+'WC Financing'!I23 -> 0 | L20: ='CAPEX Financing'!J18+'WC Financing'!J23 -> 0 | ... Y20: ='CAPEX Financing'!W18+'WC Financing'!W23 -> 0 | Z20: =ROUND(C20-SUM(E20:J20),0) -> 0 | AB20: Establishment Equity | AC20: =C20/1000 -> 18240.472 | AD20: =D20 -> 0.33333333 | AE20: =E20/1000 -> 13407.347 | AF20: =F20/1000 -> 4833.1247 | AG20: =G20/1000 -> 2.718339e-141 | AH20: =H20/1000 -> 2.8769344e-141 | AI20: =I20/1000 -> 0
B21: Establishment Loan (+ IDC, DSRA & Fees) | C21: =SUM(E21:Y21) -> 36480944 | D21: =C21/$C$23 -> 0.66666667 | E21: =SUM('CAPEX Financing'!C19:C20) -> 26814694 | F21: =SUM('CAPEX Financing'!D19:D20) -> 9666249.4 | G21: =SUM('CAPEX Financing'!E19:E20) -> 5.4366779e-138 | H21: =SUM('CAPEX Financing'!F19:F20) -> 5.7538687e-138 | I21: =SUM('CAPEX Financing'!G19:G20) -> 0 | J21: =SUM('CAPEX Financing'!H19:H20) -> 0 | K21: =SUM('CAPEX Financing'!I19:I20) -> 0 | L21: =SUM('CAPEX Financing'!J19:J20) -> 0 | ... Y21: =SUM('CAPEX Financing'!W19:W20) -> 0 | Z21: =ROUND(C21-SUM(E21:J21),0) -> 0 | AB21: Establishment Loan | AC21: =C21/1000 -> 36480.944 | AD21: =D21 -> 0.66666667 | AE21: =E21/1000 -> 26814.694 | AF21: =F21/1000 -> 9666.2494 | AG21: =G21/1000 -> 5.4366779e-141 | AH21: =H21/1000 -> 5.7538687e-141 | AI21: =I21/1000 -> 0
B22: Operations Loan | C22: =SUM(E22:Y22) -> 11975508 | D22: =C22/$C$23 -> 0.21884499 | E22: ='WC Financing'!C24 -> 0 | F22: =+'WC Financing'!D24 -> 5194550.7 | G22: =+'WC Financing'!E24 -> 3908927.2 | H22: =+'WC Financing'!F24 -> 2872029.9 | I22: =+'WC Financing'!G24 -> 0 | J22: =+'WC Financing'!H24 -> 0 | K22: =+'WC Financing'!I24 -> 0 | L22: =+'WC Financing'!J24 -> 0 | M22: =+'WC Financing'!K24 -> 0 | ... Y22: =+'WC Financing'!W24 -> 0 | AB22: Total Sources | AC22: =C23/1000 -> 54721.415 | AD22: =D23 -> 1 | AE22: =E23/1000 -> 40222.041 | AF22: =F23/1000 -> 14499.374 | AG22: =G23/1000 -> 8.1550169e-141 | AH22: =H23/1000 -> 8.6308031e-141 | AI22: =I23/1000 -> 0
B23: Total Sources | C23: =SUM(C20:C21) -> 54721415 | D23: =C23/$C$23 -> 1 | E23: =SUM(E20:E21) -> 40222041 | F23: =SUM(F20:F21) -> 14499374 | G23: =SUM(G20:G21) -> 8.1550169e-138 | H23: =SUM(H20:H21) -> 8.6308031e-138 | I23: =SUM(I20:I21) -> 0 | J23: =SUM(J20:J21) -> 0 | K23: =SUM(K20:K21) -> 0 | L23: =SUM(L20:L21) -> 0 | ... Y23: =SUM(Y20:Y21) -> 0 | Z23: =ROUND(C23-SUM(E23:J23),0) -> 0 | AB23: Uses
B24: Uses | Z24: =ROUND(C24-SUM(E24:J24),0) -> 0 | AB24: CAPEX | AC24: =C25/1000 -> 50506.97 | AD24: =D25 -> 0.92298361 | AE24: =E25/1000 -> 37124.29 | AF24: =F25/1000 -> 13382.679 | AG24: =G25/1000 -> 0 | AH24: =H25/1000 -> 0 | AI24: =I25/1000 -> 0
B25: CAPEX | C25: =SUM(E25:Y25) -> 50506970 | D25: =C25/$C$30 -> 0.92298361 | E25: ='CAPEX Financing'!C16 -> 37124290 | F25: ='CAPEX Financing'!D16 -> 13382679 | G25: ='CAPEX Financing'!E16 -> 0 | H25: ='CAPEX Financing'!F16 -> 0 | I25: ='CAPEX Financing'!G16 -> 0 | J25: ='CAPEX Financing'!H16 -> 0 | K25: ='CAPEX Financing'!I16 -> 0 | L25: ='CAPEX Financing'!J16 -> 0 | ... Y25: ='CAPEX Financing'!W16 -> 0 | Z25: =ROUND(C25-SUM(E25:J25),0) -> 0 | AB25: DSRA | AC25: =C26/1000 -> 1015.3948 | AD25: =D26 -> 0.018555712 | AE25: =E26/1000 -> 746.34689 | AF25: =F26/1000 -> 269.04796 | AG25: =G26/1000 -> 2.584198e-141 | AH25: =H26/1000 -> 2.7349672e-141 | AI25: =I26/1000 -> 0
B26: DSRA | C26: =SUM(E26:Y26) -> 1015394.8 | D26: =C26/$C$30 -> 0.018555712 | E26: ='CAPEX Financing'!C20 -> 746346.89 | F26: ='CAPEX Financing'!D20 -> 269047.96 | G26: ='CAPEX Financing'!E20 -> 2.584198e-138 | H26: ='CAPEX Financing'!F20 -> 2.7349672e-138 | I26: ='CAPEX Financing'!G20 -> 0 | J26: ='CAPEX Financing'!H20 -> 0 | K26: ='CAPEX Financing'!I20 -> 0 | L26: ='CAPEX Financing'!J20 -> 0 | ... Y26: ='CAPEX Financing'!W20 -> 0 | Z26: =ROUND(C26-SUM(E26:J26),0) -> 0 | AB26: Fees | AC26: =C27/1000 -> 1010.1394 | AD26: =D27 -> 0.018459672 | AE26: =E27/1000 -> 742.48581 | AF26: =F27/1000 -> 267.65359 | AG26: =G27/1000 -> 0 | AH26: =H27/1000 -> 0 | AI26: =I27/1000 -> 0
B27: Fees | C27: =SUM(E27:Y27) -> 1010139.4 | D27: =C27/$C$30 -> 0.018459672 | E27: ='CAPEX Financing'!$E$5 -> 742485.81 | F27: ='CAPEX Financing'!$E$6 -> 267653.59 | G27: ='CAPEX Financing'!$E$7 -> 0 | H27: ='CAPEX Financing'!$E$8 -> 0 | I27: ='CAPEX Financing'!$E$9 -> 0 | Z27: =ROUND(C27-SUM(E27:J27),0) -> 0 | AB27: IDC | AC27: =C28/1000 -> 2188.9116 | AD27: =D28 -> 0.040001004 | AE27: =E28/1000 -> 1608.9183 | AF27: =F28/1000 -> 579.99328 | AG27: =G28/1000 -> 5.5708189e-141 | AH27: =H28/1000 -> 5.8958359e-141 | AI27: =I28/1000 -> 0
B28: IDC | C28: =SUM(E28:Y28) -> 2188911.6 | D28: =C28/$C$30 -> 0.040001004 | E28: ='CAPEX Financing'!$F$5 -> 1608918.3 | F28: ='CAPEX Financing'!$F$6 -> 579993.28 | G28: ='CAPEX Financing'!$F$7 -> 5.5708189e-138 | H28: ='CAPEX Financing'!$F$8 -> 5.8958359e-138 | I28: ='CAPEX Financing'!$F$9 -> 0 | Z28: =ROUND(C28-SUM(E28:J28),0) -> 0 | AB28: Total Uses | AC28: =C30/1000 -> 54721.415 | AD28: =D30 -> 1 | AE28: =E30/1000 -> 40222.041 | AF28: =F30/1000 -> 14499.374 | AG28: =G30/1000 -> 8.1550169e-141 | AH28: =H30/1000 -> 8.6308031e-141 | AI28: =I30/1000 -> 0
B29: Operations | C29: =SUM(E29:Y29) -> 11975508 | D29: =C29/$C$30 -> 0.21884499 | E29: ='WC Financing'!C21 -> 0 | F29: ='WC Financing'!D21 -> 5194550.7 | G29: ='WC Financing'!E21 -> 3908927.2 | H29: ='WC Financing'!F21 -> 2872029.9 | I29: ='WC Financing'!G21 -> 0 | J29: ='WC Financing'!H21 -> 0 | K29: ='WC Financing'!I21 -> 0 | L29: ='WC Financing'!J21 -> 0 | ... Y29: ='WC Financing'!W21 -> 0 | Z29: =ROUND(C29-SUM(E29:J29),0) -> 0
B30: Total Uses | C30: =SUM(C25:C28) -> 54721415 | D30: =C30/$C$30 -> 1 | E30: =SUM(E25:E28) -> 40222041 | F30: =SUM(F25:F28) -> 14499374 | G30: =SUM(G25:G28) -> 8.1550169e-138 | H30: =SUM(H25:H28) -> 8.6308031e-138 | I30: =SUM(I25:I28) -> 0 | J30: =SUM(J25:J29) -> 0 | K30: =SUM(K25:K29) -> 0 | L30: =SUM(L25:L29) -> 0 | M30: =SUM(M25:M29) -> 0 | N30: =SUM(N25:N29) -> 0 | O30: =SUM(O25:O29) -> 0 | P30: =SUM(P25:P29) -> 0 | Q30: =SUM(Q25:Q29) -> 0 | ... Y30: =SUM(Y25:Y29) -> 0 | Z30: =ROUND(C30-SUM(E30:J30),0) -> 0
B31: Check | C31: =ROUND(C30-C23,0) -> 0 | D31: =ROUND(D30-D23,0) -> 0 | E31: =ROUND(E30-E23,0) -> 0 | F31: =ROUND(F30-F23,0) -> 0 | G31: =ROUND(G30-G23,0) -> 0 | H31: =ROUND(H30-H23,0) -> 0 | I31: =ROUND(I30-I23,0) -> 0 | J31: =ROUND(J30-J23,0) -> 0 | ... Y31: =ROUND(Y30-Y23,0) -> 0
B33: Financial Ratios
E34: 0 | F34: 1 | G34: 2 | H34: 3 | I34: 4 | J34: 5 | K34: 6 | L34: 7 | M34: 8 | N34: 9 | O34: 10 | P34: 11 | Q34: 12 | R34: 13 | S34: 14 | T34: 15 | U34: 16 | V34: 17 | W34: 18 | X34: 19 | Y34: 20
B35: Working Capital
B36: Working Capital | E36: =Fin.Statements!C77-Fin.Statements!C86 -> 36.632162 | F36: =Fin.Statements!D77-Fin.Statements!D86 -> -2363828.5 | G36: =Fin.Statements!E77-Fin.Statements!E86 -> -3674059.8 | H36: =Fin.Statements!F77-Fin.Statements!F86 -> -2909217.3 | I36: =Fin.Statements!G77-Fin.Statements!G86 -> 1028940 | J36: =Fin.Statements!H77-Fin.Statements!H86 -> 9339245.3 | K36: =Fin.Statements!I77-Fin.Statements!I86 -> 17319701 | L36: =Fin.Statements!J77-Fin.Statements!J86 -> 28513555 | ... Y36: =Fin.Statements!W77-Fin.Statements!W86 -> 2.6164273e+08
B37: Debt Service Coverage Ratio (DSCR)
B38: EBIDTA - TAX | E38: =Fin.Statements!C16+Fin.Statements!C13 -> 0 | F38: =Fin.Statements!D16+Fin.Statements!D13 -> -235546.73 | G38: =Fin.Statements!E16+Fin.Statements!E13 -> 3196691.7 | H38: =Fin.Statements!F16+Fin.Statements!F13 -> 5602074.4 | I38: =Fin.Statements!G16+Fin.Statements!G13 -> 8409660.6 | J38: =Fin.Statements!H16+Fin.Statements!H13 -> 12502142 | K38: =Fin.Statements!I16+Fin.Statements!I13 -> 12180292 | L38: =Fin.Statements!J16+Fin.Statements!J13 -> 15402180 | ... Y38: =Fin.Statements!W16+Fin.Statements!W13 -> 883871.97
B39: Total Debt Service | E39: =SUM('CAPEX Financing'!C23:C24)+SUM('WC Financing'!C28:C29) -> 1608881.6 | F39: =SUM('CAPEX Financing'!D23:D24)+SUM('WC Financing'!D28:D29) -> 2708311.7 | G39: =SUM('CAPEX Financing'!E23:E24)+SUM('WC Financing'!E28:E29) -> 8293755.1 | H39: =SUM('CAPEX Financing'!F23:F24)+SUM('WC Financing'!F28:F29) -> 8152317.4 | I39: =SUM('CAPEX Financing'!G23:G24)+SUM('WC Financing'!G28:G29) -> 7220710.3 | J39: =SUM('CAPEX Financing'!H23:H24)+SUM('WC Financing'!H28:H29) -> 4061477.4 | K39: =SUM('CAPEX Financing'!I23:I24)+SUM('WC Financing'!I28:I29) -> 4061477.4 | L39: =SUM('CAPEX Financing'!J23:J24)+SUM('WC Financing'!J28:J29) -> 4061477.4 | ... Y39: =SUM('CAPEX Financing'!W23:W24)+SUM('WC Financing'!W28:W29) -> 0
B40: DSCR | E40: =IF(E39<1,0,E38/E39) -> 0 | F40: =IF(F39<1,0,F38/F39) -> -0.086971796 | G40: =IF(G39<1,0,G38/G39) -> 0.38543358 | H40: =IF(H39<1,0,H38/H39) -> 0.6871757 | I40: =IF(I39<1,0,I38/I39) -> 1.1646584 | J40: =IF(J39<1,0,J38/J39) -> 3.0782253 | K40: =IF(K39<1,0,K38/K39) -> 2.9989807 | L40: =IF(L39<1,0,L38/L39) -> 3.7922605 | ... Y40: =IF(Y39<1,0,Y38/Y39) -> 0
B41: Minimum | E41: ='Data Input'!$D$42 -> 1.2 | F41: ='Data Input'!$D$42 -> 1.2 | G41: ='Data Input'!$D$42 -> 1.2 | H41: ='Data Input'!$D$42 -> 1.2 | I41: ='Data Input'!$D$42 -> 1.2 | J41: ='Data Input'!$D$42 -> 1.2 | K41: ='Data Input'!$D$42 -> 1.2 | L41: ='Data Input'!$D$42 -> 1.2 | ... Y41: ='Data Input'!$D$42 -> 1.2
B42: Financial Ratios
B43: ROI | E43: =(Fin.Statements!C15+SUM(Fin.Statements!$C$39:C39))/(-SUM(Fin.Statements!$C$39:C39)) -> -1.0433377 | F43: =(Fin.Statements!D15+SUM(Fin.Statements!$C$39:D39))/(-SUM(Fin.Statements!$C$39:D39)) -> -1.1268925 | G43: =(Fin.Statements!E15+SUM(Fin.Statements!$C$39:E39))/(-SUM(Fin.Statements!$C$39:E39)) -> -1.1749623 | H43: =(Fin.Statements!F15+SUM(Fin.Statements!$C$39:F39))/(-SUM(Fin.Statements!$C$39:F39)) -> -1.1701896 | I43: =(Fin.Statements!G15+SUM(Fin.Statements!$C$39:G39))/(-SUM(Fin.Statements!$C$39:G39)) -> -1.1001559 | J43: =(Fin.Statements!H15+SUM(Fin.Statements!$C$39:H39))/(-SUM(Fin.Statements!$C$39:H39)) -> -0.94097586 | K43: =(Fin.Statements!I15+SUM(Fin.Statements!$C$39:I39))/(-SUM(Fin.Statements!$C$39:I39)) -> -0.78558722 | L43: =(Fin.Statements!J15+SUM(Fin.Statements!$C$39:J39))/(-SUM(Fin.Statements!$C$39:J39)) -> -0.56366822 | ... Y43: =(Fin.Statements!W15+SUM(Fin.Statements!$C$39:W39))/(-SUM(Fin.Statements!$C$39:W39)) -> 3.5072794
B44: Operating Profit Margin (% EBITDA) | E44: =IFERROR(Fin.Statements!C16/Fin.Statements!C5,0) -> 0 | F44: =IFERROR(Fin.Statements!D16/Fin.Statements!D5,0) -> -0.026035067 | G44: =IFERROR(Fin.Statements!E16/Fin.Statements!E5,0) -> 0.18404455 | H44: =IFERROR(Fin.Statements!F16/Fin.Statements!F5,0) -> 0.2668157 | I44: =IFERROR(Fin.Statements!G16/Fin.Statements!G5,0) -> 0.33851494 | J44: =IFERROR(Fin.Statements!H16/Fin.Statements!H5,0) -> 0.41107751 | K44: =IFERROR(Fin.Statements!I16/Fin.Statements!I5,0) -> 0.48803194 | L44: =IFERROR(Fin.Statements!J16/Fin.Statements!J5,0) -> 0.52043292 | ... Y44: =IFERROR(Fin.Statements!W16/Fin.Statements!W5,0) -> 0
B45: Net Profit Margin | E45: =IFERROR(Fin.Statements!C14/Fin.Statements!C5,0) -> 0 | F45: =IFERROR(Fin.Statements!D14/Fin.Statements!D5,0) -> -0.53055383 | G45: =IFERROR(Fin.Statements!E14/Fin.Statements!E5,0) -> -0.13978032 | H45: =IFERROR(Fin.Statements!F14/Fin.Statements!F5,0) -> 0.01148094 | I45: =IFERROR(Fin.Statements!G14/Fin.Statements!G5,0) -> 0.14238296 | J45: =IFERROR(Fin.Statements!H14/Fin.Statements!H5,0) -> 0.26434987 | K45: =IFERROR(Fin.Statements!I14/Fin.Statements!I5,0) -> 0.21265203 | L45: =IFERROR(Fin.Statements!J14/Fin.Statements!J5,0) -> 0.2721049 | ... Y45: =IFERROR(Fin.Statements!W14/Fin.Statements!W5,0) -> 0
...

Sheet Fin.Statements
B1: Company/Project: | C1: =Cover!$C$10 -> Mr. Amir Artine | G1: Last Update: | H1: =Cover!$C$13 -> 45763
B3: Income Statement | Z3: Income Statement
C4: 0 | D4: 1 | E4: 2 | F4: 3 | G4: 4 | H4: 5 | I4: 6 | J4: 7 | K4: 8 | L4: 9 | M4: 10 | N4: 11 | O4: 12 | P4: 13 | Q4: 14 | R4: 15 | S4: 16 | T4: 17 | U4: 18 | V4: 19 | W4: 20 | AA4: 0 | AB4: 1 | AC4: 2 | AD4: 3 | AE4: 4 | AF4: 5 | AG4: 6 | AH4: 7 | AI4: 8 | AJ4: 9 | AK4: 10 | AL4: 11 | AM4: 12 | AN4: 13 | AO4: 14 | AP4: 15 | AQ4: 16 | AR4: 17 | AS4: 18 | AT4: 19 | AU4: 20
B5: Revenues | C5: ='Data Input'!C5*(1+'Data Input'!$D$38)^(C$4-1)*Dashboard!$C$100 -> 0 | D5: ='Data Input'!D5*(1+'Data Input'!$D$38)^(D$4-1)*Dashboard!$C$100 -> 9047287.3 | E5: ='Data Input'!E5*(1+'Data Input'!$D$38)^(E$4-1)*Dashboard!$C$100 -> 17369120 | F5: ='Data Input'!F5*(1+'Data Input'!$D$38)^(F$4-1)*Dashboard!$C$100 -> 20996045 | G5: ='Data Input'!G5*(1+'Data Input'!$D$38)^(G$4-1)*Dashboard!$C$100 -> 24842805 | H5: ='Data Input'!H5*(1+'Data Input'!$D$38)^(H$4-1)*Dashboard!$C$100 -> 30413102 | I5: ='Data Input'!I5*(1+'Data Input'!$D$38)^(I$4-1)*Dashboard!$C$100 -> 36906345 | J5: ='Data Input'!J5*(1+'Data Input'!$D$38)^(J$4-1)*Dashboard!$C$100 -> 41191674 | ... W5: ='Data Input'!W5*(1+'Data Input'!$D$38)^(W$4-1)*Dashboard!$C$100 -> 0 | Z5: Revenues | AA5: =C5/1000 -> 0 | AB5: =D5/1000 -> 9047.2873 | AC5: =E5/1000 -> 17369.12 | AD5: =F5/1000 -> 20996.045 | AE5: =G5/1000 -> 24842.805 | AF5: =H5/1000 -> 30413.102 | AG5: =I5/1000 -> 36906.345 | AH5: =J5/1000 -> 41191.674 | ... AU5: =W5/1000 -> 0
B6: COGS | C6: =-'Data Input'!C6*(1+'Data Input'!$D$38)^(C$4-1)*Dashboard!$C$101 -> 0 | D6: =-'Data Input'!D6*(1+'Data Input'!$D$38)^(D$4-1)*Dashboard!$C$101 -> -6987857.2 | E6: =-'Data Input'!E6*(1+'Data Input'!$D$38)^(E$4-1)*Dashboard!$C$101 -> -11690694 | F6: =-'Data Input'!F6*(1+'Data Input'!$D$38)^(F$4-1)*Dashboard!$C$101 -> -12833392 | G6: =-'Data Input'!G6*(1+'Data Input'!$D$38)^(G$4-1)*Dashboard!$C$101 -> -13790964 | H6: =-'Data Input'!H6*(1+'Data Input'!$D$38)^(H$4-1)*Dashboard!$C$101 -> -15182617 | I6: =-'Data Input'!I6*(1+'Data Input'!$D$38)^(I$4-1)*Dashboard!$C$101 -> -16515326 | J6: =-'Data Input'!J6*(1+'Data Input'!$D$38)^(J$4-1)*Dashboard!$C$101 -> -17298725 | ... W6: =-'Data Input'!W6*(1+'Data Input'!$D$38)^(W$4-1)*Dashboard!$C$101 -> 0 | Z6: COGS | AA6: =C6/1000 -> 0 | AB6: =D6/1000 -> -6987.8572 | AC6: =E6/1000 -> -11690.694 | AD6: =F6/1000 -> -12833.392 | AE6: =G6/1000 -> -13790.964 | AF6: =H6/1000 -> -15182.617 | AG6: =I6/1000 -> -16515.326 | AH6: =J6/1000 -> -17298.725 | ... AU6: =W6/1000 -> 0
B7: Gross Profit | C7: =SUM(C5:C6) -> 0 | D7: =SUM(D5:D6) -> 2059430.1 | E7: =SUM(E5:E6) -> 5678425.8 | F7: =SUM(F5:F6) -> 8162653 | G7: =SUM(G5:G6) -> 11051841 | H7: =SUM(H5:H6) -> 15230485 | I7: =SUM(I5:I6) -> 20391018 | J7: =SUM(J5:J6) -> 23892950 | ... W7: =SUM(W5:W6) -> 0 | Z7: Gross Profit | AA7: =C7/1000 -> 0 | AB7: =D7/1000 -> 2059.4301 | AC7: =E7/1000 -> 5678.4258 | AD7: =F7/1000 -> 8162.653 | AE7: =G7/1000 -> 11051.841 | AF7: =H7/1000 -> 15230.485 | AG7: =I7/1000 -> 20391.018 | AH7: =J7/1000 -> 23892.95 | ... AU7: =W7/1000 -> 0
B8: SG&A | C8: =-'Data Input'!C7*(1+'Data Input'!$D$38)^(C$4-1)*Dashboard!$C$101 -> 0 | D8: =-'Data Input'!D7*(1+'Data Input'!$D$38)^(D$4-1)*Dashboard!$C$101 -> -2294976.8 | E8: =-'Data Input'!E7*(1+'Data Input'!$D$38)^(E$4-1)*Dashboard!$C$101 -> -2481734 | F8: =-'Data Input'!F7*(1+'Data Input'!$D$38)^(F$4-1)*Dashboard!$C$101 -> -2560578.6 | G8: =-'Data Input'!G7*(1+'Data Input'!$D$38)^(G$4-1)*Dashboard!$C$101 -> -2642180.6 | H8: =-'Data Input'!H7*(1+'Data Input'!$D$38)^(H$4-1)*Dashboard!$C$101 -> -2728342.6 | I8: =-'Data Input'!I7*(1+'Data Input'!$D$38)^(I$4-1)*Dashboard!$C$101 -> -2379543.2 | J8: =-'Data Input'!J7*(1+'Data Input'!$D$38)^(J$4-1)*Dashboard!$C$101 -> -2455446.4 | ... W8: =-'Data Input'!W7*(1+'Data Input'!$D$38)^(W$4-1)*Dashboard!$C$101 -> 0 | Z8: SG&A | AA8: =C8/1000 -> 0 | AB8: =D8/1000 -> -2294.9768 | AC8: =E8/1000 -> -2481.734 | AD8: =F8/1000 -> -2560.5786 | AE8: =G8/1000 -> -2642.1806 | AF8: =H8/1000 -> -2728.3426 | AG8: =I8/1000 -> -2379.5432 | AH8: =J8/1000 -> -2455.4464 | ... AU8: =W8/1000 -> 0
B9: Depreciation | D9: =-Depreciation!D29 -> -1856214.5 | E9: =-Depreciation!E29 -> -2525348.5 | F9: =-Depreciation!F29 -> -2525348.5 | G9: =-Depreciation!G29 -> -2525348.5 | H9: =-Depreciation!H29 -> -2525348.5 | I9: =-Depreciation!I29 -> -2525348.5 | J9: =-Depreciation!J29 -> -2525348.5 | K9: =-Depreciation!K29 -> -2525348.5 | ... W9: =-Depreciation!W29 -> -2525348.5 | Z9: Depreciation | AA9: =C9/1000 -> 0 | AB9: =D9/1000 -> -1856.2145 | AC9: =E9/1000 -> -2525.3485 | AD9: =F9/1000 -> -2525.3485 | AE9: =G9/1000 -> -2525.3485 | AF9: =H9/1000 -> -2525.3485 | AG9: =I9/1000 -> -2525.3485 | AH9: =J9/1000 -> -2525.3485 | ... AU9: =W9/1000 -> -2525.3485
B10: Operating Profit | C10: =SUM(C7:C9) -> 0 | D10: =SUM(D7:D9) -> -2091761.2 | E10: =SUM(E7:E9) -> 671343.26 | F10: =SUM(F7:F9) -> 3076725.9 | G10: =SUM(G7:G9) -> 5884312.1 | H10: =SUM(H7:H9) -> 9976794 | I10: =SUM(I7:I9) -> 15486127 | J10: =SUM(J7:J9) -> 18912155 | ... W10: =SUM(W7:W9) -> -2525348.5 | Z10: Operating Profit | AA10: =C10/1000 -> 0 | AB10: =D10/1000 -> -2091.7612 | AC10: =E10/1000 -> 671.34326 | AD10: =F10/1000 -> 3076.7259 | AE10: =G10/1000 -> 5884.3121 | AF10: =H10/1000 -> 9976.794 | AG10: =I10/1000 -> 15486.127 | AH10: =J10/1000 -> 18912.155 | ... AU10: =W10/1000 -> -2525.3485
B11: Interest Payments | C11: =-'CAPEX Financing'!C23-'WC Financing'!C28 -> -1608881.6 | D11: =-'CAPEX Financing'!D23-'WC Financing'!D28 -> -2708311.7 | E11: =-'CAPEX Financing'!E23-'WC Financing'!E28 -> -3099204.4 | F11: =-'CAPEX Financing'!F23-'WC Financing'!F28 -> -2835671.6 | G11: =-'CAPEX Financing'!G23-'WC Financing'!G28 -> -2347120.1 | H11: =-'CAPEX Financing'!H23-'WC Financing'!H28 -> -1937094.3 | I11: =-'CAPEX Financing'!I23-'WC Financing'!I28 -> -1806734.6 | J11: =-'CAPEX Financing'!J23-'WC Financing'!J28 -> -1668375.5 | ... W11: =-'CAPEX Financing'!W23-'WC Financing'!W28 -> 0 | Z11: Interest Payments | AA11: =C11/1000 -> -1608.8816 | AB11: =D11/1000 -> -2708.3117 | AC11: =E11/1000 -> -3099.2044 | AD11: =F11/1000 -> -2835.6716 | AE11: =G11/1000 -> -2347.1201 | AF11: =H11/1000 -> -1937.0943 | AG11: =I11/1000 -> -1806.7346 | AH11: =J11/1000 -> -1668.3755 | ... AU11: =W11/1000 -> 0
B12: Profit Before Tax | C12: =SUM(C10:C11) -> -1608881.6 | D12: =SUM(D10:D11) -> -4800072.9 | E12: =SUM(E10:E11) -> -2427861.1 | F12: =SUM(F10:F11) -> 241054.33 | G12: =SUM(G10:G11) -> 3537192 | H12: =SUM(H10:H11) -> 8039699.7 | I12: =SUM(I10:I11) -> 13679392 | J12: =SUM(J10:J11) -> 17243779 | ... W12: =SUM(W10:W11) -> -2525348.5 | Z12: Profit Before Tax | AA12: =C12/1000 -> -1608.8816 | AB12: =D12/1000 -> -4800.0729 | AC12: =E12/1000 -> -2427.8611 | AD12: =F12/1000 -> 241.05433 | AE12: =G12/1000 -> 3537.192 | AF12: =H12/1000 -> 8039.6997 | AG12: =I12/1000 -> 13679.392 | AH12: =J12/1000 -> 17243.779 | ... AU12: =W12/1000 -> -2525.3485
B13: Tax | C13: =-IF(C4>'Data Input'!$D$34,IF(SUM($C12:C$12)>0,(SUM($C12:C$12)*'Data Input'!$D$35+SUM(B13:$C$13)),0),0) -> 0 | D13: =-IF(D4>'Data Input'!$D$34,IF(SUM($C12:D$12)>0,(SUM($C12:D$12)*'Data Input'!$D$35+SUM(C13:$C$13)),0),0) -> 0 | E13: =-IF(E4>'Data Input'!$D$34,IF(SUM($C12:E$12)>0,(SUM($C12:E$12)*'Data Input'!$D$35+SUM($C13:D$13)),0),0) -> 0 | F13: =-IF(F4>'Data Input'!$D$34,IF(SUM($C12:F$12)>0,(SUM($C12:F$12)*'Data Input'!$D$35+SUM($C13:E$13)),0),0) -> 0 | G13: =-IF(G4>'Data Input'!$D$34,IF(SUM($C12:G$12)>0,(SUM($C12:G$12)*'Data Input'!$D$35+SUM($C13:F$13)),0),0) -> 0 | H13: =-IF(H4>'Data Input'!$D$34,IF(SUM($C12:H$12)>0,(SUM($C12:H$12)*'Data Input'!$D$35+SUM($C13:G$13)),0),0) -> 0 | I13: =-IF(I4>'Data Input'!$D$34,IF(SUM($C12:I$12)>0,(SUM($C12:I$12)*'Data Input'!$D$35+SUM($C13:H$13)),0),0) -> -5831182.8 | J13: =-IF(J4>'Data Input'!$D$34,IF(SUM($C12:J$12)>0,(SUM($C12:J$12)*'Data Input'!$D$35+SUM($C13:I$13)),0),0) -> -6035322.7 | K13: =-IF(K4>'Data Input'!$D$34,IF(SUM($C12:K$12)>0,(SUM($C12:K$12)*'Data Input'!$D$35+SUM($C13:J$13)),0),0) -> -6823204.6 | L13: =-IF(L4>'Data Input'!$D$34,IF(SUM($C12:L$12)>0,(SUM($C12:L$12)*'Data Input'!$D$35+SUM($C13:K$13)),0),0) -> -7650132.3 | ... W13: =-IF(W4>'Data Input'!$D$34,IF(SUM($C12:W$12)>0,(SUM($C12:W$12)*'Data Input'!$D$35+SUM($C13:V$13)),0),0) -> 883871.97 | Z13: Tax | AA13: =C13/1000 -> 0 | AB13: =D13/1000 -> 0 | AC13: =E13/1000 -> 0 | AD13: =F13/1000 -> 0 | AE13: =G13/1000 -> 0 | AF13: =H13/1000 -> 0 | AG13: =I13/1000 -> -5831.1828 | AH13: =J13/1000 -> -6035.3227 | ... AU13: =W13/1000 -> 883.87197
B14: Net Operating Profit After Tax | C14: =SUM(C12:C13) -> -1608881.6 | D14: =SUM(D12:D13) -> -4800072.9 | E14: =SUM(E12:E13) -> -2427861.1 | F14: =SUM(F12:F13) -> 241054.33 | G14: =SUM(G12:G13) -> 3537192 | H14: =SUM(H12:H13) -> 8039699.7 | I14: =SUM(I12:I13) -> 7848209.3 | J14: =SUM(J12:J13) -> 11208456 | ... W14: =SUM(W12:W13) -> -1641476.5 | Z14: Net Operating Profit After Tax | AA14: =C14/1000 -> -1608.8816 | AB14: =D14/1000 -> -4800.0729 | AC14: =E14/1000 -> -2427.8611 | AD14: =F14/1000 -> 241.05433 | AE14: =G14/1000 -> 3537.192 | AF14: =H14/1000 -> 8039.6997 | AG14: =I14/1000 -> 7848.2093 | AH14: =J14/1000 -> 11208.456 | ... AU14: =W14/1000 -> -1641.4765
B15: Net Accumulated Profit After Tax | C15: =C14 -> -1608881.6 | D15: =D14+C15 -> -6408954.6 | E15: =E14+D15 -> -8836815.7 | F15: =F14+E15 -> -8595761.4 | G15: =G14+F15 -> -5058569.4 | H15: =H14+G15 -> 2981130.3 | I15: =I14+H15 -> 10829340 | J15: =J14+I15 -> 22037796 | K15: =K14+J15 -> 34709462 | ... W15: =W14+V15 -> 2.2764902e+08 | Z15: Net Accumulated Profit | AA15: =C15/1000 -> -1608.8816 | AB15: =D15/1000 -> -6408.9546 | AC15: =E15/1000 -> -8836.8157 | AD15: =F15/1000 -> -8595.7614 | AE15: =G15/1000 -> -5058.5694 | AF15: =H15/1000 -> 2981.1303 | AG15: =I15/1000 -> 10829.34 | AH15: =J15/1000 -> 22037.796 | ... AU15: =W15/1000 -> 227649.02
B16: EBITDA | C16: =C10-C9 -> 0 | D16: =D10-D9 -> -235546.73 | E16: =E10-E9 -> 3196691.7 | F16: =F10-F9 -> 5602074.4 | G16: =G10-G9 -> 8409660.6 | H16: =H10-H9 -> 12502142 | I16: =I10-I9 -> 18011475 | J16: =J10-J9 -> 21437503 | ... W16: =W10-W9 -> 0 | Z16: EBITDA | AA16: =C16/1000 -> 0 | AB16: =D16/1000 -> -235.54673 | AC16: =E16/1000 -> 3196.6917 | AD16: =F16/1000 -> 5602.0744 | AE16: =G16/1000 -> 8409.6606 | AF16: =H16/1000 -> 12502.142 | AG16: =I16/1000 -> 18011.475 | AH16: =J16/1000 -> 21437.503 | ... AU16: =W16/1000 -> 0
B17: EBITDA Margin | C17: =IFERROR(C16/C5,"-") -> - | D17: =IFERROR(D16/D5,"-") -> -0.026035067 | E17: =IFERROR(E16/E5,"-") -> 0.18404455 | F17: =IFERROR(F16/F5,"-") -> 0.2668157 | G17: =IFERROR(G16/G5,"-") -> 0.33851494 | H17: =IFERROR(H16/H5,"-") -> 0.41107751 | I17: =IFERROR(I16/I5,"-") -> 0.48803194 | J17: =IFERROR(J16/J5,"-") -> 0.52043292 | ... W17: =IFERROR(W16/W5,"-") -> - | Z17: EBITDA Margin | AA17: =C17 -> - | AB17: =D17 -> -0.026035067 | AC17: =E17 -> 0.18404455 | AD17: =F17 -> 0.2668157 | AE17: =G17 -> 0.33851494 | AF17: =H17 -> 0.41107751 | AG17: =I17 -> 0.48803194 | AH17: =J17 -> 0.52043292 | ... AU17: =W17 -> -
B20: Cash Flow | Z20: Cash Flow
C21: 0 | D21: 1 | E21: 2 | F21: 3 | G21: 4 | H21: 5 | I21: 6 | J21: 7 | K21: 8 | L21: 9 | M21: 10 | N21: 11 | O21: 12 | P21: 13 | Q21: 14 | R21: 15 | S21: 16 | T21: 17 | U21: 18 | V21: 19 | W21: 20 | AA21: 0 | AB21: 1 | AC21: 2 | AD21: 3 | AE21: 4 | AF21: 5 | AG21: 6 | AH21: 7 | AI21: 8 | AJ21: 9 | AK21: 10 | AL21: 11 | AM21: 12 | AN21: 13 | AO21: 14 | AP21: 15 | AQ21: 16 | AR21: 17 | AS21: 18 | AT21: 19 | AU21: 20
B22: Operating Activities | Z22: Operating Activities
B23: Net Operating Profit after Tax | C23: =C14 -> -1608881.6 | D23: =D14 -> -4800072.9 | E23: =E14 -> -2427861.1 | F23: =F14 -> 241054.33 | G23: =G14 -> 3537192 | H23: =H14 -> 8039699.7 | I23: =I14 -> 7848209.3 | J23: =J14 -> 11208456 | ... W23: =W14 -> -1641476.5 | Z23: Net Operating Profit after Tax | AA23: =C23/1000 -> -1608.8816 | AB23: =D23/1000 -> -4800.0729 | AC23: =E23/1000 -> -2427.8611 | AD23: =F23/1000 -> 241.05433 | AE23: =G23/1000 -> 3537.192 | AF23: =H23/1000 -> 8039.6997 | AG23: =I23/1000 -> 7848.2093 | AH23: =J23/1000 -> 11208.456 | ... AU23: =W23/1000 -> -1641.4765
B24: Depreciation | C24: =-C9 -> 0 | D24: =-D9 -> 1856214.5 | E24: =-E9 -> 2525348.5 | F24: =-F9 -> 2525348.5 | G24: =-G9 -> 2525348.5 | H24: =-H9 -> 2525348.5 | I24: =-I9 -> 2525348.5 | J24: =-J9 -> 2525348.5 | ... W24: =-W9 -> 2525348.5 | Z24: Depreciation | AA24: =C24/1000 -> 0 | AB24: =D24/1000 -> 1856.2145 | AC24: =E24/1000 -> 2525.3485 | AD24: =F24/1000 -> 2525.3485 | AE24: =G24/1000 -> 2525.3485 | AF24: =H24/1000 -> 2525.3485 | AG24: =I24/1000 -> 2525.3485 | AH24: =J24/1000 -> 2525.3485 | ... AU24: =W24/1000 -> 2525.3485
B25: Increase in inventory | D25: =C75-D75 -> -698785.72 | E25: =D75-E75 -> -470283.66 | F25: =E75-F75 -> -114269.81 | G25: =F75-G75 -> -95757.193 | H25: =G75-H75 -> -139165.35 | I25: =H75-I75 -> -133270.91 | J25: =I75-J75 -> -78339.817 | K25: =J75-K75 -> -67801.813 | ... W25: =V75-W75 -> 2502986.6 | Z25: Increase in inventory | AA25: =C25/1000 -> 0 | AB25: =D25/1000 -> -698.78572 | AC25: =E25/1000 -> -470.28366 | AD25: =F25/1000 -> -114.26981 | AE25: =G25/1000 -> -95.757193 | AF25: =H25/1000 -> -139.16535 | AG25: =I25/1000 -> -133.27091 | AH25: =J25/1000 -> -78.339817 | ... AU25: =W25/1000 -> 2502.9866
B26: Increase in accounts receivable | D26: =C76-D76 -> -2714186.2 | E26: =D76-E76 -> 1266759.5 | F26: =E76-F76 -> -302243.77 | G26: =F76-G76 -> -320563.34 | H26: =G76-H76 -> -464191.45 | I26: =H76-I76 -> -541103.53 | J26: =I76-J76 -> -357110.79 | K26: =J76-K76 -> -238186.25 | ... W26: =V76-W76 -> 5264079.3 | Z26: Increase in accounts receivable | AA26: =C26/1000 -> 0 | AB26: =D26/1000 -> -2714.1862 | AC26: =E26/1000 -> 1266.7595 | AD26: =F26/1000 -> -302.24377 | AE26: =G26/1000 -> -320.56334 | AF26: =H26/1000 -> -464.19145 | AG26: =I26/1000 -> -541.10353 | AH26: =J26/1000 -> -357.11079 | ... AU26: =W26/1000 -> 5264.0793
B27: Increase in accounts payable | D27: =D84-C84 -> 582321.43 | E27: =E84-D84 -> 391903.05 | F27: =F84-E84 -> 95224.839 | G27: =G84-F84 -> 79797.661 | H27: =H84-G84 -> 115971.13 | I27: =I84-H84 -> 111059.09 | J27: =J84-I84 -> 65283.181 | K27: =K84-J84 -> 56501.51 | ... W27: =W84-V84 -> -2085822.2 | Z27: Increase in accounts payable | AA27: =C27/1000 -> 0 | AB27: =D27/1000 -> 582.32143 | AC27: =E27/1000 -> 391.90305 | AD27: =F27/1000 -> 95.224839 | AE27: =G27/1000 -> 79.797661 | AF27: =H27/1000 -> 115.97113 | AG27: =I27/1000 -> 111.05909 | AH27: =J27/1000 -> 65.283181 | ... AU27: =W27/1000 -> -2085.8222
B28: Cash Flow From Operations | C28: =SUM(C23:C27) -> -1608881.6 | D28: =SUM(D23:D27) -> -5774508.9 | E28: =SUM(E23:E27) -> 1285866.3 | F28: =SUM(F23:F27) -> 2445114.1 | G28: =SUM(G23:G27) -> 5726017.6 | H28: =SUM(H23:H27) -> 10077662 | I28: =SUM(I23:I27) -> 9810242.4 | J28: =SUM(J23:J27) -> 13363638 | ... W28: =SUM(W23:W27) -> 6565115.7 | Z28: Cash Flow From Operations | AA28: =C28/1000 -> -1608.8816 | AB28: =D28/1000 -> -5774.5089 | AC28: =E28/1000 -> 1285.8663 | AD28: =F28/1000 -> 2445.1141 | AE28: =G28/1000 -> 5726.0176 | AF28: =H28/1000 -> 10077.662 | AG28: =I28/1000 -> 9810.2424 | AH28: =J28/1000 -> 13363.638 | ... AU28: =W28/1000 -> 6565.1157
B29: Financing Activities | Z29: Financing Activities
B30: Equity | C30: ='CAPEX Financing'!C18+'WC Financing'!C23 -> 13407347 | D30: ='CAPEX Financing'!D18+'WC Financing'!D23 -> 4833124.7 | E30: ='CAPEX Financing'!E18+'WC Financing'!E23 -> 2.718339e-138 | F30: ='CAPEX Financing'!F18+'WC Financing'!F23 -> 2.8769344e-138 | G30: ='CAPEX Financing'!G18+'WC Financing'!G23 -> 0 | H30: ='CAPEX Financing'!H18+'WC Financing'!H23 -> 0 | I30: ='CAPEX Financing'!I18+'WC Financing'!I23 -> 0 | J30: ='CAPEX Financing'!J18+'WC Financing'!J23 -> 0 | ... W30: ='CAPEX Financing'!W18+'WC Financing'!W23 -> 0 | Z30: Equity | AA30: =C30/1000 -> 13407.347 | AB30: =D30/1000 -> 4833.1247 | AC30: =E30/1000 -> 2.718339e-141 | AD30: =F30/1000 -> 2.8769344e-141 | AE30: =G30/1000 -> 0 | AF30: =H30/1000 -> 0 | AG30: =I30/1000 -> 0 | AH30: =J30/1000 -> 0 | ... AU30: =W30/1000 -> 0
B31: Loans Received | C31: ='CAPEX Financing'!C19+'WC Financing'!C24 -> 26068347 | D31: ='CAPEX Financing'!D19+'WC Financing'!D24 -> 14591752 | E31: ='CAPEX Financing'!E19+'WC Financing'!E24 -> 3908927.2 | F31: ='CAPEX Financing'!F19+'WC Financing'!F24 -> 2872029.9 | G31: ='CAPEX Financing'!G19+'WC Financing'!G24 -> 0 | H31: ='CAPEX Financing'!H19+'WC Financing'!H24 -> 0 | I31: ='CAPEX Financing'!I19+'WC Financing'!I24 -> 0 | J31: ='CAPEX Financing'!J19+'WC Financing'!J24 -> 0 | ... W31: ='CAPEX Financing'!W19+'WC Financing'!W24 -> 0 | Z31: Loans Received | AA31: =C31/1000 -> 26068.347 | AB31: =D31/1000 -> 14591.752 | AC31: =E31/1000 -> 3908.9272 | AD31: =F31/1000 -> 2872.0299 | AE31: =G31/1000 -> 0 | AF31: =H31/1000 -> 0 | AG31: =I31/1000 -> 0 | AH31: =J31/1000 -> 0 | ... AU31: =W31/1000 -> 0
B32: Principal Payments | C32: =-'CAPEX Financing'!C24-'WC Financing'!C29 -> 0 | D32: =-'CAPEX Financing'!D24-'WC Financing'!D29 -> 0 | E32: =-'CAPEX Financing'!E24-'WC Financing'!E29 -> -5194550.7 | F32: =-'CAPEX Financing'!F24-'WC Financing'!F29 -> -5316645.8 | G32: =-'CAPEX Financing'!G24-'WC Financing'!G29 -> -4873590.2 | H32: =-'CAPEX Financing'!H24-'WC Financing'!H29 -> -2124383.2 | I32: =-'CAPEX Financing'!I24-'WC Financing'!I29 -> -2254742.9 | J32: =-'CAPEX Financing'!J24-'WC Financing'!J29 -> -2393101.9 | ... W32: =-'CAPEX Financing'!W24-'WC Financing'!W29 -> 0 | Z32: Principal Payments | AA32: =C32/1000 -> 0 | AB32: =D32/1000 -> 0 | AC32: =E32/1000 -> -5194.5507 | AD32: =F32/1000 -> -5316.6458 | AE32: =G32/1000 -> -4873.5902 | AF32: =H32/1000 -> -2124.3832 | AG32: =I32/1000 -> -2254.7429 | AH32: =J32/1000 -> -2393.1019 | ... AU32: =W32/1000 -> 0
B33: Fees | C33: =-'CAPEX Financing'!E5 -> -742485.81 | D33: =-'CAPEX Financing'!E6 -> -267653.59 | E33: =-'CAPEX Financing'!E7 -> 0 | F33: =-'CAPEX Financing'!E8 -> 0 | G33: =-'CAPEX Financing'!E9 -> 0 | Z33: Fees | AA33: =C33/1000 -> -742.48581 | AB33: =D33/1000 -> -267.65359 | AC33: =E33/1000 -> 0 | AD33: =F33/1000 -> 0 | AE33: =G33/1000 -> 0 | AF33: =H33/1000 -> 0 | AG33: =I33/1000 -> 0 | AH33: =J33/1000 -> 0 | ... AU33: =W33/1000 -> 0
B34: DSRA | C34: ='CAPEX Financing'!C20+'CAPEX Financing'!C21 -> 746346.89 | D34: ='CAPEX Financing'!D20+'CAPEX Financing'!D21 -> 269047.96 | E34: ='CAPEX Financing'!E20+'CAPEX Financing'!E21 -> 2.584198e-138 | F34: ='CAPEX Financing'!F20+'CAPEX Financing'!F21 -> 2.7349672e-138 | G34: ='CAPEX Financing'!G20+'CAPEX Financing'!G21 -> 0 | H34: ='CAPEX Financing'!H20+'CAPEX Financing'!H21 -> 0 | I34: ='CAPEX Financing'!I20+'CAPEX Financing'!I21 -> 0 | J34: ='CAPEX Financing'!J20+'CAPEX Financing'!J21 -> 0 | ... W34: ='CAPEX Financing'!W20+'CAPEX Financing'!W21 -> 0 | Z34: DSRA | AA34: =C34/1000 -> 746.34689 | AB34: =D34/1000 -> 269.04796 | AC34: =E34/1000 -> 2.584198e-141 | AD34: =F34/1000 -> 2.7349672e-141 | AE34: =G34/1000 -> 0 | AF34: =H34/1000 -> 0 | AG34: =I34/1000 -> 0 | AH34: =J34/1000 -> 0 | ... AU34: =W34/1000 -> 0
B35: Cash Flow from Financing | C35: =SUM(C30:C34) -> 39479555 | D35: =SUM(D30:D34) -> 19426271 | E35: =SUM(E30:E34) -> -1285623.5 | F35: =SUM(F30:F34) -> -2444616 | G35: =SUM(G30:G34) -> -4873590.2 | H35: =SUM(H30:H34) -> -2124383.2 | I35: =SUM(I30:I34) -> -2254742.9 | J35: =SUM(J30:J34) -> -2393101.9 | ... W35: =SUM(W30:W34) -> 0 | Z35: Cash Flow from Financing | AA35: =C35/1000 -> 39479.555 | AB35: =D35/1000 -> 19426.271 | AC35: =E35/1000 -> -1285.6235 | AD35: =F35/1000 -> -2444.616 | AE35: =G35/1000 -> -4873.5902 | AF35: =H35/1000 -> -2124.3832 | AG35: =I35/1000 -> -2254.7429 | AH35: =J35/1000 -> -2393.1019 | ... AU35: =W35/1000 -> 0
B36: Investing Activities | Z36: Investing Activities
B37: Initial Investment | C37: =-'CAPEX Financing'!C16 -> -37124290 | D37: =-'CAPEX Financing'!D16 -> -13382679 | E37: =-'CAPEX Financing'!E16 -> 0 | F37: =-'CAPEX Financing'!F16 -> 0 | G37: =-'CAPEX Financing'!G16 -> 0 | H37: =-'CAPEX Financing'!H16 -> 0 | I37: =-'CAPEX Financing'!I16 -> 0 | J37: =-'CAPEX Financing'!J16 -> 0 | ... W37: =-'CAPEX Financing'!W16 -> 0 | Z37: Initial Investment | AA37: =C37/1000 -> -37124.29 | AB37: =D37/1000 -> -13382.679 | AC37: =E37/1000 -> 0 | AD37: =F37/1000 -> 0 | AE37: =G37/1000 -> 0 | AF37: =H37/1000 -> 0 | AG37: =I37/1000 -> 0 | AH37: =J37/1000 -> 0 | ... AU37: =W37/1000 -> 0
B38: Reinvestment | D38: =-Depreciation!D49*(1+'Data Input'!$D$38)^(D$21-1) -> 0 | E38: =-Depreciation!E49*(1+'Data Input'!$D$38)^(E$21-1) -> 0 | F38: =-Depreciation!F49*(1+'Data Input'!$D$38)^(F$21-1) -> 0 | G38: =-Depreciation!G49*(1+'Data Input'!$D$38)^(G$21-1) -> 0 | H38: =-Depreciation!H49*(1+'Data Input'!$D$38)^(H$21-1) -> 0 | I38: =-Depreciation!I49*(1+'Data Input'!$D$38)^(I$21-1) -> 0 | J38: =-Depreciation!J49*(1+'Data Input'!$D$38)^(J$21-1) -> 0 | K38: =-Depreciation!K49*(1+'Data Input'!$D$38)^(K$21-1) -> 0 | ... W38: =-Depreciation!W49*(1+'Data Input'!$D$38)^(W$21-1) -> 0 | Z38: Reinvestment | AA38: =C38/1000 -> 0 | AB38: =D38/1000 -> 0 | AC38: =E38/1000 -> 0 | AD38: =F38/1000 -> 0 | AE38: =G38/1000 -> 0 | AF38: =H38/1000 -> 0 | AG38: =I38/1000 -> 0 | AH38: =J38/1000 -> 0 | ... AU38: =W38/1000 -> 0
B39: Cash Flow From Investment | C39: =SUM(C37:C38) -> -37124290 | D39: =SUM(D37:D38) -> -13382679 | E39: =SUM(E37:E38) -> 0 | F39: =SUM(F37:F38) -> 0 | G39: =SUM(G37:G38) -> 0 | H39: =SUM(H37:H38) -> 0 | I39: =SUM(I37:I38) -> 0 | J39: =SUM(J37:J38) -> 0 | ... W39: =SUM(W37:W38) -> 0 | Z39: Cash Flow From Investment | AA39: =C39/1000 -> -37124.29 | AB39: =D39/1000 -> -13382.679 | AC39: =E39/1000 -> 0 | AD39: =F39/1000 -> 0 | AE39: =G39/1000 -> 0 | AF39: =H39/1000 -> 0 | AG39: =I39/1000 -> 0 | AH39: =J39/1000 -> 0 | ... AU39: =W39/1000 -> 0
B40: Net Cash Flow | C40: =SUM(C28+C35+C39) -> 746383.52 | D40: =SUM(D28+D35+D39) -> 269083.04 | E40: =SUM(E28+E35+E39) -> 242.77091 | F40: =SUM(F28+F35+F39) -> 498.09615 | G40: =SUM(G28+G35+G39) -> 852427.41 | H40: =SUM(H28+H35+H39) -> 7953279.3 | I40: =SUM(I28+I35+I39) -> 7555499.5 | J40: =SUM(J28+J35+J39) -> 10970536 | ... W40: =SUM(W28+W35+W39) -> 6565115.7 | Z40: Net Cash Flow | AA40: =C40/1000 -> 746.38352 | AB40: =D40/1000 -> 269.08304 | AC40: =E40/1000 -> 0.24277091 | AD40: =F40/1000 -> 0.49809615 | AE40: =G40/1000 -> 852.42741 | AF40: =H40/1000 -> 7953.2793 | AG40: =I40/1000 -> 7555.4995 | AH40: =J40/1000 -> 10970.536 | ... AU40: =W40/1000 -> 6565.1157
B41: Net Accumulated Cash Flow | C41: =C40 -> 746383.52 | D41: =D40+C41 -> 1015466.6 | E41: =E40+D41 -> 1015709.3 | F41: =F40+E41 -> 1016207.4 | G41: =G40+F41 -> 1868634.8 | H41: =H40+G41 -> 9821914.2 | I41: =I40+H41 -> 17377414 | J41: =J40+I41 -> 28347949 | K41: =K40+J41 -> 40755526 | ... W41: =W40+V41 -> 2.6062733e+08 | Z41: Net Accumulated Cash Flow | AA41: =C41/1000 -> 746.38352 | AB41: =D41/1000 -> 1015.4666 | AC41: =E41/1000 -> 1015.7093 | AD41: =F41/1000 -> 1016.2074 | AE41: =G41/1000 -> 1868.6348 | AF41: =H41/1000 -> 9821.9142 | AG41: =I41/1000 -> 17377.414 | AH41: =J41/1000 -> 28347.949 | ... AU41: =W41/1000 -> 260627.33
B42: Net Cash Flow - DSRA | C42: =C40-C34 -> 36.632162 | D42: =D40-D34 -> 35.085878 | E42: =E40-E34 -> 242.77091 | F42: =F40-F34 -> 498.09615 | G42: =G40-G34 -> 852427.41 | H42: =H40-H34 -> 7953279.3 | I42: =I40-I34 -> 7555499.5 | J42: =J40-J34 -> 10970536 | ... W42: =W40-W34 -> 6565115.7 | Z42: Net Cash Flow | AA42: =C42/1000 -> 0.036632162 | AB42: =D42/1000 -> 0.035085878 | AC42: =E42/1000 -> 0.24277091 | AD42: =F42/1000 -> 0.49809615 | AE42: =G42/1000 -> 852.42741 | AF42: =H42/1000 -> 7953.2793 | AG42: =I42/1000 -> 7555.4995 | AH42: =J42/1000 -> 10970.536 | ... AU42: =W42/1000 -> 6565.1157
B43: Net Accumulated Cash Flow - DSRA | C43: =C42 -> 36.632162 | D43: =D42+C43 -> 71.718041 | E43: =E42+D43 -> 314.48895 | F43: =F42+E43 -> 812.5851 | G43: =G42+F43 -> 853239.99 | H43: =H42+G43 -> 8806519.3 | I43: =I42+H43 -> 16362019 | J43: =J42+I43 -> 27332554 | K43: =K42+J43 -> 39740131 | ... W43: =W42+V43 -> 2.6062733e+08 | Z43: Net Accumulated Cash Flow | AA43: =C43/1000 -> 0.036632162 | AB43: =D43/1000 -> 0.071718041 | AC43: =E43/1000 -> 0.31448895 | AD43: =F43/1000 -> 0.8125851 | AE43: =G43/1000 -> 853.23999 | AF43: =H43/1000 -> 8806.5193 | AG43: =I43/1000 -> 16362.019 | AH43: =J43/1000 -> 27332.554 | ... AU43: =W43/1000 -> 260627.33
...

Sheet CAPEX Financing
B1: Company/Project: | C1: =Cover!$C$10 -> Mr. Amir Artine | D1: =Cover!$C$3 -> Cattle Integration, Baghara, Chad | G1: Last Update: | H1: =Cover!$C$13 -> 45763
B3: Financial Assumptions
B4: Year | C4: CAPEX | D4: DSRA | E4: Fees | F4: IDC | G4: Total Funding | H4: Loan % | I4: Loan | J4: Interest Rate | K4: Term | L4: Grace | M4: Payments per Year | N4: IDC? | O4: DSRA?
B5: =0 -> 0 | C5: =Depreciation!D7 -> 37124290 | D5: =A55 -> 746346.89 | E5: ='Data Input'!$D$26*C5 -> 742485.81 | F5: =A54 -> 1608918.3 | G5: =SUM(C5:F5) -> 40222041 | H5: =1-'Data Input'!$D$22 -> 0.66666667 | I5: =SUM(C5:F5)*H5 -> 26814694 | J5: ='Data Input'!D$19 -> 0.06 | K5: ='Data Input'!D$20 -> 13 | L5: ='Data Input'!D$21 -> 3 | M5: ='Data Input'!D$23 -> 4 | N5: ='Data Input'!$D$24 -> 1 | O5: ='Data Input'!$D$25 -> 1
B6: =1 -> 1 | C6: =Depreciation!E7 -> 13382679 | D6: =A84 -> 269047.96 | E6: ='Data Input'!$D$26*C6 -> 267653.59 | F6: =A83 -> 579993.28 | G6: =SUM(C6:F6) -> 14499374 | H6: =1-'Data Input'!$D$22 -> 0.66666667 | I6: =SUM(C6:F6)*H6 -> 9666249.4 | J6: ='Data Input'!D$19 -> 0.06 | K6: ='Data Input'!D$20 -> 13 | L6: ='Data Input'!D$21 -> 3 | M6: ='Data Input'!D$23 -> 4 | N6: ='Data Input'!$D$24 -> 1 | O6: ='Data Input'!$D$25 -> 1
B7: =2 -> 2 | C7: =Depreciation!F7 -> 0 | D7: =A113 -> 2.584198e-138 | E7: ='Data Input'!$D$26*C7 -> 0 | F7: =A112 -> 5.5708189e-138 | G7: =SUM(C7:F7) -> 8.1550169e-138 | H7: =1-'Data Input'!$D$22 -> 0.66666667 | I7: =SUM(C7:F7)*H7 -> 5.4366779e-138 | J7: ='Data Input'!D$19 -> 0.06 | K7: ='Data Input'!D$20 -> 13 | L7: ='Data Input'!D$21 -> 3 | M7: ='Data Input'!D$23 -> 4 | N7: ='Data Input'!$D$24 -> 1 | O7: ='Data Input'!$D$25 -> 1
B8: =3 -> 3 | C8: =Depreciation!G7 -> 0 | D8: =A142 -> 2.7349672e-138 | E8: ='Data Input'!$D$26*C8 -> 0 | F8: =A141 -> 5.8958359e-138 | G8: =SUM(C8:F8) -> 8.6308031e-138 | H8: =1-'Data Input'!$D$22 -> 0.66666667 | I8: =SUM(C8:F8)*H8 -> 5.7538687e-138 | J8: ='Data Input'!D$19 -> 0.06 | K8: ='Data Input'!D$20 -> 13 | L8: ='Data Input'!D$21 -> 3 | M8: ='Data Input'!D$23 -> 4 | N8: ='Data Input'!$D$24 -> 1 | O8: ='Data Input'!$D$25 -> 1
B9: =4 -> 4 | C9: =Depreciation!H7 -> 0 | D9: =A171 -> 0 | E9: ='Data Input'!$D$26*C9 -> 0 | F9: =A170 -> 0 | G9: =SUM(C9:F9) -> 0 | H9: =1-'Data Input'!$D$22 -> 0.66666667 | I9: =SUM(C9:F9)*H9 -> 0 | J9: ='Data Input'!D$19 -> 0.06 | K9: ='Data Input'!D$20 -> 13 | L9: ='Data Input'!D$21 -> 3 | M9: ='Data Input'!D$23 -> 4 | N9: 0 | O9: 0
B10: Total | C10: =SUM(C5:C9) -> 50506970 | D10: =SUM(D5:D9) -> 1015394.8 | E10: =SUM(E5:E9) -> 1010139.4 | F10: =SUM(F5:F9) -> 2188911.6 | G10: =SUM(G5:G9) -> 54721415 | H10: =IFERROR(I10/G10,0) -> 0.66666667 | I10: =SUM(I5:I9) -> 36480944
I11: =I10/G10 -> 0.66666667
B13: Investment Financing
C14: 0 | D14: 1 | E14: 2 | F14: 3 | G14: 4 | H14: 5 | I14: 6 | J14: 7 | K14: 8 | L14: 9 | M14: 10 | N14: 11 | O14: 12 | P14: 13 | Q14: 14 | R14: 15 | S14: 16 | T14: 17 | U14: 18 | V14: 19 | W14: 20
B15: Investment
C16: =C5 -> 37124290 | D16: =C6 -> 13382679 | E16: =C7 -> 0 | F16: =C8 -> 0 | G16: =C9 -> 0
B17: Financing
B18: Equity | C18: =G5-I5 -> 13407347 | D18: =G6-I6 -> 4833124.7 | E18: =G7-I7 -> 2.718339e-138 | F18: =G8-I8 -> 2.8769344e-138 | G18: =G9-I9 -> 0
B19: Bank Loan | C19: =I5-D5 -> 26068347 | D19: =I6-D6 -> 9397201.4 | E19: =I7-D7 -> 2.8524799e-138 | F19: =I8-D8 -> 3.0189015e-138 | G19: =I9-D9 -> 0
B20: DSRA | C20: =D5 -> 746346.89 | D20: =D6 -> 269047.96 | E20: =D7 -> 2.584198e-138 | F20: =D8 -> 2.7349672e-138 | G20: =D9 -> 0
B21: DSRA Repayment | C21: =-IF(C14=SUM($K$5:$L$5)-1,$D$5,0) -> 0 | D21: =-IF(D14=SUM($K$5:$L$5)-1,$D$5,0)-IF(C14=SUM($K$6:$L$6)-1,$D$6,0) -> 0 | E21: =-IF(E14=SUM($K$5:$L$5)-1,$D$5,0)-IF(D14=SUM($K$6:$L$6)-1,$D$6,0)-IF(C14=SUM($K$7:$L$7)-1,$D$7,0) -> 0 | F21: =-IF(F14=SUM($K$5:$L$5)-1,$D$5,0)-IF(E14=SUM($K$6:$L$6)-1,$D$6,0)-IF(D14=SUM($K$7:$L$7)-1,$D$7,0)-IF(C14=SUM($K$8:$L$8)-1,$D$8,0) -> 0 | G21: =-IF(G14=SUM($K$5:$L$5)-1,$D$5,0)-IF(F14=SUM($K$6:$L$6)-1,$D$6,0)-IF(E14=SUM($K$7:$L$7)-1,$D$7,0)-IF(D14=SUM($K$8:$L$8)-1,$D$8,0)-IF(C14=SUM($K$9:$L$9)-1,$D$9,0) -> 0 | H21: =-IF(H14=SUM($K$5:$L$5)-1,$D$5,0)-IF(G14=SUM($K$6:$L$6)-1,$D$6,0)-IF(F14=SUM($K$7:$L$7)-1,$D$7,0)-IF(E14=SUM($K$8:$L$8)-1,$D$8,0)-IF(D14=SUM($K$9:$L$9)-1,$D$9,0) -> 0 | I21: =-IF(I14=SUM($K$5:$L$5)-1,$D$5,0)-IF(H14=SUM($K$6:$L$6)-1,$D$6,0)-IF(G14=SUM($K$7:$L$7)-1,$D$7,0)-IF(F14=SUM($K$8:$L$8)-1,$D$8,0)-IF(E14=SUM($K$9:$L$9)-1,$D$9,0) -> 0 | J21: =-IF(J14=SUM($K$5:$L$5)-1,$D$5,0)-IF(I14=SUM($K$6:$L$6)-1,$D$6,0)-IF(H14=SUM($K$7:$L$7)-1,$D$7,0)-IF(G14=SUM($K$8:$L$8)-1,$D$8,0)-IF(F14=SUM($K$9:$L$9)-1,$D$9,0) -> 0 | K21: =-IF(K14=SUM($K$5:$L$5)-1,$D$5,0)-IF(J14=SUM($K$6:$L$6)-1,$D$6,0)-IF(I14=SUM($K$7:$L$7)-1,$D$7,0)-IF(H14=SUM($K$8:$L$8)-1,$D$8,0)-IF(G14=SUM($K$9:$L$9)-1,$D$9,0) -> 0 | L21: =-IF(L14=SUM($K$5:$L$5)-1,$D$5,0)-IF(K14=SUM($K$6:$L$6)-1,$D$6,0)-IF(J14=SUM($K$7:$L$7)-1,$D$7,0)-IF(I14=SUM($K$8:$L$8)-1,$D$8,0)-IF(H14=SUM($K$9:$L$9)-1,$D$9,0) -> 0 | M21: =-IF(M14=SUM($K$5:$L$5)-1,$D$5,0)-IF(L14=SUM($K$6:$L$6)-1,$D$6,0)-IF(K14=SUM($K$7:$L$7)-1,$D$7,0)-IF(J14=SUM($K$8:$L$8)-1,$D$8,0)-IF(I14=SUM($K$9:$L$9)-1,$D$9,0) -> 0 | N21: =-IF(N14=SUM($K$5:$L$5)-1,$D$5,0)-IF(M14=SUM($K$6:$L$6)-1,$D$6,0)-IF(L14=SUM($K$7:$L$7)-1,$D$7,0)-IF(K14=SUM($K$8:$L$8)-1,$D$8,0)-IF(J14=SUM($K$9:$L$9)-1,$D$9,0) -> 0 | ... W21: =-IF(W14=SUM($K$5:$L$5)-1,$D$5,0)-IF(V14=SUM($K$6:$L$6)-1,$D$6,0)-IF(U14=SUM($K$7:$L$7)-1,$D$7,0)-IF(T14=SUM($K$8:$L$8)-1,$D$8,0)-IF(S14=SUM($K$9:$L$9)-1,$D$9,0) -> 0
B22: Interest & Principal by Payment
B23: Interest Payment | C23: =C43 -> 1608881.6 | D23: =SUM(D43,C72) -> 2188856.6 | E23: =SUM(E43,D72,C101) -> 2188856.6 | F23: =SUM(F43,E72,D101,C130) -> 2157575.9 | G23: =SUM(G43,F72,E101,D130,C159) -> 2059917.1 | H23: =SUM(H43,G72,F101,E130,D159) -> 1937094.3 | I23: =SUM(I43,H72,G101,F130,E159) -> 1806734.6 | J23: =SUM(J43,I72,H101,G130,F159) -> 1668375.5 | K23: =SUM(K43,J72,I101,H130,G159) -> 1521526.3 | L23: =SUM(L43,K72,J101,I130,H159) -> 1365665.9 | M23: =SUM(M43,L72,K101,J130,I159) -> 1200241.3 | N23: =SUM(N43,M72,L101,K130,J159) -> 306229.71 | ... W23: =SUM(W43,V72,U101,T130,S159) -> 0
B24: Principal Payment | C24: =C44 -> 0 | D24: =SUM(D44,C73) -> 0 | E24: =SUM(E44,D73,C102) -> 0 | F24: =SUM(F44,E73,D102,C131) -> 1407718.6 | G24: =SUM(G44,F73,E102,D131,C160) -> 2001560.3 | H24: =SUM(H44,G73,F102,E131,D160) -> 2124383.2 | I24: =SUM(I44,H73,G102,F131,E160) -> 2254742.9 | J24: =SUM(J44,I73,H102,G131,F160) -> 2393101.9 | K24: =SUM(K44,J73,I102,H131,G160) -> 2539951.1 | L24: =SUM(L44,K73,J102,I131,H160) -> 2695811.5 | M24: =SUM(M44,L73,K102,J131,I160) -> 2861236.1 | N24: =SUM(N44,M73,L102,K131,J160) -> 769928.14 | ... W24: =SUM(W44,V73,U102,T131,S160) -> 0
B25: Current and Long-Term Liabilities
B26: Current Liabilities | C26: =SUM(C58) -> 0 | D26: =SUM(D58,C87) -> 0 | E26: =SUM(E58,D87,C116) -> 1407718.6 | F26: =SUM(F58,E87,D116,C145) -> 2001560.3 | G26: =SUM(G58,F87,E116,D145,C174) -> 2124383.2 | H26: =SUM(H58,G87,F116,E145,D174) -> 2254742.9 | I26: =SUM(I58,H87,G116,F145,E174) -> 2393101.9 | J26: =SUM(J58,I87,H116,G145,F174) -> 2539951.1 | K26: =SUM(K58,J87,I116,H145,G174) -> 2695811.5 | L26: =SUM(L58,K87,J116,I145,H174) -> 2861236.1 | M26: =SUM(M58,L87,K116,J145,I174) -> 769928.14 | N26: =SUM(N58,M87,L116,K145,J174) -> 8.6484311e-139 | ... W26: =SUM(W58,V87,U116,T145,S174) -> 0
B27: Long-Term Liabilities | C27: =SUM(C59) -> 26814694 | D27: =SUM(D59,C88) -> 36480944 | E27: =SUM(E59,D88,C117) -> 35073225 | F27: =SUM(F59,E88,D117,C146) -> 33071665 | G27: =SUM(G59,F88,E117,D146,C175) -> 30947281 | H27: =SUM(H59,G88,F117,E146,D175) -> 28692539 | I27: =SUM(I59,H88,G117,F146,E175) -> 26299437 | J27: =SUM(J59,I88,H117,G146,F175) -> 23759486 | K27: =SUM(K59,J88,I117,H146,G175) -> 21063674 | L27: =SUM(L59,K88,J117,I146,H175) -> 18202438 | M27: =SUM(M59,L88,K117,J146,I175) -> 17432510 | N27: =SUM(N59,M88,L117,K146,J175) -> 17432510 | ... W27: =SUM(W59,V88,U117,T146,S175) -> 17432510
B33: Year 0 Investment
B34: Interest & Principal by Payment
B35: Interest Pmt. | C35: 1 | D35: 2 | E35: 3 | F35: 4 | G35: 5 | H35: 6 | I35: 7 | J35: 8 | K35: 9 | L35: 10 | M35: 11 | N35: 12 | O35: 13 | P35: 14 | Q35: 15 | R35: 16 | S35: 17 | T35: 18 | U35: 19 | V35: 20 | W35: 21 | X35: 22 | Y35: 23 | Z35: 24 | AA35: 25 | AB35: 26 | AC35: 27 | AD35: 28 | AE35: 29 | AF35: 30 | AG35: 31 | AH35: 32 | AI35: 33 | AJ35: 34 | AK35: 35 | AL35: 36 | AM35: 37 | AN35: 38 | AO35: 39 | AP35: 40
B36: Principal Pmt. | C36: =MAX(C35-($L$5-1)*$M$5,0) -> 0 | D36: =MAX(D35-($L$5-1)*$M$5,0) -> 0 | E36: =MAX(E35-($L$5-1)*$M$5,0) -> 0 | F36: =MAX(F35-($L$5-1)*$M$5,0) -> 0 | G36: =MAX(G35-($L$5-1)*$M$5,0) -> 0 | H36: =MAX(H35-($L$5-1)*$M$5,0) -> 0 | I36: =MAX(I35-($L$5-1)*$M$5,0) -> 0 | J36: =MAX(J35-($L$5-1)*$M$5,0) -> 0 | ... AP36: =MAX(AP35-($L$5-1)*$M$5,0) -> 32
B37: Year | C37: =ROUNDUP(C35/$M$5,0) -> 1 | D37: =ROUNDUP(D35/$M$5,0) -> 1 | E37: =ROUNDUP(E35/$M$5,0) -> 1 | F37: =ROUNDUP(F35/$M$5,0) -> 1 | G37: =ROUNDUP(G35/$M$5,0) -> 2 | H37: =ROUNDUP(H35/$M$5,0) -> 2 | I37: =ROUNDUP(I35/$M$5,0) -> 2 | J37: =ROUNDUP(J35/$M$5,0) -> 2 | ... AP37: =ROUNDUP(AP35/$M$5,0) -> 10
B38: Interest | C38: =-IFERROR(IPMT($J$5/$M$5,MAX(C36,1),$K$5*$M$5,$I$5),0) -> 402220.41 | D38: =-IFERROR(IPMT($J$5/$M$5,MAX(D36,1),$K$5*$M$5,$I$5),0) -> 402220.41 | E38: =-IFERROR(IPMT($J$5/$M$5,MAX(E36,1),$K$5*$M$5,$I$5),0) -> 402220.41 | F38: =-IFERROR(IPMT($J$5/$M$5,MAX(F36,1),$K$5*$M$5,$I$5),0) -> 402220.41 | G38: =-IFERROR(IPMT($J$5/$M$5,MAX(G36,1),$K$5*$M$5,$I$5),0) -> 402220.41 | H38: =-IFERROR(IPMT($J$5/$M$5,MAX(H36,1),$K$5*$M$5,$I$5),0) -> 402220.41 | I38: =-IFERROR(IPMT($J$5/$M$5,MAX(I36,1),$K$5*$M$5,$I$5),0) -> 402220.41 | J38: =-IFERROR(IPMT($J$5/$M$5,MAX(J36,1),$K$5*$M$5,$I$5),0) -> 402220.41 | ... AP38: =-IFERROR(IPMT($J$5/$M$5,MAX(AP36,1),$K$5*$M$5,$I$5),0) -> 200391.11
B39: Principal | C39: =-IFERROR(PPMT($J$5/$M$5,C36,$K$5*$M$5,$I$5),0) -> 0 | D39: =-IFERROR(PPMT($J$5/$M$5,D36,$K$5*$M$5,$I$5),0) -> 0 | E39: =-IFERROR(PPMT($J$5/$M$5,E36,$K$5*$M$5,$I$5),0) -> 0 | F39: =-IFERROR(PPMT($J$5/$M$5,F36,$K$5*$M$5,$I$5),0) -> 0 | G39: =-IFERROR(PPMT($J$5/$M$5,G36,$K$5*$M$5,$I$5),0) -> 0 | H39: =-IFERROR(PPMT($J$5/$M$5,H36,$K$5*$M$5,$I$5),0) -> 0 | I39: =-IFERROR(PPMT($J$5/$M$5,I36,$K$5*$M$5,$I$5),0) -> 0 | J39: =-IFERROR(PPMT($J$5/$M$5,J36,$K$5*$M$5,$I$5),0) -> 0 | ... AP39: =-IFERROR(PPMT($J$5/$M$5,AP36,$K$5*$M$5,$I$5),0) -> 545938.79
B40: Total | C40: =SUM(C38:C39) -> 402220.41 | D40: =SUM(D38:D39) -> 402220.41 | E40: =SUM(E38:E39) -> 402220.41 | F40: =SUM(F38:F39) -> 402220.41 | G40: =SUM(G38:G39) -> 402220.41 | H40: =SUM(H38:H39) -> 402220.41 | I40: =SUM(I38:I39) -> 402220.41 | J40: =SUM(J38:J39) -> 402220.41 | ... AP40: =SUM(AP38:AP39) -> 746329.9
B41: Interest & Principal by Year
C42: 0 | D42: 1 | E42: 2 | F42: 3 | G42: 4 | H42: 5 | I42: 6 | J42: 7 | K42: 8 | L42: 9 | M42: 10 | N42: 11 | O42: 12 | P42: 13 | Q42: 14 | R42: 15 | S42: 16 | T42: 17 | U42: 18 | V42: 19 | W42: 20
B43: Interest | C43: =O51 -> 1608881.6 | D43: =SUMIF($C$37:$AP$37,D$42,$C38:$AP38) -> 1608881.6 | E43: =SUMIF($C$37:$AP$37,E$42,$C38:$AP38) -> 1608881.6 | F43: =SUMIF($C$37:$AP$37,F$42,$C38:$AP38) -> 1577600.9 | G43: =SUMIF($C$37:$AP$37,G$42,$C38:$AP38) -> 1491218.3 | H43: =SUMIF($C$37:$AP$37,H$42,$C38:$AP38) -> 1399535 | I43: =SUMIF($C$37:$AP$37,I$42,$C38:$AP38) -> 1302225.6 | J43: =SUMIF($C$37:$AP$37,J$42,$C38:$AP38) -> 1198945 | K43: =SUMIF($C$37:$AP$37,K$42,$C38:$AP38) -> 1089326.7 | ... W43: =SUMIF($C$37:$AP$37,W$42,$C38:$AP38) -> 0
B44: Principal | D44: =SUMIF($C$37:$AP$37,D$42,$C39:$AP39) -> 0 | E44: =SUMIF($C$37:$AP$37,E$42,$C39:$AP39) -> 0 | F44: =SUMIF($C$37:$AP$37,F$42,$C39:$AP39) -> 1407718.6 | G44: =SUMIF($C$37:$AP$37,G$42,$C39:$AP39) -> 1494101.3 | H44: =SUMIF($C$37:$AP$37,H$42,$C39:$AP39) -> 1585784.6 | I44: =SUMIF($C$37:$AP$37,I$42,$C39:$AP39) -> 1683094 | J44: =SUMIF($C$37:$AP$37,J$42,$C39:$AP39) -> 1786374.6 | K44: =SUMIF($C$37:$AP$37,K$42,$C39:$AP39) -> 1895992.9 | ... W44: =SUMIF($C$37:$AP$37,W$42,$C39:$AP39) -> 0
B45: Total | C45: =SUM(C43:C44) -> 1608881.6 | D45: =SUM(D43:D44) -> 1608881.6 | E45: =SUM(E43:E44) -> 1608881.6 | F45: =SUM(F43:F44) -> 2985319.6 | G45: =SUM(G43:G44) -> 2985319.6 | H45: =SUM(H43:H44) -> 2985319.6 | I45: =SUM(I43:I44) -> 2985319.6 | J45: =SUM(J43:J44) -> 2985319.6 | ... W45: =SUM(W43:W44) -> 0
B46: Interest During Construction (IDC)
C47: 1 | D47: 2 | E47: 3 | F47: 4 | G47: 5 | H47: 6 | I47: 7 | J47: 8 | K47: 9 | L47: 10 | M47: 11 | N47: 12 | O47: Total
...

Sheet WC Financing
B1: Company/Project: | C1: =Cover!$C$10 -> Mr. Amir Artine | D1: =Cover!$C$3 -> Cattle Integration, Baghara, Chad | G1: Last Update: | H1: =Cover!$C$13 -> 45763
B3: Financing Assumptions
B4: Year | C4: Working Capital | D4: Loan % | E4: Loan | F4: Interest Rate | G4: Term | H4: Grace*
B5: =1 -> 1 | C5: =Fin.Statements!D99*'Data Input'!$D$28 -> 5194550.7 | D5: =1-'Data Input'!$D$32 -> 1 | E5: =C5*D5 -> 5194550.7 | F5: ='Data Input'!D$29 -> 0.1 | G5: ='Data Input'!D$30 -> 1 | H5: ='Data Input'!D$31 -> 0
B6: =2 -> 2 | C6: =Fin.Statements!E99*'Data Input'!$D$28 -> 3908927.2 | D6: =1-'Data Input'!$D$32 -> 1 | E6: =C6*D6 -> 3908927.2 | F6: ='Data Input'!D$29 -> 0.1 | G6: ='Data Input'!D$30 -> 1 | H6: ='Data Input'!D$31 -> 0
B7: =3 -> 3 | C7: =Fin.Statements!F99*'Data Input'!$D$28 -> 2872029.9 | D7: =1-'Data Input'!$D$32 -> 1 | E7: =C7*D7 -> 2872029.9 | F7: ='Data Input'!D$29 -> 0.1 | G7: ='Data Input'!D$30 -> 1 | H7: ='Data Input'!D$31 -> 0
B8: =4 -> 4 | C8: =Fin.Statements!G99*'Data Input'!$D$28 -> 0 | D8: =1-'Data Input'!$D$32 -> 1 | E8: =C8*D8 -> 0 | F8: ='Data Input'!D$29 -> 0.1 | G8: ='Data Input'!D$30 -> 1 | H8: ='Data Input'!D$31 -> 0
B9: =5 -> 5 | C9: =Fin.Statements!H99*'Data Input'!$D$28 -> 0 | D9: =1-'Data Input'!$D$32 -> 1 | E9: =C9*D9 -> 0 | F9: ='Data Input'!D$29 -> 0.1 | G9: ='Data Input'!D$30 -> 1 | H9: ='Data Input'!D$31 -> 0
B10: 6 | C10: =Fin.Statements!I99*'Data Input'!$D$28 -> 0 | D10: =1-'Data Input'!$D$32 -> 1 | E10: =C10*D10 -> 0 | F10: ='Data Input'!D$29 -> 0.1 | G10: ='Data Input'!D$30 -> 1 | H10: ='Data Input'!D$31 -> 0
B11: 7 | C11: =Fin.Statements!J99*'Data Input'!$D$28 -> 0 | D11: =1-'Data Input'!$D$32 -> 1 | E11: =C11*D11 -> 0 | F11: ='Data Input'!D$29 -> 0.1 | G11: ='Data Input'!D$30 -> 1 | H11: ='Data Input'!D$31 -> 0
B12: 8 | C12: =Fin.Statements!K99*'Data Input'!$D$28 -> 0 | D12: =1-'Data Input'!$D$32 -> 1 | E12: =C12*D12 -> 0 | F12: ='Data Input'!D$29 -> 0.1 | G12: ='Data Input'!D$30 -> 1 | H12: ='Data Input'!D$31 -> 0
B13: 9 | C13: =Fin.Statements!L99*'Data Input'!$D$28 -> 0 | D13: =1-'Data Input'!$D$32 -> 1 | E13: =C13*D13 -> 0 | F13: ='Data Input'!D$29 -> 0.1 | G13: ='Data Input'!D$30 -> 1 | H13: ='Data Input'!D$31 -> 0
B14: 10 | C14: =Fin.Statements!M99*'Data Input'!$D$28 -> 0 | D14: =1-'Data Input'!$D$32 -> 1 | E14: =C14*D14 -> 0 | F14: ='Data Input'!D$29 -> 0.1 | G14: ='Data Input'!D$30 -> 1 | H14: ='Data Input'!D$31 -> 0
B15: Total | C15: =SUM(C5:C9) -> 11975508 | D15: =IFERROR(E15/C15,0) -> 1 | E15: =SUM(E5:E9) -> 11975508
H16: * Including Year 0
B18: Working Capital Financing
C19: 0 | D19: 1 | E19: 2 | F19: 3 | G19: 4 | H19: 5 | I19: 6 | J19: 7 | K19: 8 | L19: 9 | M19: 10 | N19: 11 | O19: 12 | P19: 13 | Q19: 14 | R19: 15 | S19: 16 | T19: 17 | U19: 18 | V19: 19 | W19: 20
B20: Working Capital
D21: =C5 -> 5194550.7 | E21: =C6 -> 3908927.2 | F21: =C7 -> 2872029.9 | G21: =C8 -> 0 | H21: =C9 -> 0 | I21: =C10 -> 0 | J21: =C11 -> 0 | K21: =C12 -> 0 | L21: =C13 -> 0 | M21: =C14 -> 0
B22: Financing
B23: Equity | D23: =C5-E5 -> 0 | E23: =C6-E6 -> 0 | F23: =C7-E7 -> 0 | G23: =C8-E8 -> 0 | H23: =C9-E9 -> 0 | I23: =C10-E10 -> 0 | J23: =C11-E11 -> 0 | K23: =C12-E12 -> 0 | L23: =C13-E13 -> 0 | M23: =C14-E14 -> 0
B24: Bank Loan | D24: =E5 -> 5194550.7 | E24: =E6 -> 3908927.2 | F24: =E7 -> 2872029.9 | G24: =E8 -> 0 | H24: =E9 -> 0 | I24: =E10 -> 0 | J24: =E11 -> 0 | K24: =E12 -> 0 | L24: =E13 -> 0 | M24: =C14 -> 0
B27: Interest & Principal by Payment
B28: Interest Payment | D28: =SUM(C47) -> 519455.07 | E28: =SUM(D47,C64) -> 910347.79 | F28: =SUM(E47,D64,C81) -> 678095.7 | G28: =SUM(F47,E64,D81,C98) -> 287202.99 | H28: =SUM(G47,F64,E81,D98,C115) -> 0 | I28: =SUM(H47,G64,F81,E98,D115,C132) -> 0 | J28: =SUM(I47,H64,G81,F98,E115,D132,C149) -> 0 | K28: =SUM(J47,I64,H81,G98,F115,E132,D149,C166) -> 0 | L28: =SUM(K47,J64,I81,H98,G115,F132,E149,D166,C183) -> 0 | M28: =SUM(L47,K64,J81,I98,H115,G132,F149,E166,D183,C200) -> 0 | N28: =SUM(M47,L64,K81,J98,I115,H132,G149,F166,E183,D200) -> 0 | O28: =SUM(N47,M64,L81,K98,J115,I132,H149,G166,F183,E200) -> 0 | P28: =SUM(O47,N64,M81,L98,K115,J132,I149,H166,G183,F200) -> 0 | Q28: =SUM(P47,O64,N81,M98,L115,K132,J149,I166,H183,G200) -> 0 | R28: =SUM(Q47,P64,O81,N98,M115,L132,K149,J166,I183,H200) -> 0 | S28: =SUM(R47,Q64,P81,O98,N115,M132,L149,K166,J183,I200) -> 0 | T28: =SUM(S47,R64,Q81,P98,O115,N132,M149,L166,K183,J200) -> 0 | ... W28: =SUM(V47,U64,T81,S98,R115,Q132,P149,O166,N183,M200) -> 0
